Workbook
Name holidays: #REF!
Name holidays: 화!$J$1:$J$5
Name holidays: 수!$J$1:$J$5
Name holidays: 목!$J$1:$J$5
Name holidays: 금!$J$1:$J$5

Sheet 2단지 농구교실(1~2학년화16시배준태)
A1: 농구교실 1~2학년 화 16시
J2: 강사 : 배준태
A3: NO | B3: 성명 | C3: 동 | D3: 호수 | E3: 연락처 | F3: =금!B1
F4: =화!B11 | G4: =화!C11 | H4: =화!D11 | I4: =화!E11
A5: 1
A6: 2
A7: 3
A8: 4
A9: 5
A10: 6
A11: 7
A12: 8
A13: 9
A14: 10
A15: 11
A16: 12
... A33: 29
A34: NO | B34: 성명 | C34: 동 | D34: 호수 | E34: 연락처 | F34: =F3
F35: =F4 | G35: =G4 | H35: =H4 | I35: =I4
A36: 31
A37: 30
A38: 31
A39: 32
A40: 33
A41: 34
A42: 35
A43: 36
A44: 37
A45: 38
A46: 39
A47: 40
... A66: 59

Sheet 2단지 농구교실(3~4학년화17시배준태)
A1: 농구교실 3~4학년 화 17시
J2: 강사 : 배준태
A3: NO | B3: 성명 | C3: 동 | D3: 호수 | E3: 연락처 | F3: =금!B1
F4: =화!B11 | G4: =화!C11 | H4: =화!D11 | I4: =화!E11
A5: 1
A6: 2
A7: 3
A8: 4
A9: 5
A10: 6
A11: 7
A12: 8
A13: 9
A14: 10
A15: 11
A16: 12
... A33: 29
A34: =A1
A35: NO | B35: 성명 | C35: 동 | D35: 호수 | E35: 연락처 | F35: =F3
F36: =F4 | G36: =G4 | H36: =H4 | I36: =I4
A37: 30
A38: 31
A39: 32
A40: 33
A41: 34
A42: 35
A43: 36
A44: 37
A45: 38
A46: 39
A47: 40
A48: 41
... A66: 59

Sheet 2단지 농구교실(5~6학년화18시배준태)
A1: 농구교실 5~6학년 화 18시
J2: 강사 : 배준태
A3: NO | B3: 성명 | C3: 동 | D3: 호수 | E3: 연락처 | F3: =금!B1
F4: =화!B11 | G4: =화!C11 | H4: =화!D11 | I4: =화!E11
A5: 1
A6: 2
A7: 3
A8: 4
A9: 5
A10: 6
A11: 7
A12: 8
A13: 9
A14: 10
A15: 11
A16: 12
... A33: 29
A34: =A1
A35: NO | B35: 성명 | C35: 동 | D35: 호수 | E35: 연락처 | F35: =F3
F36: =F4 | G36: =G4 | H36: =H4 | I36: =I4
A37: 30
A38: 31
A39: 32
A40: 33
A41: 34
A42: 35
A43: 36
A44: 37
A45: 38
A46: 39
A47: 40
A48: 41
... A66: 59

Sheet 2단지 농구교실(중학생화19시배준태)
A1: 농구교실 중1~3 화 19시
J2: 강사 : 배준태
A3: NO | B3: 성명 | C3: 동 | D3: 호수 | E3: 연락처 | F3: =금!B1
F4: =화!B11 | G4: =화!C11 | H4: =화!D11 | I4: =화!E11
A5: 1
A6: 2
A7: 3
A8: 4
A9: 5
A10: 6
A11: 7
A12: 8
A13: 9
A14: 10
A15: 11
A16: 12
... A33: 29
A34: NO | B34: 성명 | C34: 동 | D34: 호수 | E34: 연락처 | F34: =F3
F35: =F4 | G35: =G4 | H35: =H4 | I35: =I4
A36: 31
A37: 30
A38: 31
A39: 32
A40: 33
A41: 34
A42: 35
A43: 36
A44: 37
A45: 38
A46: 39
A47: 40
... A66: 59

Sheet 2단지 농구교실(1~2학년수16시배준태)
A1: 농구교실 1~2학년 수 16시
J2: 강사 : 배준태
A3: NO | B3: 성명 | C3: 동 | D3: 호수 | E3: 연락처 | F3: =금!B1
F4: =수!B11 | G4: =수!C11 | H4: =수!D11 | I4: =수!E11
A5: 1
A6: 2
A7: 3
A8: 4
A9: 5
A10: 6
A11: 7
A12: 8
A13: 9
A14: 10
A15: 11
A16: 12
... A33: 29
A34: 축구교실 1~2학년D 수17시
A35: NO | B35: 성명 | C35: 동 | D35: 호수 | E35: 연락처 | F35: =F3
F36: =F4 | G36: =G4 | H36: =H4 | I36: =I4
A37: 30
A38: 31
A39: 32
A40: 33
A41: 34
A42: 35
A43: 36
A44: 37
A45: 38
A46: 39
A47: 40
A48: 41
... A66: 59

Sheet 2단지 농구교실(3~4학년수17시배준태)
A1: 농구교실 3~4학년 수 17시
J2: 강사 : 배준태
A3: NO | B3: 성명 | C3: 동 | D3: 호수 | E3: 연락처 | F3: =금!B1
F4: =수!B11 | G4: =수!C11 | H4: =수!D11 | I4: =수!E11
A5: 1
A6: 2
A7: 3
A8: 4
A9: 5
A10: 6
A11: 7
A12: 8
A13: 9
A14: 10
A15: 11
A16: 12
... A33: 29
A34: 축구교실 1~2학년D 수17시
A35: NO | B35: 성명 | C35: 동 | D35: 호수 | E35: 연락처 | F35: =F3
F36: =F4 | G36: =G4 | H36: =H4 | I36: =I4
A37: 30
A38: 31
A39: 32
A40: 33
A41: 34
A42: 35
A43: 36
A44: 37
A45: 38
A46: 39
A47: 40
A48: 41
... A66: 59

Sheet 2단지 농구교실(5~6학년수18시배준태)
A1: 농구교실 5~6학년 수 18시
J2: 강사 : 배준태
A3: NO | B3: 성명 | C3: 동 | D3: 호수 | E3: 연락처 | F3: =금!B1
F4: =수!B11 | G4: =수!C11 | H4: =수!D11 | I4: =수!E11
A5: 1
A6: 2
A7: 3
A8: 4
A9: 5
A10: 6
A11: 7
A12: 8
A13: 9
A14: 10
A15: 11
A16: 12
... A33: 29
A34: =A1
A35: NO | B35: 성명 | C35: 동 | D35: 호수 | E35: 연락처 | F35: =F3
F36: =F4 | G36: =G4 | H36: =H4 | I36: =I4
A37: 30
A38: 31
A39: 32
A40: 33
A41: 34
A42: 35
A43: 36
A44: 37
A45: 38
A46: 39
A47: 40
A48: 41
... A66: 59

Sheet 2단지 농구교실(중학생수19시배준태)
A1: 농구교실 중1~3 수 19시
J2: 강사 : 배준태
A3: NO | B3: 성명 | C3: 동 | D3: 호수 | E3: 연락처 | F3: =금!B1
F4: =수!B11 | G4: =수!C11 | H4: =수!D11 | I4: =수!E11
A5: 1
A6: 2
A7: 3
A8: 4
A9: 5
A10: 6
A11: 7
A12: 8
A13: 9
A14: 10
A15: 11
A16: 12
... A33: 29
A34: 축구교실 1~2학년D 수17시
A35: NO | B35: 성명 | C35: 동 | D35: 호수 | E35: 연락처 | F35: =F3
F36: =F4 | G36: =G4 | H36: =H4 | I36: =I4
A37: 30
A38: 31
A39: 32
A40: 33
A41: 34
A42: 35
A43: 36
A44: 37
A45: 38
A46: 39
A47: 40
A48: 41
... A66: 59

Sheet 2단지 농구교실(1~2학년목16시배준태)
A1: 농구교실 1~2학년 목 16시
J2: 강사 : 배준태
A3: NO | B3: 성명 | C3: 동 | D3: 호수 | E3: 연락처 | F3: =금!B1
F4: =목!B11 | G4: =목!C11 | H4: =목!D11 | I4: =목!E11
A5: 1
A6: 2
A7: 3
A8: 4
A9: 5
A10: 6
A11: 7
A12: 8
A13: 9
A14: 10
A15: 11
A16: 12
... A33: 29
A34: 축구교실 1~2학년D 수17시
A35: NO | B35: 성명 | C35: 동 | D35: 호수 | E35: 연락처 | F35: =F3
F36: =F4 | G36: =G4 | H36: =H4 | I36: =I4
A37: 30
A38: 31
A39: 32
A40: 33
A41: 34
A42: 35
A43: 36
A44: 37
A45: 38
A46: 39
A47: 40
A48: 41
... A66: 59

Sheet 2단지 농구교실(3~4학년목17시배준태)
A1: 농구교실 3~4학년 목 17시
J2: 강사 : 배준태
A3: NO | B3: 성명 | C3: 동 | D3: 호수 | E3: 연락처 | F3: =금!B1
F4: =목!B11 | G4: =목!C11 | H4: =목!D11 | I4: =목!E11
A5: 1
A6: 2
A7: 3
A8: 4
A9: 5
A10: 6
A11: 7
A12: 8
A13: 9
A14: 10
A15: 11
A16: 12
... A33: 29
A34: 축구교실 1~2학년D 수17시
A35: NO | B35: 성명 | C35: 동 | D35: 호수 | E35: 연락처 | F35: =F3
F36: =F4 | G36: =G4 | H36: =H4 | I36: =I4
A37: 30
A38: 31
A39: 32
A40: 33
A41: 34
A42: 35
A43: 36
A44: 37
A45: 38
A46: 39
A47: 40
A48: 41
... A66: 59

Sheet 2단지 농구교실(5~6학년목18시배준태)
A1: 농구교실 5~6학년 목 18시
J2: 강사 : 배준태
A3: NO | B3: 성명 | C3: 동 | D3: 호수 | E3: 연락처 | F3: =금!B1
F4: =목!B11 | G4: =목!C11 | H4: =목!D11 | I4: =목!E11
A5: 1
A6: 2
A7: 3
A8: 4
A9: 5
A10: 6
A11: 7
A12: 8
A13: 9
A14: 10
A15: 11
A16: 12
... A33: 29
A34: 축구교실 1~2학년D 수17시
A35: NO | B35: 성명 | C35: 동 | D35: 호수 | E35: 연락처 | F35: =F3
F36: =F4 | G36: =G4 | H36: =H4 | I36: =I4
A37: 30
A38: 31
A39: 32
A40: 33
A41: 34
A42: 35
A43: 36
A44: 37
A45: 38
A46: 39
A47: 40
A48: 41
... A66: 59

Sheet 2단지 농구교실(중학생목19시배준태)
A1: 농구교실 중1~3 목 19시
J2: 강사 : 배준태
A3: NO | B3: 성명 | C3: 동 | D3: 호수 | E3: 연락처 | F3: =금!B1
F4: =목!B11 | G4: =목!C11 | H4: =목!D11 | I4: =목!E11
A5: 1
A6: 2
A7: 3
A8: 4
A9: 5
A10: 6
A11: 7
A12: 8
A13: 9
A14: 10
A15: 11
A16: 12
... A33: 29
A34: 축구교실 1~2학년D 수17시
A35: NO | B35: 성명 | C35: 동 | D35: 호수 | E35: 연락처 | F35: =F3
F36: =F4 | G36: =G4 | H36: =H4 | I36: =I4
A37: 30
A38: 31
A39: 32
A40: 33
A41: 34
A42: 35
A43: 36
A44: 37
A45: 38
A46: 39
A47: 40
A48: 41
... A66: 59

Sheet 2단지 농구교실(1~2학년금16시배준태)
A1: 농구교실 1~2학년 금 16시
J2: 강사 : 배준태
A3: NO | B3: 성명 | C3: 동 | D3: 호수 | E3: 연락처 | F3: =금!B1
F4: =금!B11 | G4: =금!C11 | H4: =금!D11 | I4: =금!E11
A5: 1
A6: 2
A7: 3
A8: 4
A9: 5
A10: 6
A11: 7
A12: 8
A13: 9
A14: 10
A15: 11
A16: 12
... A33: 29
A34: 축구교실 1~2학년D 수17시
A35: NO | B35: 성명 | C35: 동 | D35: 호수 | E35: 연락처 | F35: =F3
F36: =F4 | G36: =G4 | H36: =H4 | I36: =I4
A37: 30
A38: 31
A39: 32
A40: 33
A41: 34
A42: 35
A43: 36
A44: 37
A45: 38
A46: 39
A47: 40
A48: 41
... A66: 59

Sheet 2단지 농구교실(3~4학년금17시배준태)
A1: 농구교실 3~4학년 금 17시
J2: 강사 : 배준태
A3: NO | B3: 성명 | C3: 동 | D3: 호수 | E3: 연락처 | F3: =금!B1
F4: =금!B11 | G4: =금!C11 | H4: =금!D11 | I4: =금!E11
A5: 1
A6: 2
A7: 3
A8: 4
A9: 5
A10: 6
A11: 7
A12: 8
A13: 9
A14: 10
A15: 11
A16: 12
... A33: 29
A34: =A1
A35: NO | B35: 성명 | C35: 동 | D35: 호수 | E35: 연락처 | F35: =F3
F36: =F4 | G36: =G4 | H36: =H4 | I36: =I4
A37: 30
A38: 31
A39: 32
A40: 33
A41: 34
A42: 35
A43: 36
A44: 37
A45: 38
A46: 39
A47: 40
A48: 41
... A66: 59

Sheet 2단지 농구교실(5~6학년금18시배준태)
A1: 농구교실 5~6학년 금 18시
J2: 강사 : 배준태
A3: NO | B3: 성명 | C3: 동 | D3: 호수 | E3: 연락처 | F3: =금!B1
F4: =금!B11 | G4: =금!C11 | H4: =금!D11 | I4: =금!E11
A5: 1
A6: 2
A7: 3
A8: 4
A9: 5
A10: 6
A11: 7
A12: 8
A13: 9
A14: 10
A15: 11
A16: 12
... A33: 29
A34: 축구교실 1~2학년D 수17시
A35: NO | B35: 성명 | C35: 동 | D35: 호수 | E35: 연락처 | F35: =F3
F36: =F4 | G36: =G4 | H36: =H4 | I36: =I4
A37: 30
A38: 31
A39: 32
A40: 33
A41: 34
A42: 35
A43: 36
A44: 37
A45: 38
A46: 39
A47: 40
A48: 41
... A66: 59

Sheet 2단지 농구교실(중학생금19시배준태)
A1: 농구교실 중1~3 금 19시
J2: 강사 : 배준태
A3: NO | B3: 성명 | C3: 동 | D3: 호수 | E3: 연락처 | F3: =금!B1
F4: =금!B11 | G4: =금!C11 | H4: =금!D11 | I4: =금!E11
A5: 1
A6: 2
A7: 3
A8: 4
A9: 5
A10: 6
A11: 7
A12: 8
A13: 9
A14: 10
A15: 11
A16: 12
... A33: 29
A34: 축구교실 1~2학년D 수17시
A35: NO | B35: 성명 | C35: 동 | D35: 호수 | E35: 연락처 | F35: =F3
F36: =F4 | G36: =G4 | H36: =H4 | I36: =I4
A37: 30
A38: 31
A39: 32
A40: 33
A41: 34
A42: 35
A43: 36
A44: 37
A45: 38
A46: 39
A47: 40
A48: 41
... A66: 59

Sheet 화
A1: 2026 | B1: 5월 | K1: 공휴일
A2: 화 | B2: 일 | C2: 월 | D2: 화 | E2: 수 | F2: 목 | G2: 금 | H2: 토 | K2: 1
B3: =IF(MONTH(DATE($A$1,IFERROR(VALUE($B$1),VALUE(LEFT($B$1,FIND("월",$B$1)-1))),1)-WEEKDAY(DATE($A$1,IFERROR(VALUE($B$1),VALUE(LEFT($B$1,FIND("월",$B$1)-1))),1),1)+1+7*(ROW()-ROW($B$3))+(COLUMN()-COLUMN($B$3)))=IFERROR(VALUE($B$1),VALUE(LEFT($B$1,FIND("월",$B$1)-1))),IF(COUNTIF($K$1:$K$10,DAY(DATE($A$1,IFERROR(VALUE($B$1),VALUE(LEFT($B$1,FIND("월",$B$1)-1))),1)-WEEKDAY(DATE($A$1,IFERROR(VALUE($B$1),VALUE(LEFT($B$1,FIND("월",$B$1)-1))),1),1)+1+7*(ROW()-ROW($B$3))+(COLUMN()-COLUMN($B$3))))=0,DAY(DATE($A$1,IFERROR(VALUE($B$1),VALUE(LEFT($B$1,FIND("월",$B$1)-1))),1)-WEEKDAY(DATE($A$1,IFERROR(VALUE($B$1),VALUE(LEFT($B$1,FIND("월",$B$1)-1))),1),1)+1+7*(ROW()-ROW($B$3))+(COLUMN()-COLUMN($B$3))),""),"") | C3: =IF(MONTH(DATE($A$1,IFERROR(VALUE($B$1),VALUE(LEFT($B$1,FIND("월",$B$1)-1))),1)-WEEKDAY(DATE($A$1,IFERROR(VALUE($B$1),VALUE(LEFT($B$1,FIND("월",$B$1)-1))),1),1)+1+7*(ROW()-ROW($B$3))+(COLUMN()-COLUMN($B$3)))=IFERROR(VALUE($B$1),VALUE(LEFT($B$1,FIND("월",$B$1)-1))),IF(COUNTIF($K$1:$K$10,DAY(DATE($A$1,IFERROR(VALUE($B$1),VALUE(LEFT($B$1,FIND("월",$B$1)-1))),1)-WEEKDAY(DATE($A$1,IFERROR(VALUE($B$1),VALUE(LEFT($B$1,FIND("월",$B$1)-1))),1),1)+1+7*(ROW()-ROW($B$3))+(COLUMN()-COLUMN($B$3))))=0,DAY(DATE($A$1,IFERROR(VALUE($B$1),VALUE(LEFT($B$1,FIND("월",$B$1)-1))),1)-WEEKDAY(DATE($A$1,IFERROR(VALUE($B$1),VALUE(LEFT($B$1,FIND("월",$B$1)-1))),1),1)+1+7*(ROW()-ROW($B$3))+(COLUMN()-COLUMN($B$3))),""),"") | D3: =IF(MONTH(DATE($A$1,IFERROR(VALUE($B$1),VALUE(LEFT($B$1,FIND("월",$B$1)-1))),1)-WEEKDAY(DATE($A$1,IFERROR(VALUE($B$1),VALUE(LEFT($B$1,FIND("월",$B$1)-1))),1),1)+1+7*(ROW()-ROW($B$3))+(COLUMN()-COLUMN($B$3)))=IFERROR(VALUE($B$1),VALUE(LEFT($B$1,FIND("월",$B$1)-1))),IF(COUNTIF($K$1:$K$10,DAY(DATE($A$1,IFERROR(VALUE($B$1),VALUE(LEFT($B$1,FIND("월",$B$1)-1))),1)-WEEKDAY(DATE($A$1,IFERROR(VALUE($B$1),VALUE(LEFT($B$1,FIND("월",$B$1)-1))),1),1)+1+7*(ROW()-ROW($B$3))+(COLUMN()-COLUMN($B$3))))=0,DAY(DATE($A$1,IFERROR(VALUE($B$1),VALUE(LEFT($B$1,FIND("월",$B$1)-1))),1)-WEEKDAY(DATE($A$1,IFERROR(VALUE($B$1),VALUE(LEFT($B$1,FIND("월",$B$1)-1))),1),1)+1+7*(ROW()-ROW($B$3))+(COLUMN()-COLUMN($B$3))),""),"") | E3: =IF(MONTH(DATE($A$1,IFERROR(VALUE($B$1),VALUE(LEFT($B$1,FIND("월",$B$1)-1))),1)-WEEKDAY(DATE($A$1,IFERROR(VALUE($B$1),VALUE(LEFT($B$1,FIND("월",$B$1)-1))),1),1)+1+7*(ROW()-ROW($B$3))+(COLUMN()-COLUMN($B$3)))=IFERROR(VALUE($B$1),VALUE(LEFT($B$1,FIND("월",$B$1)-1))),IF(COUNTIF($K$1:$K$10,DAY(DATE($A$1,IFERROR(VALUE($B$1),VALUE(LEFT($B$1,FIND("월",$B$1)-1))),1)-WEEKDAY(DATE($A$1,IFERROR(VALUE($B$1),VALUE(LEFT($B$1,FIND("월",$B$1)-1))),1),1)+1+7*(ROW()-ROW($B$3))+(COLUMN()-COLUMN($B$3))))=0,DAY(DATE($A$1,IFERROR(VALUE($B$1),VALUE(LEFT($B$1,FIND("월",$B$1)-1))),1)-WEEKDAY(DATE($A$1,IFERROR(VALUE($B$1),VALUE(LEFT($B$1,FIND("월",$B$1)-1))),1),1)+1+7*(ROW()-ROW($B$3))+(COLUMN()-COLUMN($B$3))),""),"") | F3: =IF(MONTH(DATE($A$1,IFERROR(VALUE($B$1),VALUE(LEFT($B$1,FIND("월",$B$1)-1))),1)-WEEKDAY(DATE($A$1,IFERROR(VALUE($B$1),VALUE(LEFT($B$1,FIND("월",$B$1)-1))),1),1)+1+7*(ROW()-ROW($B$3))+(COLUMN()-COLUMN($B$3)))=IFERROR(VALUE($B$1),VALUE(LEFT($B$1,FIND("월",$B$1)-1))),IF(COUNTIF($K$1:$K$10,DAY(DATE($A$1,IFERROR(VALUE($B$1),VALUE(LEFT($B$1,FIND("월",$B$1)-1))),1)-WEEKDAY(DATE($A$1,IFERROR(VALUE($B$1),VALUE(LEFT($B$1,FIND("월",$B$1)-1))),1),1)+1+7*(ROW()-ROW($B$3))+(COLUMN()-COLUMN($B$3))))=0,DAY(DATE($A$1,IFERROR(VALUE($B$1),VALUE(LEFT($B$1,FIND("월",$B$1)-1))),1)-WEEKDAY(DATE($A$1,IFERROR(VALUE($B$1),VALUE(LEFT($B$1,FIND("월",$B$1)-1))),1),1)+1+7*(ROW()-ROW($B$3))+(COLUMN()-COLUMN($B$3))),""),"") | G3: =IF(MONTH(DATE($A$1,IFERROR(VALUE($B$1),VALUE(LEFT($B$1,FIND("월",$B$1)-1))),1)-WEEKDAY(DATE($A$1,IFERROR(VALUE($B$1),VALUE(LEFT($B$1,FIND("월",$B$1)-1))),1),1)+1+7*(ROW()-ROW($B$3))+(COLUMN()-COLUMN($B$3)))=IFERROR(VALUE($B$1),VALUE(LEFT($B$1,FIND("월",$B$1)-1))),IF(COUNTIF($K$1:$K$10,DAY(DATE($A$1,IFERROR(VALUE($B$1),VALUE(LEFT($B$1,FIND("월",$B$1)-1))),1)-WEEKDAY(DATE($A$1,IFERROR(VALUE($B$1),VALUE(LEFT($B$1,FIND("월",$B$1)-1))),1),1)+1+7*(ROW()-ROW($B$3))+(COLUMN()-COLUMN($B$3))))=0,DAY(DATE($A$1,IFERROR(VALUE($B$1),VALUE(LEFT($B$1,FIND("월",$B$1)-1))),1)-WEEKDAY(DATE($A$1,IFERROR(VALUE($B$1),VALUE(LEFT($B$1,FIND("월",$B$1)-1))),1),1)+1+7*(ROW()-ROW($B$3))+(COLUMN()-COLUMN($B$3))),""),"") | H3: =IF(MONTH(DATE($A$1,IFERROR(VALUE($B$1),VALUE(LEFT($B$1,FIND("월",$B$1)-1))),1)-WEEKDAY(DATE($A$1,IFERROR(VALUE($B$1),VALUE(LEFT($B$1,FIND("월",$B$1)-1))),1),1)+1+7*(ROW()-ROW($B$3))+(COLUMN()-COLUMN($B$3)))=IFERROR(VALUE($B$1),VALUE(LEFT($B$1,FIND("월",$B$1)-1))),IF(COUNTIF($K$1:$K$10,DAY(DATE($A$1,IFERROR(VALUE($B$1),VALUE(LEFT($B$1,FIND("월",$B$1)-1))),1)-WEEKDAY(DATE($A$1,IFERROR(VALUE($B$1),VALUE(LEFT($B$1,FIND("월",$B$1)-1))),1),1)+1+7*(ROW()-ROW($B$3))+(COLUMN()-COLUMN($B$3))))=0,DAY(DATE($A$1,IFERROR(VALUE($B$1),VALUE(LEFT($B$1,FIND("월",$B$1)-1))),1)-WEEKDAY(DATE($A$1,IFERROR(VALUE($B$1),VALUE(LEFT($B$1,FIND("월",$B$1)-1))),1),1)+1+7*(ROW()-ROW($B$3))+(COLUMN()-COLUMN($B$3))),""),"") | K3: 5
B4: =IF(MONTH(DATE($A$1,IFERROR(VALUE($B$1),VALUE(LEFT($B$1,FIND("월",$B$1)-1))),1)-WEEKDAY(DATE($A$1,IFERROR(VALUE($B$1),VALUE(LEFT($B$1,FIND("월",$B$1)-1))),1),1)+1+7*(ROW()-ROW($B$3))+(COLUMN()-COLUMN($B$3)))=IFERROR(VALUE($B$1),VALUE(LEFT($B$1,FIND("월",$B$1)-1))),IF(COUNTIF($K$1:$K$10,DAY(DATE($A$1,IFERROR(VALUE($B$1),VALUE(LEFT($B$1,FIND("월",$B$1)-1))),1)-WEEKDAY(DATE($A$1,IFERROR(VALUE($B$1),VALUE(LEFT($B$1,FIND("월",$B$1)-1))),1),1)+1+7*(ROW()-ROW($B$3))+(COLUMN()-COLUMN($B$3))))=0,DAY(DATE($A$1,IFERROR(VALUE($B$1),VALUE(LEFT($B$1,FIND("월",$B$1)-1))),1)-WEEKDAY(DATE($A$1,IFERROR(VALUE($B$1),VALUE(LEFT($B$1,FIND("월",$B$1)-1))),1),1)+1+7*(ROW()-ROW($B$3))+(COLUMN()-COLUMN($B$3))),""),"") | C4: =IF(MONTH(DATE($A$1,IFERROR(VALUE($B$1),VALUE(LEFT($B$1,FIND("월",$B$1)-1))),1)-WEEKDAY(DATE($A$1,IFERROR(VALUE($B$1),VALUE(LEFT($B$1,FIND("월",$B$1)-1))),1),1)+1+7*(ROW()-ROW($B$3))+(COLUMN()-COLUMN($B$3)))=IFERROR(VALUE($B$1),VALUE(LEFT($B$1,FIND("월",$B$1)-1))),IF(COUNTIF($K$1:$K$10,DAY(DATE($A$1,IFERROR(VALUE($B$1),VALUE(LEFT($B$1,FIND("월",$B$1)-1))),1)-WEEKDAY(DATE($A$1,IFERROR(VALUE($B$1),VALUE(LEFT($B$1,FIND("월",$B$1)-1))),1),1)+1+7*(ROW()-ROW($B$3))+(COLUMN()-COLUMN($B$3))))=0,DAY(DATE($A$1,IFERROR(VALUE($B$1),VALUE(LEFT($B$1,FIND("월",$B$1)-1))),1)-WEEKDAY(DATE($A$1,IFERROR(VALUE($B$1),VALUE(LEFT($B$1,FIND("월",$B$1)-1))),1),1)+1+7*(ROW()-ROW($B$3))+(COLUMN()-COLUMN($B$3))),""),"") | D4: =IF(MONTH(DATE($A$1,IFERROR(VALUE($B$1),VALUE(LEFT($B$1,FIND("월",$B$1)-1))),1)-WEEKDAY(DATE($A$1,IFERROR(VALUE($B$1),VALUE(LEFT($B$1,FIND("월",$B$1)-1))),1),1)+1+7*(ROW()-ROW($B$3))+(COLUMN()-COLUMN($B$3)))=IFERROR(VALUE($B$1),VALUE(LEFT($B$1,FIND("월",$B$1)-1))),IF(COUNTIF($K$1:$K$10,DAY(DATE($A$1,IFERROR(VALUE($B$1),VALUE(LEFT($B$1,FIND("월",$B$1)-1))),1)-WEEKDAY(DATE($A$1,IFERROR(VALUE($B$1),VALUE(LEFT($B$1,FIND("월",$B$1)-1))),1),1)+1+7*(ROW()-ROW($B$3))+(COLUMN()-COLUMN($B$3))))=0,DAY(DATE($A$1,IFERROR(VALUE($B$1),VALUE(LEFT($B$1,FIND("월",$B$1)-1))),1)-WEEKDAY(DATE($A$1,IFERROR(VALUE($B$1),VALUE(LEFT($B$1,FIND("월",$B$1)-1))),1),1)+1+7*(ROW()-ROW($B$3))+(COLUMN()-COLUMN($B$3))),""),"") | E4: =IF(MONTH(DATE($A$1,IFERROR(VALUE($B$1),VALUE(LEFT($B$1,FIND("월",$B$1)-1))),1)-WEEKDAY(DATE($A$1,IFERROR(VALUE($B$1),VALUE(LEFT($B$1,FIND("월",$B$1)-1))),1),1)+1+7*(ROW()-ROW($B$3))+(COLUMN()-COLUMN($B$3)))=IFERROR(VALUE($B$1),VALUE(LEFT($B$1,FIND("월",$B$1)-1))),IF(COUNTIF($K$1:$K$10,DAY(DATE($A$1,IFERROR(VALUE($B$1),VALUE(LEFT($B$1,FIND("월",$B$1)-1))),1)-WEEKDAY(DATE($A$1,IFERROR(VALUE($B$1),VALUE(LEFT($B$1,FIND("월",$B$1)-1))),1),1)+1+7*(ROW()-ROW($B$3))+(COLUMN()-COLUMN($B$3))))=0,DAY(DATE($A$1,IFERROR(VALUE($B$1),VALUE(LEFT($B$1,FIND("월",$B$1)-1))),1)-WEEKDAY(DATE($A$1,IFERROR(VALUE($B$1),VALUE(LEFT($B$1,FIND("월",$B$1)-1))),1),1)+1+7*(ROW()-ROW($B$3))+(COLUMN()-COLUMN($B$3))),""),"") | F4: =IF(MONTH(DATE($A$1,IFERROR(VALUE($B$1),VALUE(LEFT($B$1,FIND("월",$B$1)-1))),1)-WEEKDAY(DATE($A$1,IFERROR(VALUE($B$1),VALUE(LEFT($B$1,FIND("월",$B$1)-1))),1),1)+1+7*(ROW()-ROW($B$3))+(COLUMN()-COLUMN($B$3)))=IFERROR(VALUE($B$1),VALUE(LEFT($B$1,FIND("월",$B$1)-1))),IF(COUNTIF($K$1:$K$10,DAY(DATE($A$1,IFERROR(VALUE($B$1),VALUE(LEFT($B$1,FIND("월",$B$1)-1))),1)-WEEKDAY(DATE($A$1,IFERROR(VALUE($B$1),VALUE(LEFT($B$1,FIND("월",$B$1)-1))),1),1)+1+7*(ROW()-ROW($B$3))+(COLUMN()-COLUMN($B$3))))=0,DAY(DATE($A$1,IFERROR(VALUE($B$1),VALUE(LEFT($B$1,FIND("월",$B$1)-1))),1)-WEEKDAY(DATE($A$1,IFERROR(VALUE($B$1),VALUE(LEFT($B$1,FIND("월",$B$1)-1))),1),1)+1+7*(ROW()-ROW($B$3))+(COLUMN()-COLUMN($B$3))),""),"") | G4: =IF(MONTH(DATE($A$1,IFERROR(VALUE($B$1),VALUE(LEFT($B$1,FIND("월",$B$1)-1))),1)-WEEKDAY(DATE($A$1,IFERROR(VALUE($B$1),VALUE(LEFT($B$1,FIND("월",$B$1)-1))),1),1)+1+7*(ROW()-ROW($B$3))+(COLUMN()-COLUMN($B$3)))=IFERROR(VALUE($B$1),VALUE(LEFT($B$1,FIND("월",$B$1)-1))),IF(COUNTIF($K$1:$K$10,DAY(DATE($A$1,IFERROR(VALUE($B$1),VALUE(LEFT($B$1,FIND("월",$B$1)-1))),1)-WEEKDAY(DATE($A$1,IFERROR(VALUE($B$1),VALUE(LEFT($B$1,FIND("월",$B$1)-1))),1),1)+1+7*(ROW()-ROW($B$3))+(COLUMN()-COLUMN($B$3))))=0,DAY(DATE($A$1,IFERROR(VALUE($B$1),VALUE(LEFT($B$1,FIND("월",$B$1)-1))),1)-WEEKDAY(DATE($A$1,IFERROR(VALUE($B$1),VALUE(LEFT($B$1,FIND("월",$B$1)-1))),1),1)+1+7*(ROW()-ROW($B$3))+(COLUMN()-COLUMN($B$3))),""),"") | H4: =IF(MONTH(DATE($A$1,IFERROR(VALUE($B$1),VALUE(LEFT($B$1,FIND("월",$B$1)-1))),1)-WEEKDAY(DATE($A$1,IFERROR(VALUE($B$1),VALUE(LEFT($B$1,FIND("월",$B$1)-1))),1),1)+1+7*(ROW()-ROW($B$3))+(COLUMN()-COLUMN($B$3)))=IFERROR(VALUE($B$1),VALUE(LEFT($B$1,FIND("월",$B$1)-1))),IF(COUNTIF($K$1:$K$10,DAY(DATE($A$1,IFERROR(VALUE($B$1),VALUE(LEFT($B$1,FIND("월",$B$1)-1))),1)-WEEKDAY(DATE($A$1,IFERROR(VALUE($B$1),VALUE(LEFT($B$1,FIND("월",$B$1)-1))),1),1)+1+7*(ROW()-ROW($B$3))+(COLUMN()-COLUMN($B$3))))=0,DAY(DATE($A$1,IFERROR(VALUE($B$1),VALUE(LEFT($B$1,FIND("월",$B$1)-1))),1)-WEEKDAY(DATE($A$1,IFERROR(VALUE($B$1),VALUE(LEFT($B$1,FIND("월",$B$1)-1))),1),1)+1+7*(ROW()-ROW($B$3))+(COLUMN()-COLUMN($B$3))),""),"") | K4: 24
B5: =IF(MONTH(DATE($A$1,IFERROR(VALUE($B$1),VALUE(LEFT($B$1,FIND("월",$B$1)-1))),1)-WEEKDAY(DATE($A$1,IFERROR(VALUE($B$1),VALUE(LEFT($B$1,FIND("월",$B$1)-1))),1),1)+1+7*(ROW()-ROW($B$3))+(COLUMN()-COLUMN($B$3)))=IFERROR(VALUE($B$1),VALUE(LEFT($B$1,FIND("월",$B$1)-1))),IF(COUNTIF($K$1:$K$10,DAY(DATE($A$1,IFERROR(VALUE($B$1),VALUE(LEFT($B$1,FIND("월",$B$1)-1))),1)-WEEKDAY(DATE($A$1,IFERROR(VALUE($B$1),VALUE(LEFT($B$1,FIND("월",$B$1)-1))),1),1)+1+7*(ROW()-ROW($B$3))+(COLUMN()-COLUMN($B$3))))=0,DAY(DATE($A$1,IFERROR(VALUE($B$1),VALUE(LEFT($B$1,FIND("월",$B$1)-1))),1)-WEEKDAY(DATE($A$1,IFERROR(VALUE($B$1),VALUE(LEFT($B$1,FIND("월",$B$1)-1))),1),1)+1+7*(ROW()-ROW($B$3))+(COLUMN()-COLUMN($B$3))),""),"") | C5: =IF(MONTH(DATE($A$1,IFERROR(VALUE($B$1),VALUE(LEFT($B$1,FIND("월",$B$1)-1))),1)-WEEKDAY(DATE($A$1,IFERROR(VALUE($B$1),VALUE(LEFT($B$1,FIND("월",$B$1)-1))),1),1)+1+7*(ROW()-ROW($B$3))+(COLUMN()-COLUMN($B$3)))=IFERROR(VALUE($B$1),VALUE(LEFT($B$1,FIND("월",$B$1)-1))),IF(COUNTIF($K$1:$K$10,DAY(DATE($A$1,IFERROR(VALUE($B$1),VALUE(LEFT($B$1,FIND("월",$B$1)-1))),1)-WEEKDAY(DATE($A$1,IFERROR(VALUE($B$1),VALUE(LEFT($B$1,FIND("월",$B$1)-1))),1),1)+1+7*(ROW()-ROW($B$3))+(COLUMN()-COLUMN($B$3))))=0,DAY(DATE($A$1,IFERROR(VALUE($B$1),VALUE(LEFT($B$1,FIND("월",$B$1)-1))),1)-WEEKDAY(DATE($A$1,IFERROR(VALUE($B$1),VALUE(LEFT($B$1,FIND("월",$B$1)-1))),1),1)+1+7*(ROW()-ROW($B$3))+(COLUMN()-COLUMN($B$3))),""),"") | D5: =IF(MONTH(DATE($A$1,IFERROR(VALUE($B$1),VALUE(LEFT($B$1,FIND("월",$B$1)-1))),1)-WEEKDAY(DATE($A$1,IFERROR(VALUE($B$1),VALUE(LEFT($B$1,FIND("월",$B$1)-1))),1),1)+1+7*(ROW()-ROW($B$3))+(COLUMN()-COLUMN($B$3)))=IFERROR(VALUE($B$1),VALUE(LEFT($B$1,FIND("월",$B$1)-1))),IF(COUNTIF($K$1:$K$10,DAY(DATE($A$1,IFERROR(VALUE($B$1),VALUE(LEFT($B$1,FIND("월",$B$1)-1))),1)-WEEKDAY(DATE($A$1,IFERROR(VALUE($B$1),VALUE(LEFT($B$1,FIND("월",$B$1)-1))),1),1)+1+7*(ROW()-ROW($B$3))+(COLUMN()-COLUMN($B$3))))=0,DAY(DATE($A$1,IFERROR(VALUE($B$1),VALUE(LEFT($B$1,FIND("월",$B$1)-1))),1)-WEEKDAY(DATE($A$1,IFERROR(VALUE($B$1),VALUE(LEFT($B$1,FIND("월",$B$1)-1))),1),1)+1+7*(ROW()-ROW($B$3))+(COLUMN()-COLUMN($B$3))),""),"") | E5: =IF(MONTH(DATE($A$1,IFERROR(VALUE($B$1),VALUE(LEFT($B$1,FIND("월",$B$1)-1))),1)-WEEKDAY(DATE($A$1,IFERROR(VALUE($B$1),VALUE(LEFT($B$1,FIND("월",$B$1)-1))),1),1)+1+7*(ROW()-ROW($B$3))+(COLUMN()-COLUMN($B$3)))=IFERROR(VALUE($B$1),VALUE(LEFT($B$1,FIND("월",$B$1)-1))),IF(COUNTIF($K$1:$K$10,DAY(DATE($A$1,IFERROR(VALUE($B$1),VALUE(LEFT($B$1,FIND("월",$B$1)-1))),1)-WEEKDAY(DATE($A$1,IFERROR(VALUE($B$1),VALUE(LEFT($B$1,FIND("월",$B$1)-1))),1),1)+1+7*(ROW()-ROW($B$3))+(COLUMN()-COLUMN($B$3))))=0,DAY(DATE($A$1,IFERROR(VALUE($B$1),VALUE(LEFT($B$1,FIND("월",$B$1)-1))),1)-WEEKDAY(DATE($A$1,IFERROR(VALUE($B$1),VALUE(LEFT($B$1,FIND("월",$B$1)-1))),1),1)+1+7*(ROW()-ROW($B$3))+(COLUMN()-COLUMN($B$3))),""),"") | F5: =IF(MONTH(DATE($A$1,IFERROR(VALUE($B$1),VALUE(LEFT($B$1,FIND("월",$B$1)-1))),1)-WEEKDAY(DATE($A$1,IFERROR(VALUE($B$1),VALUE(LEFT($B$1,FIND("월",$B$1)-1))),1),1)+1+7*(ROW()-ROW($B$3))+(COLUMN()-COLUMN($B$3)))=IFERROR(VALUE($B$1),VALUE(LEFT($B$1,FIND("월",$B$1)-1))),IF(COUNTIF($K$1:$K$10,DAY(DATE($A$1,IFERROR(VALUE($B$1),VALUE(LEFT($B$1,FIND("월",$B$1)-1))),1)-WEEKDAY(DATE($A$1,IFERROR(VALUE($B$1),VALUE(LEFT($B$1,FIND("월",$B$1)-1))),1),1)+1+7*(ROW()-ROW($B$3))+(COLUMN()-COLUMN($B$3))))=0,DAY(DATE($A$1,IFERROR(VALUE($B$1),VALUE(LEFT($B$1,FIND("월",$B$1)-1))),1)-WEEKDAY(DATE($A$1,IFERROR(VALUE($B$1),VALUE(LEFT($B$1,FIND("월",$B$1)-1))),1),1)+1+7*(ROW()-ROW($B$3))+(COLUMN()-COLUMN($B$3))),""),"") | G5: =IF(MONTH(DATE($A$1,IFERROR(VALUE($B$1),VALUE(LEFT($B$1,FIND("월",$B$1)-1))),1)-WEEKDAY(DATE($A$1,IFERROR(VALUE($B$1),VALUE(LEFT($B$1,FIND("월",$B$1)-1))),1),1)+1+7*(ROW()-ROW($B$3))+(COLUMN()-COLUMN($B$3)))=IFERROR(VALUE($B$1),VALUE(LEFT($B$1,FIND("월",$B$1)-1))),IF(COUNTIF($K$1:$K$10,DAY(DATE($A$1,IFERROR(VALUE($B$1),VALUE(LEFT($B$1,FIND("월",$B$1)-1))),1)-WEEKDAY(DATE($A$1,IFERROR(VALUE($B$1),VALUE(LEFT($B$1,FIND("월",$B$1)-1))),1),1)+1+7*(ROW()-ROW($B$3))+(COLUMN()-COLUMN($B$3))))=0,DAY(DATE($A$1,IFERROR(VALUE($B$1),VALUE(LEFT($B$1,FIND("월",$B$1)-1))),1)-WEEKDAY(DATE($A$1,IFERROR(VALUE($B$1),VALUE(LEFT($B$1,FIND("월",$B$1)-1))),1),1)+1+7*(ROW()-ROW($B$3))+(COLUMN()-COLUMN($B$3))),""),"") | H5: =IF(MONTH(DATE($A$1,IFERROR(VALUE($B$1),VALUE(LEFT($B$1,FIND("월",$B$1)-1))),1)-WEEKDAY(DATE($A$1,IFERROR(VALUE($B$1),VALUE(LEFT($B$1,FIND("월",$B$1)-1))),1),1)+1+7*(ROW()-ROW($B$3))+(COLUMN()-COLUMN($B$3)))=IFERROR(VALUE($B$1),VALUE(LEFT($B$1,FIND("월",$B$1)-1))),IF(COUNTIF($K$1:$K$10,DAY(DATE($A$1,IFERROR(VALUE($B$1),VALUE(LEFT($B$1,FIND("월",$B$1)-1))),1)-WEEKDAY(DATE($A$1,IFERROR(VALUE($B$1),VALUE(LEFT($B$1,FIND("월",$B$1)-1))),1),1)+1+7*(ROW()-ROW($B$3))+(COLUMN()-COLUMN($B$3))))=0,DAY(DATE($A$1,IFERROR(VALUE($B$1),VALUE(LEFT($B$1,FIND("월",$B$1)-1))),1)-WEEKDAY(DATE($A$1,IFERROR(VALUE($B$1),VALUE(LEFT($B$1,FIND("월",$B$1)-1))),1),1)+1+7*(ROW()-ROW($B$3))+(COLUMN()-COLUMN($B$3))),""),"")
B6: =IF(MONTH(DATE($A$1,IFERROR(VALUE($B$1),VALUE(LEFT($B$1,FIND("월",$B$1)-1))),1)-WEEKDAY(DATE($A$1,IFERROR(VALUE($B$1),VALUE(LEFT($B$1,FIND("월",$B$1)-1))),1),1)+1+7*(ROW()-ROW($B$3))+(COLUMN()-COLUMN($B$3)))=IFERROR(VALUE($B$1),VALUE(LEFT($B$1,FIND("월",$B$1)-1))),IF(COUNTIF($K$1:$K$10,DAY(DATE($A$1,IFERROR(VALUE($B$1),VALUE(LEFT($B$1,FIND("월",$B$1)-1))),1)-WEEKDAY(DATE($A$1,IFERROR(VALUE($B$1),VALUE(LEFT($B$1,FIND("월",$B$1)-1))),1),1)+1+7*(ROW()-ROW($B$3))+(COLUMN()-COLUMN($B$3))))=0,DAY(DATE($A$1,IFERROR(VALUE($B$1),VALUE(LEFT($B$1,FIND("월",$B$1)-1))),1)-WEEKDAY(DATE($A$1,IFERROR(VALUE($B$1),VALUE(LEFT($B$1,FIND("월",$B$1)-1))),1),1)+1+7*(ROW()-ROW($B$3))+(COLUMN()-COLUMN($B$3))),""),"") | C6: =IF(MONTH(DATE($A$1,IFERROR(VALUE($B$1),VALUE(LEFT($B$1,FIND("월",$B$1)-1))),1)-WEEKDAY(DATE($A$1,IFERROR(VALUE($B$1),VALUE(LEFT($B$1,FIND("월",$B$1)-1))),1),1)+1+7*(ROW()-ROW($B$3))+(COLUMN()-COLUMN($B$3)))=IFERROR(VALUE($B$1),VALUE(LEFT($B$1,FIND("월",$B$1)-1))),IF(COUNTIF($K$1:$K$10,DAY(DATE($A$1,IFERROR(VALUE($B$1),VALUE(LEFT($B$1,FIND("월",$B$1)-1))),1)-WEEKDAY(DATE($A$1,IFERROR(VALUE($B$1),VALUE(LEFT($B$1,FIND("월",$B$1)-1))),1),1)+1+7*(ROW()-ROW($B$3))+(COLUMN()-COLUMN($B$3))))=0,DAY(DATE($A$1,IFERROR(VALUE($B$1),VALUE(LEFT($B$1,FIND("월",$B$1)-1))),1)-WEEKDAY(DATE($A$1,IFERROR(VALUE($B$1),VALUE(LEFT($B$1,FIND("월",$B$1)-1))),1),1)+1+7*(ROW()-ROW($B$3))+(COLUMN()-COLUMN($B$3))),""),"") | D6: =IF(MONTH(DATE($A$1,IFERROR(VALUE($B$1),VALUE(LEFT($B$1,FIND("월",$B$1)-1))),1)-WEEKDAY(DATE($A$1,IFERROR(VALUE($B$1),VALUE(LEFT($B$1,FIND("월",$B$1)-1))),1),1)+1+7*(ROW()-ROW($B$3))+(COLUMN()-COLUMN($B$3)))=IFERROR(VALUE($B$1),VALUE(LEFT($B$1,FIND("월",$B$1)-1))),IF(COUNTIF($K$1:$K$10,DAY(DATE($A$1,IFERROR(VALUE($B$1),VALUE(LEFT($B$1,FIND("월",$B$1)-1))),1)-WEEKDAY(DATE($A$1,IFERROR(VALUE($B$1),VALUE(LEFT($B$1,FIND("월",$B$1)-1))),1),1)+1+7*(ROW()-ROW($B$3))+(COLUMN()-COLUMN($B$3))))=0,DAY(DATE($A$1,IFERROR(VALUE($B$1),VALUE(LEFT($B$1,FIND("월",$B$1)-1))),1)-WEEKDAY(DATE($A$1,IFERROR(VALUE($B$1),VALUE(LEFT($B$1,FIND("월",$B$1)-1))),1),1)+1+7*(ROW()-ROW($B$3))+(COLUMN()-COLUMN($B$3))),""),"") | E6: =IF(MONTH(DATE($A$1,IFERROR(VALUE($B$1),VALUE(LEFT($B$1,FIND("월",$B$1)-1))),1)-WEEKDAY(DATE($A$1,IFERROR(VALUE($B$1),VALUE(LEFT($B$1,FIND("월",$B$1)-1))),1),1)+1+7*(ROW()-ROW($B$3))+(COLUMN()-COLUMN($B$3)))=IFERROR(VALUE($B$1),VALUE(LEFT($B$1,FIND("월",$B$1)-1))),IF(COUNTIF($K$1:$K$10,DAY(DATE($A$1,IFERROR(VALUE($B$1),VALUE(LEFT($B$1,FIND("월",$B$1)-1))),1)-WEEKDAY(DATE($A$1,IFERROR(VALUE($B$1),VALUE(LEFT($B$1,FIND("월",$B$1)-1))),1),1)+1+7*(ROW()-ROW($B$3))+(COLUMN()-COLUMN($B$3))))=0,DAY(DATE($A$1,IFERROR(VALUE($B$1),VALUE(LEFT($B$1,FIND("월",$B$1)-1))),1)-WEEKDAY(DATE($A$1,IFERROR(VALUE($B$1),VALUE(LEFT($B$1,FIND("월",$B$1)-1))),1),1)+1+7*(ROW()-ROW($B$3))+(COLUMN()-COLUMN($B$3))),""),"") | F6: =IF(MONTH(DATE($A$1,IFERROR(VALUE($B$1),VALUE(LEFT($B$1,FIND("월",$B$1)-1))),1)-WEEKDAY(DATE($A$1,IFERROR(VALUE($B$1),VALUE(LEFT($B$1,FIND("월",$B$1)-1))),1),1)+1+7*(ROW()-ROW($B$3))+(COLUMN()-COLUMN($B$3)))=IFERROR(VALUE($B$1),VALUE(LEFT($B$1,FIND("월",$B$1)-1))),IF(COUNTIF($K$1:$K$10,DAY(DATE($A$1,IFERROR(VALUE($B$1),VALUE(LEFT($B$1,FIND("월",$B$1)-1))),1)-WEEKDAY(DATE($A$1,IFERROR(VALUE($B$1),VALUE(LEFT($B$1,FIND("월",$B$1)-1))),1),1)+1+7*(ROW()-ROW($B$3))+(COLUMN()-COLUMN($B$3))))=0,DAY(DATE($A$1,IFERROR(VALUE($B$1),VALUE(LEFT($B$1,FIND("월",$B$1)-1))),1)-WEEKDAY(DATE($A$1,IFERROR(VALUE($B$1),VALUE(LEFT($B$1,FIND("월",$B$1)-1))),1),1)+1+7*(ROW()-ROW($B$3))+(COLUMN()-COLUMN($B$3))),""),"") | G6: =IF(MONTH(DATE($A$1,IFERROR(VALUE($B$1),VALUE(LEFT($B$1,FIND("월",$B$1)-1))),1)-WEEKDAY(DATE($A$1,IFERROR(VALUE($B$1),VALUE(LEFT($B$1,FIND("월",$B$1)-1))),1),1)+1+7*(ROW()-ROW($B$3))+(COLUMN()-COLUMN($B$3)))=IFERROR(VALUE($B$1),VALUE(LEFT($B$1,FIND("월",$B$1)-1))),IF(COUNTIF($K$1:$K$10,DAY(DATE($A$1,IFERROR(VALUE($B$1),VALUE(LEFT($B$1,FIND("월",$B$1)-1))),1)-WEEKDAY(DATE($A$1,IFERROR(VALUE($B$1),VALUE(LEFT($B$1,FIND("월",$B$1)-1))),1),1)+1+7*(ROW()-ROW($B$3))+(COLUMN()-COLUMN($B$3))))=0,DAY(DATE($A$1,IFERROR(VALUE($B$1),VALUE(LEFT($B$1,FIND("월",$B$1)-1))),1)-WEEKDAY(DATE($A$1,IFERROR(VALUE($B$1),VALUE(LEFT($B$1,FIND("월",$B$1)-1))),1),1)+1+7*(ROW()-ROW($B$3))+(COLUMN()-COLUMN($B$3))),""),"") | H6: =IF(MONTH(DATE($A$1,IFERROR(VALUE($B$1),VALUE(LEFT($B$1,FIND("월",$B$1)-1))),1)-WEEKDAY(DATE($A$1,IFERROR(VALUE($B$1),VALUE(LEFT($B$1,FIND("월",$B$1)-1))),1),1)+1+7*(ROW()-ROW($B$3))+(COLUMN()-COLUMN($B$3)))=IFERROR(VALUE($B$1),VALUE(LEFT($B$1,FIND("월",$B$1)-1))),IF(COUNTIF($K$1:$K$10,DAY(DATE($A$1,IFERROR(VALUE($B$1),VALUE(LEFT($B$1,FIND("월",$B$1)-1))),1)-WEEKDAY(DATE($A$1,IFERROR(VALUE($B$1),VALUE(LEFT($B$1,FIND("월",$B$1)-1))),1),1)+1+7*(ROW()-ROW($B$3))+(COLUMN()-COLUMN($B$3))))=0,DAY(DATE($A$1,IFERROR(VALUE($B$1),VALUE(LEFT($B$1,FIND("월",$B$1)-1))),1)-WEEKDAY(DATE($A$1,IFERROR(VALUE($B$1),VALUE(LEFT($B$1,FIND("월",$B$1)-1))),1),1)+1+7*(ROW()-ROW($B$3))+(COLUMN()-COLUMN($B$3))),""),"")
B7: =IF(MONTH(DATE($A$1,IFERROR(VALUE($B$1),VALUE(LEFT($B$1,FIND("월",$B$1)-1))),1)-WEEKDAY(DATE($A$1,IFERROR(VALUE($B$1),VALUE(LEFT($B$1,FIND("월",$B$1)-1))),1),1)+1+7*(ROW()-ROW($B$3))+(COLUMN()-COLUMN($B$3)))=IFERROR(VALUE($B$1),VALUE(LEFT($B$1,FIND("월",$B$1)-1))),IF(COUNTIF($K$1:$K$10,DAY(DATE($A$1,IFERROR(VALUE($B$1),VALUE(LEFT($B$1,FIND("월",$B$1)-1))),1)-WEEKDAY(DATE($A$1,IFERROR(VALUE($B$1),VALUE(LEFT($B$1,FIND("월",$B$1)-1))),1),1)+1+7*(ROW()-ROW($B$3))+(COLUMN()-COLUMN($B$3))))=0,DAY(DATE($A$1,IFERROR(VALUE($B$1),VALUE(LEFT($B$1,FIND("월",$B$1)-1))),1)-WEEKDAY(DATE($A$1,IFERROR(VALUE($B$1),VALUE(LEFT($B$1,FIND("월",$B$1)-1))),1),1)+1+7*(ROW()-ROW($B$3))+(COLUMN()-COLUMN($B$3))),""),"") | C7: =IF(MONTH(DATE($A$1,IFERROR(VALUE($B$1),VALUE(LEFT($B$1,FIND("월",$B$1)-1))),1)-WEEKDAY(DATE($A$1,IFERROR(VALUE($B$1),VALUE(LEFT($B$1,FIND("월",$B$1)-1))),1),1)+1+7*(ROW()-ROW($B$3))+(COLUMN()-COLUMN($B$3)))=IFERROR(VALUE($B$1),VALUE(LEFT($B$1,FIND("월",$B$1)-1))),IF(COUNTIF($K$1:$K$10,DAY(DATE($A$1,IFERROR(VALUE($B$1),VALUE(LEFT($B$1,FIND("월",$B$1)-1))),1)-WEEKDAY(DATE($A$1,IFERROR(VALUE($B$1),VALUE(LEFT($B$1,FIND("월",$B$1)-1))),1),1)+1+7*(ROW()-ROW($B$3))+(COLUMN()-COLUMN($B$3))))=0,DAY(DATE($A$1,IFERROR(VALUE($B$1),VALUE(LEFT($B$1,FIND("월",$B$1)-1))),1)-WEEKDAY(DATE($A$1,IFERROR(VALUE($B$1),VALUE(LEFT($B$1,FIND("월",$B$1)-1))),1),1)+1+7*(ROW()-ROW($B$3))+(COLUMN()-COLUMN($B$3))),""),"") | D7: =IF(MONTH(DATE($A$1,IFERROR(VALUE($B$1),VALUE(LEFT($B$1,FIND("월",$B$1)-1))),1)-WEEKDAY(DATE($A$1,IFERROR(VALUE($B$1),VALUE(LEFT($B$1,FIND("월",$B$1)-1))),1),1)+1+7*(ROW()-ROW($B$3))+(COLUMN()-COLUMN($B$3)))=IFERROR(VALUE($B$1),VALUE(LEFT($B$1,FIND("월",$B$1)-1))),IF(COUNTIF($K$1:$K$10,DAY(DATE($A$1,IFERROR(VALUE($B$1),VALUE(LEFT($B$1,FIND("월",$B$1)-1))),1)-WEEKDAY(DATE($A$1,IFERROR(VALUE($B$1),VALUE(LEFT($B$1,FIND("월",$B$1)-1))),1),1)+1+7*(ROW()-ROW($B$3))+(COLUMN()-COLUMN($B$3))))=0,DAY(DATE($A$1,IFERROR(VALUE($B$1),VALUE(LEFT($B$1,FIND("월",$B$1)-1))),1)-WEEKDAY(DATE($A$1,IFERROR(VALUE($B$1),VALUE(LEFT($B$1,FIND("월",$B$1)-1))),1),1)+1+7*(ROW()-ROW($B$3))+(COLUMN()-COLUMN($B$3))),""),"") | E7: =IF(MONTH(DATE($A$1,IFERROR(VALUE($B$1),VALUE(LEFT($B$1,FIND("월",$B$1)-1))),1)-WEEKDAY(DATE($A$1,IFERROR(VALUE($B$1),VALUE(LEFT($B$1,FIND("월",$B$1)-1))),1),1)+1+7*(ROW()-ROW($B$3))+(COLUMN()-COLUMN($B$3)))=IFERROR(VALUE($B$1),VALUE(LEFT($B$1,FIND("월",$B$1)-1))),IF(COUNTIF($K$1:$K$10,DAY(DATE($A$1,IFERROR(VALUE($B$1),VALUE(LEFT($B$1,FIND("월",$B$1)-1))),1)-WEEKDAY(DATE($A$1,IFERROR(VALUE($B$1),VALUE(LEFT($B$1,FIND("월",$B$1)-1))),1),1)+1+7*(ROW()-ROW($B$3))+(COLUMN()-COLUMN($B$3))))=0,DAY(DATE($A$1,IFERROR(VALUE($B$1),VALUE(LEFT($B$1,FIND("월",$B$1)-1))),1)-WEEKDAY(DATE($A$1,IFERROR(VALUE($B$1),VALUE(LEFT($B$1,FIND("월",$B$1)-1))),1),1)+1+7*(ROW()-ROW($B$3))+(COLUMN()-COLUMN($B$3))),""),"") | F7: =IF(MONTH(DATE($A$1,IFERROR(VALUE($B$1),VALUE(LEFT($B$1,FIND("월",$B$1)-1))),1)-WEEKDAY(DATE($A$1,IFERROR(VALUE($B$1),VALUE(LEFT($B$1,FIND("월",$B$1)-1))),1),1)+1+7*(ROW()-ROW($B$3))+(COLUMN()-COLUMN($B$3)))=IFERROR(VALUE($B$1),VALUE(LEFT($B$1,FIND("월",$B$1)-1))),IF(COUNTIF($K$1:$K$10,DAY(DATE($A$1,IFERROR(VALUE($B$1),VALUE(LEFT($B$1,FIND("월",$B$1)-1))),1)-WEEKDAY(DATE($A$1,IFERROR(VALUE($B$1),VALUE(LEFT($B$1,FIND("월",$B$1)-1))),1),1)+1+7*(ROW()-ROW($B$3))+(COLUMN()-COLUMN($B$3))))=0,DAY(DATE($A$1,IFERROR(VALUE($B$1),VALUE(LEFT($B$1,FIND("월",$B$1)-1))),1)-WEEKDAY(DATE($A$1,IFERROR(VALUE($B$1),VALUE(LEFT($B$1,FIND("월",$B$1)-1))),1),1)+1+7*(ROW()-ROW($B$3))+(COLUMN()-COLUMN($B$3))),""),"") | G7: =IF(MONTH(DATE($A$1,IFERROR(VALUE($B$1),VALUE(LEFT($B$1,FIND("월",$B$1)-1))),1)-WEEKDAY(DATE($A$1,IFERROR(VALUE($B$1),VALUE(LEFT($B$1,FIND("월",$B$1)-1))),1),1)+1+7*(ROW()-ROW($B$3))+(COLUMN()-COLUMN($B$3)))=IFERROR(VALUE($B$1),VALUE(LEFT($B$1,FIND("월",$B$1)-1))),IF(COUNTIF($K$1:$K$10,DAY(DATE($A$1,IFERROR(VALUE($B$1),VALUE(LEFT($B$1,FIND("월",$B$1)-1))),1)-WEEKDAY(DATE($A$1,IFERROR(VALUE($B$1),VALUE(LEFT($B$1,FIND("월",$B$1)-1))),1),1)+1+7*(ROW()-ROW($B$3))+(COLUMN()-COLUMN($B$3))))=0,DAY(DATE($A$1,IFERROR(VALUE($B$1),VALUE(LEFT($B$1,FIND("월",$B$1)-1))),1)-WEEKDAY(DATE($A$1,IFERROR(VALUE($B$1),VALUE(LEFT($B$1,FIND("월",$B$1)-1))),1),1)+1+7*(ROW()-ROW($B$3))+(COLUMN()-COLUMN($B$3))),""),"") | H7: =IF(MONTH(DATE($A$1,IFERROR(VALUE($B$1),VALUE(LEFT($B$1,FIND("월",$B$1)-1))),1)-WEEKDAY(DATE($A$1,IFERROR(VALUE($B$1),VALUE(LEFT($B$1,FIND("월",$B$1)-1))),1),1)+1+7*(ROW()-ROW($B$3))+(COLUMN()-COLUMN($B$3)))=IFERROR(VALUE($B$1),VALUE(LEFT($B$1,FIND("월",$B$1)-1))),IF(COUNTIF($K$1:$K$10,DAY(DATE($A$1,IFERROR(VALUE($B$1),VALUE(LEFT($B$1,FIND("월",$B$1)-1))),1)-WEEKDAY(DATE($A$1,IFERROR(VALUE($B$1),VALUE(LEFT($B$1,FIND("월",$B$1)-1))),1),1)+1+7*(ROW()-ROW($B$3))+(COLUMN()-COLUMN($B$3))))=0,DAY(DATE($A$1,IFERROR(VALUE($B$1),VALUE(LEFT($B$1,FIND("월",$B$1)-1))),1)-WEEKDAY(DATE($A$1,IFERROR(VALUE($B$1),VALUE(LEFT($B$1,FIND("월",$B$1)-1))),1),1)+1+7*(ROW()-ROW($B$3))+(COLUMN()-COLUMN($B$3))),""),"")
B8: =IF(MONTH(DATE(YEAR(TODAY()),IFERROR(VALUE($B$1),VALUE(LEFT($B$1,FIND("월",$B$1)-1))),1)-WEEKDAY(DATE(YEAR(TODAY()),IFERROR(VALUE($B$1),VALUE(LEFT($B$1,FIND("월",$B$1)-1))),1),1)+1+7*(ROW()-ROW($B$3))+(COLUMN()-COLUMN($B$3)))=IFERROR(VALUE($B$1),VALUE(LEFT($B$1,FIND("월",$B$1)-1))),DAY(DATE(YEAR(TODAY()),IFERROR(VALUE($B$1),VALUE(LEFT($B$1,FIND("월",$B$1)-1))),1)-WEEKDAY(DATE(YEAR(TODAY()),IFERROR(VALUE($B$1),VALUE(LEFT($B$1,FIND("월",$B$1)-1))),1),1)+1+7*(ROW()-ROW($B$3))+(COLUMN()-COLUMN($B$3))),"") | C8: =IF(MONTH(DATE(YEAR(TODAY()),IFERROR(VALUE($B$1),VALUE(LEFT($B$1,FIND("월",$B$1)-1))),1)-WEEKDAY(DATE(YEAR(TODAY()),IFERROR(VALUE($B$1),VALUE(LEFT($B$1,FIND("월",$B$1)-1))),1),1)+1+7*(ROW()-ROW($B$3))+(COLUMN()-COLUMN($B$3)))=IFERROR(VALUE($B$1),VALUE(LEFT($B$1,FIND("월",$B$1)-1))),DAY(DATE(YEAR(TODAY()),IFERROR(VALUE($B$1),VALUE(LEFT($B$1,FIND("월",$B$1)-1))),1)-WEEKDAY(DATE(YEAR(TODAY()),IFERROR(VALUE($B$1),VALUE(LEFT($B$1,FIND("월",$B$1)-1))),1),1)+1+7*(ROW()-ROW($B$3))+(COLUMN()-COLUMN($B$3))),"") | D8: =IF(MONTH(DATE(YEAR(TODAY()),IFERROR(VALUE($B$1),VALUE(LEFT($B$1,FIND("월",$B$1)-1))),1)-WEEKDAY(DATE(YEAR(TODAY()),IFERROR(VALUE($B$1),VALUE(LEFT($B$1,FIND("월",$B$1)-1))),1),1)+1+7*(ROW()-ROW($B$3))+(COLUMN()-COLUMN($B$3)))=IFERROR(VALUE($B$1),VALUE(LEFT($B$1,FIND("월",$B$1)-1))),DAY(DATE(YEAR(TODAY()),IFERROR(VALUE($B$1),VALUE(LEFT($B$1,FIND("월",$B$1)-1))),1)-WEEKDAY(DATE(YEAR(TODAY()),IFERROR(VALUE($B$1),VALUE(LEFT($B$1,FIND("월",$B$1)-1))),1),1)+1+7*(ROW()-ROW($B$3))+(COLUMN()-COLUMN($B$3))),"") | E8: =IF(MONTH(DATE(YEAR(TODAY()),IFERROR(VALUE($B$1),VALUE(LEFT($B$1,FIND("월",$B$1)-1))),1)-WEEKDAY(DATE(YEAR(TODAY()),IFERROR(VALUE($B$1),VALUE(LEFT($B$1,FIND("월",$B$1)-1))),1),1)+1+7*(ROW()-ROW($B$3))+(COLUMN()-COLUMN($B$3)))=IFERROR(VALUE($B$1),VALUE(LEFT($B$1,FIND("월",$B$1)-1))),DAY(DATE(YEAR(TODAY()),IFERROR(VALUE($B$1),VALUE(LEFT($B$1,FIND("월",$B$1)-1))),1)-WEEKDAY(DATE(YEAR(TODAY()),IFERROR(VALUE($B$1),VALUE(LEFT($B$1,FIND("월",$B$1)-1))),1),1)+1+7*(ROW()-ROW($B$3))+(COLUMN()-COLUMN($B$3))),"") | F8: =IF(MONTH(DATE(YEAR(TODAY()),IFERROR(VALUE($B$1),VALUE(LEFT($B$1,FIND("월",$B$1)-1))),1)-WEEKDAY(DATE(YEAR(TODAY()),IFERROR(VALUE($B$1),VALUE(LEFT($B$1,FIND("월",$B$1)-1))),1),1)+1+7*(ROW()-ROW($B$3))+(COLUMN()-COLUMN($B$3)))=IFERROR(VALUE($B$1),VALUE(LEFT($B$1,FIND("월",$B$1)-1))),DAY(DATE(YEAR(TODAY()),IFERROR(VALUE($B$1),VALUE(LEFT($B$1,FIND("월",$B$1)-1))),1)-WEEKDAY(DATE(YEAR(TODAY()),IFERROR(VALUE($B$1),VALUE(LEFT($B$1,FIND("월",$B$1)-1))),1),1)+1+7*(ROW()-ROW($B$3))+(COLUMN()-COLUMN($B$3))),"") | G8: =IF(MONTH(DATE(YEAR(TODAY()),IFERROR(VALUE($B$1),VALUE(LEFT($B$1,FIND("월",$B$1)-1))),1)-WEEKDAY(DATE(YEAR(TODAY()),IFERROR(VALUE($B$1),VALUE(LEFT($B$1,FIND("월",$B$1)-1))),1),1)+1+7*(ROW()-ROW($B$3))+(COLUMN()-COLUMN($B$3)))=IFERROR(VALUE($B$1),VALUE(LEFT($B$1,FIND("월",$B$1)-1))),DAY(DATE(YEAR(TODAY()),IFERROR(VALUE($B$1),VALUE(LEFT($B$1,FIND("월",$B$1)-1))),1)-WEEKDAY(DATE(YEAR(TODAY()),IFERROR(VALUE($B$1),VALUE(LEFT($B$1,FIND("월",$B$1)-1))),1),1)+1+7*(ROW()-ROW($B$3))+(COLUMN()-COLUMN($B$3))),"") | H8: =IF(MONTH(DATE(YEAR(TODAY()),IFERROR(VALUE($B$1),VALUE(LEFT($B$1,FIND("월",$B$1)-1))),1)-WEEKDAY(DATE(YEAR(TODAY()),IFERROR(VALUE($B$1),VALUE(LEFT($B$1,FIND("월",$B$1)-1))),1),1)+1+7*(ROW()-ROW($B$3))+(COLUMN()-COLUMN($B$3)))=IFERROR(VALUE($B$1),VALUE(LEFT($B$1,FIND("월",$B$1)-1))),DAY(DATE(YEAR(TODAY()),IFERROR(VALUE($B$1),VALUE(LEFT($B$1,FIND("월",$B$1)-1))),1)-WEEKDAY(DATE(YEAR(TODAY()),IFERROR(VALUE($B$1),VALUE(LEFT($B$1,FIND("월",$B$1)-1))),1),1)+1+7*(ROW()-ROW($B$3))+(COLUMN()-COLUMN($B$3))),"")
B11: {=IFERROR(SMALL(IF((($B$2:$H$2=LEFT($A$2,1))+($B$2:$H$2=LEFT($A$3,1)))*($B$3:$H$8<>"")*ISNUMBER($B$3:$H$8), $B$3:$H$8), COLUMN(A1)), "")} | C11: {=IFERROR(SMALL(IF((($B$2:$H$2=LEFT($A$2,1))+($B$2:$H$2=LEFT($A$3,1)))*($B$3:$H$8<>"")*ISNUMBER($B$3:$H$8), $B$3:$H$8), COLUMN(B1)), "")} | D11: {=IFERROR(SMALL(IF((($B$2:$H$2=LEFT($A$2,1))+($B$2:$H$2=LEFT($A$3,1)))*($B$3:$H$8<>"")*ISNUMBER($B$3:$H$8), $B$3:$H$8), COLUMN(C1)), "")} | E11: {=IFERROR(SMALL(IF((($B$2:$H$2=LEFT($A$2,1))+($B$2:$H$2=LEFT($A$3,1)))*($B$3:$H$8<>"")*ISNUMBER($B$3:$H$8), $B$3:$H$8), COLUMN(D1)), "")} | F11: {=IFERROR(SMALL(IF((($B$2:$H$2=LEFT($A$2,1))+($B$2:$H$2=LEFT($A$3,1)))*($B$3:$H$8<>"")*ISNUMBER($B$3:$H$8), $B$3:$H$8), COLUMN(E1)), "")} | G11: {=IFERROR(SMALL(IF((($B$2:$H$2=LEFT($A$2,1))+($B$2:$H$2=LEFT($A$3,1)))*($B$3:$H$8<>"")*ISNUMBER($B$3:$H$8), $B$3:$H$8), COLUMN(F1)), "")} | H11: {=IFERROR(SMALL(IF((($B$2:$H$2=LEFT($A$2,1))+($B$2:$H$2=LEFT($A$3,1)))*($B$3:$H$8<>"")*ISNUMBER($B$3:$H$8), $B$3:$H$8), COLUMN(G1)), "")} | I11: {=IFERROR(SMALL(IF((($B$2:$H$2=LEFT($A$2,1))+($B$2:$H$2=LEFT($A$3,1)))*($B$3:$H$8<>"")*ISNUMBER($B$3:$H$8), $B$3:$H$8), COLUMN(H1)), "")}

Sheet 수
A1: 2026 | B1: 5월 | K1: 공휴일
A2: 수 | B2: 일 | C2: 월 | D2: 화 | E2: 수 | F2: 목 | G2: 금 | H2: 토 | K2: 1
B3: =IF(MONTH(DATE($A$1,IFERROR(VALUE($B$1),VALUE(LEFT($B$1,FIND("월",$B$1)-1))),1)-WEEKDAY(DATE($A$1,IFERROR(VALUE($B$1),VALUE(LEFT($B$1,FIND("월",$B$1)-1))),1),1)+1+7*(ROW()-ROW($B$3))+(COLUMN()-COLUMN($B$3)))=IFERROR(VALUE($B$1),VALUE(LEFT($B$1,FIND("월",$B$1)-1))),IF(COUNTIF($K$1:$K$10,DAY(DATE($A$1,IFERROR(VALUE($B$1),VALUE(LEFT($B$1,FIND("월",$B$1)-1))),1)-WEEKDAY(DATE($A$1,IFERROR(VALUE($B$1),VALUE(LEFT($B$1,FIND("월",$B$1)-1))),1),1)+1+7*(ROW()-ROW($B$3))+(COLUMN()-COLUMN($B$3))))=0,DAY(DATE($A$1,IFERROR(VALUE($B$1),VALUE(LEFT($B$1,FIND("월",$B$1)-1))),1)-WEEKDAY(DATE($A$1,IFERROR(VALUE($B$1),VALUE(LEFT($B$1,FIND("월",$B$1)-1))),1),1)+1+7*(ROW()-ROW($B$3))+(COLUMN()-COLUMN($B$3))),""),"") | C3: =IF(MONTH(DATE($A$1,IFERROR(VALUE($B$1),VALUE(LEFT($B$1,FIND("월",$B$1)-1))),1)-WEEKDAY(DATE($A$1,IFERROR(VALUE($B$1),VALUE(LEFT($B$1,FIND("월",$B$1)-1))),1),1)+1+7*(ROW()-ROW($B$3))+(COLUMN()-COLUMN($B$3)))=IFERROR(VALUE($B$1),VALUE(LEFT($B$1,FIND("월",$B$1)-1))),IF(COUNTIF($K$1:$K$10,DAY(DATE($A$1,IFERROR(VALUE($B$1),VALUE(LEFT($B$1,FIND("월",$B$1)-1))),1)-WEEKDAY(DATE($A$1,IFERROR(VALUE($B$1),VALUE(LEFT($B$1,FIND("월",$B$1)-1))),1),1)+1+7*(ROW()-ROW($B$3))+(COLUMN()-COLUMN($B$3))))=0,DAY(DATE($A$1,IFERROR(VALUE($B$1),VALUE(LEFT($B$1,FIND("월",$B$1)-1))),1)-WEEKDAY(DATE($A$1,IFERROR(VALUE($B$1),VALUE(LEFT($B$1,FIND("월",$B$1)-1))),1),1)+1+7*(ROW()-ROW($B$3))+(COLUMN()-COLUMN($B$3))),""),"") | D3: =IF(MONTH(DATE($A$1,IFERROR(VALUE($B$1),VALUE(LEFT($B$1,FIND("월",$B$1)-1))),1)-WEEKDAY(DATE($A$1,IFERROR(VALUE($B$1),VALUE(LEFT($B$1,FIND("월",$B$1)-1))),1),1)+1+7*(ROW()-ROW($B$3))+(COLUMN()-COLUMN($B$3)))=IFERROR(VALUE($B$1),VALUE(LEFT($B$1,FIND("월",$B$1)-1))),IF(COUNTIF($K$1:$K$10,DAY(DATE($A$1,IFERROR(VALUE($B$1),VALUE(LEFT($B$1,FIND("월",$B$1)-1))),1)-WEEKDAY(DATE($A$1,IFERROR(VALUE($B$1),VALUE(LEFT($B$1,FIND("월",$B$1)-1))),1),1)+1+7*(ROW()-ROW($B$3))+(COLUMN()-COLUMN($B$3))))=0,DAY(DATE($A$1,IFERROR(VALUE($B$1),VALUE(LEFT($B$1,FIND("월",$B$1)-1))),1)-WEEKDAY(DATE($A$1,IFERROR(VALUE($B$1),VALUE(LEFT($B$1,FIND("월",$B$1)-1))),1),1)+1+7*(ROW()-ROW($B$3))+(COLUMN()-COLUMN($B$3))),""),"") | E3: =IF(MONTH(DATE($A$1,IFERROR(VALUE($B$1),VALUE(LEFT($B$1,FIND("월",$B$1)-1))),1)-WEEKDAY(DATE($A$1,IFERROR(VALUE($B$1),VALUE(LEFT($B$1,FIND("월",$B$1)-1))),1),1)+1+7*(ROW()-ROW($B$3))+(COLUMN()-COLUMN($B$3)))=IFERROR(VALUE($B$1),VALUE(LEFT($B$1,FIND("월",$B$1)-1))),IF(COUNTIF($K$1:$K$10,DAY(DATE($A$1,IFERROR(VALUE($B$1),VALUE(LEFT($B$1,FIND("월",$B$1)-1))),1)-WEEKDAY(DATE($A$1,IFERROR(VALUE($B$1),VALUE(LEFT($B$1,FIND("월",$B$1)-1))),1),1)+1+7*(ROW()-ROW($B$3))+(COLUMN()-COLUMN($B$3))))=0,DAY(DATE($A$1,IFERROR(VALUE($B$1),VALUE(LEFT($B$1,FIND("월",$B$1)-1))),1)-WEEKDAY(DATE($A$1,IFERROR(VALUE($B$1),VALUE(LEFT($B$1,FIND("월",$B$1)-1))),1),1)+1+7*(ROW()-ROW($B$3))+(COLUMN()-COLUMN($B$3))),""),"") | F3: =IF(MONTH(DATE($A$1,IFERROR(VALUE($B$1),VALUE(LEFT($B$1,FIND("월",$B$1)-1))),1)-WEEKDAY(DATE($A$1,IFERROR(VALUE($B$1),VALUE(LEFT($B$1,FIND("월",$B$1)-1))),1),1)+1+7*(ROW()-ROW($B$3))+(COLUMN()-COLUMN($B$3)))=IFERROR(VALUE($B$1),VALUE(LEFT($B$1,FIND("월",$B$1)-1))),IF(COUNTIF($K$1:$K$10,DAY(DATE($A$1,IFERROR(VALUE($B$1),VALUE(LEFT($B$1,FIND("월",$B$1)-1))),1)-WEEKDAY(DATE($A$1,IFERROR(VALUE($B$1),VALUE(LEFT($B$1,FIND("월",$B$1)-1))),1),1)+1+7*(ROW()-ROW($B$3))+(COLUMN()-COLUMN($B$3))))=0,DAY(DATE($A$1,IFERROR(VALUE($B$1),VALUE(LEFT($B$1,FIND("월",$B$1)-1))),1)-WEEKDAY(DATE($A$1,IFERROR(VALUE($B$1),VALUE(LEFT($B$1,FIND("월",$B$1)-1))),1),1)+1+7*(ROW()-ROW($B$3))+(COLUMN()-COLUMN($B$3))),""),"") | G3: =IF(MONTH(DATE($A$1,IFERROR(VALUE($B$1),VALUE(LEFT($B$1,FIND("월",$B$1)-1))),1)-WEEKDAY(DATE($A$1,IFERROR(VALUE($B$1),VALUE(LEFT($B$1,FIND("월",$B$1)-1))),1),1)+1+7*(ROW()-ROW($B$3))+(COLUMN()-COLUMN($B$3)))=IFERROR(VALUE($B$1),VALUE(LEFT($B$1,FIND("월",$B$1)-1))),IF(COUNTIF($K$1:$K$10,DAY(DATE($A$1,IFERROR(VALUE($B$1),VALUE(LEFT($B$1,FIND("월",$B$1)-1))),1)-WEEKDAY(DATE($A$1,IFERROR(VALUE($B$1),VALUE(LEFT($B$1,FIND("월",$B$1)-1))),1),1)+1+7*(ROW()-ROW($B$3))+(COLUMN()-COLUMN($B$3))))=0,DAY(DATE($A$1,IFERROR(VALUE($B$1),VALUE(LEFT($B$1,FIND("월",$B$1)-1))),1)-WEEKDAY(DATE($A$1,IFERROR(VALUE($B$1),VALUE(LEFT($B$1,FIND("월",$B$1)-1))),1),1)+1+7*(ROW()-ROW($B$3))+(COLUMN()-COLUMN($B$3))),""),"") | H3: =IF(MONTH(DATE($A$1,IFERROR(VALUE($B$1),VALUE(LEFT($B$1,FIND("월",$B$1)-1))),1)-WEEKDAY(DATE($A$1,IFERROR(VALUE($B$1),VALUE(LEFT($B$1,FIND("월",$B$1)-1))),1),1)+1+7*(ROW()-ROW($B$3))+(COLUMN()-COLUMN($B$3)))=IFERROR(VALUE($B$1),VALUE(LEFT($B$1,FIND("월",$B$1)-1))),IF(COUNTIF($K$1:$K$10,DAY(DATE($A$1,IFERROR(VALUE($B$1),VALUE(LEFT($B$1,FIND("월",$B$1)-1))),1)-WEEKDAY(DATE($A$1,IFERROR(VALUE($B$1),VALUE(LEFT($B$1,FIND("월",$B$1)-1))),1),1)+1+7*(ROW()-ROW($B$3))+(COLUMN()-COLUMN($B$3))))=0,DAY(DATE($A$1,IFERROR(VALUE($B$1),VALUE(LEFT($B$1,FIND("월",$B$1)-1))),1)-WEEKDAY(DATE($A$1,IFERROR(VALUE($B$1),VALUE(LEFT($B$1,FIND("월",$B$1)-1))),1),1)+1+7*(ROW()-ROW($B$3))+(COLUMN()-COLUMN($B$3))),""),"") | K3: 5
B4: =IF(MONTH(DATE($A$1,IFERROR(VALUE($B$1),VALUE(LEFT($B$1,FIND("월",$B$1)-1))),1)-WEEKDAY(DATE($A$1,IFERROR(VALUE($B$1),VALUE(LEFT($B$1,FIND("월",$B$1)-1))),1),1)+1+7*(ROW()-ROW($B$3))+(COLUMN()-COLUMN($B$3)))=IFERROR(VALUE($B$1),VALUE(LEFT($B$1,FIND("월",$B$1)-1))),IF(COUNTIF($K$1:$K$10,DAY(DATE($A$1,IFERROR(VALUE($B$1),VALUE(LEFT($B$1,FIND("월",$B$1)-1))),1)-WEEKDAY(DATE($A$1,IFERROR(VALUE($B$1),VALUE(LEFT($B$1,FIND("월",$B$1)-1))),1),1)+1+7*(ROW()-ROW($B$3))+(COLUMN()-COLUMN($B$3))))=0,DAY(DATE($A$1,IFERROR(VALUE($B$1),VALUE(LEFT($B$1,FIND("월",$B$1)-1))),1)-WEEKDAY(DATE($A$1,IFERROR(VALUE($B$1),VALUE(LEFT($B$1,FIND("월",$B$1)-1))),1),1)+1+7*(ROW()-ROW($B$3))+(COLUMN()-COLUMN($B$3))),""),"") | C4: =IF(MONTH(DATE($A$1,IFERROR(VALUE($B$1),VALUE(LEFT($B$1,FIND("월",$B$1)-1))),1)-WEEKDAY(DATE($A$1,IFERROR(VALUE($B$1),VALUE(LEFT($B$1,FIND("월",$B$1)-1))),1),1)+1+7*(ROW()-ROW($B$3))+(COLUMN()-COLUMN($B$3)))=IFERROR(VALUE($B$1),VALUE(LEFT($B$1,FIND("월",$B$1)-1))),IF(COUNTIF($K$1:$K$10,DAY(DATE($A$1,IFERROR(VALUE($B$1),VALUE(LEFT($B$1,FIND("월",$B$1)-1))),1)-WEEKDAY(DATE($A$1,IFERROR(VALUE($B$1),VALUE(LEFT($B$1,FIND("월",$B$1)-1))),1),1)+1+7*(ROW()-ROW($B$3))+(COLUMN()-COLUMN($B$3))))=0,DAY(DATE($A$1,IFERROR(VALUE($B$1),VALUE(LEFT($B$1,FIND("월",$B$1)-1))),1)-WEEKDAY(DATE($A$1,IFERROR(VALUE($B$1),VALUE(LEFT($B$1,FIND("월",$B$1)-1))),1),1)+1+7*(ROW()-ROW($B$3))+(COLUMN()-COLUMN($B$3))),""),"") | D4: =IF(MONTH(DATE($A$1,IFERROR(VALUE($B$1),VALUE(LEFT($B$1,FIND("월",$B$1)-1))),1)-WEEKDAY(DATE($A$1,IFERROR(VALUE($B$1),VALUE(LEFT($B$1,FIND("월",$B$1)-1))),1),1)+1+7*(ROW()-ROW($B$3))+(COLUMN()-COLUMN($B$3)))=IFERROR(VALUE($B$1),VALUE(LEFT($B$1,FIND("월",$B$1)-1))),IF(COUNTIF($K$1:$K$10,DAY(DATE($A$1,IFERROR(VALUE($B$1),VALUE(LEFT($B$1,FIND("월",$B$1)-1))),1)-WEEKDAY(DATE($A$1,IFERROR(VALUE($B$1),VALUE(LEFT($B$1,FIND("월",$B$1)-1))),1),1)+1+7*(ROW()-ROW($B$3))+(COLUMN()-COLUMN($B$3))))=0,DAY(DATE($A$1,IFERROR(VALUE($B$1),VALUE(LEFT($B$1,FIND("월",$B$1)-1))),1)-WEEKDAY(DATE($A$1,IFERROR(VALUE($B$1),VALUE(LEFT($B$1,FIND("월",$B$1)-1))),1),1)+1+7*(ROW()-ROW($B$3))+(COLUMN()-COLUMN($B$3))),""),"") | E4: =IF(MONTH(DATE($A$1,IFERROR(VALUE($B$1),VALUE(LEFT($B$1,FIND("월",$B$1)-1))),1)-WEEKDAY(DATE($A$1,IFERROR(VALUE($B$1),VALUE(LEFT($B$1,FIND("월",$B$1)-1))),1),1)+1+7*(ROW()-ROW($B$3))+(COLUMN()-COLUMN($B$3)))=IFERROR(VALUE($B$1),VALUE(LEFT($B$1,FIND("월",$B$1)-1))),IF(COUNTIF($K$1:$K$10,DAY(DATE($A$1,IFERROR(VALUE($B$1),VALUE(LEFT($B$1,FIND("월",$B$1)-1))),1)-WEEKDAY(DATE($A$1,IFERROR(VALUE($B$1),VALUE(LEFT($B$1,FIND("월",$B$1)-1))),1),1)+1+7*(ROW()-ROW($B$3))+(COLUMN()-COLUMN($B$3))))=0,DAY(DATE($A$1,IFERROR(VALUE($B$1),VALUE(LEFT($B$1,FIND("월",$B$1)-1))),1)-WEEKDAY(DATE($A$1,IFERROR(VALUE($B$1),VALUE(LEFT($B$1,FIND("월",$B$1)-1))),1),1)+1+7*(ROW()-ROW($B$3))+(COLUMN()-COLUMN($B$3))),""),"") | F4: =IF(MONTH(DATE($A$1,IFERROR(VALUE($B$1),VALUE(LEFT($B$1,FIND("월",$B$1)-1))),1)-WEEKDAY(DATE($A$1,IFERROR(VALUE($B$1),VALUE(LEFT($B$1,FIND("월",$B$1)-1))),1),1)+1+7*(ROW()-ROW($B$3))+(COLUMN()-COLUMN($B$3)))=IFERROR(VALUE($B$1),VALUE(LEFT($B$1,FIND("월",$B$1)-1))),IF(COUNTIF($K$1:$K$10,DAY(DATE($A$1,IFERROR(VALUE($B$1),VALUE(LEFT($B$1,FIND("월",$B$1)-1))),1)-WEEKDAY(DATE($A$1,IFERROR(VALUE($B$1),VALUE(LEFT($B$1,FIND("월",$B$1)-1))),1),1)+1+7*(ROW()-ROW($B$3))+(COLUMN()-COLUMN($B$3))))=0,DAY(DATE($A$1,IFERROR(VALUE($B$1),VALUE(LEFT($B$1,FIND("월",$B$1)-1))),1)-WEEKDAY(DATE($A$1,IFERROR(VALUE($B$1),VALUE(LEFT($B$1,FIND("월",$B$1)-1))),1),1)+1+7*(ROW()-ROW($B$3))+(COLUMN()-COLUMN($B$3))),""),"") | G4: =IF(MONTH(DATE($A$1,IFERROR(VALUE($B$1),VALUE(LEFT($B$1,FIND("월",$B$1)-1))),1)-WEEKDAY(DATE($A$1,IFERROR(VALUE($B$1),VALUE(LEFT($B$1,FIND("월",$B$1)-1))),1),1)+1+7*(ROW()-ROW($B$3))+(COLUMN()-COLUMN($B$3)))=IFERROR(VALUE($B$1),VALUE(LEFT($B$1,FIND("월",$B$1)-1))),IF(COUNTIF($K$1:$K$10,DAY(DATE($A$1,IFERROR(VALUE($B$1),VALUE(LEFT($B$1,FIND("월",$B$1)-1))),1)-WEEKDAY(DATE($A$1,IFERROR(VALUE($B$1),VALUE(LEFT($B$1,FIND("월",$B$1)-1))),1),1)+1+7*(ROW()-ROW($B$3))+(COLUMN()-COLUMN($B$3))))=0,DAY(DATE($A$1,IFERROR(VALUE($B$1),VALUE(LEFT($B$1,FIND("월",$B$1)-1))),1)-WEEKDAY(DATE($A$1,IFERROR(VALUE($B$1),VALUE(LEFT($B$1,FIND("월",$B$1)-1))),1),1)+1+7*(ROW()-ROW($B$3))+(COLUMN()-COLUMN($B$3))),""),"") | H4: =IF(MONTH(DATE($A$1,IFERROR(VALUE($B$1),VALUE(LEFT($B$1,FIND("월",$B$1)-1))),1)-WEEKDAY(DATE($A$1,IFERROR(VALUE($B$1),VALUE(LEFT($B$1,FIND("월",$B$1)-1))),1),1)+1+7*(ROW()-ROW($B$3))+(COLUMN()-COLUMN($B$3)))=IFERROR(VALUE($B$1),VALUE(LEFT($B$1,FIND("월",$B$1)-1))),IF(COUNTIF($K$1:$K$10,DAY(DATE($A$1,IFERROR(VALUE($B$1),VALUE(LEFT($B$1,FIND("월",$B$1)-1))),1)-WEEKDAY(DATE($A$1,IFERROR(VALUE($B$1),VALUE(LEFT($B$1,FIND("월",$B$1)-1))),1),1)+1+7*(ROW()-ROW($B$3))+(COLUMN()-COLUMN($B$3))))=0,DAY(DATE($A$1,IFERROR(VALUE($B$1),VALUE(LEFT($B$1,FIND("월",$B$1)-1))),1)-WEEKDAY(DATE($A$1,IFERROR(VALUE($B$1),VALUE(LEFT($B$1,FIND("월",$B$1)-1))),1),1)+1+7*(ROW()-ROW($B$3))+(COLUMN()-COLUMN($B$3))),""),"") | K4: 24
B5: =IF(MONTH(DATE($A$1,IFERROR(VALUE($B$1),VALUE(LEFT($B$1,FIND("월",$B$1)-1))),1)-WEEKDAY(DATE($A$1,IFERROR(VALUE($B$1),VALUE(LEFT($B$1,FIND("월",$B$1)-1))),1),1)+1+7*(ROW()-ROW($B$3))+(COLUMN()-COLUMN($B$3)))=IFERROR(VALUE($B$1),VALUE(LEFT($B$1,FIND("월",$B$1)-1))),IF(COUNTIF($K$1:$K$10,DAY(DATE($A$1,IFERROR(VALUE($B$1),VALUE(LEFT($B$1,FIND("월",$B$1)-1))),1)-WEEKDAY(DATE($A$1,IFERROR(VALUE($B$1),VALUE(LEFT($B$1,FIND("월",$B$1)-1))),1),1)+1+7*(ROW()-ROW($B$3))+(COLUMN()-COLUMN($B$3))))=0,DAY(DATE($A$1,IFERROR(VALUE($B$1),VALUE(LEFT($B$1,FIND("월",$B$1)-1))),1)-WEEKDAY(DATE($A$1,IFERROR(VALUE($B$1),VALUE(LEFT($B$1,FIND("월",$B$1)-1))),1),1)+1+7*(ROW()-ROW($B$3))+(COLUMN()-COLUMN($B$3))),""),"") | C5: =IF(MONTH(DATE($A$1,IFERROR(VALUE($B$1),VALUE(LEFT($B$1,FIND("월",$B$1)-1))),1)-WEEKDAY(DATE($A$1,IFERROR(VALUE($B$1),VALUE(LEFT($B$1,FIND("월",$B$1)-1))),1),1)+1+7*(ROW()-ROW($B$3))+(COLUMN()-COLUMN($B$3)))=IFERROR(VALUE($B$1),VALUE(LEFT($B$1,FIND("월",$B$1)-1))),IF(COUNTIF($K$1:$K$10,DAY(DATE($A$1,IFERROR(VALUE($B$1),VALUE(LEFT($B$1,FIND("월",$B$1)-1))),1)-WEEKDAY(DATE($A$1,IFERROR(VALUE($B$1),VALUE(LEFT($B$1,FIND("월",$B$1)-1))),1),1)+1+7*(ROW()-ROW($B$3))+(COLUMN()-COLUMN($B$3))))=0,DAY(DATE($A$1,IFERROR(VALUE($B$1),VALUE(LEFT($B$1,FIND("월",$B$1)-1))),1)-WEEKDAY(DATE($A$1,IFERROR(VALUE($B$1),VALUE(LEFT($B$1,FIND("월",$B$1)-1))),1),1)+1+7*(ROW()-ROW($B$3))+(COLUMN()-COLUMN($B$3))),""),"") | D5: =IF(MONTH(DATE($A$1,IFERROR(VALUE($B$1),VALUE(LEFT($B$1,FIND("월",$B$1)-1))),1)-WEEKDAY(DATE($A$1,IFERROR(VALUE($B$1),VALUE(LEFT($B$1,FIND("월",$B$1)-1))),1),1)+1+7*(ROW()-ROW($B$3))+(COLUMN()-COLUMN($B$3)))=IFERROR(VALUE($B$1),VALUE(LEFT($B$1,FIND("월",$B$1)-1))),IF(COUNTIF($K$1:$K$10,DAY(DATE($A$1,IFERROR(VALUE($B$1),VALUE(LEFT($B$1,FIND("월",$B$1)-1))),1)-WEEKDAY(DATE($A$1,IFERROR(VALUE($B$1),VALUE(LEFT($B$1,FIND("월",$B$1)-1))),1),1)+1+7*(ROW()-ROW($B$3))+(COLUMN()-COLUMN($B$3))))=0,DAY(DATE($A$1,IFERROR(VALUE($B$1),VALUE(LEFT($B$1,FIND("월",$B$1)-1))),1)-WEEKDAY(DATE($A$1,IFERROR(VALUE($B$1),VALUE(LEFT($B$1,FIND("월",$B$1)-1))),1),1)+1+7*(ROW()-ROW($B$3))+(COLUMN()-COLUMN($B$3))),""),"") | E5: =IF(MONTH(DATE($A$1,IFERROR(VALUE($B$1),VALUE(LEFT($B$1,FIND("월",$B$1)-1))),1)-WEEKDAY(DATE($A$1,IFERROR(VALUE($B$1),VALUE(LEFT($B$1,FIND("월",$B$1)-1))),1),1)+1+7*(ROW()-ROW($B$3))+(COLUMN()-COLUMN($B$3)))=IFERROR(VALUE($B$1),VALUE(LEFT($B$1,FIND("월",$B$1)-1))),IF(COUNTIF($K$1:$K$10,DAY(DATE($A$1,IFERROR(VALUE($B$1),VALUE(LEFT($B$1,FIND("월",$B$1)-1))),1)-WEEKDAY(DATE($A$1,IFERROR(VALUE($B$1),VALUE(LEFT($B$1,FIND("월",$B$1)-1))),1),1)+1+7*(ROW()-ROW($B$3))+(COLUMN()-COLUMN($B$3))))=0,DAY(DATE($A$1,IFERROR(VALUE($B$1),VALUE(LEFT($B$1,FIND("월",$B$1)-1))),1)-WEEKDAY(DATE($A$1,IFERROR(VALUE($B$1),VALUE(LEFT($B$1,FIND("월",$B$1)-1))),1),1)+1+7*(ROW()-ROW($B$3))+(COLUMN()-COLUMN($B$3))),""),"") | F5: =IF(MONTH(DATE($A$1,IFERROR(VALUE($B$1),VALUE(LEFT($B$1,FIND("월",$B$1)-1))),1)-WEEKDAY(DATE($A$1,IFERROR(VALUE($B$1),VALUE(LEFT($B$1,FIND("월",$B$1)-1))),1),1)+1+7*(ROW()-ROW($B$3))+(COLUMN()-COLUMN($B$3)))=IFERROR(VALUE($B$1),VALUE(LEFT($B$1,FIND("월",$B$1)-1))),IF(COUNTIF($K$1:$K$10,DAY(DATE($A$1,IFERROR(VALUE($B$1),VALUE(LEFT($B$1,FIND("월",$B$1)-1))),1)-WEEKDAY(DATE($A$1,IFERROR(VALUE($B$1),VALUE(LEFT($B$1,FIND("월",$B$1)-1))),1),1)+1+7*(ROW()-ROW($B$3))+(COLUMN()-COLUMN($B$3))))=0,DAY(DATE($A$1,IFERROR(VALUE($B$1),VALUE(LEFT($B$1,FIND("월",$B$1)-1))),1)-WEEKDAY(DATE($A$1,IFERROR(VALUE($B$1),VALUE(LEFT($B$1,FIND("월",$B$1)-1))),1),1)+1+7*(ROW()-ROW($B$3))+(COLUMN()-COLUMN($B$3))),""),"") | G5: =IF(MONTH(DATE($A$1,IFERROR(VALUE($B$1),VALUE(LEFT($B$1,FIND("월",$B$1)-1))),1)-WEEKDAY(DATE($A$1,IFERROR(VALUE($B$1),VALUE(LEFT($B$1,FIND("월",$B$1)-1))),1),1)+1+7*(ROW()-ROW($B$3))+(COLUMN()-COLUMN($B$3)))=IFERROR(VALUE($B$1),VALUE(LEFT($B$1,FIND("월",$B$1)-1))),IF(COUNTIF($K$1:$K$10,DAY(DATE($A$1,IFERROR(VALUE($B$1),VALUE(LEFT($B$1,FIND("월",$B$1)-1))),1)-WEEKDAY(DATE($A$1,IFERROR(VALUE($B$1),VALUE(LEFT($B$1,FIND("월",$B$1)-1))),1),1)+1+7*(ROW()-ROW($B$3))+(COLUMN()-COLUMN($B$3))))=0,DAY(DATE($A$1,IFERROR(VALUE($B$1),VALUE(LEFT($B$1,FIND("월",$B$1)-1))),1)-WEEKDAY(DATE($A$1,IFERROR(VALUE($B$1),VALUE(LEFT($B$1,FIND("월",$B$1)-1))),1),1)+1+7*(ROW()-ROW($B$3))+(COLUMN()-COLUMN($B$3))),""),"") | H5: =IF(MONTH(DATE($A$1,IFERROR(VALUE($B$1),VALUE(LEFT($B$1,FIND("월",$B$1)-1))),1)-WEEKDAY(DATE($A$1,IFERROR(VALUE($B$1),VALUE(LEFT($B$1,FIND("월",$B$1)-1))),1),1)+1+7*(ROW()-ROW($B$3))+(COLUMN()-COLUMN($B$3)))=IFERROR(VALUE($B$1),VALUE(LEFT($B$1,FIND("월",$B$1)-1))),IF(COUNTIF($K$1:$K$10,DAY(DATE($A$1,IFERROR(VALUE($B$1),VALUE(LEFT($B$1,FIND("월",$B$1)-1))),1)-WEEKDAY(DATE($A$1,IFERROR(VALUE($B$1),VALUE(LEFT($B$1,FIND("월",$B$1)-1))),1),1)+1+7*(ROW()-ROW($B$3))+(COLUMN()-COLUMN($B$3))))=0,DAY(DATE($A$1,IFERROR(VALUE($B$1),VALUE(LEFT($B$1,FIND("월",$B$1)-1))),1)-WEEKDAY(DATE($A$1,IFERROR(VALUE($B$1),VALUE(LEFT($B$1,FIND("월",$B$1)-1))),1),1)+1+7*(ROW()-ROW($B$3))+(COLUMN()-COLUMN($B$3))),""),"")
B6: =IF(MONTH(DATE($A$1,IFERROR(VALUE($B$1),VALUE(LEFT($B$1,FIND("월",$B$1)-1))),1)-WEEKDAY(DATE($A$1,IFERROR(VALUE($B$1),VALUE(LEFT($B$1,FIND("월",$B$1)-1))),1),1)+1+7*(ROW()-ROW($B$3))+(COLUMN()-COLUMN($B$3)))=IFERROR(VALUE($B$1),VALUE(LEFT($B$1,FIND("월",$B$1)-1))),IF(COUNTIF($K$1:$K$10,DAY(DATE($A$1,IFERROR(VALUE($B$1),VALUE(LEFT($B$1,FIND("월",$B$1)-1))),1)-WEEKDAY(DATE($A$1,IFERROR(VALUE($B$1),VALUE(LEFT($B$1,FIND("월",$B$1)-1))),1),1)+1+7*(ROW()-ROW($B$3))+(COLUMN()-COLUMN($B$3))))=0,DAY(DATE($A$1,IFERROR(VALUE($B$1),VALUE(LEFT($B$1,FIND("월",$B$1)-1))),1)-WEEKDAY(DATE($A$1,IFERROR(VALUE($B$1),VALUE(LEFT($B$1,FIND("월",$B$1)-1))),1),1)+1+7*(ROW()-ROW($B$3))+(COLUMN()-COLUMN($B$3))),""),"") | C6: =IF(MONTH(DATE($A$1,IFERROR(VALUE($B$1),VALUE(LEFT($B$1,FIND("월",$B$1)-1))),1)-WEEKDAY(DATE($A$1,IFERROR(VALUE($B$1),VALUE(LEFT($B$1,FIND("월",$B$1)-1))),1),1)+1+7*(ROW()-ROW($B$3))+(COLUMN()-COLUMN($B$3)))=IFERROR(VALUE($B$1),VALUE(LEFT($B$1,FIND("월",$B$1)-1))),IF(COUNTIF($K$1:$K$10,DAY(DATE($A$1,IFERROR(VALUE($B$1),VALUE(LEFT($B$1,FIND("월",$B$1)-1))),1)-WEEKDAY(DATE($A$1,IFERROR(VALUE($B$1),VALUE(LEFT($B$1,FIND("월",$B$1)-1))),1),1)+1+7*(ROW()-ROW($B$3))+(COLUMN()-COLUMN($B$3))))=0,DAY(DATE($A$1,IFERROR(VALUE($B$1),VALUE(LEFT($B$1,FIND("월",$B$1)-1))),1)-WEEKDAY(DATE($A$1,IFERROR(VALUE($B$1),VALUE(LEFT($B$1,FIND("월",$B$1)-1))),1),1)+1+7*(ROW()-ROW($B$3))+(COLUMN()-COLUMN($B$3))),""),"") | D6: =IF(MONTH(DATE($A$1,IFERROR(VALUE($B$1),VALUE(LEFT($B$1,FIND("월",$B$1)-1))),1)-WEEKDAY(DATE($A$1,IFERROR(VALUE($B$1),VALUE(LEFT($B$1,FIND("월",$B$1)-1))),1),1)+1+7*(ROW()-ROW($B$3))+(COLUMN()-COLUMN($B$3)))=IFERROR(VALUE($B$1),VALUE(LEFT($B$1,FIND("월",$B$1)-1))),IF(COUNTIF($K$1:$K$10,DAY(DATE($A$1,IFERROR(VALUE($B$1),VALUE(LEFT($B$1,FIND("월",$B$1)-1))),1)-WEEKDAY(DATE($A$1,IFERROR(VALUE($B$1),VALUE(LEFT($B$1,FIND("월",$B$1)-1))),1),1)+1+7*(ROW()-ROW($B$3))+(COLUMN()-COLUMN($B$3))))=0,DAY(DATE($A$1,IFERROR(VALUE($B$1),VALUE(LEFT($B$1,FIND("월",$B$1)-1))),1)-WEEKDAY(DATE($A$1,IFERROR(VALUE($B$1),VALUE(LEFT($B$1,FIND("월",$B$1)-1))),1),1)+1+7*(ROW()-ROW($B$3))+(COLUMN()-COLUMN($B$3))),""),"") | E6: =IF(MONTH(DATE($A$1,IFERROR(VALUE($B$1),VALUE(LEFT($B$1,FIND("월",$B$1)-1))),1)-WEEKDAY(DATE($A$1,IFERROR(VALUE($B$1),VALUE(LEFT($B$1,FIND("월",$B$1)-1))),1),1)+1+7*(ROW()-ROW($B$3))+(COLUMN()-COLUMN($B$3)))=IFERROR(VALUE($B$1),VALUE(LEFT($B$1,FIND("월",$B$1)-1))),IF(COUNTIF($K$1:$K$10,DAY(DATE($A$1,IFERROR(VALUE($B$1),VALUE(LEFT($B$1,FIND("월",$B$1)-1))),1)-WEEKDAY(DATE($A$1,IFERROR(VALUE($B$1),VALUE(LEFT($B$1,FIND("월",$B$1)-1))),1),1)+1+7*(ROW()-ROW($B$3))+(COLUMN()-COLUMN($B$3))))=0,DAY(DATE($A$1,IFERROR(VALUE($B$1),VALUE(LEFT($B$1,FIND("월",$B$1)-1))),1)-WEEKDAY(DATE($A$1,IFERROR(VALUE($B$1),VALUE(LEFT($B$1,FIND("월",$B$1)-1))),1),1)+1+7*(ROW()-ROW($B$3))+(COLUMN()-COLUMN($B$3))),""),"") | F6: =IF(MONTH(DATE($A$1,IFERROR(VALUE($B$1),VALUE(LEFT($B$1,FIND("월",$B$1)-1))),1)-WEEKDAY(DATE($A$1,IFERROR(VALUE($B$1),VALUE(LEFT($B$1,FIND("월",$B$1)-1))),1),1)+1+7*(ROW()-ROW($B$3))+(COLUMN()-COLUMN($B$3)))=IFERROR(VALUE($B$1),VALUE(LEFT($B$1,FIND("월",$B$1)-1))),IF(COUNTIF($K$1:$K$10,DAY(DATE($A$1,IFERROR(VALUE($B$1),VALUE(LEFT($B$1,FIND("월",$B$1)-1))),1)-WEEKDAY(DATE($A$1,IFERROR(VALUE($B$1),VALUE(LEFT($B$1,FIND("월",$B$1)-1))),1),1)+1+7*(ROW()-ROW($B$3))+(COLUMN()-COLUMN($B$3))))=0,DAY(DATE($A$1,IFERROR(VALUE($B$1),VALUE(LEFT($B$1,FIND("월",$B$1)-1))),1)-WEEKDAY(DATE($A$1,IFERROR(VALUE($B$1),VALUE(LEFT($B$1,FIND("월",$B$1)-1))),1),1)+1+7*(ROW()-ROW($B$3))+(COLUMN()-COLUMN($B$3))),""),"") | G6: =IF(MONTH(DATE($A$1,IFERROR(VALUE($B$1),VALUE(LEFT($B$1,FIND("월",$B$1)-1))),1)-WEEKDAY(DATE($A$1,IFERROR(VALUE($B$1),VALUE(LEFT($B$1,FIND("월",$B$1)-1))),1),1)+1+7*(ROW()-ROW($B$3))+(COLUMN()-COLUMN($B$3)))=IFERROR(VALUE($B$1),VALUE(LEFT($B$1,FIND("월",$B$1)-1))),IF(COUNTIF($K$1:$K$10,DAY(DATE($A$1,IFERROR(VALUE($B$1),VALUE(LEFT($B$1,FIND("월",$B$1)-1))),1)-WEEKDAY(DATE($A$1,IFERROR(VALUE($B$1),VALUE(LEFT($B$1,FIND("월",$B$1)-1))),1),1)+1+7*(ROW()-ROW($B$3))+(COLUMN()-COLUMN($B$3))))=0,DAY(DATE($A$1,IFERROR(VALUE($B$1),VALUE(LEFT($B$1,FIND("월",$B$1)-1))),1)-WEEKDAY(DATE($A$1,IFERROR(VALUE($B$1),VALUE(LEFT($B$1,FIND("월",$B$1)-1))),1),1)+1+7*(ROW()-ROW($B$3))+(COLUMN()-COLUMN($B$3))),""),"") | H6: =IF(MONTH(DATE($A$1,IFERROR(VALUE($B$1),VALUE(LEFT($B$1,FIND("월",$B$1)-1))),1)-WEEKDAY(DATE($A$1,IFERROR(VALUE($B$1),VALUE(LEFT($B$1,FIND("월",$B$1)-1))),1),1)+1+7*(ROW()-ROW($B$3))+(COLUMN()-COLUMN($B$3)))=IFERROR(VALUE($B$1),VALUE(LEFT($B$1,FIND("월",$B$1)-1))),IF(COUNTIF($K$1:$K$10,DAY(DATE($A$1,IFERROR(VALUE($B$1),VALUE(LEFT($B$1,FIND("월",$B$1)-1))),1)-WEEKDAY(DATE($A$1,IFERROR(VALUE($B$1),VALUE(LEFT($B$1,FIND("월",$B$1)-1))),1),1)+1+7*(ROW()-ROW($B$3))+(COLUMN()-COLUMN($B$3))))=0,DAY(DATE($A$1,IFERROR(VALUE($B$1),VALUE(LEFT($B$1,FIND("월",$B$1)-1))),1)-WEEKDAY(DATE($A$1,IFERROR(VALUE($B$1),VALUE(LEFT($B$1,FIND("월",$B$1)-1))),1),1)+1+7*(ROW()-ROW($B$3))+(COLUMN()-COLUMN($B$3))),""),"")
