Workbook
Name holidays: #REF!
Name holidays: 화목!$J$1:$J$5
Name holidays: 수금!$J$1:$J$5
Name holidays: 토!$J$1:$J$5

Sheet 2단지 성인수영-초급(화목06시30분김소운)
A1: {=_xlfn.LET( _xlpm.FullName, _xlfn.SINGLE(CELL("filename", A1)), _xlpm.SheetName, MID(_xlpm.FullName, FIND("]", _xlpm.FullName) + 1, 255), _xlpm.RemoveFront, REPLACE(_xlpm.SheetName, 1, 4, ""), _xlpm.ClassPart, SUBSTITUTE(LEFT(_xlpm.RemoveFront, FIND("(", _xlpm.RemoveFront) - 1), "-", " "), _xlpm.TimePart, MID(_xlpm.RemoveFront, FIND("(", _xlpm.RemoveFront) + 1, FIND(")", _xlpm.RemoveFront) - FIND("(", _xlpm.RemoveFront) - 4), _xlpm.ClassPart & " " & _xlpm.TimePart & " 출석부" )}
K2: 김소운 강사
A3: NO | B3: 성명 | C3: 동 | D3: 호수 | E3: 연락처 | F3: =화목!B1
F4: =화목!B11 | G4: =화목!C11 | H4: =화목!D11 | I4: =화목!E11 | J4: =화목!F11 | K4: =화목!G11 | L4: =화목!H11 | M4: =화목!I11
A5: 1
A6: 2
A7: 3
A8: 4
A9: 5
A10: 6
A11: 7
A12: 8
A13: 9
A14: 10
A15: 11
A16: 12
... A34: 30
A35: =A1
A36: NO | B36: 성명 | C36: 동 | D36: 호수 | E36: 연락처 | F36: =F3
F37: =F4 | G37: =G4 | H37: =H4 | I37: =I4 | J37: =J4 | K37: =K4 | L37: =L4 | M37: =M4
A38: 31
A39: 32
A40: 33
A41: 34
A42: 35
A43: 36
A44: 37
A45: 38
A46: 39
A47: 40
A48: 41
A49: 42
... A67: 60

Sheet 2단지 성인수영-초급(화목07시30분김소운)
A1: {=_xlfn.LET( _xlpm.FullName, _xlfn.SINGLE(CELL("filename", A1)), _xlpm.SheetName, MID(_xlpm.FullName, FIND("]", _xlpm.FullName) + 1, 255), _xlpm.RemoveFront, REPLACE(_xlpm.SheetName, 1, 4, ""), _xlpm.ClassPart, SUBSTITUTE(LEFT(_xlpm.RemoveFront, FIND("(", _xlpm.RemoveFront) - 1), "-", " "), _xlpm.TimePart, MID(_xlpm.RemoveFront, FIND("(", _xlpm.RemoveFront) + 1, FIND(")", _xlpm.RemoveFront) - FIND("(", _xlpm.RemoveFront) - 4), _xlpm.ClassPart & " " & _xlpm.TimePart & " 출석부" )}
K2: 김소운 강사
A3: NO | B3: 성명 | C3: 동 | D3: 호수 | E3: 연락처 | F3: =화목!B1
F4: =화목!B11 | G4: =화목!C11 | H4: =화목!D11 | I4: =화목!E11 | J4: =화목!F11 | K4: =화목!G11 | L4: =화목!H11 | M4: =화목!I11
A5: 1
A6: 2
A7: 3
A8: 4
A9: 5
A10: 6
A11: 7
A12: 8
A13: 9
A14: 10
A15: 11
A16: 12
... A34: 30
A35: =A1
A36: NO | B36: 성명 | C36: 동 | D36: 호수 | E36: 연락처 | F36: =F3
F37: =F4 | G37: =G4 | H37: =H4 | I37: =I4 | J37: =J4 | K37: =K4 | L37: =L4 | M37: =M4
A38: 31
A39: 32
A40: 33
A41: 34
A42: 35
A43: 36
A44: 37
A45: 38
A46: 39
A47: 40
A48: 41
A49: 42
... A67: 60

Sheet 2단지 성인수영-초급(화목09시김소운)
A1: {=_xlfn.LET( _xlpm.FullName, _xlfn.SINGLE(CELL("filename", A1)), _xlpm.SheetName, MID(_xlpm.FullName, FIND("]", _xlpm.FullName) + 1, 255), _xlpm.RemoveFront, REPLACE(_xlpm.SheetName, 1, 4, ""), _xlpm.ClassPart, SUBSTITUTE(LEFT(_xlpm.RemoveFront, FIND("(", _xlpm.RemoveFront) - 1), "-", " "), _xlpm.TimePart, MID(_xlpm.RemoveFront, FIND("(", _xlpm.RemoveFront) + 1, FIND(")", _xlpm.RemoveFront) - FIND("(", _xlpm.RemoveFront) - 4), _xlpm.ClassPart & " " & _xlpm.TimePart & " 출석부" )}
K2: 김소운 강사
A3: NO | B3: 성명 | C3: 동 | D3: 호수 | E3: 연락처 | F3: =화목!B1
F4: =화목!B11 | G4: =화목!C11 | H4: =화목!D11 | I4: =화목!E11 | J4: =화목!F11 | K4: =화목!G11 | L4: =화목!H11 | M4: =화목!I11
A5: 1
A6: 2
A7: 3
A8: 4
A9: 5
A10: 6
A11: 7
A12: 8
A13: 9
A14: 10
A15: 11
A16: 12
... A34: 30
A35: =A1
A36: NO | B36: 성명 | C36: 동 | D36: 호수 | E36: 연락처 | F36: =F3
F37: =F4 | G37: =G4 | H37: =H4 | I37: =I4 | J37: =J4 | K37: =K4 | L37: =L4 | M37: =M4
A38: 31
A39: 32
A40: 33
A41: 34
A42: 35
A43: 36
A44: 37
A45: 38
A46: 39
A47: 40
A48: 41
A49: 42
... A67: 60

Sheet 2단지 성인수영-초급(화목10시김소운)
A1: {=_xlfn.LET( _xlpm.FullName, _xlfn.SINGLE(CELL("filename", A1)), _xlpm.SheetName, MID(_xlpm.FullName, FIND("]", _xlpm.FullName) + 1, 255), _xlpm.RemoveFront, REPLACE(_xlpm.SheetName, 1, 4, ""), _xlpm.ClassPart, SUBSTITUTE(LEFT(_xlpm.RemoveFront, FIND("(", _xlpm.RemoveFront) - 1), "-", " "), _xlpm.TimePart, MID(_xlpm.RemoveFront, FIND("(", _xlpm.RemoveFront) + 1, FIND(")", _xlpm.RemoveFront) - FIND("(", _xlpm.RemoveFront) - 4), _xlpm.ClassPart & " " & _xlpm.TimePart & " 출석부" )}
K2: 김소운 강사
A3: NO | B3: 성명 | C3: 동 | D3: 호수 | E3: 연락처 | F3: =화목!B1
F4: =화목!B11 | G4: =화목!C11 | H4: =화목!D11 | I4: =화목!E11 | J4: =화목!F11 | K4: =화목!G11 | L4: =화목!H11 | M4: =화목!I11
A5: 1
A6: 2
A7: 3
A8: 4
A9: 5
A10: 6
A11: 7
A12: 8
A13: 9
A14: 10
A15: 11
A16: 12
... A34: 30
A35: =A1
A36: NO | B36: 성명 | C36: 동 | D36: 호수 | E36: 연락처 | F36: =F3
F37: =F4 | G37: =G4 | H37: =H4 | I37: =I4 | J37: =J4 | K37: =K4 | L37: =L4 | M37: =M4
A38: 31
A39: 32
A40: 33
A41: 34
A42: 35
A43: 36
A44: 37
A45: 38
A46: 39
A47: 40
A48: 41
A49: 42
... A67: 60

Sheet 2단지 성인수영-중급(수금06시30분김소운)
A1: {=_xlfn.LET( _xlpm.FullName, _xlfn.SINGLE(CELL("filename", A1)), _xlpm.SheetName, MID(_xlpm.FullName, FIND("]", _xlpm.FullName) + 1, 255), _xlpm.RemoveFront, REPLACE(_xlpm.SheetName, 1, 4, ""), _xlpm.ClassPart, SUBSTITUTE(LEFT(_xlpm.RemoveFront, FIND("(", _xlpm.RemoveFront) - 1), "-", " "), _xlpm.TimePart, MID(_xlpm.RemoveFront, FIND("(", _xlpm.RemoveFront) + 1, FIND(")", _xlpm.RemoveFront) - FIND("(", _xlpm.RemoveFront) - 4), _xlpm.ClassPart & " " & _xlpm.TimePart & " 출석부" )}
K2: 김소운 강사
A3: NO | B3: 성명 | C3: 동 | D3: 호수 | E3: 연락처 | F3: =수금!B1
F4: =수금!B11 | G4: =수금!C11 | H4: =수금!D11 | I4: =수금!E11 | J4: =수금!F11 | K4: =수금!G11 | L4: =수금!H11 | M4: =수금!I11
A5: 1
A6: 2
A7: 3
A8: 4
A9: 5
A10: 6
A11: 7
A12: 8
A13: 9
A14: 10
A15: 11
A16: 12
... A34: 30
A35: =A1
A36: NO | B36: 성명 | C36: 동 | D36: 호수 | E36: 연락처 | F36: =F3
F37: =F4 | G37: =G4 | H37: =H4 | I37: =I4 | J37: =J4 | K37: =K4 | L37: =L4 | M37: =M4
A38: 31
A39: 32
A40: 33
A41: 34
A42: 35
A43: 36
A44: 37
A45: 38
A46: 39
A47: 40
A48: 41
A49: 42
... A67: 60

Sheet 2단지 성인수영-중급(수금07시30분김소운)
A1: {=_xlfn.LET( _xlpm.FullName, _xlfn.SINGLE(CELL("filename", A1)), _xlpm.SheetName, MID(_xlpm.FullName, FIND("]", _xlpm.FullName) + 1, 255), _xlpm.RemoveFront, REPLACE(_xlpm.SheetName, 1, 4, ""), _xlpm.ClassPart, SUBSTITUTE(LEFT(_xlpm.RemoveFront, FIND("(", _xlpm.RemoveFront) - 1), "-", " "), _xlpm.TimePart, MID(_xlpm.RemoveFront, FIND("(", _xlpm.RemoveFront) + 1, FIND(")", _xlpm.RemoveFront) - FIND("(", _xlpm.RemoveFront) - 4), _xlpm.ClassPart & " " & _xlpm.TimePart & " 출석부" )}
K2: 김소운 강사
A3: NO | B3: 성명 | C3: 동 | D3: 호수 | E3: 연락처 | F3: =수금!B1
F4: =수금!B11 | G4: =수금!C11 | H4: =수금!D11 | I4: =수금!E11 | J4: =수금!F11 | K4: =수금!G11 | L4: =수금!H11 | M4: =수금!I11
A5: 1
A6: 2
A7: 3
A8: 4
A9: 5
A10: 6
A11: 7
A12: 8
A13: 9
A14: 10
A15: 11
A16: 12
... A34: 30
A35: =A1
A36: NO | B36: 성명 | C36: 동 | D36: 호수 | E36: 연락처 | F36: =F3
F37: =F4 | G37: =G4 | H37: =H4 | I37: =I4 | J37: =J4 | K37: =K4 | L37: =L4 | M37: =M4
A38: 31
A39: 32
A40: 33
A41: 34
A42: 35
A43: 36
A44: 37
A45: 38
A46: 39
A47: 40
A48: 41
A49: 42
... A67: 60

Sheet 2단지 성인수영-중급(수금09시김소운)
A1: {=_xlfn.LET( _xlpm.FullName, _xlfn.SINGLE(CELL("filename", A1)), _xlpm.SheetName, MID(_xlpm.FullName, FIND("]", _xlpm.FullName) + 1, 255), _xlpm.RemoveFront, REPLACE(_xlpm.SheetName, 1, 4, ""), _xlpm.ClassPart, SUBSTITUTE(LEFT(_xlpm.RemoveFront, FIND("(", _xlpm.RemoveFront) - 1), "-", " "), _xlpm.TimePart, MID(_xlpm.RemoveFront, FIND("(", _xlpm.RemoveFront) + 1, FIND(")", _xlpm.RemoveFront) - FIND("(", _xlpm.RemoveFront) - 4), _xlpm.ClassPart & " " & _xlpm.TimePart & " 출석부" )}
K2: 김소운 강사
A3: NO | B3: 성명 | C3: 동 | D3: 호수 | E3: 연락처 | F3: =수금!B1
F4: =수금!B11 | G4: =수금!C11 | H4: =수금!D11 | I4: =수금!E11 | J4: =수금!F11 | K4: =수금!G11 | L4: =수금!H11 | M4: =수금!I11
A5: 1
A6: 2
A7: 3
A8: 4
A9: 5
A10: 6
A11: 7
A12: 8
A13: 9
A14: 10
A15: 11
A16: 12
... A34: 30
A35: =A1
A36: NO | B36: 성명 | C36: 동 | D36: 호수 | E36: 연락처 | F36: =F3
F37: =F4 | G37: =G4 | H37: =H4 | I37: =I4 | J37: =J4 | K37: =K4 | L37: =L4 | M37: =M4
A38: 31
A39: 32
A40: 33
A41: 34
A42: 35
A43: 36
A44: 37
A45: 38
A46: 39
A47: 40
A48: 41
A49: 42
... A67: 60

Sheet 2단지 성인수영-중급(수금10시김소운)
A1: {=_xlfn.LET( _xlpm.FullName, _xlfn.SINGLE(CELL("filename", A1)), _xlpm.SheetName, MID(_xlpm.FullName, FIND("]", _xlpm.FullName) + 1, 255), _xlpm.RemoveFront, REPLACE(_xlpm.SheetName, 1, 4, ""), _xlpm.ClassPart, SUBSTITUTE(LEFT(_xlpm.RemoveFront, FIND("(", _xlpm.RemoveFront) - 1), "-", " "), _xlpm.TimePart, MID(_xlpm.RemoveFront, FIND("(", _xlpm.RemoveFront) + 1, FIND(")", _xlpm.RemoveFront) - FIND("(", _xlpm.RemoveFront) - 4), _xlpm.ClassPart & " " & _xlpm.TimePart & " 출석부" )}
K2: 김소운 강사
A3: NO | B3: 성명 | C3: 동 | D3: 호수 | E3: 연락처 | F3: =수금!B1
F4: =수금!B11 | G4: =수금!C11 | H4: =수금!D11 | I4: =수금!E11 | J4: =수금!F11 | K4: =수금!G11 | L4: =수금!H11 | M4: =수금!I11
A5: 1
A6: 2
A7: 3
A8: 4
A9: 5
A10: 6
A11: 7
A12: 8
A13: 9
A14: 10
A15: 11
A16: 12
... A34: 30
A35: =A1
A36: NO | B36: 성명 | C36: 동 | D36: 호수 | E36: 연락처 | F36: =F3
F37: =F4 | G37: =G4 | H37: =H4 | I37: =I4 | J37: =J4 | K37: =K4 | L37: =L4 | M37: =M4
A38: 31
A39: 32
A40: 33
A41: 34
A42: 35
A43: 36
A44: 37
A45: 38
A46: 39
A47: 40
A48: 41
A49: 42
... A67: 60

Sheet 2단지 성인수영-상급(토06시30분김소운)
A1: {=_xlfn.LET( _xlpm.FullName, _xlfn.SINGLE(CELL("filename", A1)), _xlpm.SheetName, MID(_xlpm.FullName, FIND("]", _xlpm.FullName) + 1, 255), _xlpm.RemoveFront, REPLACE(_xlpm.SheetName, 1, 4, ""), _xlpm.ClassPart, SUBSTITUTE(LEFT(_xlpm.RemoveFront, FIND("(", _xlpm.RemoveFront) - 1), "-", " "), _xlpm.TimePart, MID(_xlpm.RemoveFront, FIND("(", _xlpm.RemoveFront) + 1, FIND(")", _xlpm.RemoveFront) - FIND("(", _xlpm.RemoveFront) - 4), _xlpm.ClassPart & " " & _xlpm.TimePart & " 출석부" )}
K2: 김소운 강사
A3: NO | B3: 성명 | C3: 동 | D3: 호수 | E3: 연락처 | F3: =토!B1
F4: =토!B11 | G4: =토!C11 | H4: =토!D11 | I4: =토!E11
A5: 1
A6: 2
A7: 3
A8: 4
A9: 5
A10: 6
A11: 7
A12: 8
A13: 9
A14: 10
A15: 11
A16: 12
... A34: 30
A35: =A1
A36: NO | B36: 성명 | C36: 동 | D36: 호수 | E36: 연락처 | F36: =F3
F37: =F4 | G37: =G4 | H37: =H4 | I37: =I4
A38: 31
A39: 32
A40: 33
A41: 34
A42: 35
A43: 36
A44: 37
A45: 38
A46: 39
A47: 40
A48: 41
A49: 42
... A67: 60

Sheet 2단지 성인수영-상급(토07시30분김소운)
A1: {=_xlfn.LET( _xlpm.FullName, _xlfn.SINGLE(CELL("filename", A1)), _xlpm.SheetName, MID(_xlpm.FullName, FIND("]", _xlpm.FullName) + 1, 255), _xlpm.RemoveFront, REPLACE(_xlpm.SheetName, 1, 4, ""), _xlpm.ClassPart, SUBSTITUTE(LEFT(_xlpm.RemoveFront, FIND("(", _xlpm.RemoveFront) - 1), "-", " "), _xlpm.TimePart, MID(_xlpm.RemoveFront, FIND("(", _xlpm.RemoveFront) + 1, FIND(")", _xlpm.RemoveFront) - FIND("(", _xlpm.RemoveFront) - 4), _xlpm.ClassPart & " " & _xlpm.TimePart & " 출석부" )}
K2: 김소운 강사
A3: NO | B3: 성명 | C3: 동 | D3: 호수 | E3: 연락처 | F3: =토!B1
F4: =토!B11 | G4: =토!C11 | H4: =토!D11 | I4: =토!E11
A5: 1
A6: 2
A7: 3
A8: 4
A9: 5
A10: 6
A11: 7
A12: 8
A13: 9
A14: 10
A15: 11
A16: 12
... A34: 30
A35: =A1
A36: NO | B36: 성명 | C36: 동 | D36: 호수 | E36: 연락처 | F36: =F3
F37: =F4 | G37: =G4 | H37: =H4 | I37: =I4
A38: 31
A39: 32
A40: 33
A41: 34
A42: 35
A43: 36
A44: 37
A45: 38
A46: 39
A47: 40
A48: 41
A49: 42
... A67: 60

Sheet 2단지 성인수영-중상급(토09시김소운)
A1: {=_xlfn.LET( _xlpm.FullName, _xlfn.SINGLE(CELL("filename", A1)), _xlpm.SheetName, MID(_xlpm.FullName, FIND("]", _xlpm.FullName) + 1, 255), _xlpm.RemoveFront, REPLACE(_xlpm.SheetName, 1, 4, ""), _xlpm.ClassPart, SUBSTITUTE(LEFT(_xlpm.RemoveFront, FIND("(", _xlpm.RemoveFront) - 1), "-", " "), _xlpm.TimePart, MID(_xlpm.RemoveFront, FIND("(", _xlpm.RemoveFront) + 1, FIND(")", _xlpm.RemoveFront) - FIND("(", _xlpm.RemoveFront) - 4), _xlpm.ClassPart & " " & _xlpm.TimePart & " 출석부" )}
K2: 김소운 강사
A3: NO | B3: 성명 | C3: 동 | D3: 호수 | E3: 연락처 | F3: =토!B1
F4: =토!B11 | G4: =토!C11 | H4: =토!D11 | I4: =토!E11
A5: 1
A6: 2
A7: 3
A8: 4
A9: 5
A10: 6
A11: 7
A12: 8
A13: 9
A14: 10
A15: 11
A16: 12
... A34: 30
A35: =A1
A36: NO | B36: 성명 | C36: 동 | D36: 호수 | E36: 연락처 | F36: =F3
F37: =F4 | G37: =G4 | H37: =H4 | I37: =I4
A38: 31
A39: 32
A40: 33
A41: 34
A42: 35
A43: 36
A44: 37
A45: 38
A46: 39
A47: 40
A48: 41
A49: 42
... A67: 60

Sheet 2단지 성인수영-중상급(토10시김소운)
A1: {=_xlfn.LET( _xlpm.FullName, _xlfn.SINGLE(CELL("filename", A1)), _xlpm.SheetName, MID(_xlpm.FullName, FIND("]", _xlpm.FullName) + 1, 255), _xlpm.RemoveFront, REPLACE(_xlpm.SheetName, 1, 4, ""), _xlpm.ClassPart, SUBSTITUTE(LEFT(_xlpm.RemoveFront, FIND("(", _xlpm.RemoveFront) - 1), "-", " "), _xlpm.TimePart, MID(_xlpm.RemoveFront, FIND("(", _xlpm.RemoveFront) + 1, FIND(")", _xlpm.RemoveFront) - FIND("(", _xlpm.RemoveFront) - 4), _xlpm.ClassPart & " " & _xlpm.TimePart & " 출석부" )}
K2: 김소운 강사
A3: NO | B3: 성명 | C3: 동 | D3: 호수 | E3: 연락처 | F3: =토!B1
F4: =토!B11 | G4: =토!C11 | H4: =토!D11 | I4: =토!E11
A5: 1
A6: 2
A7: 3
A8: 4
A9: 5
A10: 6
A11: 7
A12: 8
A13: 9
A14: 10
A15: 11
A16: 12
... A34: 30
A35: =A1
A36: NO | B36: 성명 | C36: 동 | D36: 호수 | E36: 연락처 | F36: =F3
F37: =F4 | G37: =G4 | H37: =H4 | I37: =I4
A38: 31
A39: 32
A40: 33
A41: 34
A42: 35
A43: 36
A44: 37
A45: 38
A46: 39
A47: 40
A48: 41
A49: 42
... A67: 60

Sheet 화목
A1: 2026 | B1: 6월 | K1: 공휴일
A2: 화 | B2: 일 | C2: 월 | D2: 화 | E2: 수 | F2: 목 | G2: 금 | H2: 토 | K2: 3
A3: 목 | B3: =IF(MONTH(DATE($A$1,IFERROR(VALUE($B$1),VALUE(LEFT($B$1,FIND("월",$B$1)-1))),1)-WEEKDAY(DATE($A$1,IFERROR(VALUE($B$1),VALUE(LEFT($B$1,FIND("월",$B$1)-1))),1),1)+1+7*(ROW()-ROW($B$3))+(COLUMN()-COLUMN($B$3)))=IFERROR(VALUE($B$1),VALUE(LEFT($B$1,FIND("월",$B$1)-1))),IF(COUNTIF($K$1:$K$10,DAY(DATE($A$1,IFERROR(VALUE($B$1),VALUE(LEFT($B$1,FIND("월",$B$1)-1))),1)-WEEKDAY(DATE($A$1,IFERROR(VALUE($B$1),VALUE(LEFT($B$1,FIND("월",$B$1)-1))),1),1)+1+7*(ROW()-ROW($B$3))+(COLUMN()-COLUMN($B$3))))=0,DAY(DATE($A$1,IFERROR(VALUE($B$1),VALUE(LEFT($B$1,FIND("월",$B$1)-1))),1)-WEEKDAY(DATE($A$1,IFERROR(VALUE($B$1),VALUE(LEFT($B$1,FIND("월",$B$1)-1))),1),1)+1+7*(ROW()-ROW($B$3))+(COLUMN()-COLUMN($B$3))),""),"") | C3: =IF(MONTH(DATE($A$1,IFERROR(VALUE($B$1),VALUE(LEFT($B$1,FIND("월",$B$1)-1))),1)-WEEKDAY(DATE($A$1,IFERROR(VALUE($B$1),VALUE(LEFT($B$1,FIND("월",$B$1)-1))),1),1)+1+7*(ROW()-ROW($B$3))+(COLUMN()-COLUMN($B$3)))=IFERROR(VALUE($B$1),VALUE(LEFT($B$1,FIND("월",$B$1)-1))),IF(COUNTIF($K$1:$K$10,DAY(DATE($A$1,IFERROR(VALUE($B$1),VALUE(LEFT($B$1,FIND("월",$B$1)-1))),1)-WEEKDAY(DATE($A$1,IFERROR(VALUE($B$1),VALUE(LEFT($B$1,FIND("월",$B$1)-1))),1),1)+1+7*(ROW()-ROW($B$3))+(COLUMN()-COLUMN($B$3))))=0,DAY(DATE($A$1,IFERROR(VALUE($B$1),VALUE(LEFT($B$1,FIND("월",$B$1)-1))),1)-WEEKDAY(DATE($A$1,IFERROR(VALUE($B$1),VALUE(LEFT($B$1,FIND("월",$B$1)-1))),1),1)+1+7*(ROW()-ROW($B$3))+(COLUMN()-COLUMN($B$3))),""),"") | D3: =IF(MONTH(DATE($A$1,IFERROR(VALUE($B$1),VALUE(LEFT($B$1,FIND("월",$B$1)-1))),1)-WEEKDAY(DATE($A$1,IFERROR(VALUE($B$1),VALUE(LEFT($B$1,FIND("월",$B$1)-1))),1),1)+1+7*(ROW()-ROW($B$3))+(COLUMN()-COLUMN($B$3)))=IFERROR(VALUE($B$1),VALUE(LEFT($B$1,FIND("월",$B$1)-1))),IF(COUNTIF($K$1:$K$10,DAY(DATE($A$1,IFERROR(VALUE($B$1),VALUE(LEFT($B$1,FIND("월",$B$1)-1))),1)-WEEKDAY(DATE($A$1,IFERROR(VALUE($B$1),VALUE(LEFT($B$1,FIND("월",$B$1)-1))),1),1)+1+7*(ROW()-ROW($B$3))+(COLUMN()-COLUMN($B$3))))=0,DAY(DATE($A$1,IFERROR(VALUE($B$1),VALUE(LEFT($B$1,FIND("월",$B$1)-1))),1)-WEEKDAY(DATE($A$1,IFERROR(VALUE($B$1),VALUE(LEFT($B$1,FIND("월",$B$1)-1))),1),1)+1+7*(ROW()-ROW($B$3))+(COLUMN()-COLUMN($B$3))),""),"") | E3: =IF(MONTH(DATE($A$1,IFERROR(VALUE($B$1),VALUE(LEFT($B$1,FIND("월",$B$1)-1))),1)-WEEKDAY(DATE($A$1,IFERROR(VALUE($B$1),VALUE(LEFT($B$1,FIND("월",$B$1)-1))),1),1)+1+7*(ROW()-ROW($B$3))+(COLUMN()-COLUMN($B$3)))=IFERROR(VALUE($B$1),VALUE(LEFT($B$1,FIND("월",$B$1)-1))),IF(COUNTIF($K$1:$K$10,DAY(DATE($A$1,IFERROR(VALUE($B$1),VALUE(LEFT($B$1,FIND("월",$B$1)-1))),1)-WEEKDAY(DATE($A$1,IFERROR(VALUE($B$1),VALUE(LEFT($B$1,FIND("월",$B$1)-1))),1),1)+1+7*(ROW()-ROW($B$3))+(COLUMN()-COLUMN($B$3))))=0,DAY(DATE($A$1,IFERROR(VALUE($B$1),VALUE(LEFT($B$1,FIND("월",$B$1)-1))),1)-WEEKDAY(DATE($A$1,IFERROR(VALUE($B$1),VALUE(LEFT($B$1,FIND("월",$B$1)-1))),1),1)+1+7*(ROW()-ROW($B$3))+(COLUMN()-COLUMN($B$3))),""),"") | F3: =IF(MONTH(DATE($A$1,IFERROR(VALUE($B$1),VALUE(LEFT($B$1,FIND("월",$B$1)-1))),1)-WEEKDAY(DATE($A$1,IFERROR(VALUE($B$1),VALUE(LEFT($B$1,FIND("월",$B$1)-1))),1),1)+1+7*(ROW()-ROW($B$3))+(COLUMN()-COLUMN($B$3)))=IFERROR(VALUE($B$1),VALUE(LEFT($B$1,FIND("월",$B$1)-1))),IF(COUNTIF($K$1:$K$10,DAY(DATE($A$1,IFERROR(VALUE($B$1),VALUE(LEFT($B$1,FIND("월",$B$1)-1))),1)-WEEKDAY(DATE($A$1,IFERROR(VALUE($B$1),VALUE(LEFT($B$1,FIND("월",$B$1)-1))),1),1)+1+7*(ROW()-ROW($B$3))+(COLUMN()-COLUMN($B$3))))=0,DAY(DATE($A$1,IFERROR(VALUE($B$1),VALUE(LEFT($B$1,FIND("월",$B$1)-1))),1)-WEEKDAY(DATE($A$1,IFERROR(VALUE($B$1),VALUE(LEFT($B$1,FIND("월",$B$1)-1))),1),1)+1+7*(ROW()-ROW($B$3))+(COLUMN()-COLUMN($B$3))),""),"") | G3: =IF(MONTH(DATE($A$1,IFERROR(VALUE($B$1),VALUE(LEFT($B$1,FIND("월",$B$1)-1))),1)-WEEKDAY(DATE($A$1,IFERROR(VALUE($B$1),VALUE(LEFT($B$1,FIND("월",$B$1)-1))),1),1)+1+7*(ROW()-ROW($B$3))+(COLUMN()-COLUMN($B$3)))=IFERROR(VALUE($B$1),VALUE(LEFT($B$1,FIND("월",$B$1)-1))),IF(COUNTIF($K$1:$K$10,DAY(DATE($A$1,IFERROR(VALUE($B$1),VALUE(LEFT($B$1,FIND("월",$B$1)-1))),1)-WEEKDAY(DATE($A$1,IFERROR(VALUE($B$1),VALUE(LEFT($B$1,FIND("월",$B$1)-1))),1),1)+1+7*(ROW()-ROW($B$3))+(COLUMN()-COLUMN($B$3))))=0,DAY(DATE($A$1,IFERROR(VALUE($B$1),VALUE(LEFT($B$1,FIND("월",$B$1)-1))),1)-WEEKDAY(DATE($A$1,IFERROR(VALUE($B$1),VALUE(LEFT($B$1,FIND("월",$B$1)-1))),1),1)+1+7*(ROW()-ROW($B$3))+(COLUMN()-COLUMN($B$3))),""),"") | H3: =IF(MONTH(DATE($A$1,IFERROR(VALUE($B$1),VALUE(LEFT($B$1,FIND("월",$B$1)-1))),1)-WEEKDAY(DATE($A$1,IFERROR(VALUE($B$1),VALUE(LEFT($B$1,FIND("월",$B$1)-1))),1),1)+1+7*(ROW()-ROW($B$3))+(COLUMN()-COLUMN($B$3)))=IFERROR(VALUE($B$1),VALUE(LEFT($B$1,FIND("월",$B$1)-1))),IF(COUNTIF($K$1:$K$10,DAY(DATE($A$1,IFERROR(VALUE($B$1),VALUE(LEFT($B$1,FIND("월",$B$1)-1))),1)-WEEKDAY(DATE($A$1,IFERROR(VALUE($B$1),VALUE(LEFT($B$1,FIND("월",$B$1)-1))),1),1)+1+7*(ROW()-ROW($B$3))+(COLUMN()-COLUMN($B$3))))=0,DAY(DATE($A$1,IFERROR(VALUE($B$1),VALUE(LEFT($B$1,FIND("월",$B$1)-1))),1)-WEEKDAY(DATE($A$1,IFERROR(VALUE($B$1),VALUE(LEFT($B$1,FIND("월",$B$1)-1))),1),1)+1+7*(ROW()-ROW($B$3))+(COLUMN()-COLUMN($B$3))),""),"") | K3: 6
B4: =IF(MONTH(DATE($A$1,IFERROR(VALUE($B$1),VALUE(LEFT($B$1,FIND("월",$B$1)-1))),1)-WEEKDAY(DATE($A$1,IFERROR(VALUE($B$1),VALUE(LEFT($B$1,FIND("월",$B$1)-1))),1),1)+1+7*(ROW()-ROW($B$3))+(COLUMN()-COLUMN($B$3)))=IFERROR(VALUE($B$1),VALUE(LEFT($B$1,FIND("월",$B$1)-1))),IF(COUNTIF($K$1:$K$10,DAY(DATE($A$1,IFERROR(VALUE($B$1),VALUE(LEFT($B$1,FIND("월",$B$1)-1))),1)-WEEKDAY(DATE($A$1,IFERROR(VALUE($B$1),VALUE(LEFT($B$1,FIND("월",$B$1)-1))),1),1)+1+7*(ROW()-ROW($B$3))+(COLUMN()-COLUMN($B$3))))=0,DAY(DATE($A$1,IFERROR(VALUE($B$1),VALUE(LEFT($B$1,FIND("월",$B$1)-1))),1)-WEEKDAY(DATE($A$1,IFERROR(VALUE($B$1),VALUE(LEFT($B$1,FIND("월",$B$1)-1))),1),1)+1+7*(ROW()-ROW($B$3))+(COLUMN()-COLUMN($B$3))),""),"") | C4: =IF(MONTH(DATE($A$1,IFERROR(VALUE($B$1),VALUE(LEFT($B$1,FIND("월",$B$1)-1))),1)-WEEKDAY(DATE($A$1,IFERROR(VALUE($B$1),VALUE(LEFT($B$1,FIND("월",$B$1)-1))),1),1)+1+7*(ROW()-ROW($B$3))+(COLUMN()-COLUMN($B$3)))=IFERROR(VALUE($B$1),VALUE(LEFT($B$1,FIND("월",$B$1)-1))),IF(COUNTIF($K$1:$K$10,DAY(DATE($A$1,IFERROR(VALUE($B$1),VALUE(LEFT($B$1,FIND("월",$B$1)-1))),1)-WEEKDAY(DATE($A$1,IFERROR(VALUE($B$1),VALUE(LEFT($B$1,FIND("월",$B$1)-1))),1),1)+1+7*(ROW()-ROW($B$3))+(COLUMN()-COLUMN($B$3))))=0,DAY(DATE($A$1,IFERROR(VALUE($B$1),VALUE(LEFT($B$1,FIND("월",$B$1)-1))),1)-WEEKDAY(DATE($A$1,IFERROR(VALUE($B$1),VALUE(LEFT($B$1,FIND("월",$B$1)-1))),1),1)+1+7*(ROW()-ROW($B$3))+(COLUMN()-COLUMN($B$3))),""),"") | D4: =IF(MONTH(DATE($A$1,IFERROR(VALUE($B$1),VALUE(LEFT($B$1,FIND("월",$B$1)-1))),1)-WEEKDAY(DATE($A$1,IFERROR(VALUE($B$1),VALUE(LEFT($B$1,FIND("월",$B$1)-1))),1),1)+1+7*(ROW()-ROW($B$3))+(COLUMN()-COLUMN($B$3)))=IFERROR(VALUE($B$1),VALUE(LEFT($B$1,FIND("월",$B$1)-1))),IF(COUNTIF($K$1:$K$10,DAY(DATE($A$1,IFERROR(VALUE($B$1),VALUE(LEFT($B$1,FIND("월",$B$1)-1))),1)-WEEKDAY(DATE($A$1,IFERROR(VALUE($B$1),VALUE(LEFT($B$1,FIND("월",$B$1)-1))),1),1)+1+7*(ROW()-ROW($B$3))+(COLUMN()-COLUMN($B$3))))=0,DAY(DATE($A$1,IFERROR(VALUE($B$1),VALUE(LEFT($B$1,FIND("월",$B$1)-1))),1)-WEEKDAY(DATE($A$1,IFERROR(VALUE($B$1),VALUE(LEFT($B$1,FIND("월",$B$1)-1))),1),1)+1+7*(ROW()-ROW($B$3))+(COLUMN()-COLUMN($B$3))),""),"") | E4: =IF(MONTH(DATE($A$1,IFERROR(VALUE($B$1),VALUE(LEFT($B$1,FIND("월",$B$1)-1))),1)-WEEKDAY(DATE($A$1,IFERROR(VALUE($B$1),VALUE(LEFT($B$1,FIND("월",$B$1)-1))),1),1)+1+7*(ROW()-ROW($B$3))+(COLUMN()-COLUMN($B$3)))=IFERROR(VALUE($B$1),VALUE(LEFT($B$1,FIND("월",$B$1)-1))),IF(COUNTIF($K$1:$K$10,DAY(DATE($A$1,IFERROR(VALUE($B$1),VALUE(LEFT($B$1,FIND("월",$B$1)-1))),1)-WEEKDAY(DATE($A$1,IFERROR(VALUE($B$1),VALUE(LEFT($B$1,FIND("월",$B$1)-1))),1),1)+1+7*(ROW()-ROW($B$3))+(COLUMN()-COLUMN($B$3))))=0,DAY(DATE($A$1,IFERROR(VALUE($B$1),VALUE(LEFT($B$1,FIND("월",$B$1)-1))),1)-WEEKDAY(DATE($A$1,IFERROR(VALUE($B$1),VALUE(LEFT($B$1,FIND("월",$B$1)-1))),1),1)+1+7*(ROW()-ROW($B$3))+(COLUMN()-COLUMN($B$3))),""),"") | F4: =IF(MONTH(DATE($A$1,IFERROR(VALUE($B$1),VALUE(LEFT($B$1,FIND("월",$B$1)-1))),1)-WEEKDAY(DATE($A$1,IFERROR(VALUE($B$1),VALUE(LEFT($B$1,FIND("월",$B$1)-1))),1),1)+1+7*(ROW()-ROW($B$3))+(COLUMN()-COLUMN($B$3)))=IFERROR(VALUE($B$1),VALUE(LEFT($B$1,FIND("월",$B$1)-1))),IF(COUNTIF($K$1:$K$10,DAY(DATE($A$1,IFERROR(VALUE($B$1),VALUE(LEFT($B$1,FIND("월",$B$1)-1))),1)-WEEKDAY(DATE($A$1,IFERROR(VALUE($B$1),VALUE(LEFT($B$1,FIND("월",$B$1)-1))),1),1)+1+7*(ROW()-ROW($B$3))+(COLUMN()-COLUMN($B$3))))=0,DAY(DATE($A$1,IFERROR(VALUE($B$1),VALUE(LEFT($B$1,FIND("월",$B$1)-1))),1)-WEEKDAY(DATE($A$1,IFERROR(VALUE($B$1),VALUE(LEFT($B$1,FIND("월",$B$1)-1))),1),1)+1+7*(ROW()-ROW($B$3))+(COLUMN()-COLUMN($B$3))),""),"") | G4: =IF(MONTH(DATE($A$1,IFERROR(VALUE($B$1),VALUE(LEFT($B$1,FIND("월",$B$1)-1))),1)-WEEKDAY(DATE($A$1,IFERROR(VALUE($B$1),VALUE(LEFT($B$1,FIND("월",$B$1)-1))),1),1)+1+7*(ROW()-ROW($B$3))+(COLUMN()-COLUMN($B$3)))=IFERROR(VALUE($B$1),VALUE(LEFT($B$1,FIND("월",$B$1)-1))),IF(COUNTIF($K$1:$K$10,DAY(DATE($A$1,IFERROR(VALUE($B$1),VALUE(LEFT($B$1,FIND("월",$B$1)-1))),1)-WEEKDAY(DATE($A$1,IFERROR(VALUE($B$1),VALUE(LEFT($B$1,FIND("월",$B$1)-1))),1),1)+1+7*(ROW()-ROW($B$3))+(COLUMN()-COLUMN($B$3))))=0,DAY(DATE($A$1,IFERROR(VALUE($B$1),VALUE(LEFT($B$1,FIND("월",$B$1)-1))),1)-WEEKDAY(DATE($A$1,IFERROR(VALUE($B$1),VALUE(LEFT($B$1,FIND("월",$B$1)-1))),1),1)+1+7*(ROW()-ROW($B$3))+(COLUMN()-COLUMN($B$3))),""),"") | H4: =IF(MONTH(DATE($A$1,IFERROR(VALUE($B$1),VALUE(LEFT($B$1,FIND("월",$B$1)-1))),1)-WEEKDAY(DATE($A$1,IFERROR(VALUE($B$1),VALUE(LEFT($B$1,FIND("월",$B$1)-1))),1),1)+1+7*(ROW()-ROW($B$3))+(COLUMN()-COLUMN($B$3)))=IFERROR(VALUE($B$1),VALUE(LEFT($B$1,FIND("월",$B$1)-1))),IF(COUNTIF($K$1:$K$10,DAY(DATE($A$1,IFERROR(VALUE($B$1),VALUE(LEFT($B$1,FIND("월",$B$1)-1))),1)-WEEKDAY(DATE($A$1,IFERROR(VALUE($B$1),VALUE(LEFT($B$1,FIND("월",$B$1)-1))),1),1)+1+7*(ROW()-ROW($B$3))+(COLUMN()-COLUMN($B$3))))=0,DAY(DATE($A$1,IFERROR(VALUE($B$1),VALUE(LEFT($B$1,FIND("월",$B$1)-1))),1)-WEEKDAY(DATE($A$1,IFERROR(VALUE($B$1),VALUE(LEFT($B$1,FIND("월",$B$1)-1))),1),1)+1+7*(ROW()-ROW($B$3))+(COLUMN()-COLUMN($B$3))),""),"")
B5: =IF(MONTH(DATE($A$1,IFERROR(VALUE($B$1),VALUE(LEFT($B$1,FIND("월",$B$1)-1))),1)-WEEKDAY(DATE($A$1,IFERROR(VALUE($B$1),VALUE(LEFT($B$1,FIND("월",$B$1)-1))),1),1)+1+7*(ROW()-ROW($B$3))+(COLUMN()-COLUMN($B$3)))=IFERROR(VALUE($B$1),VALUE(LEFT($B$1,FIND("월",$B$1)-1))),IF(COUNTIF($K$1:$K$10,DAY(DATE($A$1,IFERROR(VALUE($B$1),VALUE(LEFT($B$1,FIND("월",$B$1)-1))),1)-WEEKDAY(DATE($A$1,IFERROR(VALUE($B$1),VALUE(LEFT($B$1,FIND("월",$B$1)-1))),1),1)+1+7*(ROW()-ROW($B$3))+(COLUMN()-COLUMN($B$3))))=0,DAY(DATE($A$1,IFERROR(VALUE($B$1),VALUE(LEFT($B$1,FIND("월",$B$1)-1))),1)-WEEKDAY(DATE($A$1,IFERROR(VALUE($B$1),VALUE(LEFT($B$1,FIND("월",$B$1)-1))),1),1)+1+7*(ROW()-ROW($B$3))+(COLUMN()-COLUMN($B$3))),""),"") | C5: =IF(MONTH(DATE($A$1,IFERROR(VALUE($B$1),VALUE(LEFT($B$1,FIND("월",$B$1)-1))),1)-WEEKDAY(DATE($A$1,IFERROR(VALUE($B$1),VALUE(LEFT($B$1,FIND("월",$B$1)-1))),1),1)+1+7*(ROW()-ROW($B$3))+(COLUMN()-COLUMN($B$3)))=IFERROR(VALUE($B$1),VALUE(LEFT($B$1,FIND("월",$B$1)-1))),IF(COUNTIF($K$1:$K$10,DAY(DATE($A$1,IFERROR(VALUE($B$1),VALUE(LEFT($B$1,FIND("월",$B$1)-1))),1)-WEEKDAY(DATE($A$1,IFERROR(VALUE($B$1),VALUE(LEFT($B$1,FIND("월",$B$1)-1))),1),1)+1+7*(ROW()-ROW($B$3))+(COLUMN()-COLUMN($B$3))))=0,DAY(DATE($A$1,IFERROR(VALUE($B$1),VALUE(LEFT($B$1,FIND("월",$B$1)-1))),1)-WEEKDAY(DATE($A$1,IFERROR(VALUE($B$1),VALUE(LEFT($B$1,FIND("월",$B$1)-1))),1),1)+1+7*(ROW()-ROW($B$3))+(COLUMN()-COLUMN($B$3))),""),"") | D5: =IF(MONTH(DATE($A$1,IFERROR(VALUE($B$1),VALUE(LEFT($B$1,FIND("월",$B$1)-1))),1)-WEEKDAY(DATE($A$1,IFERROR(VALUE($B$1),VALUE(LEFT($B$1,FIND("월",$B$1)-1))),1),1)+1+7*(ROW()-ROW($B$3))+(COLUMN()-COLUMN($B$3)))=IFERROR(VALUE($B$1),VALUE(LEFT($B$1,FIND("월",$B$1)-1))),IF(COUNTIF($K$1:$K$10,DAY(DATE($A$1,IFERROR(VALUE($B$1),VALUE(LEFT($B$1,FIND("월",$B$1)-1))),1)-WEEKDAY(DATE($A$1,IFERROR(VALUE($B$1),VALUE(LEFT($B$1,FIND("월",$B$1)-1))),1),1)+1+7*(ROW()-ROW($B$3))+(COLUMN()-COLUMN($B$3))))=0,DAY(DATE($A$1,IFERROR(VALUE($B$1),VALUE(LEFT($B$1,FIND("월",$B$1)-1))),1)-WEEKDAY(DATE($A$1,IFERROR(VALUE($B$1),VALUE(LEFT($B$1,FIND("월",$B$1)-1))),1),1)+1+7*(ROW()-ROW($B$3))+(COLUMN()-COLUMN($B$3))),""),"") | E5: =IF(MONTH(DATE($A$1,IFERROR(VALUE($B$1),VALUE(LEFT($B$1,FIND("월",$B$1)-1))),1)-WEEKDAY(DATE($A$1,IFERROR(VALUE($B$1),VALUE(LEFT($B$1,FIND("월",$B$1)-1))),1),1)+1+7*(ROW()-ROW($B$3))+(COLUMN()-COLUMN($B$3)))=IFERROR(VALUE($B$1),VALUE(LEFT($B$1,FIND("월",$B$1)-1))),IF(COUNTIF($K$1:$K$10,DAY(DATE($A$1,IFERROR(VALUE($B$1),VALUE(LEFT($B$1,FIND("월",$B$1)-1))),1)-WEEKDAY(DATE($A$1,IFERROR(VALUE($B$1),VALUE(LEFT($B$1,FIND("월",$B$1)-1))),1),1)+1+7*(ROW()-ROW($B$3))+(COLUMN()-COLUMN($B$3))))=0,DAY(DATE($A$1,IFERROR(VALUE($B$1),VALUE(LEFT($B$1,FIND("월",$B$1)-1))),1)-WEEKDAY(DATE($A$1,IFERROR(VALUE($B$1),VALUE(LEFT($B$1,FIND("월",$B$1)-1))),1),1)+1+7*(ROW()-ROW($B$3))+(COLUMN()-COLUMN($B$3))),""),"") | F5: =IF(MONTH(DATE($A$1,IFERROR(VALUE($B$1),VALUE(LEFT($B$1,FIND("월",$B$1)-1))),1)-WEEKDAY(DATE($A$1,IFERROR(VALUE($B$1),VALUE(LEFT($B$1,FIND("월",$B$1)-1))),1),1)+1+7*(ROW()-ROW($B$3))+(COLUMN()-COLUMN($B$3)))=IFERROR(VALUE($B$1),VALUE(LEFT($B$1,FIND("월",$B$1)-1))),IF(COUNTIF($K$1:$K$10,DAY(DATE($A$1,IFERROR(VALUE($B$1),VALUE(LEFT($B$1,FIND("월",$B$1)-1))),1)-WEEKDAY(DATE($A$1,IFERROR(VALUE($B$1),VALUE(LEFT($B$1,FIND("월",$B$1)-1))),1),1)+1+7*(ROW()-ROW($B$3))+(COLUMN()-COLUMN($B$3))))=0,DAY(DATE($A$1,IFERROR(VALUE($B$1),VALUE(LEFT($B$1,FIND("월",$B$1)-1))),1)-WEEKDAY(DATE($A$1,IFERROR(VALUE($B$1),VALUE(LEFT($B$1,FIND("월",$B$1)-1))),1),1)+1+7*(ROW()-ROW($B$3))+(COLUMN()-COLUMN($B$3))),""),"") | G5: =IF(MONTH(DATE($A$1,IFERROR(VALUE($B$1),VALUE(LEFT($B$1,FIND("월",$B$1)-1))),1)-WEEKDAY(DATE($A$1,IFERROR(VALUE($B$1),VALUE(LEFT($B$1,FIND("월",$B$1)-1))),1),1)+1+7*(ROW()-ROW($B$3))+(COLUMN()-COLUMN($B$3)))=IFERROR(VALUE($B$1),VALUE(LEFT($B$1,FIND("월",$B$1)-1))),IF(COUNTIF($K$1:$K$10,DAY(DATE($A$1,IFERROR(VALUE($B$1),VALUE(LEFT($B$1,FIND("월",$B$1)-1))),1)-WEEKDAY(DATE($A$1,IFERROR(VALUE($B$1),VALUE(LEFT($B$1,FIND("월",$B$1)-1))),1),1)+1+7*(ROW()-ROW($B$3))+(COLUMN()-COLUMN($B$3))))=0,DAY(DATE($A$1,IFERROR(VALUE($B$1),VALUE(LEFT($B$1,FIND("월",$B$1)-1))),1)-WEEKDAY(DATE($A$1,IFERROR(VALUE($B$1),VALUE(LEFT($B$1,FIND("월",$B$1)-1))),1),1)+1+7*(ROW()-ROW($B$3))+(COLUMN()-COLUMN($B$3))),""),"") | H5: =IF(MONTH(DATE($A$1,IFERROR(VALUE($B$1),VALUE(LEFT($B$1,FIND("월",$B$1)-1))),1)-WEEKDAY(DATE($A$1,IFERROR(VALUE($B$1),VALUE(LEFT($B$1,FIND("월",$B$1)-1))),1),1)+1+7*(ROW()-ROW($B$3))+(COLUMN()-COLUMN($B$3)))=IFERROR(VALUE($B$1),VALUE(LEFT($B$1,FIND("월",$B$1)-1))),IF(COUNTIF($K$1:$K$10,DAY(DATE($A$1,IFERROR(VALUE($B$1),VALUE(LEFT($B$1,FIND("월",$B$1)-1))),1)-WEEKDAY(DATE($A$1,IFERROR(VALUE($B$1),VALUE(LEFT($B$1,FIND("월",$B$1)-1))),1),1)+1+7*(ROW()-ROW($B$3))+(COLUMN()-COLUMN($B$3))))=0,DAY(DATE($A$1,IFERROR(VALUE($B$1),VALUE(LEFT($B$1,FIND("월",$B$1)-1))),1)-WEEKDAY(DATE($A$1,IFERROR(VALUE($B$1),VALUE(LEFT($B$1,FIND("월",$B$1)-1))),1),1)+1+7*(ROW()-ROW($B$3))+(COLUMN()-COLUMN($B$3))),""),"")
B6: =IF(MONTH(DATE($A$1,IFERROR(VALUE($B$1),VALUE(LEFT($B$1,FIND("월",$B$1)-1))),1)-WEEKDAY(DATE($A$1,IFERROR(VALUE($B$1),VALUE(LEFT($B$1,FIND("월",$B$1)-1))),1),1)+1+7*(ROW()-ROW($B$3))+(COLUMN()-COLUMN($B$3)))=IFERROR(VALUE($B$1),VALUE(LEFT($B$1,FIND("월",$B$1)-1))),IF(COUNTIF($K$1:$K$10,DAY(DATE($A$1,IFERROR(VALUE($B$1),VALUE(LEFT($B$1,FIND("월",$B$1)-1))),1)-WEEKDAY(DATE($A$1,IFERROR(VALUE($B$1),VALUE(LEFT($B$1,FIND("월",$B$1)-1))),1),1)+1+7*(ROW()-ROW($B$3))+(COLUMN()-COLUMN($B$3))))=0,DAY(DATE($A$1,IFERROR(VALUE($B$1),VALUE(LEFT($B$1,FIND("월",$B$1)-1))),1)-WEEKDAY(DATE($A$1,IFERROR(VALUE($B$1),VALUE(LEFT($B$1,FIND("월",$B$1)-1))),1),1)+1+7*(ROW()-ROW($B$3))+(COLUMN()-COLUMN($B$3))),""),"") | C6: =IF(MONTH(DATE($A$1,IFERROR(VALUE($B$1),VALUE(LEFT($B$1,FIND("월",$B$1)-1))),1)-WEEKDAY(DATE($A$1,IFERROR(VALUE($B$1),VALUE(LEFT($B$1,FIND("월",$B$1)-1))),1),1)+1+7*(ROW()-ROW($B$3))+(COLUMN()-COLUMN($B$3)))=IFERROR(VALUE($B$1),VALUE(LEFT($B$1,FIND("월",$B$1)-1))),IF(COUNTIF($K$1:$K$10,DAY(DATE($A$1,IFERROR(VALUE($B$1),VALUE(LEFT($B$1,FIND("월",$B$1)-1))),1)-WEEKDAY(DATE($A$1,IFERROR(VALUE($B$1),VALUE(LEFT($B$1,FIND("월",$B$1)-1))),1),1)+1+7*(ROW()-ROW($B$3))+(COLUMN()-COLUMN($B$3))))=0,DAY(DATE($A$1,IFERROR(VALUE($B$1),VALUE(LEFT($B$1,FIND("월",$B$1)-1))),1)-WEEKDAY(DATE($A$1,IFERROR(VALUE($B$1),VALUE(LEFT($B$1,FIND("월",$B$1)-1))),1),1)+1+7*(ROW()-ROW($B$3))+(COLUMN()-COLUMN($B$3))),""),"") | D6: =IF(MONTH(DATE($A$1,IFERROR(VALUE($B$1),VALUE(LEFT($B$1,FIND("월",$B$1)-1))),1)-WEEKDAY(DATE($A$1,IFERROR(VALUE($B$1),VALUE(LEFT($B$1,FIND("월",$B$1)-1))),1),1)+1+7*(ROW()-ROW($B$3))+(COLUMN()-COLUMN($B$3)))=IFERROR(VALUE($B$1),VALUE(LEFT($B$1,FIND("월",$B$1)-1))),IF(COUNTIF($K$1:$K$10,DAY(DATE($A$1,IFERROR(VALUE($B$1),VALUE(LEFT($B$1,FIND("월",$B$1)-1))),1)-WEEKDAY(DATE($A$1,IFERROR(VALUE($B$1),VALUE(LEFT($B$1,FIND("월",$B$1)-1))),1),1)+1+7*(ROW()-ROW($B$3))+(COLUMN()-COLUMN($B$3))))=0,DAY(DATE($A$1,IFERROR(VALUE($B$1),VALUE(LEFT($B$1,FIND("월",$B$1)-1))),1)-WEEKDAY(DATE($A$1,IFERROR(VALUE($B$1),VALUE(LEFT($B$1,FIND("월",$B$1)-1))),1),1)+1+7*(ROW()-ROW($B$3))+(COLUMN()-COLUMN($B$3))),""),"") | E6: =IF(MONTH(DATE($A$1,IFERROR(VALUE($B$1),VALUE(LEFT($B$1,FIND("월",$B$1)-1))),1)-WEEKDAY(DATE($A$1,IFERROR(VALUE($B$1),VALUE(LEFT($B$1,FIND("월",$B$1)-1))),1),1)+1+7*(ROW()-ROW($B$3))+(COLUMN()-COLUMN($B$3)))=IFERROR(VALUE($B$1),VALUE(LEFT($B$1,FIND("월",$B$1)-1))),IF(COUNTIF($K$1:$K$10,DAY(DATE($A$1,IFERROR(VALUE($B$1),VALUE(LEFT($B$1,FIND("월",$B$1)-1))),1)-WEEKDAY(DATE($A$1,IFERROR(VALUE($B$1),VALUE(LEFT($B$1,FIND("월",$B$1)-1))),1),1)+1+7*(ROW()-ROW($B$3))+(COLUMN()-COLUMN($B$3))))=0,DAY(DATE($A$1,IFERROR(VALUE($B$1),VALUE(LEFT($B$1,FIND("월",$B$1)-1))),1)-WEEKDAY(DATE($A$1,IFERROR(VALUE($B$1),VALUE(LEFT($B$1,FIND("월",$B$1)-1))),1),1)+1+7*(ROW()-ROW($B$3))+(COLUMN()-COLUMN($B$3))),""),"") | F6: =IF(MONTH(DATE($A$1,IFERROR(VALUE($B$1),VALUE(LEFT($B$1,FIND("월",$B$1)-1))),1)-WEEKDAY(DATE($A$1,IFERROR(VALUE($B$1),VALUE(LEFT($B$1,FIND("월",$B$1)-1))),1),1)+1+7*(ROW()-ROW($B$3))+(COLUMN()-COLUMN($B$3)))=IFERROR(VALUE($B$1),VALUE(LEFT($B$1,FIND("월",$B$1)-1))),IF(COUNTIF($K$1:$K$10,DAY(DATE($A$1,IFERROR(VALUE($B$1),VALUE(LEFT($B$1,FIND("월",$B$1)-1))),1)-WEEKDAY(DATE($A$1,IFERROR(VALUE($B$1),VALUE(LEFT($B$1,FIND("월",$B$1)-1))),1),1)+1+7*(ROW()-ROW($B$3))+(COLUMN()-COLUMN($B$3))))=0,DAY(DATE($A$1,IFERROR(VALUE($B$1),VALUE(LEFT($B$1,FIND("월",$B$1)-1))),1)-WEEKDAY(DATE($A$1,IFERROR(VALUE($B$1),VALUE(LEFT($B$1,FIND("월",$B$1)-1))),1),1)+1+7*(ROW()-ROW($B$3))+(COLUMN()-COLUMN($B$3))),""),"") | G6: =IF(MONTH(DATE($A$1,IFERROR(VALUE($B$1),VALUE(LEFT($B$1,FIND("월",$B$1)-1))),1)-WEEKDAY(DATE($A$1,IFERROR(VALUE($B$1),VALUE(LEFT($B$1,FIND("월",$B$1)-1))),1),1)+1+7*(ROW()-ROW($B$3))+(COLUMN()-COLUMN($B$3)))=IFERROR(VALUE($B$1),VALUE(LEFT($B$1,FIND("월",$B$1)-1))),IF(COUNTIF($K$1:$K$10,DAY(DATE($A$1,IFERROR(VALUE($B$1),VALUE(LEFT($B$1,FIND("월",$B$1)-1))),1)-WEEKDAY(DATE($A$1,IFERROR(VALUE($B$1),VALUE(LEFT($B$1,FIND("월",$B$1)-1))),1),1)+1+7*(ROW()-ROW($B$3))+(COLUMN()-COLUMN($B$3))))=0,DAY(DATE($A$1,IFERROR(VALUE($B$1),VALUE(LEFT($B$1,FIND("월",$B$1)-1))),1)-WEEKDAY(DATE($A$1,IFERROR(VALUE($B$1),VALUE(LEFT($B$1,FIND("월",$B$1)-1))),1),1)+1+7*(ROW()-ROW($B$3))+(COLUMN()-COLUMN($B$3))),""),"") | H6: =IF(MONTH(DATE($A$1,IFERROR(VALUE($B$1),VALUE(LEFT($B$1,FIND("월",$B$1)-1))),1)-WEEKDAY(DATE($A$1,IFERROR(VALUE($B$1),VALUE(LEFT($B$1,FIND("월",$B$1)-1))),1),1)+1+7*(ROW()-ROW($B$3))+(COLUMN()-COLUMN($B$3)))=IFERROR(VALUE($B$1),VALUE(LEFT($B$1,FIND("월",$B$1)-1))),IF(COUNTIF($K$1:$K$10,DAY(DATE($A$1,IFERROR(VALUE($B$1),VALUE(LEFT($B$1,FIND("월",$B$1)-1))),1)-WEEKDAY(DATE($A$1,IFERROR(VALUE($B$1),VALUE(LEFT($B$1,FIND("월",$B$1)-1))),1),1)+1+7*(ROW()-ROW($B$3))+(COLUMN()-COLUMN($B$3))))=0,DAY(DATE($A$1,IFERROR(VALUE($B$1),VALUE(LEFT($B$1,FIND("월",$B$1)-1))),1)-WEEKDAY(DATE($A$1,IFERROR(VALUE($B$1),VALUE(LEFT($B$1,FIND("월",$B$1)-1))),1),1)+1+7*(ROW()-ROW($B$3))+(COLUMN()-COLUMN($B$3))),""),"")
B7: =IF(MONTH(DATE($A$1,IFERROR(VALUE($B$1),VALUE(LEFT($B$1,FIND("월",$B$1)-1))),1)-WEEKDAY(DATE($A$1,IFERROR(VALUE($B$1),VALUE(LEFT($B$1,FIND("월",$B$1)-1))),1),1)+1+7*(ROW()-ROW($B$3))+(COLUMN()-COLUMN($B$3)))=IFERROR(VALUE($B$1),VALUE(LEFT($B$1,FIND("월",$B$1)-1))),IF(COUNTIF($K$1:$K$10,DAY(DATE($A$1,IFERROR(VALUE($B$1),VALUE(LEFT($B$1,FIND("월",$B$1)-1))),1)-WEEKDAY(DATE($A$1,IFERROR(VALUE($B$1),VALUE(LEFT($B$1,FIND("월",$B$1)-1))),1),1)+1+7*(ROW()-ROW($B$3))+(COLUMN()-COLUMN($B$3))))=0,DAY(DATE($A$1,IFERROR(VALUE($B$1),VALUE(LEFT($B$1,FIND("월",$B$1)-1))),1)-WEEKDAY(DATE($A$1,IFERROR(VALUE($B$1),VALUE(LEFT($B$1,FIND("월",$B$1)-1))),1),1)+1+7*(ROW()-ROW($B$3))+(COLUMN()-COLUMN($B$3))),""),"") | C7: =IF(MONTH(DATE($A$1,IFERROR(VALUE($B$1),VALUE(LEFT($B$1,FIND("월",$B$1)-1))),1)-WEEKDAY(DATE($A$1,IFERROR(VALUE($B$1),VALUE(LEFT($B$1,FIND("월",$B$1)-1))),1),1)+1+7*(ROW()-ROW($B$3))+(COLUMN()-COLUMN($B$3)))=IFERROR(VALUE($B$1),VALUE(LEFT($B$1,FIND("월",$B$1)-1))),IF(COUNTIF($K$1:$K$10,DAY(DATE($A$1,IFERROR(VALUE($B$1),VALUE(LEFT($B$1,FIND("월",$B$1)-1))),1)-WEEKDAY(DATE($A$1,IFERROR(VALUE($B$1),VALUE(LEFT($B$1,FIND("월",$B$1)-1))),1),1)+1+7*(ROW()-ROW($B$3))+(COLUMN()-COLUMN($B$3))))=0,DAY(DATE($A$1,IFERROR(VALUE($B$1),VALUE(LEFT($B$1,FIND("월",$B$1)-1))),1)-WEEKDAY(DATE($A$1,IFERROR(VALUE($B$1),VALUE(LEFT($B$1,FIND("월",$B$1)-1))),1),1)+1+7*(ROW()-ROW($B$3))+(COLUMN()-COLUMN($B$3))),""),"") | D7: =IF(MONTH(DATE($A$1,IFERROR(VALUE($B$1),VALUE(LEFT($B$1,FIND("월",$B$1)-1))),1)-WEEKDAY(DATE($A$1,IFERROR(VALUE($B$1),VALUE(LEFT($B$1,FIND("월",$B$1)-1))),1),1)+1+7*(ROW()-ROW($B$3))+(COLUMN()-COLUMN($B$3)))=IFERROR(VALUE($B$1),VALUE(LEFT($B$1,FIND("월",$B$1)-1))),IF(COUNTIF($K$1:$K$10,DAY(DATE($A$1,IFERROR(VALUE($B$1),VALUE(LEFT($B$1,FIND("월",$B$1)-1))),1)-WEEKDAY(DATE($A$1,IFERROR(VALUE($B$1),VALUE(LEFT($B$1,FIND("월",$B$1)-1))),1),1)+1+7*(ROW()-ROW($B$3))+(COLUMN()-COLUMN($B$3))))=0,DAY(DATE($A$1,IFERROR(VALUE($B$1),VALUE(LEFT($B$1,FIND("월",$B$1)-1))),1)-WEEKDAY(DATE($A$1,IFERROR(VALUE($B$1),VALUE(LEFT($B$1,FIND("월",$B$1)-1))),1),1)+1+7*(ROW()-ROW($B$3))+(COLUMN()-COLUMN($B$3))),""),"") | E7: =IF(MONTH(DATE($A$1,IFERROR(VALUE($B$1),VALUE(LEFT($B$1,FIND("월",$B$1)-1))),1)-WEEKDAY(DATE($A$1,IFERROR(VALUE($B$1),VALUE(LEFT($B$1,FIND("월",$B$1)-1))),1),1)+1+7*(ROW()-ROW($B$3))+(COLUMN()-COLUMN($B$3)))=IFERROR(VALUE($B$1),VALUE(LEFT($B$1,FIND("월",$B$1)-1))),IF(COUNTIF($K$1:$K$10,DAY(DATE($A$1,IFERROR(VALUE($B$1),VALUE(LEFT($B$1,FIND("월",$B$1)-1))),1)-WEEKDAY(DATE($A$1,IFERROR(VALUE($B$1),VALUE(LEFT($B$1,FIND("월",$B$1)-1))),1),1)+1+7*(ROW()-ROW($B$3))+(COLUMN()-COLUMN($B$3))))=0,DAY(DATE($A$1,IFERROR(VALUE($B$1),VALUE(LEFT($B$1,FIND("월",$B$1)-1))),1)-WEEKDAY(DATE($A$1,IFERROR(VALUE($B$1),VALUE(LEFT($B$1,FIND("월",$B$1)-1))),1),1)+1+7*(ROW()-ROW($B$3))+(COLUMN()-COLUMN($B$3))),""),"") | F7: =IF(MONTH(DATE($A$1,IFERROR(VALUE($B$1),VALUE(LEFT($B$1,FIND("월",$B$1)-1))),1)-WEEKDAY(DATE($A$1,IFERROR(VALUE($B$1),VALUE(LEFT($B$1,FIND("월",$B$1)-1))),1),1)+1+7*(ROW()-ROW($B$3))+(COLUMN()-COLUMN($B$3)))=IFERROR(VALUE($B$1),VALUE(LEFT($B$1,FIND("월",$B$1)-1))),IF(COUNTIF($K$1:$K$10,DAY(DATE($A$1,IFERROR(VALUE($B$1),VALUE(LEFT($B$1,FIND("월",$B$1)-1))),1)-WEEKDAY(DATE($A$1,IFERROR(VALUE($B$1),VALUE(LEFT($B$1,FIND("월",$B$1)-1))),1),1)+1+7*(ROW()-ROW($B$3))+(COLUMN()-COLUMN($B$3))))=0,DAY(DATE($A$1,IFERROR(VALUE($B$1),VALUE(LEFT($B$1,FIND("월",$B$1)-1))),1)-WEEKDAY(DATE($A$1,IFERROR(VALUE($B$1),VALUE(LEFT($B$1,FIND("월",$B$1)-1))),1),1)+1+7*(ROW()-ROW($B$3))+(COLUMN()-COLUMN($B$3))),""),"") | G7: =IF(MONTH(DATE($A$1,IFERROR(VALUE($B$1),VALUE(LEFT($B$1,FIND("월",$B$1)-1))),1)-WEEKDAY(DATE($A$1,IFERROR(VALUE($B$1),VALUE(LEFT($B$1,FIND("월",$B$1)-1))),1),1)+1+7*(ROW()-ROW($B$3))+(COLUMN()-COLUMN($B$3)))=IFERROR(VALUE($B$1),VALUE(LEFT($B$1,FIND("월",$B$1)-1))),IF(COUNTIF($K$1:$K$10,DAY(DATE($A$1,IFERROR(VALUE($B$1),VALUE(LEFT($B$1,FIND("월",$B$1)-1))),1)-WEEKDAY(DATE($A$1,IFERROR(VALUE($B$1),VALUE(LEFT($B$1,FIND("월",$B$1)-1))),1),1)+1+7*(ROW()-ROW($B$3))+(COLUMN()-COLUMN($B$3))))=0,DAY(DATE($A$1,IFERROR(VALUE($B$1),VALUE(LEFT($B$1,FIND("월",$B$1)-1))),1)-WEEKDAY(DATE($A$1,IFERROR(VALUE($B$1),VALUE(LEFT($B$1,FIND("월",$B$1)-1))),1),1)+1+7*(ROW()-ROW($B$3))+(COLUMN()-COLUMN($B$3))),""),"") | H7: =IF(MONTH(DATE($A$1,IFERROR(VALUE($B$1),VALUE(LEFT($B$1,FIND("월",$B$1)-1))),1)-WEEKDAY(DATE($A$1,IFERROR(VALUE($B$1),VALUE(LEFT($B$1,FIND("월",$B$1)-1))),1),1)+1+7*(ROW()-ROW($B$3))+(COLUMN()-COLUMN($B$3)))=IFERROR(VALUE($B$1),VALUE(LEFT($B$1,FIND("월",$B$1)-1))),IF(COUNTIF($K$1:$K$10,DAY(DATE($A$1,IFERROR(VALUE($B$1),VALUE(LEFT($B$1,FIND("월",$B$1)-1))),1)-WEEKDAY(DATE($A$1,IFERROR(VALUE($B$1),VALUE(LEFT($B$1,FIND("월",$B$1)-1))),1),1)+1+7*(ROW()-ROW($B$3))+(COLUMN()-COLUMN($B$3))))=0,DAY(DATE($A$1,IFERROR(VALUE($B$1),VALUE(LEFT($B$1,FIND("월",$B$1)-1))),1)-WEEKDAY(DATE($A$1,IFERROR(VALUE($B$1),VALUE(LEFT($B$1,FIND("월",$B$1)-1))),1),1)+1+7*(ROW()-ROW($B$3))+(COLUMN()-COLUMN($B$3))),""),"")
B8: =IF(MONTH(DATE(YEAR(TODAY()),IFERROR(VALUE($B$1),VALUE(LEFT($B$1,FIND("월",$B$1)-1))),1)-WEEKDAY(DATE(YEAR(TODAY()),IFERROR(VALUE($B$1),VALUE(LEFT($B$1,FIND("월",$B$1)-1))),1),1)+1+7*(ROW()-ROW($B$3))+(COLUMN()-COLUMN($B$3)))=IFERROR(VALUE($B$1),VALUE(LEFT($B$1,FIND("월",$B$1)-1))),DAY(DATE(YEAR(TODAY()),IFERROR(VALUE($B$1),VALUE(LEFT($B$1,FIND("월",$B$1)-1))),1)-WEEKDAY(DATE(YEAR(TODAY()),IFERROR(VALUE($B$1),VALUE(LEFT($B$1,FIND("월",$B$1)-1))),1),1)+1+7*(ROW()-ROW($B$3))+(COLUMN()-COLUMN($B$3))),"") | C8: =IF(MONTH(DATE(YEAR(TODAY()),IFERROR(VALUE($B$1),VALUE(LEFT($B$1,FIND("월",$B$1)-1))),1)-WEEKDAY(DATE(YEAR(TODAY()),IFERROR(VALUE($B$1),VALUE(LEFT($B$1,FIND("월",$B$1)-1))),1),1)+1+7*(ROW()-ROW($B$3))+(COLUMN()-COLUMN($B$3)))=IFERROR(VALUE($B$1),VALUE(LEFT($B$1,FIND("월",$B$1)-1))),DAY(DATE(YEAR(TODAY()),IFERROR(VALUE($B$1),VALUE(LEFT($B$1,FIND("월",$B$1)-1))),1)-WEEKDAY(DATE(YEAR(TODAY()),IFERROR(VALUE($B$1),VALUE(LEFT($B$1,FIND("월",$B$1)-1))),1),1)+1+7*(ROW()-ROW($B$3))+(COLUMN()-COLUMN($B$3))),"") | D8: =IF(MONTH(DATE(YEAR(TODAY()),IFERROR(VALUE($B$1),VALUE(LEFT($B$1,FIND("월",$B$1)-1))),1)-WEEKDAY(DATE(YEAR(TODAY()),IFERROR(VALUE($B$1),VALUE(LEFT($B$1,FIND("월",$B$1)-1))),1),1)+1+7*(ROW()-ROW($B$3))+(COLUMN()-COLUMN($B$3)))=IFERROR(VALUE($B$1),VALUE(LEFT($B$1,FIND("월",$B$1)-1))),DAY(DATE(YEAR(TODAY()),IFERROR(VALUE($B$1),VALUE(LEFT($B$1,FIND("월",$B$1)-1))),1)-WEEKDAY(DATE(YEAR(TODAY()),IFERROR(VALUE($B$1),VALUE(LEFT($B$1,FIND("월",$B$1)-1))),1),1)+1+7*(ROW()-ROW($B$3))+(COLUMN()-COLUMN($B$3))),"") | E8: =IF(MONTH(DATE(YEAR(TODAY()),IFERROR(VALUE($B$1),VALUE(LEFT($B$1,FIND("월",$B$1)-1))),1)-WEEKDAY(DATE(YEAR(TODAY()),IFERROR(VALUE($B$1),VALUE(LEFT($B$1,FIND("월",$B$1)-1))),1),1)+1+7*(ROW()-ROW($B$3))+(COLUMN()-COLUMN($B$3)))=IFERROR(VALUE($B$1),VALUE(LEFT($B$1,FIND("월",$B$1)-1))),DAY(DATE(YEAR(TODAY()),IFERROR(VALUE($B$1),VALUE(LEFT($B$1,FIND("월",$B$1)-1))),1)-WEEKDAY(DATE(YEAR(TODAY()),IFERROR(VALUE($B$1),VALUE(LEFT($B$1,FIND("월",$B$1)-1))),1),1)+1+7*(ROW()-ROW($B$3))+(COLUMN()-COLUMN($B$3))),"") | F8: =IF(MONTH(DATE(YEAR(TODAY()),IFERROR(VALUE($B$1),VALUE(LEFT($B$1,FIND("월",$B$1)-1))),1)-WEEKDAY(DATE(YEAR(TODAY()),IFERROR(VALUE($B$1),VALUE(LEFT($B$1,FIND("월",$B$1)-1))),1),1)+1+7*(ROW()-ROW($B$3))+(COLUMN()-COLUMN($B$3)))=IFERROR(VALUE($B$1),VALUE(LEFT($B$1,FIND("월",$B$1)-1))),DAY(DATE(YEAR(TODAY()),IFERROR(VALUE($B$1),VALUE(LEFT($B$1,FIND("월",$B$1)-1))),1)-WEEKDAY(DATE(YEAR(TODAY()),IFERROR(VALUE($B$1),VALUE(LEFT($B$1,FIND("월",$B$1)-1))),1),1)+1+7*(ROW()-ROW($B$3))+(COLUMN()-COLUMN($B$3))),"") | G8: =IF(MONTH(DATE(YEAR(TODAY()),IFERROR(VALUE($B$1),VALUE(LEFT($B$1,FIND("월",$B$1)-1))),1)-WEEKDAY(DATE(YEAR(TODAY()),IFERROR(VALUE($B$1),VALUE(LEFT($B$1,FIND("월",$B$1)-1))),1),1)+1+7*(ROW()-ROW($B$3))+(COLUMN()-COLUMN($B$3)))=IFERROR(VALUE($B$1),VALUE(LEFT($B$1,FIND("월",$B$1)-1))),DAY(DATE(YEAR(TODAY()),IFERROR(VALUE($B$1),VALUE(LEFT($B$1,FIND("월",$B$1)-1))),1)-WEEKDAY(DATE(YEAR(TODAY()),IFERROR(VALUE($B$1),VALUE(LEFT($B$1,FIND("월",$B$1)-1))),1),1)+1+7*(ROW()-ROW($B$3))+(COLUMN()-COLUMN($B$3))),"") | H8: =IF(MONTH(DATE(YEAR(TODAY()),IFERROR(VALUE($B$1),VALUE(LEFT($B$1,FIND("월",$B$1)-1))),1)-WEEKDAY(DATE(YEAR(TODAY()),IFERROR(VALUE($B$1),VALUE(LEFT($B$1,FIND("월",$B$1)-1))),1),1)+1+7*(ROW()-ROW($B$3))+(COLUMN()-COLUMN($B$3)))=IFERROR(VALUE($B$1),VALUE(LEFT($B$1,FIND("월",$B$1)-1))),DAY(DATE(YEAR(TODAY()),IFERROR(VALUE($B$1),VALUE(LEFT($B$1,FIND("월",$B$1)-1))),1)-WEEKDAY(DATE(YEAR(TODAY()),IFERROR(VALUE($B$1),VALUE(LEFT($B$1,FIND("월",$B$1)-1))),1),1)+1+7*(ROW()-ROW($B$3))+(COLUMN()-COLUMN($B$3))),"")
B11: {=IFERROR(SMALL(IF((($B$2:$H$2=LEFT($A$2,1))+($B$2:$H$2=LEFT($A$3,1)))*($B$3:$H$8<>"")*ISNUMBER($B$3:$H$8), $B$3:$H$8), COLUMN(A1)), "")} | C11: {=IFERROR(SMALL(IF((($B$2:$H$2=LEFT($A$2,1))+($B$2:$H$2=LEFT($A$3,1)))*($B$3:$H$8<>"")*ISNUMBER($B$3:$H$8), $B$3:$H$8), COLUMN(B1)), "")} | D11: {=IFERROR(SMALL(IF((($B$2:$H$2=LEFT($A$2,1))+($B$2:$H$2=LEFT($A$3,1)))*($B$3:$H$8<>"")*ISNUMBER($B$3:$H$8), $B$3:$H$8), COLUMN(C1)), "")} | E11: {=IFERROR(SMALL(IF((($B$2:$H$2=LEFT($A$2,1))+($B$2:$H$2=LEFT($A$3,1)))*($B$3:$H$8<>"")*ISNUMBER($B$3:$H$8), $B$3:$H$8), COLUMN(D1)), "")} | F11: {=IFERROR(SMALL(IF((($B$2:$H$2=LEFT($A$2,1))+($B$2:$H$2=LEFT($A$3,1)))*($B$3:$H$8<>"")*ISNUMBER($B$3:$H$8), $B$3:$H$8), COLUMN(E1)), "")} | G11: {=IFERROR(SMALL(IF((($B$2:$H$2=LEFT($A$2,1))+($B$2:$H$2=LEFT($A$3,1)))*($B$3:$H$8<>"")*ISNUMBER($B$3:$H$8), $B$3:$H$8), COLUMN(F1)), "")} | H11: {=IFERROR(SMALL(IF((($B$2:$H$2=LEFT($A$2,1))+($B$2:$H$2=LEFT($A$3,1)))*($B$3:$H$8<>"")*ISNUMBER($B$3:$H$8), $B$3:$H$8), COLUMN(G1)), "")} | I11: {=IFERROR(SMALL(IF((($B$2:$H$2=LEFT($A$2,1))+($B$2:$H$2=LEFT($A$3,1)))*($B$3:$H$8<>"")*ISNUMBER($B$3:$H$8), $B$3:$H$8), COLUMN(H1)), "")}

Sheet 수금
A1: 2026 | B1: 6월 | K1: 공휴일
A2: 수 | B2: 일 | C2: 월 | D2: 화 | E2: 수 | F2: 목 | G2: 금 | H2: 토 | K2: 3
A3: 금 | B3: =IF(MONTH(DATE($A$1,IFERROR(VALUE($B$1),VALUE(LEFT($B$1,FIND("월",$B$1)-1))),1)-WEEKDAY(DATE($A$1,IFERROR(VALUE($B$1),VALUE(LEFT($B$1,FIND("월",$B$1)-1))),1),1)+1+7*(ROW()-ROW($B$3))+(COLUMN()-COLUMN($B$3)))=IFERROR(VALUE($B$1),VALUE(LEFT($B$1,FIND("월",$B$1)-1))),IF(COUNTIF($K$1:$K$10,DAY(DATE($A$1,IFERROR(VALUE($B$1),VALUE(LEFT($B$1,FIND("월",$B$1)-1))),1)-WEEKDAY(DATE($A$1,IFERROR(VALUE($B$1),VALUE(LEFT($B$1,FIND("월",$B$1)-1))),1),1)+1+7*(ROW()-ROW($B$3))+(COLUMN()-COLUMN($B$3))))=0,DAY(DATE($A$1,IFERROR(VALUE($B$1),VALUE(LEFT($B$1,FIND("월",$B$1)-1))),1)-WEEKDAY(DATE($A$1,IFERROR(VALUE($B$1),VALUE(LEFT($B$1,FIND("월",$B$1)-1))),1),1)+1+7*(ROW()-ROW($B$3))+(COLUMN()-COLUMN($B$3))),""),"") | C3: =IF(MONTH(DATE($A$1,IFERROR(VALUE($B$1),VALUE(LEFT($B$1,FIND("월",$B$1)-1))),1)-WEEKDAY(DATE($A$1,IFERROR(VALUE($B$1),VALUE(LEFT($B$1,FIND("월",$B$1)-1))),1),1)+1+7*(ROW()-ROW($B$3))+(COLUMN()-COLUMN($B$3)))=IFERROR(VALUE($B$1),VALUE(LEFT($B$1,FIND("월",$B$1)-1))),IF(COUNTIF($K$1:$K$10,DAY(DATE($A$1,IFERROR(VALUE($B$1),VALUE(LEFT($B$1,FIND("월",$B$1)-1))),1)-WEEKDAY(DATE($A$1,IFERROR(VALUE($B$1),VALUE(LEFT($B$1,FIND("월",$B$1)-1))),1),1)+1+7*(ROW()-ROW($B$3))+(COLUMN()-COLUMN($B$3))))=0,DAY(DATE($A$1,IFERROR(VALUE($B$1),VALUE(LEFT($B$1,FIND("월",$B$1)-1))),1)-WEEKDAY(DATE($A$1,IFERROR(VALUE($B$1),VALUE(LEFT($B$1,FIND("월",$B$1)-1))),1),1)+1+7*(ROW()-ROW($B$3))+(COLUMN()-COLUMN($B$3))),""),"") | D3: =IF(MONTH(DATE($A$1,IFERROR(VALUE($B$1),VALUE(LEFT($B$1,FIND("월",$B$1)-1))),1)-WEEKDAY(DATE($A$1,IFERROR(VALUE($B$1),VALUE(LEFT($B$1,FIND("월",$B$1)-1))),1),1)+1+7*(ROW()-ROW($B$3))+(COLUMN()-COLUMN($B$3)))=IFERROR(VALUE($B$1),VALUE(LEFT($B$1,FIND("월",$B$1)-1))),IF(COUNTIF($K$1:$K$10,DAY(DATE($A$1,IFERROR(VALUE($B$1),VALUE(LEFT($B$1,FIND("월",$B$1)-1))),1)-WEEKDAY(DATE($A$1,IFERROR(VALUE($B$1),VALUE(LEFT($B$1,FIND("월",$B$1)-1))),1),1)+1+7*(ROW()-ROW($B$3))+(COLUMN()-COLUMN($B$3))))=0,DAY(DATE($A$1,IFERROR(VALUE($B$1),VALUE(LEFT($B$1,FIND("월",$B$1)-1))),1)-WEEKDAY(DATE($A$1,IFERROR(VALUE($B$1),VALUE(LEFT($B$1,FIND("월",$B$1)-1))),1),1)+1+7*(ROW()-ROW($B$3))+(COLUMN()-COLUMN($B$3))),""),"") | E3: =IF(MONTH(DATE($A$1,IFERROR(VALUE($B$1),VALUE(LEFT($B$1,FIND("월",$B$1)-1))),1)-WEEKDAY(DATE($A$1,IFERROR(VALUE($B$1),VALUE(LEFT($B$1,FIND("월",$B$1)-1))),1),1)+1+7*(ROW()-ROW($B$3))+(COLUMN()-COLUMN($B$3)))=IFERROR(VALUE($B$1),VALUE(LEFT($B$1,FIND("월",$B$1)-1))),IF(COUNTIF($K$1:$K$10,DAY(DATE($A$1,IFERROR(VALUE($B$1),VALUE(LEFT($B$1,FIND("월",$B$1)-1))),1)-WEEKDAY(DATE($A$1,IFERROR(VALUE($B$1),VALUE(LEFT($B$1,FIND("월",$B$1)-1))),1),1)+1+7*(ROW()-ROW($B$3))+(COLUMN()-COLUMN($B$3))))=0,DAY(DATE($A$1,IFERROR(VALUE($B$1),VALUE(LEFT($B$1,FIND("월",$B$1)-1))),1)-WEEKDAY(DATE($A$1,IFERROR(VALUE($B$1),VALUE(LEFT($B$1,FIND("월",$B$1)-1))),1),1)+1+7*(ROW()-ROW($B$3))+(COLUMN()-COLUMN($B$3))),""),"") | F3: =IF(MONTH(DATE($A$1,IFERROR(VALUE($B$1),VALUE(LEFT($B$1,FIND("월",$B$1)-1))),1)-WEEKDAY(DATE($A$1,IFERROR(VALUE($B$1),VALUE(LEFT($B$1,FIND("월",$B$1)-1))),1),1)+1+7*(ROW()-ROW($B$3))+(COLUMN()-COLUMN($B$3)))=IFERROR(VALUE($B$1),VALUE(LEFT($B$1,FIND("월",$B$1)-1))),IF(COUNTIF($K$1:$K$10,DAY(DATE($A$1,IFERROR(VALUE($B$1),VALUE(LEFT($B$1,FIND("월",$B$1)-1))),1)-WEEKDAY(DATE($A$1,IFERROR(VALUE($B$1),VALUE(LEFT($B$1,FIND("월",$B$1)-1))),1),1)+1+7*(ROW()-ROW($B$3))+(COLUMN()-COLUMN($B$3))))=0,DAY(DATE($A$1,IFERROR(VALUE($B$1),VALUE(LEFT($B$1,FIND("월",$B$1)-1))),1)-WEEKDAY(DATE($A$1,IFERROR(VALUE($B$1),VALUE(LEFT($B$1,FIND("월",$B$1)-1))),1),1)+1+7*(ROW()-ROW($B$3))+(COLUMN()-COLUMN($B$3))),""),"") | G3: =IF(MONTH(DATE($A$1,IFERROR(VALUE($B$1),VALUE(LEFT($B$1,FIND("월",$B$1)-1))),1)-WEEKDAY(DATE($A$1,IFERROR(VALUE($B$1),VALUE(LEFT($B$1,FIND("월",$B$1)-1))),1),1)+1+7*(ROW()-ROW($B$3))+(COLUMN()-COLUMN($B$3)))=IFERROR(VALUE($B$1),VALUE(LEFT($B$1,FIND("월",$B$1)-1))),IF(COUNTIF($K$1:$K$10,DAY(DATE($A$1,IFERROR(VALUE($B$1),VALUE(LEFT($B$1,FIND("월",$B$1)-1))),1)-WEEKDAY(DATE($A$1,IFERROR(VALUE($B$1),VALUE(LEFT($B$1,FIND("월",$B$1)-1))),1),1)+1+7*(ROW()-ROW($B$3))+(COLUMN()-COLUMN($B$3))))=0,DAY(DATE($A$1,IFERROR(VALUE($B$1),VALUE(LEFT($B$1,FIND("월",$B$1)-1))),1)-WEEKDAY(DATE($A$1,IFERROR(VALUE($B$1),VALUE(LEFT($B$1,FIND("월",$B$1)-1))),1),1)+1+7*(ROW()-ROW($B$3))+(COLUMN()-COLUMN($B$3))),""),"") | H3: =IF(MONTH(DATE($A$1,IFERROR(VALUE($B$1),VALUE(LEFT($B$1,FIND("월",$B$1)-1))),1)-WEEKDAY(DATE($A$1,IFERROR(VALUE($B$1),VALUE(LEFT($B$1,FIND("월",$B$1)-1))),1),1)+1+7*(ROW()-ROW($B$3))+(COLUMN()-COLUMN($B$3)))=IFERROR(VALUE($B$1),VALUE(LEFT($B$1,FIND("월",$B$1)-1))),IF(COUNTIF($K$1:$K$10,DAY(DATE($A$1,IFERROR(VALUE($B$1),VALUE(LEFT($B$1,FIND("월",$B$1)-1))),1)-WEEKDAY(DATE($A$1,IFERROR(VALUE($B$1),VALUE(LEFT($B$1,FIND("월",$B$1)-1))),1),1)+1+7*(ROW()-ROW($B$3))+(COLUMN()-COLUMN($B$3))))=0,DAY(DATE($A$1,IFERROR(VALUE($B$1),VALUE(LEFT($B$1,FIND("월",$B$1)-1))),1)-WEEKDAY(DATE($A$1,IFERROR(VALUE($B$1),VALUE(LEFT($B$1,FIND("월",$B$1)-1))),1),1)+1+7*(ROW()-ROW($B$3))+(COLUMN()-COLUMN($B$3))),""),"") | K3: 6
B4: =IF(MONTH(DATE($A$1,IFERROR(VALUE($B$1),VALUE(LEFT($B$1,FIND("월",$B$1)-1))),1)-WEEKDAY(DATE($A$1,IFERROR(VALUE($B$1),VALUE(LEFT($B$1,FIND("월",$B$1)-1))),1),1)+1+7*(ROW()-ROW($B$3))+(COLUMN()-COLUMN($B$3)))=IFERROR(VALUE($B$1),VALUE(LEFT($B$1,FIND("월",$B$1)-1))),IF(COUNTIF($K$1:$K$10,DAY(DATE($A$1,IFERROR(VALUE($B$1),VALUE(LEFT($B$1,FIND("월",$B$1)-1))),1)-WEEKDAY(DATE($A$1,IFERROR(VALUE($B$1),VALUE(LEFT($B$1,FIND("월",$B$1)-1))),1),1)+1+7*(ROW()-ROW($B$3))+(COLUMN()-COLUMN($B$3))))=0,DAY(DATE($A$1,IFERROR(VALUE($B$1),VALUE(LEFT($B$1,FIND("월",$B$1)-1))),1)-WEEKDAY(DATE($A$1,IFERROR(VALUE($B$1),VALUE(LEFT($B$1,FIND("월",$B$1)-1))),1),1)+1+7*(ROW()-ROW($B$3))+(COLUMN()-COLUMN($B$3))),""),"") | C4: =IF(MONTH(DATE($A$1,IFERROR(VALUE($B$1),VALUE(LEFT($B$1,FIND("월",$B$1)-1))),1)-WEEKDAY(DATE($A$1,IFERROR(VALUE($B$1),VALUE(LEFT($B$1,FIND("월",$B$1)-1))),1),1)+1+7*(ROW()-ROW($B$3))+(COLUMN()-COLUMN($B$3)))=IFERROR(VALUE($B$1),VALUE(LEFT($B$1,FIND("월",$B$1)-1))),IF(COUNTIF($K$1:$K$10,DAY(DATE($A$1,IFERROR(VALUE($B$1),VALUE(LEFT($B$1,FIND("월",$B$1)-1))),1)-WEEKDAY(DATE($A$1,IFERROR(VALUE($B$1),VALUE(LEFT($B$1,FIND("월",$B$1)-1))),1),1)+1+7*(ROW()-ROW($B$3))+(COLUMN()-COLUMN($B$3))))=0,DAY(DATE($A$1,IFERROR(VALUE($B$1),VALUE(LEFT($B$1,FIND("월",$B$1)-1))),1)-WEEKDAY(DATE($A$1,IFERROR(VALUE($B$1),VALUE(LEFT($B$1,FIND("월",$B$1)-1))),1),1)+1+7*(ROW()-ROW($B$3))+(COLUMN()-COLUMN($B$3))),""),"") | D4: =IF(MONTH(DATE($A$1,IFERROR(VALUE($B$1),VALUE(LEFT($B$1,FIND("월",$B$1)-1))),1)-WEEKDAY(DATE($A$1,IFERROR(VALUE($B$1),VALUE(LEFT($B$1,FIND("월",$B$1)-1))),1),1)+1+7*(ROW()-ROW($B$3))+(COLUMN()-COLUMN($B$3)))=IFERROR(VALUE($B$1),VALUE(LEFT($B$1,FIND("월",$B$1)-1))),IF(COUNTIF($K$1:$K$10,DAY(DATE($A$1,IFERROR(VALUE($B$1),VALUE(LEFT($B$1,FIND("월",$B$1)-1))),1)-WEEKDAY(DATE($A$1,IFERROR(VALUE($B$1),VALUE(LEFT($B$1,FIND("월",$B$1)-1))),1),1)+1+7*(ROW()-ROW($B$3))+(COLUMN()-COLUMN($B$3))))=0,DAY(DATE($A$1,IFERROR(VALUE($B$1),VALUE(LEFT($B$1,FIND("월",$B$1)-1))),1)-WEEKDAY(DATE($A$1,IFERROR(VALUE($B$1),VALUE(LEFT($B$1,FIND("월",$B$1)-1))),1),1)+1+7*(ROW()-ROW($B$3))+(COLUMN()-COLUMN($B$3))),""),"") | E4: =IF(MONTH(DATE($A$1,IFERROR(VALUE($B$1),VALUE(LEFT($B$1,FIND("월",$B$1)-1))),1)-WEEKDAY(DATE($A$1,IFERROR(VALUE($B$1),VALUE(LEFT($B$1,FIND("월",$B$1)-1))),1),1)+1+7*(ROW()-ROW($B$3))+(COLUMN()-COLUMN($B$3)))=IFERROR(VALUE($B$1),VALUE(LEFT($B$1,FIND("월",$B$1)-1))),IF(COUNTIF($K$1:$K$10,DAY(DATE($A$1,IFERROR(VALUE($B$1),VALUE(LEFT($B$1,FIND("월",$B$1)-1))),1)-WEEKDAY(DATE($A$1,IFERROR(VALUE($B$1),VALUE(LEFT($B$1,FIND("월",$B$1)-1))),1),1)+1+7*(ROW()-ROW($B$3))+(COLUMN()-COLUMN($B$3))))=0,DAY(DATE($A$1,IFERROR(VALUE($B$1),VALUE(LEFT($B$1,FIND("월",$B$1)-1))),1)-WEEKDAY(DATE($A$1,IFERROR(VALUE($B$1),VALUE(LEFT($B$1,FIND("월",$B$1)-1))),1),1)+1+7*(ROW()-ROW($B$3))+(COLUMN()-COLUMN($B$3))),""),"") | F4: =IF(MONTH(DATE($A$1,IFERROR(VALUE($B$1),VALUE(LEFT($B$1,FIND("월",$B$1)-1))),1)-WEEKDAY(DATE($A$1,IFERROR(VALUE($B$1),VALUE(LEFT($B$1,FIND("월",$B$1)-1))),1),1)+1+7*(ROW()-ROW($B$3))+(COLUMN()-COLUMN($B$3)))=IFERROR(VALUE($B$1),VALUE(LEFT($B$1,FIND("월",$B$1)-1))),IF(COUNTIF($K$1:$K$10,DAY(DATE($A$1,IFERROR(VALUE($B$1),VALUE(LEFT($B$1,FIND("월",$B$1)-1))),1)-WEEKDAY(DATE($A$1,IFERROR(VALUE($B$1),VALUE(LEFT($B$1,FIND("월",$B$1)-1))),1),1)+1+7*(ROW()-ROW($B$3))+(COLUMN()-COLUMN($B$3))))=0,DAY(DATE($A$1,IFERROR(VALUE($B$1),VALUE(LEFT($B$1,FIND("월",$B$1)-1))),1)-WEEKDAY(DATE($A$1,IFERROR(VALUE($B$1),VALUE(LEFT($B$1,FIND("월",$B$1)-1))),1),1)+1+7*(ROW()-ROW($B$3))+(COLUMN()-COLUMN($B$3))),""),"") | G4: =IF(MONTH(DATE($A$1,IFERROR(VALUE($B$1),VALUE(LEFT($B$1,FIND("월",$B$1)-1))),1)-WEEKDAY(DATE($A$1,IFERROR(VALUE($B$1),VALUE(LEFT($B$1,FIND("월",$B$1)-1))),1),1)+1+7*(ROW()-ROW($B$3))+(COLUMN()-COLUMN($B$3)))=IFERROR(VALUE($B$1),VALUE(LEFT($B$1,FIND("월",$B$1)-1))),IF(COUNTIF($K$1:$K$10,DAY(DATE($A$1,IFERROR(VALUE($B$1),VALUE(LEFT($B$1,FIND("월",$B$1)-1))),1)-WEEKDAY(DATE($A$1,IFERROR(VALUE($B$1),VALUE(LEFT($B$1,FIND("월",$B$1)-1))),1),1)+1+7*(ROW()-ROW($B$3))+(COLUMN()-COLUMN($B$3))))=0,DAY(DATE($A$1,IFERROR(VALUE($B$1),VALUE(LEFT($B$1,FIND("월",$B$1)-1))),1)-WEEKDAY(DATE($A$1,IFERROR(VALUE($B$1),VALUE(LEFT($B$1,FIND("월",$B$1)-1))),1),1)+1+7*(ROW()-ROW($B$3))+(COLUMN()-COLUMN($B$3))),""),"") | H4: =IF(MONTH(DATE($A$1,IFERROR(VALUE($B$1),VALUE(LEFT($B$1,FIND("월",$B$1)-1))),1)-WEEKDAY(DATE($A$1,IFERROR(VALUE($B$1),VALUE(LEFT($B$1,FIND("월",$B$1)-1))),1),1)+1+7*(ROW()-ROW($B$3))+(COLUMN()-COLUMN($B$3)))=IFERROR(VALUE($B$1),VALUE(LEFT($B$1,FIND("월",$B$1)-1))),IF(COUNTIF($K$1:$K$10,DAY(DATE($A$1,IFERROR(VALUE($B$1),VALUE(LEFT($B$1,FIND("월",$B$1)-1))),1)-WEEKDAY(DATE($A$1,IFERROR(VALUE($B$1),VALUE(LEFT($B$1,FIND("월",$B$1)-1))),1),1)+1+7*(ROW()-ROW($B$3))+(COLUMN()-COLUMN($B$3))))=0,DAY(DATE($A$1,IFERROR(VALUE($B$1),VALUE(LEFT($B$1,FIND("월",$B$1)-1))),1)-WEEKDAY(DATE($A$1,IFERROR(VALUE($B$1),VALUE(LEFT($B$1,FIND("월",$B$1)-1))),1),1)+1+7*(ROW()-ROW($B$3))+(COLUMN()-COLUMN($B$3))),""),"")
B5: =IF(MONTH(DATE($A$1,IFERROR(VALUE($B$1),VALUE(LEFT($B$1,FIND("월",$B$1)-1))),1)-WEEKDAY(DATE($A$1,IFERROR(VALUE($B$1),VALUE(LEFT($B$1,FIND("월",$B$1)-1))),1),1)+1+7*(ROW()-ROW($B$3))+(COLUMN()-COLUMN($B$3)))=IFERROR(VALUE($B$1),VALUE(LEFT($B$1,FIND("월",$B$1)-1))),IF(COUNTIF($K$1:$K$10,DAY(DATE($A$1,IFERROR(VALUE($B$1),VALUE(LEFT($B$1,FIND("월",$B$1)-1))),1)-WEEKDAY(DATE($A$1,IFERROR(VALUE($B$1),VALUE(LEFT($B$1,FIND("월",$B$1)-1))),1),1)+1+7*(ROW()-ROW($B$3))+(COLUMN()-COLUMN($B$3))))=0,DAY(DATE($A$1,IFERROR(VALUE($B$1),VALUE(LEFT($B$1,FIND("월",$B$1)-1))),1)-WEEKDAY(DATE($A$1,IFERROR(VALUE($B$1),VALUE(LEFT($B$1,FIND("월",$B$1)-1))),1),1)+1+7*(ROW()-ROW($B$3))+(COLUMN()-COLUMN($B$3))),""),"") | C5: =IF(MONTH(DATE($A$1,IFERROR(VALUE($B$1),VALUE(LEFT($B$1,FIND("월",$B$1)-1))),1)-WEEKDAY(DATE($A$1,IFERROR(VALUE($B$1),VALUE(LEFT($B$1,FIND("월",$B$1)-1))),1),1)+1+7*(ROW()-ROW($B$3))+(COLUMN()-COLUMN($B$3)))=IFERROR(VALUE($B$1),VALUE(LEFT($B$1,FIND("월",$B$1)-1))),IF(COUNTIF($K$1:$K$10,DAY(DATE($A$1,IFERROR(VALUE($B$1),VALUE(LEFT($B$1,FIND("월",$B$1)-1))),1)-WEEKDAY(DATE($A$1,IFERROR(VALUE($B$1),VALUE(LEFT($B$1,FIND("월",$B$1)-1))),1),1)+1+7*(ROW()-ROW($B$3))+(COLUMN()-COLUMN($B$3))))=0,DAY(DATE($A$1,IFERROR(VALUE($B$1),VALUE(LEFT($B$1,FIND("월",$B$1)-1))),1)-WEEKDAY(DATE($A$1,IFERROR(VALUE($B$1),VALUE(LEFT($B$1,FIND("월",$B$1)-1))),1),1)+1+7*(ROW()-ROW($B$3))+(COLUMN()-COLUMN($B$3))),""),"") | D5: =IF(MONTH(DATE($A$1,IFERROR(VALUE($B$1),VALUE(LEFT($B$1,FIND("월",$B$1)-1))),1)-WEEKDAY(DATE($A$1,IFERROR(VALUE($B$1),VALUE(LEFT($B$1,FIND("월",$B$1)-1))),1),1)+1+7*(ROW()-ROW($B$3))+(COLUMN()-COLUMN($B$3)))=IFERROR(VALUE($B$1),VALUE(LEFT($B$1,FIND("월",$B$1)-1))),IF(COUNTIF($K$1:$K$10,DAY(DATE($A$1,IFERROR(VALUE($B$1),VALUE(LEFT($B$1,FIND("월",$B$1)-1))),1)-WEEKDAY(DATE($A$1,IFERROR(VALUE($B$1),VALUE(LEFT($B$1,FIND("월",$B$1)-1))),1),1)+1+7*(ROW()-ROW($B$3))+(COLUMN()-COLUMN($B$3))))=0,DAY(DATE($A$1,IFERROR(VALUE($B$1),VALUE(LEFT($B$1,FIND("월",$B$1)-1))),1)-WEEKDAY(DATE($A$1,IFERROR(VALUE($B$1),VALUE(LEFT($B$1,FIND("월",$B$1)-1))),1),1)+1+7*(ROW()-ROW($B$3))+(COLUMN()-COLUMN($B$3))),""),"") | E5: =IF(MONTH(DATE($A$1,IFERROR(VALUE($B$1),VALUE(LEFT($B$1,FIND("월",$B$1)-1))),1)-WEEKDAY(DATE($A$1,IFERROR(VALUE($B$1),VALUE(LEFT($B$1,FIND("월",$B$1)-1))),1),1)+1+7*(ROW()-ROW($B$3))+(COLUMN()-COLUMN($B$3)))=IFERROR(VALUE($B$1),VALUE(LEFT($B$1,FIND("월",$B$1)-1))),IF(COUNTIF($K$1:$K$10,DAY(DATE($A$1,IFERROR(VALUE($B$1),VALUE(LEFT($B$1,FIND("월",$B$1)-1))),1)-WEEKDAY(DATE($A$1,IFERROR(VALUE($B$1),VALUE(LEFT($B$1,FIND("월",$B$1)-1))),1),1)+1+7*(ROW()-ROW($B$3))+(COLUMN()-COLUMN($B$3))))=0,DAY(DATE($A$1,IFERROR(VALUE($B$1),VALUE(LEFT($B$1,FIND("월",$B$1)-1))),1)-WEEKDAY(DATE($A$1,IFERROR(VALUE($B$1),VALUE(LEFT($B$1,FIND("월",$B$1)-1))),1),1)+1+7*(ROW()-ROW($B$3))+(COLUMN()-COLUMN($B$3))),""),"") | F5: =IF(MONTH(DATE($A$1,IFERROR(VALUE($B$1),VALUE(LEFT($B$1,FIND("월",$B$1)-1))),1)-WEEKDAY(DATE($A$1,IFERROR(VALUE($B$1),VALUE(LEFT($B$1,FIND("월",$B$1)-1))),1),1)+1+7*(ROW()-ROW($B$3))+(COLUMN()-COLUMN($B$3)))=IFERROR(VALUE($B$1),VALUE(LEFT($B$1,FIND("월",$B$1)-1))),IF(COUNTIF($K$1:$K$10,DAY(DATE($A$1,IFERROR(VALUE($B$1),VALUE(LEFT($B$1,FIND("월",$B$1)-1))),1)-WEEKDAY(DATE($A$1,IFERROR(VALUE($B$1),VALUE(LEFT($B$1,FIND("월",$B$1)-1))),1),1)+1+7*(ROW()-ROW($B$3))+(COLUMN()-COLUMN($B$3))))=0,DAY(DATE($A$1,IFERROR(VALUE($B$1),VALUE(LEFT($B$1,FIND("월",$B$1)-1))),1)-WEEKDAY(DATE($A$1,IFERROR(VALUE($B$1),VALUE(LEFT($B$1,FIND("월",$B$1)-1))),1),1)+1+7*(ROW()-ROW($B$3))+(COLUMN()-COLUMN($B$3))),""),"") | G5: =IF(MONTH(DATE($A$1,IFERROR(VALUE($B$1),VALUE(LEFT($B$1,FIND("월",$B$1)-1))),1)-WEEKDAY(DATE($A$1,IFERROR(VALUE($B$1),VALUE(LEFT($B$1,FIND("월",$B$1)-1))),1),1)+1+7*(ROW()-ROW($B$3))+(COLUMN()-COLUMN($B$3)))=IFERROR(VALUE($B$1),VALUE(LEFT($B$1,FIND("월",$B$1)-1))),IF(COUNTIF($K$1:$K$10,DAY(DATE($A$1,IFERROR(VALUE($B$1),VALUE(LEFT($B$1,FIND("월",$B$1)-1))),1)-WEEKDAY(DATE($A$1,IFERROR(VALUE($B$1),VALUE(LEFT($B$1,FIND("월",$B$1)-1))),1),1)+1+7*(ROW()-ROW($B$3))+(COLUMN()-COLUMN($B$3))))=0,DAY(DATE($A$1,IFERROR(VALUE($B$1),VALUE(LEFT($B$1,FIND("월",$B$1)-1))),1)-WEEKDAY(DATE($A$1,IFERROR(VALUE($B$1),VALUE(LEFT($B$1,FIND("월",$B$1)-1))),1),1)+1+7*(ROW()-ROW($B$3))+(COLUMN()-COLUMN($B$3))),""),"") | H5: =IF(MONTH(DATE($A$1,IFERROR(VALUE($B$1),VALUE(LEFT($B$1,FIND("월",$B$1)-1))),1)-WEEKDAY(DATE($A$1,IFERROR(VALUE($B$1),VALUE(LEFT($B$1,FIND("월",$B$1)-1))),1),1)+1+7*(ROW()-ROW($B$3))+(COLUMN()-COLUMN($B$3)))=IFERROR(VALUE($B$1),VALUE(LEFT($B$1,FIND("월",$B$1)-1))),IF(COUNTIF($K$1:$K$10,DAY(DATE($A$1,IFERROR(VALUE($B$1),VALUE(LEFT($B$1,FIND("월",$B$1)-1))),1)-WEEKDAY(DATE($A$1,IFERROR(VALUE($B$1),VALUE(LEFT($B$1,FIND("월",$B$1)-1))),1),1)+1+7*(ROW()-ROW($B$3))+(COLUMN()-COLUMN($B$3))))=0,DAY(DATE($A$1,IFERROR(VALUE($B$1),VALUE(LEFT($B$1,FIND("월",$B$1)-1))),1)-WEEKDAY(DATE($A$1,IFERROR(VALUE($B$1),VALUE(LEFT($B$1,FIND("월",$B$1)-1))),1),1)+1+7*(ROW()-ROW($B$3))+(COLUMN()-COLUMN($B$3))),""),"")
