Workbook

Sheet 2단지 요가(화목07시김수정)
A1: =월!$A$1 & "월 " & SUBSTITUTE(LEFT(MID(CELL("filename",A1), FIND("]",CELL("filename",A1))+1, 255), FIND("(", MID(CELL("filename",A1), FIND("]",CELL("filename",A1))+1, 255))-1), "2단지 ", "") & " " & LEFT(MID(MID(CELL("filename",A1), FIND("]",CELL("filename",A1))+1, 255), FIND("(", MID(CELL("filename",A1), FIND("]",CELL("filename",A1))+1, 255))+1, 255), FIND("시", MID(MID(CELL("filename",A1), FIND("]",CELL("filename",A1))+1, 255), FIND("(", MID(CELL("filename",A1), FIND("]",CELL("filename",A1))+1, 255))+1, 255))-3) & " " & RIGHT(LEFT(MID(MID(CELL("filename",A1), FIND("]",CELL("filename",A1))+1, 255), FIND("(", MID(CELL("filename",A1), FIND("]",CELL("filename",A1))+1, 255))+1, 255), FIND("시", MID(MID(CELL("filename",A1), FIND("]",CELL("filename",A1))+1, 255), FIND("(", MID(CELL("filename",A1), FIND("]",CELL("filename",A1))+1, 255))+1, 255))), 3) & " 신청서" -> 10월 요가 화목 07시 신청서
G4: 강사: 김수정
G5: 요일: 화 , 목 / 시간: 오전 07시
A6: 1. 강습료는 월 8회 50,000원이며, 당월 관리비에 자동 부과됩니다.
A7: 2. 강습은 매주 화,목(주2회) 이며 국/공휴일은 강습이 없습니다.
A8: 3. 각반 정원은 30명이며, 10명미만 접수시 폐강 할 수 있습니다.
A9: 4. 강습대상은 성인이며, 청소년도 가능합니다. 강습양도 불가합니다.
A10: 5. 중도 등록, 취소시 일할계산(월8회 기준)되어 강습료 부과되며 강습 취소 미신청 시 전액부과됩니다.(당일 취소는 불가)
A11: 6. 중도취소 신청은 방문 신청만 가능합니다.(장소: 2단지 안내데스크 방문)
A12: 7. 강습은 3개월 단위 재추첨하며, 강습 기간중 중도 취소 하지 않는 경우 3개월간 자동 재등록 됩니다.
A14: 시간 | B14: 순번 | C14: 날 짜 | D14: 성함 | E14: 동 | F14: 호수 | G14: 서명 | H14: 취소날짜 | I14: 취소서명 | J14: 비고
A15: 07:00 ~ 07:50 | B15: 1
B16: 2
B17: 3
B18: 4
B19: 5
B20: 6
B21: 7
B22: 8
B23: 9
B24: 10
B25: 11
B26: 12
B27: 13
... B34: 20
A35: =A1 -> 10월 요가 화목 07시 신청서
G38: =G4 -> 강사: 김수정
G39: =G5 -> 요일: 화 , 목 / 시간: 오전 07시
A40: =A6 -> 1. 강습료는 월 8회 50,000원이며, 당월 관리비에 자동 부과됩니다.
A41: =A7 -> 2. 강습은 매주 화,목(주2회) 이며 국/공휴일은 강습이 없습니다.
A42: =A8 -> 3. 각반 정원은 30명이며, 10명미만 접수시 폐강 할 수 있습니다.
A43: =A9 -> 4. 강습대상은 성인이며, 청소년도 가능합니다. 강습양도 불가합니다.
A44: =A10 -> 5. 중도 등록, 취소시 일할계산(월8회 기준)되어 강습료 부과되며 강습 취소 미신청 시 전액부과됩니다.(당일 취소는 불가)
A45: =A11 -> 6. 중도취소 신청은 방문 신청만 가능합니다.(장소: 2단지 안내데스크 방문)
A46: =A12 -> 7. 강습은 3개월 단위 재추첨하며, 강습 기간중 중도 취소 하지 않는 경우 3개월간 자동 재등록 됩니다.
A48: 시간 | B48: 순번 | C48: 날 짜 | D48: 성함 | E48: 동 | F48: 호수 | G48: 서명 | H48: 취소날짜 | I48: 취소서명 | J48: 비고
A49: =A15 -> 07:00 ~ 07:50 | B49: 21
B50: 22
B51: 23
B52: 24
...

Sheet 2단지 요가(화목08시김수정)
A1: =월!$A$1 & "월 " & SUBSTITUTE(LEFT(MID(CELL("filename",A1), FIND("]",CELL("filename",A1))+1, 255), FIND("(", MID(CELL("filename",A1), FIND("]",CELL("filename",A1))+1, 255))-1), "2단지 ", "") & " " & LEFT(MID(MID(CELL("filename",A1), FIND("]",CELL("filename",A1))+1, 255), FIND("(", MID(CELL("filename",A1), FIND("]",CELL("filename",A1))+1, 255))+1, 255), FIND("시", MID(MID(CELL("filename",A1), FIND("]",CELL("filename",A1))+1, 255), FIND("(", MID(CELL("filename",A1), FIND("]",CELL("filename",A1))+1, 255))+1, 255))-3) & " " & RIGHT(LEFT(MID(MID(CELL("filename",A1), FIND("]",CELL("filename",A1))+1, 255), FIND("(", MID(CELL("filename",A1), FIND("]",CELL("filename",A1))+1, 255))+1, 255), FIND("시", MID(MID(CELL("filename",A1), FIND("]",CELL("filename",A1))+1, 255), FIND("(", MID(CELL("filename",A1), FIND("]",CELL("filename",A1))+1, 255))+1, 255))), 3) & " 신청서" -> 10월 요가 화목 08시 신청서
G4: 강사: 김수정
G5: 요일: 화 , 목 / 시간: 오전 08시
A6: 1. 강습료는 월 8회 50,000원이며, 당월 관리비에 자동 부과됩니다.
A7: 2. 강습은 매주 화,목(주2회) 이며 국/공휴일은 강습이 없습니다.
A8: 3. 각반 정원은 30명이며, 10명미만 접수시 폐강 할 수 있습니다.
A9: 4. 강습대상은 성인이며, 청소년도 가능합니다. 강습양도 불가합니다.
A10: 5. 중도 등록, 취소시 일할계산(월8회 기준)되어 강습료 부과되며 강습 취소 미신청 시 전액부과됩니다.(당일 취소는 불가)
A11: 6. 중도취소 신청은 방문 신청만 가능합니다.(장소: 2단지 안내데스크 방문)
A12: 7. 강습은 3개월 단위 재추첨하며, 강습 기간중 중도 취소 하지 않는 경우 3개월간 자동 재등록 됩니다.
A14: 시간 | B14: 순번 | C14: 날 짜 | D14: 성함 | E14: 동 | F14: 호수 | G14: 서명 | H14: 취소날짜 | I14: 취소서명 | J14: 비고
A15: 08:00 ~ 08:50 | B15: 1
B16: 2
B17: 3
B18: 4
B19: 5
B20: 6
B21: 7
B22: 8
B23: 9
B24: 10
B25: 11
B26: 12
B27: 13
... B34: 20
A35: =A1 -> 10월 요가 화목 08시 신청서
G38: =G4 -> 강사: 김수정
G39: =G5 -> 요일: 화 , 목 / 시간: 오전 08시
A40: =A6 -> 1. 강습료는 월 8회 50,000원이며, 당월 관리비에 자동 부과됩니다.
A41: =A7 -> 2. 강습은 매주 화,목(주2회) 이며 국/공휴일은 강습이 없습니다.
A42: =A8 -> 3. 각반 정원은 30명이며, 10명미만 접수시 폐강 할 수 있습니다.
A43: =A9 -> 4. 강습대상은 성인이며, 청소년도 가능합니다. 강습양도 불가합니다.
A44: =A10 -> 5. 중도 등록, 취소시 일할계산(월8회 기준)되어 강습료 부과되며 강습 취소 미신청 시 전액부과됩니다.(당일 취소는 불가)
A45: =A11 -> 6. 중도취소 신청은 방문 신청만 가능합니다.(장소: 2단지 안내데스크 방문)
A46: =A12 -> 7. 강습은 3개월 단위 재추첨하며, 강습 기간중 중도 취소 하지 않는 경우 3개월간 자동 재등록 됩니다.
A48: 시간 | B48: 순번 | C48: 날 짜 | D48: 성함 | E48: 동 | F48: 호수 | G48: 서명 | H48: 취소날짜 | I48: 취소서명 | J48: 비고
A49: =A15 -> 08:00 ~ 08:50 | B49: 21
B50: 22
B51: 23
B52: 24
...

Sheet 2단지 요가(화목09시도은진)
A1: =월!$A$1 & "월 " & SUBSTITUTE(LEFT(MID(CELL("filename",A1), FIND("]",CELL("filename",A1))+1, 255), FIND("(", MID(CELL("filename",A1), FIND("]",CELL("filename",A1))+1, 255))-1), "2단지 ", "") & " " & LEFT(MID(MID(CELL("filename",A1), FIND("]",CELL("filename",A1))+1, 255), FIND("(", MID(CELL("filename",A1), FIND("]",CELL("filename",A1))+1, 255))+1, 255), FIND("시", MID(MID(CELL("filename",A1), FIND("]",CELL("filename",A1))+1, 255), FIND("(", MID(CELL("filename",A1), FIND("]",CELL("filename",A1))+1, 255))+1, 255))-3) & " " & RIGHT(LEFT(MID(MID(CELL("filename",A1), FIND("]",CELL("filename",A1))+1, 255), FIND("(", MID(CELL("filename",A1), FIND("]",CELL("filename",A1))+1, 255))+1, 255), FIND("시", MID(MID(CELL("filename",A1), FIND("]",CELL("filename",A1))+1, 255), FIND("(", MID(CELL("filename",A1), FIND("]",CELL("filename",A1))+1, 255))+1, 255))), 3) & " 신청서" -> 10월 요가 화목 09시 신청서
G4: 강사: 도은진
G5: 요일: 화 , 목 / 시간: 오전 09시
A6: 1. 강습료는 월 8회 50,000원이며, 당월 관리비에 자동 부과됩니다.
A7: 2. 강습은 매주 화,목(주2회) 이며 국/공휴일은 강습이 없습니다.
A8: 3. 각반 정원은 30명이며, 10명미만 접수시 폐강 할 수 있습니다.
A9: 4. 강습대상은 성인이며, 청소년도 가능합니다. 강습양도 불가합니다.
A10: 5. 중도 등록, 취소시 일할계산(월8회 기준)되어 강습료 부과되며 강습 취소 미신청 시 전액부과됩니다.(당일 취소는 불가)
A11: 6. 중도취소 신청은 방문 신청만 가능합니다.(장소: 2단지 안내데스크 방문)
A12: 7. 강습은 3개월 단위 재추첨하며, 강습 기간중 중도 취소 하지 않는 경우 3개월간 자동 재등록 됩니다.
A14: 시간 | B14: 순번 | C14: 날 짜 | D14: 성함 | E14: 동 | F14: 호수 | G14: 서명 | H14: 취소날짜 | I14: 취소서명 | J14: 비고
A15: 09:00 ~ 09:50 | B15: 1
B16: 2
B17: 3
B18: 4
B19: 5
B20: 6
B21: 7
B22: 8
B23: 9
B24: 10
B25: 11
B26: 12
B27: 13
... B34: 20
A35: =A1 -> 10월 요가 화목 09시 신청서
G38: =G4 -> 강사: 도은진
G39: =G5 -> 요일: 화 , 목 / 시간: 오전 09시
A40: =A6 -> 1. 강습료는 월 8회 50,000원이며, 당월 관리비에 자동 부과됩니다.
A41: =A7 -> 2. 강습은 매주 화,목(주2회) 이며 국/공휴일은 강습이 없습니다.
A42: =A8 -> 3. 각반 정원은 30명이며, 10명미만 접수시 폐강 할 수 있습니다.
A43: =A9 -> 4. 강습대상은 성인이며, 청소년도 가능합니다. 강습양도 불가합니다.
A44: =A10 -> 5. 중도 등록, 취소시 일할계산(월8회 기준)되어 강습료 부과되며 강습 취소 미신청 시 전액부과됩니다.(당일 취소는 불가)
A45: =A11 -> 6. 중도취소 신청은 방문 신청만 가능합니다.(장소: 2단지 안내데스크 방문)
A46: =A12 -> 7. 강습은 3개월 단위 재추첨하며, 강습 기간중 중도 취소 하지 않는 경우 3개월간 자동 재등록 됩니다.
A48: 시간 | B48: 순번 | C48: 날 짜 | D48: 성함 | E48: 동 | F48: 호수 | G48: 서명 | H48: 취소날짜 | I48: 취소서명 | J48: 비고
A49: =A15 -> 09:00 ~ 09:50 | B49: 21
B50: 22
B51: 23
B52: 24
...

Sheet 2단지 요가(화목10시도은진)
A1: =월!$A$1 & "월 " & SUBSTITUTE(LEFT(MID(CELL("filename",A1), FIND("]",CELL("filename",A1))+1, 255), FIND("(", MID(CELL("filename",A1), FIND("]",CELL("filename",A1))+1, 255))-1), "2단지 ", "") & " " & LEFT(MID(MID(CELL("filename",A1), FIND("]",CELL("filename",A1))+1, 255), FIND("(", MID(CELL("filename",A1), FIND("]",CELL("filename",A1))+1, 255))+1, 255), FIND("시", MID(MID(CELL("filename",A1), FIND("]",CELL("filename",A1))+1, 255), FIND("(", MID(CELL("filename",A1), FIND("]",CELL("filename",A1))+1, 255))+1, 255))-3) & " " & RIGHT(LEFT(MID(MID(CELL("filename",A1), FIND("]",CELL("filename",A1))+1, 255), FIND("(", MID(CELL("filename",A1), FIND("]",CELL("filename",A1))+1, 255))+1, 255), FIND("시", MID(MID(CELL("filename",A1), FIND("]",CELL("filename",A1))+1, 255), FIND("(", MID(CELL("filename",A1), FIND("]",CELL("filename",A1))+1, 255))+1, 255))), 3) & " 신청서" -> 10월 요가 화목 10시 신청서
G4: 강사: 도은진
G5: 요일: 화 , 목 / 시간: 오전 10시
A6: 1. 강습료는 월 8회 50,000원이며, 당월 관리비에 자동 부과됩니다.
A7: 2. 강습은 매주 화,목(주2회) 이며 국/공휴일은 강습이 없습니다.
A8: 3. 각반 정원은 30명이며, 10명미만 접수시 폐강 할 수 있습니다.
A9: 4. 강습대상은 성인이며, 청소년도 가능합니다. 강습양도 불가합니다.
A10: 5. 중도 등록, 취소시 일할계산(월8회 기준)되어 강습료 부과되며 강습 취소 미신청 시 전액부과됩니다.(당일 취소는 불가)
A11: 6. 중도취소 신청은 방문 신청만 가능합니다.(장소: 2단지 안내데스크 방문)
A12: 7. 강습은 3개월 단위 재추첨하며, 강습 기간중 중도 취소 하지 않는 경우 3개월간 자동 재등록 됩니다.
A14: 시간 | B14: 순번 | C14: 날 짜 | D14: 성함 | E14: 동 | F14: 호수 | G14: 서명 | H14: 취소날짜 | I14: 취소서명 | J14: 비고
A15: 10:00 ~ 10:50 | B15: 1
B16: 2
B17: 3
B18: 4
B19: 5
B20: 6
B21: 7
B22: 8
B23: 9
B24: 10
B25: 11
B26: 12
B27: 13
... B34: 20
A35: =A1 -> 10월 요가 화목 10시 신청서
G38: =G4 -> 강사: 도은진
G39: =G5 -> 요일: 화 , 목 / 시간: 오전 10시
A40: =A6 -> 1. 강습료는 월 8회 50,000원이며, 당월 관리비에 자동 부과됩니다.
A41: =A7 -> 2. 강습은 매주 화,목(주2회) 이며 국/공휴일은 강습이 없습니다.
A42: =A8 -> 3. 각반 정원은 30명이며, 10명미만 접수시 폐강 할 수 있습니다.
A43: =A9 -> 4. 강습대상은 성인이며, 청소년도 가능합니다. 강습양도 불가합니다.
A44: =A10 -> 5. 중도 등록, 취소시 일할계산(월8회 기준)되어 강습료 부과되며 강습 취소 미신청 시 전액부과됩니다.(당일 취소는 불가)
A45: =A11 -> 6. 중도취소 신청은 방문 신청만 가능합니다.(장소: 2단지 안내데스크 방문)
A46: =A12 -> 7. 강습은 3개월 단위 재추첨하며, 강습 기간중 중도 취소 하지 않는 경우 3개월간 자동 재등록 됩니다.
A48: 시간 | B48: 순번 | C48: 날 짜 | D48: 성함 | E48: 동 | F48: 호수 | G48: 서명 | H48: 취소날짜 | I48: 취소서명 | J48: 비고
A49: =A15 -> 10:00 ~ 10:50 | B49: 21
B50: 22
B51: 23
B52: 24
...

Sheet 2단지 요가(화목20시이인지)
A1: =월!$A$1 & "월 " & SUBSTITUTE(LEFT(MID(CELL("filename",A1), FIND("]",CELL("filename",A1))+1, 255), FIND("(", MID(CELL("filename",A1), FIND("]",CELL("filename",A1))+1, 255))-1), "2단지 ", "") & " " & LEFT(MID(MID(CELL("filename",A1), FIND("]",CELL("filename",A1))+1, 255), FIND("(", MID(CELL("filename",A1), FIND("]",CELL("filename",A1))+1, 255))+1, 255), FIND("시", MID(MID(CELL("filename",A1), FIND("]",CELL("filename",A1))+1, 255), FIND("(", MID(CELL("filename",A1), FIND("]",CELL("filename",A1))+1, 255))+1, 255))-3) & " " & RIGHT(LEFT(MID(MID(CELL("filename",A1), FIND("]",CELL("filename",A1))+1, 255), FIND("(", MID(CELL("filename",A1), FIND("]",CELL("filename",A1))+1, 255))+1, 255), FIND("시", MID(MID(CELL("filename",A1), FIND("]",CELL("filename",A1))+1, 255), FIND("(", MID(CELL("filename",A1), FIND("]",CELL("filename",A1))+1, 255))+1, 255))), 3) & " 신청서" -> 10월 요가 화목 20시 신청서
G4: 강사: 이인지
G5: 요일: 화 , 목 / 시간: 오후 8시
A6: 1. 강습료는 월 8회 50,000원이며, 당월 관리비에 자동 부과됩니다.
A7: 2. 강습은 매주 화,목(주2회) 이며 국/공휴일은 강습이 없습니다.
A8: 3. 각반 정원은 30명이며, 10명미만 접수시 폐강 할 수 있습니다.
A9: 4. 강습대상은 성인이며, 청소년도 가능합니다. 강습양도 불가합니다.
A10: 5. 중도 등록, 취소시 일할계산(월8회 기준)되어 강습료 부과되며 강습 취소 미신청 시 전액부과됩니다.(당일 취소는 불가)
A11: 6. 중도취소 신청은 방문 신청만 가능합니다.(장소: 2단지 안내데스크 방문)
A12: 7. 강습은 3개월 단위 재추첨하며, 강습 기간중 중도 취소 하지 않는 경우 3개월간 자동 재등록 됩니다.
A14: 시간 | B14: 순번 | C14: 날 짜 | D14: 성함 | E14: 동 | F14: 호수 | G14: 서명 | H14: 취소날짜 | I14: 취소서명 | J14: 비고
A15: 20:00 ~ 20:50 | B15: 1
B16: 2
B17: 3
B18: 4
B19: 5
B20: 6
B21: 7
B22: 8
B23: 9
B24: 10
B25: 11
B26: 12
B27: 13
... B34: 20
A35: =A1 -> 10월 요가 화목 20시 신청서
G38: =G4 -> 강사: 이인지
G39: =G5 -> 요일: 화 , 목 / 시간: 오후 8시
A40: =A6 -> 1. 강습료는 월 8회 50,000원이며, 당월 관리비에 자동 부과됩니다.
A41: =A7 -> 2. 강습은 매주 화,목(주2회) 이며 국/공휴일은 강습이 없습니다.
A42: =A8 -> 3. 각반 정원은 30명이며, 10명미만 접수시 폐강 할 수 있습니다.
A43: =A9 -> 4. 강습대상은 성인이며, 청소년도 가능합니다. 강습양도 불가합니다.
A44: =A10 -> 5. 중도 등록, 취소시 일할계산(월8회 기준)되어 강습료 부과되며 강습 취소 미신청 시 전액부과됩니다.(당일 취소는 불가)
A45: =A11 -> 6. 중도취소 신청은 방문 신청만 가능합니다.(장소: 2단지 안내데스크 방문)
A46: =A12 -> 7. 강습은 3개월 단위 재추첨하며, 강습 기간중 중도 취소 하지 않는 경우 3개월간 자동 재등록 됩니다.
A48: 시간 | B48: 순번 | C48: 날 짜 | D48: 성함 | E48: 동 | F48: 호수 | G48: 서명 | H48: 취소날짜 | I48: 취소서명 | J48: 비고
A49: =A15 -> 20:00 ~ 20:50 | B49: 21
B50: 22
B51: 23
B52: 24
...

Sheet 2단지 요가(화목21시이인지)
A1: =월!$A$1 & "월 " & SUBSTITUTE(LEFT(MID(CELL("filename",A1), FIND("]",CELL("filename",A1))+1, 255), FIND("(", MID(CELL("filename",A1), FIND("]",CELL("filename",A1))+1, 255))-1), "2단지 ", "") & " " & LEFT(MID(MID(CELL("filename",A1), FIND("]",CELL("filename",A1))+1, 255), FIND("(", MID(CELL("filename",A1), FIND("]",CELL("filename",A1))+1, 255))+1, 255), FIND("시", MID(MID(CELL("filename",A1), FIND("]",CELL("filename",A1))+1, 255), FIND("(", MID(CELL("filename",A1), FIND("]",CELL("filename",A1))+1, 255))+1, 255))-3) & " " & RIGHT(LEFT(MID(MID(CELL("filename",A1), FIND("]",CELL("filename",A1))+1, 255), FIND("(", MID(CELL("filename",A1), FIND("]",CELL("filename",A1))+1, 255))+1, 255), FIND("시", MID(MID(CELL("filename",A1), FIND("]",CELL("filename",A1))+1, 255), FIND("(", MID(CELL("filename",A1), FIND("]",CELL("filename",A1))+1, 255))+1, 255))), 3) & " 신청서" -> 10월 요가 화목 21시 신청서
G4: 강사: 이인지
G5: 요일: 화 , 목 / 시간: 오후 9시
A6: 1. 강습료는 월 8회 50,000원이며, 당월 관리비에 자동 부과됩니다.
A7: 2. 강습은 매주 화,목(주2회) 이며 국/공휴일은 강습이 없습니다.
A8: 3. 각반 정원은 30명이며, 10명미만 접수시 폐강 할 수 있습니다.
A9: 4. 강습대상은 성인이며, 청소년도 가능합니다. 강습양도 불가합니다.
A10: 5. 중도 등록, 취소시 일할계산(월8회 기준)되어 강습료 부과되며 강습 취소 미신청 시 전액부과됩니다.(당일 취소는 불가)
A11: 6. 중도취소 신청은 방문 신청만 가능합니다.(장소: 2단지 안내데스크 방문)
A12: 7. 강습은 3개월 단위 재추첨하며, 강습 기간중 중도 취소 하지 않는 경우 3개월간 자동 재등록 됩니다.
A14: 시간 | B14: 순번 | C14: 날 짜 | D14: 성함 | E14: 동 | F14: 호수 | G14: 서명 | H14: 취소날짜 | I14: 취소서명 | J14: 비고
A15: 21:00 ~ 21:50 | B15: 1
B16: 2
B17: 3
B18: 4
B19: 5
B20: 6
B21: 7
B22: 8
B23: 9
B24: 10
B25: 11
B26: 12
B27: 13
... B34: 20
A35: =A1 -> 10월 요가 화목 21시 신청서
G38: =G4 -> 강사: 이인지
G39: =G5 -> 요일: 화 , 목 / 시간: 오후 9시
A40: =A6 -> 1. 강습료는 월 8회 50,000원이며, 당월 관리비에 자동 부과됩니다.
A41: =A7 -> 2. 강습은 매주 화,목(주2회) 이며 국/공휴일은 강습이 없습니다.
A42: =A8 -> 3. 각반 정원은 30명이며, 10명미만 접수시 폐강 할 수 있습니다.
A43: =A9 -> 4. 강습대상은 성인이며, 청소년도 가능합니다. 강습양도 불가합니다.
A44: =A10 -> 5. 중도 등록, 취소시 일할계산(월8회 기준)되어 강습료 부과되며 강습 취소 미신청 시 전액부과됩니다.(당일 취소는 불가)
A45: =A11 -> 6. 중도취소 신청은 방문 신청만 가능합니다.(장소: 2단지 안내데스크 방문)
A46: =A12 -> 7. 강습은 3개월 단위 재추첨하며, 강습 기간중 중도 취소 하지 않는 경우 3개월간 자동 재등록 됩니다.
A48: 시간 | B48: 순번 | C48: 날 짜 | D48: 성함 | E48: 동 | F48: 호수 | G48: 서명 | H48: 취소날짜 | I48: 취소서명 | J48: 비고
A49: =A15 -> 21:00 ~ 21:50 | B49: 21
B50: 22
B51: 23
B52: 24
...

Sheet 2단지 요가(수금08시윤명원)
A1: =월!$A$1 & "월 " & SUBSTITUTE(LEFT(MID(CELL("filename",A1), FIND("]",CELL("filename",A1))+1, 255), FIND("(", MID(CELL("filename",A1), FIND("]",CELL("filename",A1))+1, 255))-1), "2단지 ", "") & " " & LEFT(MID(MID(CELL("filename",A1), FIND("]",CELL("filename",A1))+1, 255), FIND("(", MID(CELL("filename",A1), FIND("]",CELL("filename",A1))+1, 255))+1, 255), FIND("시", MID(MID(CELL("filename",A1), FIND("]",CELL("filename",A1))+1, 255), FIND("(", MID(CELL("filename",A1), FIND("]",CELL("filename",A1))+1, 255))+1, 255))-3) & " " & RIGHT(LEFT(MID(MID(CELL("filename",A1), FIND("]",CELL("filename",A1))+1, 255), FIND("(", MID(CELL("filename",A1), FIND("]",CELL("filename",A1))+1, 255))+1, 255), FIND("시", MID(MID(CELL("filename",A1), FIND("]",CELL("filename",A1))+1, 255), FIND("(", MID(CELL("filename",A1), FIND("]",CELL("filename",A1))+1, 255))+1, 255))), 3) & " 신청서" -> 10월 요가 수금 08시 신청서
G4: 강사: 윤명원
G5: 요일: 수 , 금 / 시간: 오전 8시
A6: 1. 강습료는 월 8회 50,000원이며, 당월 관리비에 자동 부과됩니다.
A7: 2. 강습은 매주 수,금(주2회) 이며 국/공휴일은 강습이 없습니다.
A8: 3. 각반 정원은 30명이며, 10명미만 접수시 폐강 할 수 있습니다.
A9: 4. 강습대상은 성인이며, 청소년도 가능합니다. 강습양도 불가합니다.
A10: 5. 중도 등록, 취소시 일할계산(월8회 기준)되어 강습료 부과되며 강습 취소 미신청 시 전액부과됩니다.(당일 취소는 불가)
A11: 6. 중도취소 신청은 방문 신청만 가능합니다.(장소: 2단지 안내데스크 방문)
A12: 7. 강습은 3개월 단위 재추첨하며, 강습 기간중 중도 취소 하지 않는 경우 3개월간 자동 재등록 됩니다.
A14: 시간 | B14: 순번 | C14: 날 짜 | D14: 성함 | E14: 동 | F14: 호수 | G14: 서명 | H14: 취소날짜 | I14: 취소서명 | J14: 비고
A15: 08:00 ~ 08:50 | B15: 1
B16: 2
B17: 3
B18: 4
B19: 5
B20: 6
B21: 7
B22: 8
B23: 9
B24: 10
B25: 11
B26: 12
B27: 13
... B34: 20
A35: =A1 -> 10월 요가 수금 08시 신청서
G38: =G4 -> 강사: 윤명원
G39: =G5 -> 요일: 수 , 금 / 시간: 오전 8시
A40: =A6 -> 1. 강습료는 월 8회 50,000원이며, 당월 관리비에 자동 부과됩니다.
A41: =A7 -> 2. 강습은 매주 수,금(주2회) 이며 국/공휴일은 강습이 없습니다.
A42: =A8 -> 3. 각반 정원은 30명이며, 10명미만 접수시 폐강 할 수 있습니다.
A43: =A9 -> 4. 강습대상은 성인이며, 청소년도 가능합니다. 강습양도 불가합니다.
A44: =A10 -> 5. 중도 등록, 취소시 일할계산(월8회 기준)되어 강습료 부과되며 강습 취소 미신청 시 전액부과됩니다.(당일 취소는 불가)
A45: =A11 -> 6. 중도취소 신청은 방문 신청만 가능합니다.(장소: 2단지 안내데스크 방문)
A46: =A12 -> 7. 강습은 3개월 단위 재추첨하며, 강습 기간중 중도 취소 하지 않는 경우 3개월간 자동 재등록 됩니다.
A48: 시간 | B48: 순번 | C48: 날 짜 | D48: 성함 | E48: 동 | F48: 호수 | G48: 서명 | H48: 취소날짜 | I48: 취소서명 | J48: 비고
A49: =A15 -> 08:00 ~ 08:50 | B49: 21
B50: 22
B51: 23
B52: 24
...

Sheet 2단지 요가(수금09시윤명원)
A1: =월!$A$1 & "월 " & SUBSTITUTE(LEFT(MID(CELL("filename",A1), FIND("]",CELL("filename",A1))+1, 255), FIND("(", MID(CELL("filename",A1), FIND("]",CELL("filename",A1))+1, 255))-1), "2단지 ", "") & " " & LEFT(MID(MID(CELL("filename",A1), FIND("]",CELL("filename",A1))+1, 255), FIND("(", MID(CELL("filename",A1), FIND("]",CELL("filename",A1))+1, 255))+1, 255), FIND("시", MID(MID(CELL("filename",A1), FIND("]",CELL("filename",A1))+1, 255), FIND("(", MID(CELL("filename",A1), FIND("]",CELL("filename",A1))+1, 255))+1, 255))-3) & " " & RIGHT(LEFT(MID(MID(CELL("filename",A1), FIND("]",CELL("filename",A1))+1, 255), FIND("(", MID(CELL("filename",A1), FIND("]",CELL("filename",A1))+1, 255))+1, 255), FIND("시", MID(MID(CELL("filename",A1), FIND("]",CELL("filename",A1))+1, 255), FIND("(", MID(CELL("filename",A1), FIND("]",CELL("filename",A1))+1, 255))+1, 255))), 3) & " 신청서" -> 10월 요가 수금 09시 신청서
G4: 강사: 윤명원
G5: 요일: 수 , 금 / 시간: 오전 9시
A6: 1. 강습료는 월 8회 50,000원이며, 당월 관리비에 자동 부과됩니다.
A7: 2. 강습은 매주 수,금(주2회) 이며 국/공휴일은 강습이 없습니다.
A8: 3. 각반 정원은 30명이며, 10명미만 접수시 폐강 할 수 있습니다.
A9: 4. 강습대상은 성인이며, 청소년도 가능합니다. 강습양도 불가합니다.
A10: 5. 중도 등록, 취소시 일할계산(월8회 기준)되어 강습료 부과되며 강습 취소 미신청 시 전액부과됩니다.(당일 취소는 불가)
A11: 6. 중도취소 신청은 방문 신청만 가능합니다.(장소: 2단지 안내데스크 방문)
A12: 7. 강습은 3개월 단위 재추첨하며, 강습 기간중 중도 취소 하지 않는 경우 3개월간 자동 재등록 됩니다.
A14: 시간 | B14: 순번 | C14: 날 짜 | D14: 성함 | E14: 동 | F14: 호수 | G14: 서명 | H14: 취소날짜 | I14: 취소서명 | J14: 비고
A15: 09:00 ~ 09:50 | B15: 1
B16: 2
B17: 3
B18: 4
B19: 5
B20: 6
B21: 7
B22: 8
B23: 9
B24: 10
B25: 11
B26: 12
B27: 13
... B34: 20
A35: =A1 -> 10월 요가 수금 09시 신청서
G38: =G4 -> 강사: 윤명원
G39: =G5 -> 요일: 수 , 금 / 시간: 오전 9시
A40: =A6 -> 1. 강습료는 월 8회 50,000원이며, 당월 관리비에 자동 부과됩니다.
A41: =A7 -> 2. 강습은 매주 수,금(주2회) 이며 국/공휴일은 강습이 없습니다.
A42: =A8 -> 3. 각반 정원은 30명이며, 10명미만 접수시 폐강 할 수 있습니다.
A43: =A9 -> 4. 강습대상은 성인이며, 청소년도 가능합니다. 강습양도 불가합니다.
A44: =A10 -> 5. 중도 등록, 취소시 일할계산(월8회 기준)되어 강습료 부과되며 강습 취소 미신청 시 전액부과됩니다.(당일 취소는 불가)
A45: =A11 -> 6. 중도취소 신청은 방문 신청만 가능합니다.(장소: 2단지 안내데스크 방문)
A46: =A12 -> 7. 강습은 3개월 단위 재추첨하며, 강습 기간중 중도 취소 하지 않는 경우 3개월간 자동 재등록 됩니다.
A48: 시간 | B48: 순번 | C48: 날 짜 | D48: 성함 | E48: 동 | F48: 호수 | G48: 서명 | H48: 취소날짜 | I48: 취소서명 | J48: 비고
A49: =A15 -> 09:00 ~ 09:50 | B49: 21
B50: 22
B51: 23
B52: 24
...

Sheet 2단지 요가(수금10시윤명원)
A1: =월!$A$1 & "월 " & SUBSTITUTE(LEFT(MID(CELL("filename",A1), FIND("]",CELL("filename",A1))+1, 255), FIND("(", MID(CELL("filename",A1), FIND("]",CELL("filename",A1))+1, 255))-1), "2단지 ", "") & " " & LEFT(MID(MID(CELL("filename",A1), FIND("]",CELL("filename",A1))+1, 255), FIND("(", MID(CELL("filename",A1), FIND("]",CELL("filename",A1))+1, 255))+1, 255), FIND("시", MID(MID(CELL("filename",A1), FIND("]",CELL("filename",A1))+1, 255), FIND("(", MID(CELL("filename",A1), FIND("]",CELL("filename",A1))+1, 255))+1, 255))-3) & " " & RIGHT(LEFT(MID(MID(CELL("filename",A1), FIND("]",CELL("filename",A1))+1, 255), FIND("(", MID(CELL("filename",A1), FIND("]",CELL("filename",A1))+1, 255))+1, 255), FIND("시", MID(MID(CELL("filename",A1), FIND("]",CELL("filename",A1))+1, 255), FIND("(", MID(CELL("filename",A1), FIND("]",CELL("filename",A1))+1, 255))+1, 255))), 3) & " 신청서" -> 10월 요가 수금 10시 신청서
G4: 강사: 윤명원
G5: 요일: 수 , 금 / 시간: 오전 10시
A6: 1. 강습료는 월 8회 50,000원이며, 당월 관리비에 자동 부과됩니다.
A7: 2. 강습은 매주 수,금(주2회) 이며 국/공휴일은 강습이 없습니다.
A8: 3. 각반 정원은 30명이며, 10명미만 접수시 폐강 할 수 있습니다.
A9: 4. 강습대상은 성인이며, 청소년도 가능합니다. 강습양도 불가합니다.
A10: 5. 중도 등록, 취소시 일할계산(월8회 기준)되어 강습료 부과되며 강습 취소 미신청 시 전액부과됩니다.(당일 취소는 불가)
A11: 6. 중도취소 신청은 방문 신청만 가능합니다.(장소: 2단지 안내데스크 방문)
A12: 7. 강습은 3개월 단위 재추첨하며, 강습 기간중 중도 취소 하지 않는 경우 3개월간 자동 재등록 됩니다.
A14: 시간 | B14: 순번 | C14: 날 짜 | D14: 성함 | E14: 동 | F14: 호수 | G14: 서명 | H14: 취소날짜 | I14: 취소서명 | J14: 비고
A15: 10:00 ~ 10:50 | B15: 1
B16: 2
B17: 3
B18: 4
B19: 5
B20: 6
B21: 7
B22: 8
B23: 9
B24: 10
B25: 11
B26: 12
B27: 13
... B34: 20
A35: =A1 -> 10월 요가 수금 10시 신청서
G38: =G4 -> 강사: 윤명원
G39: =G5 -> 요일: 수 , 금 / 시간: 오전 10시
A40: =A6 -> 1. 강습료는 월 8회 50,000원이며, 당월 관리비에 자동 부과됩니다.
A41: =A7 -> 2. 강습은 매주 수,금(주2회) 이며 국/공휴일은 강습이 없습니다.
A42: =A8 -> 3. 각반 정원은 30명이며, 10명미만 접수시 폐강 할 수 있습니다.
A43: =A9 -> 4. 강습대상은 성인이며, 청소년도 가능합니다. 강습양도 불가합니다.
A44: =A10 -> 5. 중도 등록, 취소시 일할계산(월8회 기준)되어 강습료 부과되며 강습 취소 미신청 시 전액부과됩니다.(당일 취소는 불가)
A45: =A11 -> 6. 중도취소 신청은 방문 신청만 가능합니다.(장소: 2단지 안내데스크 방문)
A46: =A12 -> 7. 강습은 3개월 단위 재추첨하며, 강습 기간중 중도 취소 하지 않는 경우 3개월간 자동 재등록 됩니다.
A48: 시간 | B48: 순번 | C48: 날 짜 | D48: 성함 | E48: 동 | F48: 호수 | G48: 서명 | H48: 취소날짜 | I48: 취소서명 | J48: 비고
A49: =A15 -> 10:00 ~ 10:50 | B49: 21
B50: 22
B51: 23
B52: 24
...

Sheet 2단지 요가(수금19시한승지)
A1: =월!$A$1 & "월 " & SUBSTITUTE(LEFT(MID(CELL("filename",A1), FIND("]",CELL("filename",A1))+1, 255), FIND("(", MID(CELL("filename",A1), FIND("]",CELL("filename",A1))+1, 255))-1), "2단지 ", "") & " " & LEFT(MID(MID(CELL("filename",A1), FIND("]",CELL("filename",A1))+1, 255), FIND("(", MID(CELL("filename",A1), FIND("]",CELL("filename",A1))+1, 255))+1, 255), FIND("시", MID(MID(CELL("filename",A1), FIND("]",CELL("filename",A1))+1, 255), FIND("(", MID(CELL("filename",A1), FIND("]",CELL("filename",A1))+1, 255))+1, 255))-3) & " " & RIGHT(LEFT(MID(MID(CELL("filename",A1), FIND("]",CELL("filename",A1))+1, 255), FIND("(", MID(CELL("filename",A1), FIND("]",CELL("filename",A1))+1, 255))+1, 255), FIND("시", MID(MID(CELL("filename",A1), FIND("]",CELL("filename",A1))+1, 255), FIND("(", MID(CELL("filename",A1), FIND("]",CELL("filename",A1))+1, 255))+1, 255))), 3) & " 신청서" -> 10월 요가 수금 19시 신청서
G4: 강사: 한승지
G5: 요일: 수 , 금 / 시간: 오후7시
A6: 1. 강습료는 월 8회 50,000원이며, 당월 관리비에 자동 부과됩니다.
A7: 2. 강습은 매주 수,금(주2회) 이며 국/공휴일은 강습이 없습니다.
A8: 3. 각반 정원은 30명이며, 10명미만 접수시 폐강 할 수 있습니다.
A9: 4. 강습대상은 성인이며, 청소년도 가능합니다. 강습양도 불가합니다.
A10: 5. 중도 등록, 취소시 일할계산(월8회 기준)되어 강습료 부과되며 강습 취소 미신청 시 전액부과됩니다.(당일 취소는 불가)
A11: 6. 중도취소 신청은 방문 신청만 가능합니다.(장소: 2단지 안내데스크 방문)
A12: 7. 강습은 3개월 단위 재추첨하며, 강습 기간중 중도 취소 하지 않는 경우 3개월간 자동 재등록 됩니다.
A14: 시간 | B14: 순번 | C14: 날 짜 | D14: 성함 | E14: 동 | F14: 호수 | G14: 서명 | H14: 취소날짜 | I14: 취소서명 | J14: 비고
A15: 19:00 ~ 19:50 | B15: 1
B16: 2
B17: 3
B18: 4
B19: 5
B20: 6
B21: 7
B22: 8
B23: 9
B24: 10
B25: 11
B26: 12
B27: 13
... B34: 20
A35: =A1 -> 10월 요가 수금 19시 신청서
G38: =G4 -> 강사: 한승지
G39: =G5 -> 요일: 수 , 금 / 시간: 오후7시
A40: =A6 -> 1. 강습료는 월 8회 50,000원이며, 당월 관리비에 자동 부과됩니다.
A41: =A7 -> 2. 강습은 매주 수,금(주2회) 이며 국/공휴일은 강습이 없습니다.
A42: =A8 -> 3. 각반 정원은 30명이며, 10명미만 접수시 폐강 할 수 있습니다.
A43: =A9 -> 4. 강습대상은 성인이며, 청소년도 가능합니다. 강습양도 불가합니다.
A44: =A10 -> 5. 중도 등록, 취소시 일할계산(월8회 기준)되어 강습료 부과되며 강습 취소 미신청 시 전액부과됩니다.(당일 취소는 불가)
A45: =A11 -> 6. 중도취소 신청은 방문 신청만 가능합니다.(장소: 2단지 안내데스크 방문)
A46: =A12 -> 7. 강습은 3개월 단위 재추첨하며, 강습 기간중 중도 취소 하지 않는 경우 3개월간 자동 재등록 됩니다.
A48: 시간 | B48: 순번 | C48: 날 짜 | D48: 성함 | E48: 동 | F48: 호수 | G48: 서명 | H48: 취소날짜 | I48: 취소서명 | J48: 비고
A49: =A15 -> 19:00 ~ 19:50 | B49: 21
B50: 22
B51: 23
B52: 24
...

Sheet 2단지 요가(수금20시한승지)
A1: =월!$A$1 & "월 " & SUBSTITUTE(LEFT(MID(CELL("filename",A1), FIND("]",CELL("filename",A1))+1, 255), FIND("(", MID(CELL("filename",A1), FIND("]",CELL("filename",A1))+1, 255))-1), "2단지 ", "") & " " & LEFT(MID(MID(CELL("filename",A1), FIND("]",CELL("filename",A1))+1, 255), FIND("(", MID(CELL("filename",A1), FIND("]",CELL("filename",A1))+1, 255))+1, 255), FIND("시", MID(MID(CELL("filename",A1), FIND("]",CELL("filename",A1))+1, 255), FIND("(", MID(CELL("filename",A1), FIND("]",CELL("filename",A1))+1, 255))+1, 255))-3) & " " & RIGHT(LEFT(MID(MID(CELL("filename",A1), FIND("]",CELL("filename",A1))+1, 255), FIND("(", MID(CELL("filename",A1), FIND("]",CELL("filename",A1))+1, 255))+1, 255), FIND("시", MID(MID(CELL("filename",A1), FIND("]",CELL("filename",A1))+1, 255), FIND("(", MID(CELL("filename",A1), FIND("]",CELL("filename",A1))+1, 255))+1, 255))), 3) & " 신청서" -> 10월 요가 수금 20시 신청서
G4: 강사: 한승지
G5: 요일: 수 , 금 / 시간: 오후 8시
A6: 1. 강습료는 월 8회 50,000원이며, 당월 관리비에 자동 부과됩니다.
A7: 2. 강습은 매주 수,금(주2회) 이며 국/공휴일은 강습이 없습니다.
A8: 3. 각반 정원은 30명이며, 10명미만 접수시 폐강 할 수 있습니다.
A9: 4. 강습대상은 성인이며, 청소년도 가능합니다. 강습양도 불가합니다.
A10: 5. 중도 등록, 취소시 일할계산(월8회 기준)되어 강습료 부과되며 강습 취소 미신청 시 전액부과됩니다.(당일 취소는 불가)
A11: 6. 중도취소 신청은 방문 신청만 가능합니다.(장소: 2단지 안내데스크 방문)
A12: 7. 강습은 3개월 단위 재추첨하며, 강습 기간중 중도 취소 하지 않는 경우 3개월간 자동 재등록 됩니다.
A14: 시간 | B14: 순번 | C14: 날 짜 | D14: 성함 | E14: 동 | F14: 호수 | G14: 서명 | H14: 취소날짜 | I14: 취소서명 | J14: 비고
A15: 20:00 ~ 20:50 | B15: 1
B16: 2
B17: 3
B18: 4
B19: 5
B20: 6
B21: 7
B22: 8
B23: 9
B24: 10
B25: 11
B26: 12
B27: 13
... B34: 20
A35: =A1 -> 10월 요가 수금 20시 신청서
G38: =G4 -> 강사: 한승지
G39: =G5 -> 요일: 수 , 금 / 시간: 오후 8시
A40: =A6 -> 1. 강습료는 월 8회 50,000원이며, 당월 관리비에 자동 부과됩니다.
A41: =A7 -> 2. 강습은 매주 수,금(주2회) 이며 국/공휴일은 강습이 없습니다.
A42: =A8 -> 3. 각반 정원은 30명이며, 10명미만 접수시 폐강 할 수 있습니다.
A43: =A9 -> 4. 강습대상은 성인이며, 청소년도 가능합니다. 강습양도 불가합니다.
A44: =A10 -> 5. 중도 등록, 취소시 일할계산(월8회 기준)되어 강습료 부과되며 강습 취소 미신청 시 전액부과됩니다.(당일 취소는 불가)
A45: =A11 -> 6. 중도취소 신청은 방문 신청만 가능합니다.(장소: 2단지 안내데스크 방문)
A46: =A12 -> 7. 강습은 3개월 단위 재추첨하며, 강습 기간중 중도 취소 하지 않는 경우 3개월간 자동 재등록 됩니다.
A48: 시간 | B48: 순번 | C48: 날 짜 | D48: 성함 | E48: 동 | F48: 호수 | G48: 서명 | H48: 취소날짜 | I48: 취소서명 | J48: 비고
A49: =A15 -> 20:00 ~ 20:50 | B49: 21
B50: 22
B51: 23
B52: 24
...

Sheet 2단지 요가(수금21시한승지)
A1: =월!$A$1 & "월 " & SUBSTITUTE(LEFT(MID(CELL("filename",A1), FIND("]",CELL("filename",A1))+1, 255), FIND("(", MID(CELL("filename",A1), FIND("]",CELL("filename",A1))+1, 255))-1), "2단지 ", "") & " " & LEFT(MID(MID(CELL("filename",A1), FIND("]",CELL("filename",A1))+1, 255), FIND("(", MID(CELL("filename",A1), FIND("]",CELL("filename",A1))+1, 255))+1, 255), FIND("시", MID(MID(CELL("filename",A1), FIND("]",CELL("filename",A1))+1, 255), FIND("(", MID(CELL("filename",A1), FIND("]",CELL("filename",A1))+1, 255))+1, 255))-3) & " " & RIGHT(LEFT(MID(MID(CELL("filename",A1), FIND("]",CELL("filename",A1))+1, 255), FIND("(", MID(CELL("filename",A1), FIND("]",CELL("filename",A1))+1, 255))+1, 255), FIND("시", MID(MID(CELL("filename",A1), FIND("]",CELL("filename",A1))+1, 255), FIND("(", MID(CELL("filename",A1), FIND("]",CELL("filename",A1))+1, 255))+1, 255))), 3) & " 신청서" -> 10월 요가 수금 21시 신청서
G4: 강사: 한승지
G5: 요일: 수 , 금 / 시간: 오후 9시
A6: 1. 강습료는 월 8회 50,000원이며, 당월 관리비에 자동 부과됩니다.
A7: 2. 강습은 매주 수,금(주2회) 이며 국/공휴일은 강습이 없습니다.
A8: 3. 각반 정원은 30명이며, 10명미만 접수시 폐강 할 수 있습니다.
A9: 4. 강습대상은 성인이며, 청소년도 가능합니다. 강습양도 불가합니다.
A10: 5. 중도 등록, 취소시 일할계산(월8회 기준)되어 강습료 부과되며 강습 취소 미신청 시 전액부과됩니다.(당일 취소는 불가)
A11: 6. 중도취소 신청은 방문 신청만 가능합니다.(장소: 2단지 안내데스크 방문)
A12: 7. 강습은 3개월 단위 재추첨하며, 강습 기간중 중도 취소 하지 않는 경우 3개월간 자동 재등록 됩니다.
A14: 시간 | B14: 순번 | C14: 날 짜 | D14: 성함 | E14: 동 | F14: 호수 | G14: 서명 | H14: 취소날짜 | I14: 취소서명 | J14: 비고
A15: 21:00 ~ 21:50 | B15: 1
B16: 2
B17: 3
B18: 4
B19: 5
B20: 6
B21: 7
B22: 8
B23: 9
B24: 10
B25: 11
B26: 12
B27: 13
... B34: 20
A35: =A1 -> 10월 요가 수금 21시 신청서
G38: =G4 -> 강사: 한승지
G39: =G5 -> 요일: 수 , 금 / 시간: 오후 9시
A40: =A6 -> 1. 강습료는 월 8회 50,000원이며, 당월 관리비에 자동 부과됩니다.
A41: =A7 -> 2. 강습은 매주 수,금(주2회) 이며 국/공휴일은 강습이 없습니다.
A42: =A8 -> 3. 각반 정원은 30명이며, 10명미만 접수시 폐강 할 수 있습니다.
A43: =A9 -> 4. 강습대상은 성인이며, 청소년도 가능합니다. 강습양도 불가합니다.
A44: =A10 -> 5. 중도 등록, 취소시 일할계산(월8회 기준)되어 강습료 부과되며 강습 취소 미신청 시 전액부과됩니다.(당일 취소는 불가)
A45: =A11 -> 6. 중도취소 신청은 방문 신청만 가능합니다.(장소: 2단지 안내데스크 방문)
A46: =A12 -> 7. 강습은 3개월 단위 재추첨하며, 강습 기간중 중도 취소 하지 않는 경우 3개월간 자동 재등록 됩니다.
A48: 시간 | B48: 순번 | C48: 날 짜 | D48: 성함 | E48: 동 | F48: 호수 | G48: 서명 | H48: 취소날짜 | I48: 취소서명 | J48: 비고
A49: =A15 -> 21:00 ~ 21:50 | B49: 21
B50: 22
B51: 23
B52: 24
...

Sheet 2단지 줌바댄스(화목11시김지희)
A1: =월!$A$1 & "월 " & SUBSTITUTE(LEFT(MID(CELL("filename",A1), FIND("]",CELL("filename",A1))+1, 255), FIND("(", MID(CELL("filename",A1), FIND("]",CELL("filename",A1))+1, 255))-1), "2단지 ", "") & " " & LEFT(MID(MID(CELL("filename",A1), FIND("]",CELL("filename",A1))+1, 255), FIND("(", MID(CELL("filename",A1), FIND("]",CELL("filename",A1))+1, 255))+1, 255), FIND("시", MID(MID(CELL("filename",A1), FIND("]",CELL("filename",A1))+1, 255), FIND("(", MID(CELL("filename",A1), FIND("]",CELL("filename",A1))+1, 255))+1, 255))-3) & " " & RIGHT(LEFT(MID(MID(CELL("filename",A1), FIND("]",CELL("filename",A1))+1, 255), FIND("(", MID(CELL("filename",A1), FIND("]",CELL("filename",A1))+1, 255))+1, 255), FIND("시", MID(MID(CELL("filename",A1), FIND("]",CELL("filename",A1))+1, 255), FIND("(", MID(CELL("filename",A1), FIND("]",CELL("filename",A1))+1, 255))+1, 255))), 3) & " 신청서" -> 10월 줌바댄스 화목 11시 신청서
G4: 강사: 김지희
G5: 요일: 화 , 목 / 시간: 오전 11시
A6: 1. 강습료는 월 8회 50,000원이며, 당월 관리비에 자동 부과됩니다.
A7: 2. 강습은 매주 화,목(주2회) 이며 국/공휴일은 강습이 없습니다.
A8: 3. 각반 정원은 30명이며, 10명미만 접수시 폐강 할 수 있습니다.
A9: 4. 강습대상은 성인이며, 청소년도 가능합니다. 강습양도 불가합니다.
A10: 5. 중도 등록, 취소시 일할계산(월8회 기준)되어 강습료 부과되며 강습 취소 미신청 시 전액부과됩니다.(당일 취소는 불가)
A11: 6. 중도취소 신청은 방문 신청만 가능합니다.(장소: 2단지 안내데스크 방문)
A12: 7. 강습은 3개월 단위 재추첨하며, 강습 기간중 중도 취소 하지 않는 경우 3개월간 자동 재등록 됩니다.
A14: 시간 | B14: 순번 | C14: 날 짜 | D14: 성함 | E14: 동 | F14: 호수 | G14: 서명 | H14: 취소날짜 | I14: 취소서명 | J14: 비고
A15: 11:00 ~ 11:50 | B15: 1
B16: 2
B17: 3
B18: 4
B19: 5
B20: 6
B21: 7
B22: 8
B23: 9
B24: 10
B25: 11
B26: 12
B27: 13
... B34: 20
A35: =A1 -> 10월 줌바댄스 화목 11시 신청서
G38: =G4 -> 강사: 김지희
G39: =G5 -> 요일: 화 , 목 / 시간: 오전 11시
A40: =A6 -> 1. 강습료는 월 8회 50,000원이며, 당월 관리비에 자동 부과됩니다.
A41: =A7 -> 2. 강습은 매주 화,목(주2회) 이며 국/공휴일은 강습이 없습니다.
A42: =A8 -> 3. 각반 정원은 30명이며, 10명미만 접수시 폐강 할 수 있습니다.
A43: =A9 -> 4. 강습대상은 성인이며, 청소년도 가능합니다. 강습양도 불가합니다.
A44: =A10 -> 5. 중도 등록, 취소시 일할계산(월8회 기준)되어 강습료 부과되며 강습 취소 미신청 시 전액부과됩니다.(당일 취소는 불가)
A45: =A11 -> 6. 중도취소 신청은 방문 신청만 가능합니다.(장소: 2단지 안내데스크 방문)
A46: =A12 -> 7. 강습은 3개월 단위 재추첨하며, 강습 기간중 중도 취소 하지 않는 경우 3개월간 자동 재등록 됩니다.
A48: 시간 | B48: 순번 | C48: 날 짜 | D48: 성함 | E48: 동 | F48: 호수 | G48: 서명 | H48: 취소날짜 | I48: 취소서명 | J48: 비고
A49: =A15 -> 11:00 ~ 11:50 | B49: 21
B50: 22
B51: 23
B52: 24
...

Sheet 김지희 줌바 화목 12시
A1: =월!$A$1 & "월 " & SUBSTITUTE(LEFT(MID(CELL("filename",A1), FIND("]",CELL("filename",A1))+1, 255), FIND("(", MID(CELL("filename",A1), FIND("]",CELL("filename",A1))+1, 255))-1), "2단지 ", "") & " " & LEFT(MID(MID(CELL("filename",A1), FIND("]",CELL("filename",A1))+1, 255), FIND("(", MID(CELL("filename",A1), FIND("]",CELL("filename",A1))+1, 255))+1, 255), FIND("시", MID(MID(CELL("filename",A1), FIND("]",CELL("filename",A1))+1, 255), FIND("(", MID(CELL("filename",A1), FIND("]",CELL("filename",A1))+1, 255))+1, 255))-3) & " " & RIGHT(LEFT(MID(MID(CELL("filename",A1), FIND("]",CELL("filename",A1))+1, 255), FIND("(", MID(CELL("filename",A1), FIND("]",CELL("filename",A1))+1, 255))+1, 255), FIND("시", MID(MID(CELL("filename",A1), FIND("]",CELL("filename",A1))+1, 255), FIND("(", MID(CELL("filename",A1), FIND("]",CELL("filename",A1))+1, 255))+1, 255))), 3) & " 신청서" -> #VALUE!
G4: 강사: 김지희
G5: 요일: 화 , 목 / 시간: 오후 12시
A6: 1. 강습료는 월 8회 50,000원이며, 당월 관리비에 자동 부과됩니다.
A7: 2. 강습은 매주 화,목(주2회) 이며 국/공휴일은 강습이 없습니다.
A8: 3. 각반 정원은 30명이며, 10명미만 접수시 폐강 할 수 있습니다.
A9: 4. 강습대상은 성인이며, 청소년도 가능합니다. 강습양도 불가합니다.
A10: 5. 중도 등록, 취소시 일할계산(월8회 기준)되어 강습료 부과되며 강습 취소 미신청 시 전액부과됩니다.(당일 취소는 불가)
A11: 6. 중도취소 신청은 방문 신청만 가능합니다.(장소: 2단지 안내데스크 방문)
A12: 7. 강습은 3개월 단위 재추첨하며, 강습 기간중 중도 취소 하지 않는 경우 3개월간 자동 재등록 됩니다.
A14: 시간 | B14: 순번 | C14: 날 짜 | D14: 성함 | E14: 동 | F14: 호수 | G14: 서명 | H14: 취소날짜 | I14: 취소서명 | J14: 비고
A15: 12:00 ~ 12:50 | B15: 1
B16: 2
B17: 3
B18: 4
B19: 5
B20: 6
B21: 7
B22: 8
B23: 9
B24: 10
B25: 11
B26: 12
B27: 13
... B34: 20
A35: =A1 -> #VALUE!
G38: =G4 -> 강사: 김지희
G39: =G5 -> 요일: 화 , 목 / 시간: 오후 12시
A40: =A6 -> 1. 강습료는 월 8회 50,000원이며, 당월 관리비에 자동 부과됩니다.
A41: =A7 -> 2. 강습은 매주 화,목(주2회) 이며 국/공휴일은 강습이 없습니다.
A42: =A8 -> 3. 각반 정원은 30명이며, 10명미만 접수시 폐강 할 수 있습니다.
A43: =A9 -> 4. 강습대상은 성인이며, 청소년도 가능합니다. 강습양도 불가합니다.
A44: =A10 -> 5. 중도 등록, 취소시 일할계산(월8회 기준)되어 강습료 부과되며 강습 취소 미신청 시 전액부과됩니다.(당일 취소는 불가)
A45: =A11 -> 6. 중도취소 신청은 방문 신청만 가능합니다.(장소: 2단지 안내데스크 방문)
A46: =A12 -> 7. 강습은 3개월 단위 재추첨하며, 강습 기간중 중도 취소 하지 않는 경우 3개월간 자동 재등록 됩니다.
A48: 시간 | B48: 순번 | C48: 날 짜 | D48: 성함 | E48: 동 | F48: 호수 | G48: 서명 | H48: 취소날짜 | I48: 취소서명 | J48: 비고
A49: =A15 -> 12:00 ~ 12:50 | B49: 21
B50: 22
B51: 23
B52: 24
...

Sheet 2단지 줌바댄스(화목17시신성희)
A1: =월!$A$1 & "월 " & SUBSTITUTE(LEFT(MID(CELL("filename",A1), FIND("]",CELL("filename",A1))+1, 255), FIND("(", MID(CELL("filename",A1), FIND("]",CELL("filename",A1))+1, 255))-1), "2단지 ", "") & " " & LEFT(MID(MID(CELL("filename",A1), FIND("]",CELL("filename",A1))+1, 255), FIND("(", MID(CELL("filename",A1), FIND("]",CELL("filename",A1))+1, 255))+1, 255), FIND("시", MID(MID(CELL("filename",A1), FIND("]",CELL("filename",A1))+1, 255), FIND("(", MID(CELL("filename",A1), FIND("]",CELL("filename",A1))+1, 255))+1, 255))-3) & " " & RIGHT(LEFT(MID(MID(CELL("filename",A1), FIND("]",CELL("filename",A1))+1, 255), FIND("(", MID(CELL("filename",A1), FIND("]",CELL("filename",A1))+1, 255))+1, 255), FIND("시", MID(MID(CELL("filename",A1), FIND("]",CELL("filename",A1))+1, 255), FIND("(", MID(CELL("filename",A1), FIND("]",CELL("filename",A1))+1, 255))+1, 255))), 3) & " 신청서" -> 10월 줌바댄스 화목 17시 신청서
G4: 강사: 신성희
G5: 요일: 화 , 목 / 시간: 오후 5시
A6: 1. 강습료는 월 8회 50,000원이며, 당월 관리비에 자동 부과됩니다.
A7: 2. 강습은 매주 화,목(주2회) 이며 국/공휴일은 강습이 없습니다.
A8: 3. 각반 정원은 30명이며, 10명미만 접수시 폐강 할 수 있습니다.
A9: 4. 강습대상은 성인이며, 청소년도 가능합니다. 강습양도 불가합니다.
A10: 5. 중도 등록, 취소시 일할계산(월8회 기준)되어 강습료 부과되며 강습 취소 미신청 시 전액부과됩니다.(당일 취소는 불가)
A11: 6. 중도취소 신청은 방문 신청만 가능합니다.(장소: 2단지 안내데스크 방문)
A12: 7. 강습은 3개월 단위 재추첨하며, 강습 기간중 중도 취소 하지 않는 경우 3개월간 자동 재등록 됩니다.
A14: 시간 | B14: 순번 | C14: 날 짜 | D14: 성함 | E14: 동 | F14: 호수 | G14: 서명 | H14: 취소날짜 | I14: 취소서명 | J14: 비고
A15: 17:00 ~ 17:50 | B15: 1
B16: 2
B17: 3
B18: 4
B19: 5
B20: 6
B21: 7
B22: 8
B23: 9
B24: 10
B25: 11
B26: 12
B27: 13
... B34: 20
A35: =A1 -> 10월 줌바댄스 화목 17시 신청서
G38: =G4 -> 강사: 신성희
G39: =G5 -> 요일: 화 , 목 / 시간: 오후 5시
A40: =A6 -> 1. 강습료는 월 8회 50,000원이며, 당월 관리비에 자동 부과됩니다.
A41: =A7 -> 2. 강습은 매주 화,목(주2회) 이며 국/공휴일은 강습이 없습니다.
A42: =A8 -> 3. 각반 정원은 30명이며, 10명미만 접수시 폐강 할 수 있습니다.
A43: =A9 -> 4. 강습대상은 성인이며, 청소년도 가능합니다. 강습양도 불가합니다.
A44: =A10 -> 5. 중도 등록, 취소시 일할계산(월8회 기준)되어 강습료 부과되며 강습 취소 미신청 시 전액부과됩니다.(당일 취소는 불가)
A45: =A11 -> 6. 중도취소 신청은 방문 신청만 가능합니다.(장소: 2단지 안내데스크 방문)
A46: =A12 -> 7. 강습은 3개월 단위 재추첨하며, 강습 기간중 중도 취소 하지 않는 경우 3개월간 자동 재등록 됩니다.
A48: 시간 | B48: 순번 | C48: 날 짜 | D48: 성함 | E48: 동 | F48: 호수 | G48: 서명 | H48: 취소날짜 | I48: 취소서명 | J48: 비고
A49: =A15 -> 17:00 ~ 17:50 | B49: 21
B50: 22
B51: 23
B52: 24
...

Sheet 2단지 줌바댄스(화목18시신성희)
A1: =월!$A$1 & "월 " & SUBSTITUTE(LEFT(MID(CELL("filename",A1), FIND("]",CELL("filename",A1))+1, 255), FIND("(", MID(CELL("filename",A1), FIND("]",CELL("filename",A1))+1, 255))-1), "2단지 ", "") & " " & LEFT(MID(MID(CELL("filename",A1), FIND("]",CELL("filename",A1))+1, 255), FIND("(", MID(CELL("filename",A1), FIND("]",CELL("filename",A1))+1, 255))+1, 255), FIND("시", MID(MID(CELL("filename",A1), FIND("]",CELL("filename",A1))+1, 255), FIND("(", MID(CELL("filename",A1), FIND("]",CELL("filename",A1))+1, 255))+1, 255))-3) & " " & RIGHT(LEFT(MID(MID(CELL("filename",A1), FIND("]",CELL("filename",A1))+1, 255), FIND("(", MID(CELL("filename",A1), FIND("]",CELL("filename",A1))+1, 255))+1, 255), FIND("시", MID(MID(CELL("filename",A1), FIND("]",CELL("filename",A1))+1, 255), FIND("(", MID(CELL("filename",A1), FIND("]",CELL("filename",A1))+1, 255))+1, 255))), 3) & " 신청서" -> 10월 줌바댄스 화목 18시 신청서
G4: 강사: 신성희
G5: 요일: 화 , 목 / 시간: 오후 6시
A6: 1. 강습료는 월 8회 50,000원이며, 당월 관리비에 자동 부과됩니다.
A7: 2. 강습은 매주 화,목(주2회) 이며 국/공휴일은 강습이 없습니다.
A8: 3. 각반 정원은 30명이며, 10명미만 접수시 폐강 할 수 있습니다.
A9: 4. 강습대상은 성인이며, 청소년도 가능합니다. 강습양도 불가합니다.
A10: 5. 중도 등록, 취소시 일할계산(월8회 기준)되어 강습료 부과되며 강습 취소 미신청 시 전액부과됩니다.(당일 취소는 불가)
A11: 6. 중도취소 신청은 방문 신청만 가능합니다.(장소: 2단지 안내데스크 방문)
A12: 7. 강습은 3개월 단위 재추첨하며, 강습 기간중 중도 취소 하지 않는 경우 3개월간 자동 재등록 됩니다.
A14: 시간 | B14: 순번 | C14: 날 짜 | D14: 성함 | E14: 동 | F14: 호수 | G14: 서명 | H14: 취소날짜 | I14: 취소서명 | J14: 비고
A15: 18:00 ~ 18:50 | B15: 1
B16: 2
B17: 3
B18: 4
B19: 5
B20: 6
B21: 7
B22: 8
B23: 9
B24: 10
B25: 11
B26: 12
B27: 13
... B34: 20
A35: =A1 -> 10월 줌바댄스 화목 18시 신청서
G38: =G4 -> 강사: 신성희
G39: =G5 -> 요일: 화 , 목 / 시간: 오후 6시
A40: =A6 -> 1. 강습료는 월 8회 50,000원이며, 당월 관리비에 자동 부과됩니다.
A41: =A7 -> 2. 강습은 매주 화,목(주2회) 이며 국/공휴일은 강습이 없습니다.
A42: =A8 -> 3. 각반 정원은 30명이며, 10명미만 접수시 폐강 할 수 있습니다.
A43: =A9 -> 4. 강습대상은 성인이며, 청소년도 가능합니다. 강습양도 불가합니다.
A44: =A10 -> 5. 중도 등록, 취소시 일할계산(월8회 기준)되어 강습료 부과되며 강습 취소 미신청 시 전액부과됩니다.(당일 취소는 불가)
A45: =A11 -> 6. 중도취소 신청은 방문 신청만 가능합니다.(장소: 2단지 안내데스크 방문)
A46: =A12 -> 7. 강습은 3개월 단위 재추첨하며, 강습 기간중 중도 취소 하지 않는 경우 3개월간 자동 재등록 됩니다.
A48: 시간 | B48: 순번 | C48: 날 짜 | D48: 성함 | E48: 동 | F48: 호수 | G48: 서명 | H48: 취소날짜 | I48: 취소서명 | J48: 비고
A49: =A15 -> 18:00 ~ 18:50 | B49: 21
B50: 22
B51: 23
B52: 24
...

Sheet 2단지 줌바댄스(수금16시김지인)
A1: =월!$A$1 & "월 " & SUBSTITUTE(LEFT(MID(CELL("filename",A1), FIND("]",CELL("filename",A1))+1, 255), FIND("(", MID(CELL("filename",A1), FIND("]",CELL("filename",A1))+1, 255))-1), "2단지 ", "") & " " & LEFT(MID(MID(CELL("filename",A1), FIND("]",CELL("filename",A1))+1, 255), FIND("(", MID(CELL("filename",A1), FIND("]",CELL("filename",A1))+1, 255))+1, 255), FIND("시", MID(MID(CELL("filename",A1), FIND("]",CELL("filename",A1))+1, 255), FIND("(", MID(CELL("filename",A1), FIND("]",CELL("filename",A1))+1, 255))+1, 255))-3) & " " & RIGHT(LEFT(MID(MID(CELL("filename",A1), FIND("]",CELL("filename",A1))+1, 255), FIND("(", MID(CELL("filename",A1), FIND("]",CELL("filename",A1))+1, 255))+1, 255), FIND("시", MID(MID(CELL("filename",A1), FIND("]",CELL("filename",A1))+1, 255), FIND("(", MID(CELL("filename",A1), FIND("]",CELL("filename",A1))+1, 255))+1, 255))), 3) & " 신청서" -> 10월 줌바댄스 수금 16시 신청서
G4: 강사: 김지인
G5: 요일: 수 , 금 / 시간: 오후 4시
A6: 1. 강습료는 월 8회 50,000원이며, 당월 관리비에 자동 부과됩니다.
A7: 2. 강습은 매주 수,금(주2회) 이며 국/공휴일은 강습이 없습니다.
A8: 3. 각반 정원은 30명이며, 10명미만 접수시 폐강 할 수 있습니다.
A9: 4. 강습대상은 성인이며, 청소년도 가능합니다. 강습양도 불가합니다.
A10: 5. 중도 등록, 취소시 일할계산(월8회 기준)되어 강습료 부과되며 강습 취소 미신청 시 전액부과됩니다.(당일 취소는 불가)
A11: 6. 중도취소 신청은 방문 신청만 가능합니다.(장소: 2단지 안내데스크 방문)
A12: 7. 강습은 3개월 단위 재추첨하며, 강습 기간중 중도 취소 하지 않는 경우 3개월간 자동 재등록 됩니다.
A14: 시간 | B14: 순번 | C14: 날 짜 | D14: 성함 | E14: 동 | F14: 호수 | G14: 서명 | H14: 취소날짜 | I14: 취소서명 | J14: 비고
A15: 16:00 ~ 16:50 | B15: 1
B16: 2
B17: 3
B18: 4
B19: 5
B20: 6
B21: 7
B22: 8
B23: 9
B24: 10
B25: 11
B26: 12
B27: 13
... B34: 20
A35: =A1 -> 10월 줌바댄스 수금 16시 신청서
G38: =G4 -> 강사: 김지인
G39: =G5 -> 요일: 수 , 금 / 시간: 오후 4시
A40: =A6 -> 1. 강습료는 월 8회 50,000원이며, 당월 관리비에 자동 부과됩니다.
A41: =A7 -> 2. 강습은 매주 수,금(주2회) 이며 국/공휴일은 강습이 없습니다.
A42: =A8 -> 3. 각반 정원은 30명이며, 10명미만 접수시 폐강 할 수 있습니다.
A43: =A9 -> 4. 강습대상은 성인이며, 청소년도 가능합니다. 강습양도 불가합니다.
A44: =A10 -> 5. 중도 등록, 취소시 일할계산(월8회 기준)되어 강습료 부과되며 강습 취소 미신청 시 전액부과됩니다.(당일 취소는 불가)
A45: =A11 -> 6. 중도취소 신청은 방문 신청만 가능합니다.(장소: 2단지 안내데스크 방문)
A46: =A12 -> 7. 강습은 3개월 단위 재추첨하며, 강습 기간중 중도 취소 하지 않는 경우 3개월간 자동 재등록 됩니다.
A48: 시간 | B48: 순번 | C48: 날 짜 | D48: 성함 | E48: 동 | F48: 호수 | G48: 서명 | H48: 취소날짜 | I48: 취소서명 | J48: 비고
A49: =A15 -> 16:00 ~ 16:50 | B49: 21
B50: 22
B51: 23
B52: 24
...

Sheet 2단지 줌바댄스(수금17시김지인)
A1: =월!$A$1 & "월 " & SUBSTITUTE(LEFT(MID(CELL("filename",A1), FIND("]",CELL("filename",A1))+1, 255), FIND("(", MID(CELL("filename",A1), FIND("]",CELL("filename",A1))+1, 255))-1), "2단지 ", "") & " " & LEFT(MID(MID(CELL("filename",A1), FIND("]",CELL("filename",A1))+1, 255), FIND("(", MID(CELL("filename",A1), FIND("]",CELL("filename",A1))+1, 255))+1, 255), FIND("시", MID(MID(CELL("filename",A1), FIND("]",CELL("filename",A1))+1, 255), FIND("(", MID(CELL("filename",A1), FIND("]",CELL("filename",A1))+1, 255))+1, 255))-3) & " " & RIGHT(LEFT(MID(MID(CELL("filename",A1), FIND("]",CELL("filename",A1))+1, 255), FIND("(", MID(CELL("filename",A1), FIND("]",CELL("filename",A1))+1, 255))+1, 255), FIND("시", MID(MID(CELL("filename",A1), FIND("]",CELL("filename",A1))+1, 255), FIND("(", MID(CELL("filename",A1), FIND("]",CELL("filename",A1))+1, 255))+1, 255))), 3) & " 신청서" -> 10월 줌바댄스 수금 17시 신청서
G4: 강사: 김지인
G5: 요일: 수 , 금 / 시간: 오후 5시
A6: 1. 강습료는 월 8회 50,000원이며, 당월 관리비에 자동 부과됩니다.
A7: 2. 강습은 매주 수,금(주2회) 이며 국/공휴일은 강습이 없습니다.
A8: 3. 각반 정원은 30명이며, 10명미만 접수시 폐강 할 수 있습니다.
A9: 4. 강습대상은 성인이며, 청소년도 가능합니다. 강습양도 불가합니다.
A10: 5. 중도 등록, 취소시 일할계산(월8회 기준)되어 강습료 부과되며 강습 취소 미신청 시 전액부과됩니다.(당일 취소는 불가)
A11: 6. 중도취소 신청은 방문 신청만 가능합니다.(장소: 2단지 안내데스크 방문)
A12: 7. 강습은 3개월 단위 재추첨하며, 강습 기간중 중도 취소 하지 않는 경우 3개월간 자동 재등록 됩니다.
A14: 시간 | B14: 순번 | C14: 날 짜 | D14: 성함 | E14: 동 | F14: 호수 | G14: 서명 | H14: 취소날짜 | I14: 취소서명 | J14: 비고
A15: 17:00 ~ 17:50 | B15: 1
B16: 2
B17: 3
B18: 4
B19: 5
B20: 6
B21: 7
B22: 8
B23: 9
B24: 10
B25: 11
B26: 12
B27: 13
... B34: 20
A35: =A1 -> 10월 줌바댄스 수금 17시 신청서
G38: =G4 -> 강사: 김지인
G39: =G5 -> 요일: 수 , 금 / 시간: 오후 5시
A40: =A6 -> 1. 강습료는 월 8회 50,000원이며, 당월 관리비에 자동 부과됩니다.
A41: =A7 -> 2. 강습은 매주 수,금(주2회) 이며 국/공휴일은 강습이 없습니다.
A42: =A8 -> 3. 각반 정원은 30명이며, 10명미만 접수시 폐강 할 수 있습니다.
A43: =A9 -> 4. 강습대상은 성인이며, 청소년도 가능합니다. 강습양도 불가합니다.
A44: =A10 -> 5. 중도 등록, 취소시 일할계산(월8회 기준)되어 강습료 부과되며 강습 취소 미신청 시 전액부과됩니다.(당일 취소는 불가)
A45: =A11 -> 6. 중도취소 신청은 방문 신청만 가능합니다.(장소: 2단지 안내데스크 방문)
A46: =A12 -> 7. 강습은 3개월 단위 재추첨하며, 강습 기간중 중도 취소 하지 않는 경우 3개월간 자동 재등록 됩니다.
A48: 시간 | B48: 순번 | C48: 날 짜 | D48: 성함 | E48: 동 | F48: 호수 | G48: 서명 | H48: 취소날짜 | I48: 취소서명 | J48: 비고
A49: =A15 -> 17:00 ~ 17:50 | B49: 21
B50: 22
B51: 23
B52: 24
...

Sheet 2단지 타바타(수금11시신수경)
A1: =월!$A$1 & "월 " & SUBSTITUTE(LEFT(MID(CELL("filename",A1), FIND("]",CELL("filename",A1))+1, 255), FIND("(", MID(CELL("filename",A1), FIND("]",CELL("filename",A1))+1, 255))-1), "2단지 ", "") & " " & LEFT(MID(MID(CELL("filename",A1), FIND("]",CELL("filename",A1))+1, 255), FIND("(", MID(CELL("filename",A1), FIND("]",CELL("filename",A1))+1, 255))+1, 255), FIND("시", MID(MID(CELL("filename",A1), FIND("]",CELL("filename",A1))+1, 255), FIND("(", MID(CELL("filename",A1), FIND("]",CELL("filename",A1))+1, 255))+1, 255))-3) & " " & RIGHT(LEFT(MID(MID(CELL("filename",A1), FIND("]",CELL("filename",A1))+1, 255), FIND("(", MID(CELL("filename",A1), FIND("]",CELL("filename",A1))+1, 255))+1, 255), FIND("시", MID(MID(CELL("filename",A1), FIND("]",CELL("filename",A1))+1, 255), FIND("(", MID(CELL("filename",A1), FIND("]",CELL("filename",A1))+1, 255))+1, 255))), 3) & " 신청서" -> 10월 타바타 수금 11시 신청서
G4: 강사: 신수경
G5: 요일: 수 , 금 / 시간: 오전 11시
A6: 1. 강습료는 월 8회 50,000원이며, 당월 관리비에 자동 부과됩니다.
A7: 2. 강습은 매주 수,금(주2회) 이며 국/공휴일은 강습이 없습니다.
A8: 3. 각반 정원은 30명이며, 10명미만 접수시 폐강 할 수 있습니다.
A9: 4. 강습대상은 성인이며, 청소년도 가능합니다. 강습양도 불가합니다.
A10: 5. 중도 등록, 취소시 일할계산(월8회 기준)되어 강습료 부과되며 강습 취소 미신청 시 전액부과됩니다.(당일 취소는 불가)
A11: 6. 중도취소 신청은 방문 신청만 가능합니다.(장소: 2단지 안내데스크 방문)
A12: 7. 강습은 3개월 단위 재추첨하며, 강습 기간중 중도 취소 하지 않는 경우 3개월간 자동 재등록 됩니다.
A14: 시간 | B14: 순번 | C14: 날 짜 | D14: 성함 | E14: 동 | F14: 호수 | G14: 서명 | H14: 취소날짜 | I14: 취소서명 | J14: 비고
A15: 11:00 ~ 11:50 | B15: 1
B16: 2
B17: 3
B18: 4
B19: 5
B20: 6
B21: 7
B22: 8
B23: 9
B24: 10
B25: 11
B26: 12
B27: 13
... B34: 20
A35: =A1 -> 10월 타바타 수금 11시 신청서
G38: =G4 -> 강사: 신수경
G39: =G5 -> 요일: 수 , 금 / 시간: 오전 11시
A40: =A6 -> 1. 강습료는 월 8회 50,000원이며, 당월 관리비에 자동 부과됩니다.
A41: =A7 -> 2. 강습은 매주 수,금(주2회) 이며 국/공휴일은 강습이 없습니다.
A42: =A8 -> 3. 각반 정원은 30명이며, 10명미만 접수시 폐강 할 수 있습니다.
A43: =A9 -> 4. 강습대상은 성인이며, 청소년도 가능합니다. 강습양도 불가합니다.
A44: =A10 -> 5. 중도 등록, 취소시 일할계산(월8회 기준)되어 강습료 부과되며 강습 취소 미신청 시 전액부과됩니다.(당일 취소는 불가)
A45: =A11 -> 6. 중도취소 신청은 방문 신청만 가능합니다.(장소: 2단지 안내데스크 방문)
A46: =A12 -> 7. 강습은 3개월 단위 재추첨하며, 강습 기간중 중도 취소 하지 않는 경우 3개월간 자동 재등록 됩니다.
A48: 시간 | B48: 순번 | C48: 날 짜 | D48: 성함 | E48: 동 | F48: 호수 | G48: 서명 | H48: 취소날짜 | I48: 취소서명 | J48: 비고
A49: =A15 -> 11:00 ~ 11:50 | B49: 21
B50: 22
B51: 23
B52: 24
...

Sheet 2단지 타바타(수금12시신수경)
A1: =월!$A$1 & "월 " & SUBSTITUTE(LEFT(MID(CELL("filename",A1), FIND("]",CELL("filename",A1))+1, 255), FIND("(", MID(CELL("filename",A1), FIND("]",CELL("filename",A1))+1, 255))-1), "2단지 ", "") & " " & LEFT(MID(MID(CELL("filename",A1), FIND("]",CELL("filename",A1))+1, 255), FIND("(", MID(CELL("filename",A1), FIND("]",CELL("filename",A1))+1, 255))+1, 255), FIND("시", MID(MID(CELL("filename",A1), FIND("]",CELL("filename",A1))+1, 255), FIND("(", MID(CELL("filename",A1), FIND("]",CELL("filename",A1))+1, 255))+1, 255))-3) & " " & RIGHT(LEFT(MID(MID(CELL("filename",A1), FIND("]",CELL("filename",A1))+1, 255), FIND("(", MID(CELL("filename",A1), FIND("]",CELL("filename",A1))+1, 255))+1, 255), FIND("시", MID(MID(CELL("filename",A1), FIND("]",CELL("filename",A1))+1, 255), FIND("(", MID(CELL("filename",A1), FIND("]",CELL("filename",A1))+1, 255))+1, 255))), 3) & " 신청서" -> 10월 타바타 수금 12시 신청서
G4: 강사: 신수경
G5: 요일: 수 , 금 / 시간: 오후 12시
A6: 1. 강습료는 월 8회 50,000원이며, 당월 관리비에 자동 부과됩니다.
A7: 2. 강습은 매주 수,금(주2회) 이며 국/공휴일은 강습이 없습니다.
A8: 3. 각반 정원은 30명이며, 10명미만 접수시 폐강 할 수 있습니다.
A9: 4. 강습대상은 성인이며, 청소년도 가능합니다. 강습양도 불가합니다.
A10: 5. 중도 등록, 취소시 일할계산(월8회 기준)되어 강습료 부과되며 강습 취소 미신청 시 전액부과됩니다.(당일 취소는 불가)
A11: 6. 중도취소 신청은 방문 신청만 가능합니다.(장소: 2단지 안내데스크 방문)
A12: 7. 강습은 3개월 단위 재추첨하며, 강습 기간중 중도 취소 하지 않는 경우 3개월간 자동 재등록 됩니다.
A14: 시간 | B14: 순번 | C14: 날 짜 | D14: 성함 | E14: 동 | F14: 호수 | G14: 서명 | H14: 취소날짜 | I14: 취소서명 | J14: 비고
A15: 12:00 ~ 12:50 | B15: 1
B16: 2
B17: 3
B18: 4
B19: 5
B20: 6
B21: 7
B22: 8
B23: 9
B24: 10
B25: 11
B26: 12
B27: 13
... B34: 20
A35: =A1 -> 10월 타바타 수금 12시 신청서
G38: =G4 -> 강사: 신수경
G39: =G5 -> 요일: 수 , 금 / 시간: 오후 12시
A40: =A6 -> 1. 강습료는 월 8회 50,000원이며, 당월 관리비에 자동 부과됩니다.
A41: =A7 -> 2. 강습은 매주 수,금(주2회) 이며 국/공휴일은 강습이 없습니다.
A42: =A8 -> 3. 각반 정원은 30명이며, 10명미만 접수시 폐강 할 수 있습니다.
A43: =A9 -> 4. 강습대상은 성인이며, 청소년도 가능합니다. 강습양도 불가합니다.
A44: =A10 -> 5. 중도 등록, 취소시 일할계산(월8회 기준)되어 강습료 부과되며 강습 취소 미신청 시 전액부과됩니다.(당일 취소는 불가)
A45: =A11 -> 6. 중도취소 신청은 방문 신청만 가능합니다.(장소: 2단지 안내데스크 방문)
A46: =A12 -> 7. 강습은 3개월 단위 재추첨하며, 강습 기간중 중도 취소 하지 않는 경우 3개월간 자동 재등록 됩니다.
A48: 시간 | B48: 순번 | C48: 날 짜 | D48: 성함 | E48: 동 | F48: 호수 | G48: 서명 | H48: 취소날짜 | I48: 취소서명 | J48: 비고
A49: =A15 -> 12:00 ~ 12:50 | B49: 21
B50: 22
B51: 23
B52: 24
...

Sheet 2단지 매트필라테스(화목16시김혜인)
A1: =월!$A$1 & "월 " & SUBSTITUTE(LEFT(MID(CELL("filename",A1), FIND("]",CELL("filename",A1))+1, 255), FIND("(", MID(CELL("filename",A1), FIND("]",CELL("filename",A1))+1, 255))-1), "2단지 ", "") & " " & LEFT(MID(MID(CELL("filename",A1), FIND("]",CELL("filename",A1))+1, 255), FIND("(", MID(CELL("filename",A1), FIND("]",CELL("filename",A1))+1, 255))+1, 255), FIND("시", MID(MID(CELL("filename",A1), FIND("]",CELL("filename",A1))+1, 255), FIND("(", MID(CELL("filename",A1), FIND("]",CELL("filename",A1))+1, 255))+1, 255))-3) & " " & RIGHT(LEFT(MID(MID(CELL("filename",A1), FIND("]",CELL("filename",A1))+1, 255), FIND("(", MID(CELL("filename",A1), FIND("]",CELL("filename",A1))+1, 255))+1, 255), FIND("시", MID(MID(CELL("filename",A1), FIND("]",CELL("filename",A1))+1, 255), FIND("(", MID(CELL("filename",A1), FIND("]",CELL("filename",A1))+1, 255))+1, 255))), 3) & " 신청서" -> 10월 매트필라테스 화목 16시 신청서
G4: 강사: 김혜인
G5: 요일: 화 , 목 / 시간: 오후 4시
A6: 1. 강습료는 월 8회 50,000원이며, 당월 관리비에 자동 부과됩니다.
A7: 2. 강습은 매주 화,목(주2회) 이며 국/공휴일은 강습이 없습니다.
A8: 3. 각반 정원은 30명이며, 10명미만 접수시 폐강 할 수 있습니다.
A9: 4. 강습대상은 성인이며, 청소년도 가능합니다. 강습양도 불가합니다.
A10: 5. 중도 등록, 취소시 일할계산(월8회 기준)되어 강습료 부과되며 강습 취소 미신청 시 전액부과됩니다.(당일 취소는 불가)
A11: 6. 중도취소 신청은 방문 신청만 가능합니다.(장소: 2단지 안내데스크 방문)
A12: 7. 강습은 3개월 단위 재추첨하며, 강습 기간중 중도 취소 하지 않는 경우 3개월간 자동 재등록 됩니다.
A14: 시간 | B14: 순번 | C14: 날 짜 | D14: 성함 | E14: 동 | F14: 호수 | G14: 서명 | H14: 취소날짜 | I14: 취소서명 | J14: 비고
A15: 16:00 ~ 16:50 | B15: 1
B16: 2
B17: 3
B18: 4
B19: 5
B20: 6
B21: 7
B22: 8
B23: 9
B24: 10
B25: 11
B26: 12
B27: 13
... B34: 20
A35: =A1 -> 10월 매트필라테스 화목 16시 신청서
G38: =G4 -> 강사: 김혜인
G39: =G5 -> 요일: 화 , 목 / 시간: 오후 4시
A40: =A6 -> 1. 강습료는 월 8회 50,000원이며, 당월 관리비에 자동 부과됩니다.
A41: =A7 -> 2. 강습은 매주 화,목(주2회) 이며 국/공휴일은 강습이 없습니다.
A42: =A8 -> 3. 각반 정원은 30명이며, 10명미만 접수시 폐강 할 수 있습니다.
A43: =A9 -> 4. 강습대상은 성인이며, 청소년도 가능합니다. 강습양도 불가합니다.
A44: =A10 -> 5. 중도 등록, 취소시 일할계산(월8회 기준)되어 강습료 부과되며 강습 취소 미신청 시 전액부과됩니다.(당일 취소는 불가)
A45: =A11 -> 6. 중도취소 신청은 방문 신청만 가능합니다.(장소: 2단지 안내데스크 방문)
A46: =A12 -> 7. 강습은 3개월 단위 재추첨하며, 강습 기간중 중도 취소 하지 않는 경우 3개월간 자동 재등록 됩니다.
A48: 시간 | B48: 순번 | C48: 날 짜 | D48: 성함 | E48: 동 | F48: 호수 | G48: 서명 | H48: 취소날짜 | I48: 취소서명 | J48: 비고
A49: =A15 -> 16:00 ~ 16:50 | B49: 21
B50: 22
B51: 23
B52: 24
...

Sheet 2단지 방송댄스(화목19시박선화)
A1: =월!$A$1 & "월 " & SUBSTITUTE(LEFT(MID(CELL("filename",A1), FIND("]",CELL("filename",A1))+1, 255), FIND("(", MID(CELL("filename",A1), FIND("]",CELL("filename",A1))+1, 255))-1), "2단지 ", "") & " " & LEFT(MID(MID(CELL("filename",A1), FIND("]",CELL("filename",A1))+1, 255), FIND("(", MID(CELL("filename",A1), FIND("]",CELL("filename",A1))+1, 255))+1, 255), FIND("시", MID(MID(CELL("filename",A1), FIND("]",CELL("filename",A1))+1, 255), FIND("(", MID(CELL("filename",A1), FIND("]",CELL("filename",A1))+1, 255))+1, 255))-3) & " " & RIGHT(LEFT(MID(MID(CELL("filename",A1), FIND("]",CELL("filename",A1))+1, 255), FIND("(", MID(CELL("filename",A1), FIND("]",CELL("filename",A1))+1, 255))+1, 255), FIND("시", MID(MID(CELL("filename",A1), FIND("]",CELL("filename",A1))+1, 255), FIND("(", MID(CELL("filename",A1), FIND("]",CELL("filename",A1))+1, 255))+1, 255))), 3) & " 신청서" -> 10월 방송댄스 화목 19시 신청서
G4: 강사: 박선화
G5: 요일: 화 , 목 / 시간: 오후 7시
A6: 1. 강습료는 월 8회 50,000원이며, 당월 관리비에 자동 부과됩니다.
A7: 2. 강습은 매주 화,목(주2회) 이며 국/공휴일은 강습이 없습니다.
A8: 3. 각반 정원은 30명이며, 10명미만 접수시 폐강 할 수 있습니다.
A9: 4. 강습대상은 성인이며, 청소년도 가능합니다. 강습양도 불가합니다.
A10: 5. 중도 등록, 취소시 일할계산(월8회 기준)되어 강습료 부과되며 강습 취소 미신청 시 전액부과됩니다.(당일 취소는 불가)
A11: 6. 중도취소 신청은 방문 신청만 가능합니다.(장소: 2단지 안내데스크 방문)
A12: 7. 강습은 3개월 단위 재추첨하며, 강습 기간중 중도 취소 하지 않는 경우 3개월간 자동 재등록 됩니다.
A14: 시간 | B14: 순번 | C14: 날 짜 | D14: 성함 | E14: 동 | F14: 호수 | G14: 서명 | H14: 취소날짜 | I14: 취소서명 | J14: 비고
A15: 19:00 ~ 19:50 | B15: 1
B16: 2
B17: 3
B18: 4
B19: 5
B20: 6
B21: 7
B22: 8 | M22: 2
B23: 9
B24: 10
B25: 11
B26: 12
B27: 13
B28: 14
B29: 15
B30: 16
B31: 17
B32: 18
B33: 19
B34: 20
A35: =A1 -> 10월 방송댄스 화목 19시 신청서
G38: =G4 -> 강사: 박선화
G39: =G5 -> 요일: 화 , 목 / 시간: 오후 7시
A40: =A6 -> 1. 강습료는 월 8회 50,000원이며, 당월 관리비에 자동 부과됩니다.
A41: =A7 -> 2. 강습은 매주 화,목(주2회) 이며 국/공휴일은 강습이 없습니다.
A42: =A8 -> 3. 각반 정원은 30명이며, 10명미만 접수시 폐강 할 수 있습니다.
A43: =A9 -> 4. 강습대상은 성인이며, 청소년도 가능합니다. 강습양도 불가합니다.
A44: =A10 -> 5. 중도 등록, 취소시 일할계산(월8회 기준)되어 강습료 부과되며 강습 취소 미신청 시 전액부과됩니다.(당일 취소는 불가)
A45: =A11 -> 6. 중도취소 신청은 방문 신청만 가능합니다.(장소: 2단지 안내데스크 방문)
...

Sheet 2단지 근력(토08시이재욱)
A1: =월!$A$1 & "월 " & SUBSTITUTE(LEFT(MID(CELL("filename",A1), FIND("]",CELL("filename",A1))+1, 255), FIND("(", MID(CELL("filename",A1), FIND("]",CELL("filename",A1))+1, 255))-1), "2단지 ", "") & " " & LEFT(MID(MID(CELL("filename",A1), FIND("]",CELL("filename",A1))+1, 255), FIND("(", MID(CELL("filename",A1), FIND("]",CELL("filename",A1))+1, 255))+1, 255), FIND("시", MID(MID(CELL("filename",A1), FIND("]",CELL("filename",A1))+1, 255), FIND("(", MID(CELL("filename",A1), FIND("]",CELL("filename",A1))+1, 255))+1, 255))-3) & " " & RIGHT(LEFT(MID(MID(CELL("filename",A1), FIND("]",CELL("filename",A1))+1, 255), FIND("(", MID(CELL("filename",A1), FIND("]",CELL("filename",A1))+1, 255))+1, 255), FIND("시", MID(MID(CELL("filename",A1), FIND("]",CELL("filename",A1))+1, 255), FIND("(", MID(CELL("filename",A1), FIND("]",CELL("filename",A1))+1, 255))+1, 255))), 3) & " 신청서" -> 10월 근력 토 08시 신청서
G4: 강사: 이재욱
G5: 요일: 토 / 시간: 오전 8시
A6: 1. 강습료는 월 4회 30,000원이며, 당월 관리비에 자동 부과됩니다.
A7: 2. 강습은 매주 토(주1회) 이며 국/공휴일은 강습이 없습니다.
A8: 3. 각반 정원은 30명이며, 10명미만 접수시 폐강 할 수 있습니다.
A9: 4. 강습대상은 성인이며, 청소년도 가능합니다. 강습양도 불가합니다.
A10: 5. 중도 등록, 취소시 일할계산(월4회 기준)되어 강습료 부과되며 강습 취소 미신청 시 전액부과됩니다.(당일 취소는 불가)
A11: 6. 중도취소 신청은 방문 신청만 가능합니다.(장소: 2단지 안내데스크 방문)
A12: 7. 강습은 3개월 단위 재추첨하며, 강습 기간중 중도 취소 하지 않는 경우 3개월간 자동 재등록 됩니다.
A14: 시간 | B14: 순번 | C14: 날 짜 | D14: 성함 | E14: 동 | F14: 호수 | G14: 서명 | H14: 취소날짜 | I14: 취소서명 | J14: 비고
A15: 08:00 ~ 08:50 | B15: 1
B16: 2
B17: 3
B18: 4
B19: 5
B20: 6
B21: 7
B22: 8
B23: 9
B24: 10
B25: 11
B26: 12
B27: 13
... B34: 20
A35: =A1 -> 10월 근력 토 08시 신청서
G38: =G4 -> 강사: 이재욱
G39: =G5 -> 요일: 토 / 시간: 오전 8시
A40: =A6 -> 1. 강습료는 월 4회 30,000원이며, 당월 관리비에 자동 부과됩니다.
A41: =A7 -> 2. 강습은 매주 토(주1회) 이며 국/공휴일은 강습이 없습니다.
A42: =A8 -> 3. 각반 정원은 30명이며, 10명미만 접수시 폐강 할 수 있습니다.
A43: =A9 -> 4. 강습대상은 성인이며, 청소년도 가능합니다. 강습양도 불가합니다.
A44: =A10 -> 5. 중도 등록, 취소시 일할계산(월4회 기준)되어 강습료 부과되며 강습 취소 미신청 시 전액부과됩니다.(당일 취소는 불가)
A45: =A11 -> 6. 중도취소 신청은 방문 신청만 가능합니다.(장소: 2단지 안내데스크 방문)
A46: =A12 -> 7. 강습은 3개월 단위 재추첨하며, 강습 기간중 중도 취소 하지 않는 경우 3개월간 자동 재등록 됩니다.
A48: 시간 | B48: 순번 | C48: 날 짜 | D48: 성함 | E48: 동 | F48: 호수 | G48: 서명 | H48: 취소날짜 | I48: 취소서명 | J48: 비고
A49: =A15 -> 08:00 ~ 08:50 | B49: 21
B50: 22
B51: 23
B52: 24
...

Sheet 2단지 근력(토09시이재욱)
A1: =월!$A$1 & "월 " & SUBSTITUTE(LEFT(MID(CELL("filename",A1), FIND("]",CELL("filename",A1))+1, 255), FIND("(", MID(CELL("filename",A1), FIND("]",CELL("filename",A1))+1, 255))-1), "2단지 ", "") & " " & LEFT(MID(MID(CELL("filename",A1), FIND("]",CELL("filename",A1))+1, 255), FIND("(", MID(CELL("filename",A1), FIND("]",CELL("filename",A1))+1, 255))+1, 255), FIND("시", MID(MID(CELL("filename",A1), FIND("]",CELL("filename",A1))+1, 255), FIND("(", MID(CELL("filename",A1), FIND("]",CELL("filename",A1))+1, 255))+1, 255))-3) & " " & RIGHT(LEFT(MID(MID(CELL("filename",A1), FIND("]",CELL("filename",A1))+1, 255), FIND("(", MID(CELL("filename",A1), FIND("]",CELL("filename",A1))+1, 255))+1, 255), FIND("시", MID(MID(CELL("filename",A1), FIND("]",CELL("filename",A1))+1, 255), FIND("(", MID(CELL("filename",A1), FIND("]",CELL("filename",A1))+1, 255))+1, 255))), 3) & " 신청서" -> 10월 근력 토 09시 신청서
G4: 강사: 이재욱
G5: 요일: 토 / 시간: 오전 9시
A6: 1. 강습료는 월 4회 30,000원이며, 당월 관리비에 자동 부과됩니다.
A7: 2. 강습은 매주 토(주1회) 이며 국/공휴일은 강습이 없습니다.
A8: 3. 각반 정원은 30명이며, 10명미만 접수시 폐강 할 수 있습니다.
A9: 4. 강습대상은 성인이며, 청소년도 가능합니다. 강습양도 불가합니다.
A10: 5. 중도 등록, 취소시 일할계산(월4회 기준)되어 강습료 부과되며 강습 취소 미신청 시 전액부과됩니다.(당일 취소는 불가)
A11: 6. 중도취소 신청은 방문 신청만 가능합니다.(장소: 2단지 안내데스크 방문)
A12: 7. 강습은 3개월 단위 재추첨하며, 강습 기간중 중도 취소 하지 않는 경우 3개월간 자동 재등록 됩니다.
A14: 시간 | B14: 순번 | C14: 날 짜 | D14: 성함 | E14: 동 | F14: 호수 | G14: 서명 | H14: 취소날짜 | I14: 취소서명 | J14: 비고
A15: 09:00 ~ 09:50 | B15: 1
B16: 2
B17: 3
B18: 4
B19: 5
B20: 6
B21: 7
B22: 8
B23: 9
B24: 10
B25: 11
B26: 12
B27: 13
... B34: 20
A35: =A1 -> 10월 근력 토 09시 신청서
G38: =G4 -> 강사: 이재욱
G39: =G5 -> 요일: 토 / 시간: 오전 9시
A40: =A6 -> 1. 강습료는 월 4회 30,000원이며, 당월 관리비에 자동 부과됩니다.
A41: =A7 -> 2. 강습은 매주 토(주1회) 이며 국/공휴일은 강습이 없습니다.
A42: =A8 -> 3. 각반 정원은 30명이며, 10명미만 접수시 폐강 할 수 있습니다.
A43: =A9 -> 4. 강습대상은 성인이며, 청소년도 가능합니다. 강습양도 불가합니다.
A44: =A10 -> 5. 중도 등록, 취소시 일할계산(월4회 기준)되어 강습료 부과되며 강습 취소 미신청 시 전액부과됩니다.(당일 취소는 불가)
A45: =A11 -> 6. 중도취소 신청은 방문 신청만 가능합니다.(장소: 2단지 안내데스크 방문)
A46: =A12 -> 7. 강습은 3개월 단위 재추첨하며, 강습 기간중 중도 취소 하지 않는 경우 3개월간 자동 재등록 됩니다.
A48: 시간 | B48: 순번 | C48: 날 짜 | D48: 성함 | E48: 동 | F48: 호수 | G48: 서명 | H48: 취소날짜 | I48: 취소서명 | J48: 비고
A49: =A15 -> 09:00 ~ 09:50 | B49: 21
B50: 22
B51: 23
B52: 24
...

Sheet 2단지 요가(토20시송혜정)
A1: =월!$A$1 & "월 " & SUBSTITUTE(LEFT(MID(CELL("filename",A1), FIND("]",CELL("filename",A1))+1, 255), FIND("(", MID(CELL("filename",A1), FIND("]",CELL("filename",A1))+1, 255))-1), "2단지 ", "") & " " & LEFT(MID(MID(CELL("filename",A1), FIND("]",CELL("filename",A1))+1, 255), FIND("(", MID(CELL("filename",A1), FIND("]",CELL("filename",A1))+1, 255))+1, 255), FIND("시", MID(MID(CELL("filename",A1), FIND("]",CELL("filename",A1))+1, 255), FIND("(", MID(CELL("filename",A1), FIND("]",CELL("filename",A1))+1, 255))+1, 255))-3) & " " & RIGHT(LEFT(MID(MID(CELL("filename",A1), FIND("]",CELL("filename",A1))+1, 255), FIND("(", MID(CELL("filename",A1), FIND("]",CELL("filename",A1))+1, 255))+1, 255), FIND("시", MID(MID(CELL("filename",A1), FIND("]",CELL("filename",A1))+1, 255), FIND("(", MID(CELL("filename",A1), FIND("]",CELL("filename",A1))+1, 255))+1, 255))), 3) & " 신청서" -> 10월 요가 토 20시 신청서
G4: 강사: 송혜정
G5: 요일: 토 / 시간: 20시
A6: 1. 강습료는 월 4회 30,000원이며, 당월 관리비에 자동 부과됩니다.
A7: 2. 강습은 매주 토(주1회) 이며 국/공휴일은 강습이 없습니다.
A8: 3. 각반 정원은 30명이며, 10명미만 접수시 폐강 할 수 있습니다.
A9: 4. 강습대상은 성인이며, 청소년도 가능합니다. 강습양도 불가합니다.
A10: 5. 중도 등록, 취소시 일할계산(월4회 기준)되어 강습료 부과되며 강습 취소 미신청 시 전액부과됩니다.(당일 취소는 불가)
A11: 6. 중도취소 신청은 방문 신청만 가능합니다.(장소: 2단지 안내데스크 방문)
A12: 7. 강습은 3개월 단위 재추첨하며, 강습 기간중 중도 취소 하지 않는 경우 3개월간 자동 재등록 됩니다.
A14: 시간 | B14: 순번 | C14: 날 짜 | D14: 성함 | E14: 동 | F14: 호수 | G14: 서명 | H14: 취소날짜 | I14: 취소서명 | J14: 비고
A15: 20:00 ~ 20:50 | B15: 1
B16: 2
B17: 3
B18: 4
B19: 5
B20: 6
B21: 7
B22: 8
B23: 9
B24: 10
B25: 11
B26: 12
B27: 13
... B34: 20
A35: =A1 -> 10월 요가 토 20시 신청서
G38: =G4 -> 강사: 송혜정
G39: =G5 -> 요일: 토 / 시간: 20시
A40: =A6 -> 1. 강습료는 월 4회 30,000원이며, 당월 관리비에 자동 부과됩니다.
A41: =A7 -> 2. 강습은 매주 토(주1회) 이며 국/공휴일은 강습이 없습니다.
A42: =A8 -> 3. 각반 정원은 30명이며, 10명미만 접수시 폐강 할 수 있습니다.
A43: =A9 -> 4. 강습대상은 성인이며, 청소년도 가능합니다. 강습양도 불가합니다.
A44: =A10 -> 5. 중도 등록, 취소시 일할계산(월4회 기준)되어 강습료 부과되며 강습 취소 미신청 시 전액부과됩니다.(당일 취소는 불가)
A45: =A11 -> 6. 중도취소 신청은 방문 신청만 가능합니다.(장소: 2단지 안내데스크 방문)
A46: =A12 -> 7. 강습은 3개월 단위 재추첨하며, 강습 기간중 중도 취소 하지 않는 경우 3개월간 자동 재등록 됩니다.
A48: 시간 | B48: 순번 | C48: 날 짜 | D48: 성함 | E48: 동 | F48: 호수 | G48: 서명 | H48: 취소날짜 | I48: 취소서명 | J48: 비고
A49: =A15 -> 20:00 ~ 20:50 | B49: 21
B50: 22
B51: 23
B52: 24
...

Sheet 2단지 줌바댄스(토10시박나리)
A1: =월!$A$1 & "월 " & SUBSTITUTE(LEFT(MID(CELL("filename",A1), FIND("]",CELL("filename",A1))+1, 255), FIND("(", MID(CELL("filename",A1), FIND("]",CELL("filename",A1))+1, 255))-1), "2단지 ", "") & " " & LEFT(MID(MID(CELL("filename",A1), FIND("]",CELL("filename",A1))+1, 255), FIND("(", MID(CELL("filename",A1), FIND("]",CELL("filename",A1))+1, 255))+1, 255), FIND("시", MID(MID(CELL("filename",A1), FIND("]",CELL("filename",A1))+1, 255), FIND("(", MID(CELL("filename",A1), FIND("]",CELL("filename",A1))+1, 255))+1, 255))-3) & " " & RIGHT(LEFT(MID(MID(CELL("filename",A1), FIND("]",CELL("filename",A1))+1, 255), FIND("(", MID(CELL("filename",A1), FIND("]",CELL("filename",A1))+1, 255))+1, 255), FIND("시", MID(MID(CELL("filename",A1), FIND("]",CELL("filename",A1))+1, 255), FIND("(", MID(CELL("filename",A1), FIND("]",CELL("filename",A1))+1, 255))+1, 255))), 3) & " 신청서" -> 10월 줌바댄스 토 10시 신청서
G4: 강사: 박나리
G5: 요일: 토 / 시간: 오전 10시
A6: 1. 강습료는 월 4회 30,000원이며, 당월 관리비에 자동 부과됩니다.
A7: 2. 강습은 매주 토(주1회) 이며 국/공휴일은 강습이 없습니다.
A8: 3. 각반 정원은 30명이며, 10명미만 접수시 폐강 할 수 있습니다.
A9: 4. 강습대상은 성인이며, 청소년도 가능합니다. 강습양도 불가합니다.
A10: 5. 중도 등록, 취소시 일할계산(월4회 기준)되어 강습료 부과되며 강습 취소 미신청 시 전액부과됩니다.(당일 취소는 불가)
A11: 6. 중도취소 신청은 방문 신청만 가능합니다.(장소: 2단지 안내데스크 방문)
A12: 7. 강습은 3개월 단위 재추첨하며, 강습 기간중 중도 취소 하지 않는 경우 3개월간 자동 재등록 됩니다.
A14: 시간 | B14: 순번 | C14: 날 짜 | D14: 성함 | E14: 동 | F14: 호수 | G14: 서명 | H14: 취소날짜 | I14: 취소서명 | J14: 비고
A15: 10:00 ~ 10:50 | B15: 1
B16: 2
B17: 3
B18: 4
B19: 5
B20: 6
B21: 7
B22: 8
B23: 9
B24: 10
B25: 11
B26: 12
B27: 13
... B34: 20
A35: =A1 -> 10월 줌바댄스 토 10시 신청서
G38: =G4 -> 강사: 박나리
G39: =G5 -> 요일: 토 / 시간: 오전 10시
A40: =A6 -> 1. 강습료는 월 4회 30,000원이며, 당월 관리비에 자동 부과됩니다.
A41: =A7 -> 2. 강습은 매주 토(주1회) 이며 국/공휴일은 강습이 없습니다.
A42: =A8 -> 3. 각반 정원은 30명이며, 10명미만 접수시 폐강 할 수 있습니다.
A43: =A9 -> 4. 강습대상은 성인이며, 청소년도 가능합니다. 강습양도 불가합니다.
A44: =A10 -> 5. 중도 등록, 취소시 일할계산(월4회 기준)되어 강습료 부과되며 강습 취소 미신청 시 전액부과됩니다.(당일 취소는 불가)
A45: =A11 -> 6. 중도취소 신청은 방문 신청만 가능합니다.(장소: 2단지 안내데스크 방문)
A46: =A12 -> 7. 강습은 3개월 단위 재추첨하며, 강습 기간중 중도 취소 하지 않는 경우 3개월간 자동 재등록 됩니다.
A48: 시간 | B48: 순번 | C48: 날 짜 | D48: 성함 | E48: 동 | F48: 호수 | G48: 서명 | H48: 취소날짜 | I48: 취소서명 | J48: 비고
A49: =A15 -> 10:00 ~ 10:50 | B49: 21
B50: 22
B51: 23
B52: 24
...

Sheet 2단지 줌바댄스(토11시박나리)
A1: =월!$A$1 & "월 " & SUBSTITUTE(LEFT(MID(CELL("filename",A1), FIND("]",CELL("filename",A1))+1, 255), FIND("(", MID(CELL("filename",A1), FIND("]",CELL("filename",A1))+1, 255))-1), "2단지 ", "") & " " & LEFT(MID(MID(CELL("filename",A1), FIND("]",CELL("filename",A1))+1, 255), FIND("(", MID(CELL("filename",A1), FIND("]",CELL("filename",A1))+1, 255))+1, 255), FIND("시", MID(MID(CELL("filename",A1), FIND("]",CELL("filename",A1))+1, 255), FIND("(", MID(CELL("filename",A1), FIND("]",CELL("filename",A1))+1, 255))+1, 255))-3) & " " & RIGHT(LEFT(MID(MID(CELL("filename",A1), FIND("]",CELL("filename",A1))+1, 255), FIND("(", MID(CELL("filename",A1), FIND("]",CELL("filename",A1))+1, 255))+1, 255), FIND("시", MID(MID(CELL("filename",A1), FIND("]",CELL("filename",A1))+1, 255), FIND("(", MID(CELL("filename",A1), FIND("]",CELL("filename",A1))+1, 255))+1, 255))), 3) & " 신청서" -> 10월 줌바댄스 토 11시 신청서
G4: 강사: 박나리
G5: 요일: 토 / 시간: 오전 11시
A6: 1. 강습료는 월 4회 30,000원이며, 당월 관리비에 자동 부과됩니다.
A7: 2. 강습은 매주 토(주1회) 이며 국/공휴일은 강습이 없습니다.
A8: 3. 각반 정원은 30명이며, 10명미만 접수시 폐강 할 수 있습니다.
A9: 4. 강습대상은 성인이며, 청소년도 가능합니다. 강습양도 불가합니다.
A10: 5. 중도 등록, 취소시 일할계산(월4회 기준)되어 강습료 부과되며 강습 취소 미신청 시 전액부과됩니다.(당일 취소는 불가)
A11: 6. 중도취소 신청은 방문 신청만 가능합니다.(장소: 2단지 안내데스크 방문)
A12: 7. 강습은 3개월 단위 재추첨하며, 강습 기간중 중도 취소 하지 않는 경우 3개월간 자동 재등록 됩니다.
A14: 시간 | B14: 순번 | C14: 날 짜 | D14: 성함 | E14: 동 | F14: 호수 | G14: 서명 | H14: 취소날짜 | I14: 취소서명 | J14: 비고
A15: 11:00 ~ 11:50 | B15: 1
B16: 2
B17: 3
B18: 4
B19: 5
B20: 6
B21: 7
B22: 8
B23: 9
B24: 10
B25: 11
B26: 12
B27: 13
... B34: 20
A35: =A1 -> 10월 줌바댄스 토 11시 신청서
G38: =G4 -> 강사: 박나리
G39: =G5 -> 요일: 토 / 시간: 오전 11시
A40: =A6 -> 1. 강습료는 월 4회 30,000원이며, 당월 관리비에 자동 부과됩니다.
A41: =A7 -> 2. 강습은 매주 토(주1회) 이며 국/공휴일은 강습이 없습니다.
A42: =A8 -> 3. 각반 정원은 30명이며, 10명미만 접수시 폐강 할 수 있습니다.
A43: =A9 -> 4. 강습대상은 성인이며, 청소년도 가능합니다. 강습양도 불가합니다.
A44: =A10 -> 5. 중도 등록, 취소시 일할계산(월4회 기준)되어 강습료 부과되며 강습 취소 미신청 시 전액부과됩니다.(당일 취소는 불가)
A45: =A11 -> 6. 중도취소 신청은 방문 신청만 가능합니다.(장소: 2단지 안내데스크 방문)
A46: =A12 -> 7. 강습은 3개월 단위 재추첨하며, 강습 기간중 중도 취소 하지 않는 경우 3개월간 자동 재등록 됩니다.
A48: 시간 | B48: 순번 | C48: 날 짜 | D48: 성함 | E48: 동 | F48: 호수 | G48: 서명 | H48: 취소날짜 | I48: 취소서명 | J48: 비고
A49: =A15 -> 11:00 ~ 11:50 | B49: 21
B50: 22
B51: 23
B52: 24
...

Sheet 월
A1: 10 | B1: < | C1: 월 적으면 모든 제목 변경
C2: 시트 이름 변경시 제목 변경
