Workbook

Sheet 2단지 농구교실(1~2학년화16시배준태)
A1: {=IF(ISNUMBER(월!A1), 월!A1 & "월 ", 월!A1 & " ") & SUBSTITUTE(SUBSTITUTE(SUBSTITUTE(SUBSTITUTE(MID(CELL("filename",A1),FIND("]",CELL("filename",A1))+1,255),"2단지 ",""),"배준태",""),"학년","학년 "),"화","화 ") & " 신청서"} -> 10월 농구교실(1~2학년 화 16시) 신청서
G4: 강사: 배준태
G5: 요일: 화 / 시간: 16시
A6: 1. 강습료는 월 4회 100,000원이며, 당월 관리비에 자동 부과됩니다.
A7: 2. 강습은 매주 화(주1회) 이며 국/공휴일은 강습이 없습니다. 보강수업은 진행하지 않습니다.(월 3회 강습 시 3회분만 부과)
A8: 3. 정원은 12명이며, 6명미만 접수시 폐강 할 수 있습니다.
A9: 4. 강습대상은 1~2학년이며, 성인은 불가능합니다. 강습양도 불가합니다.
A10: 5. 중도 등록, 취소시 일할계산(월4회 기준)되어 강습료 부과되며 강습 취소 미신청 시 전액부과됩니다.(당일 취소는 불가)
A11: 6. 중도취소 신청은 방문 신청만 가능합니다.(장소: 2단지 안내데스크 방문)
A12: 7. 강습은 재추첨은 없으며, 강습 기간중 중도 취소 하지 않는 경우 자동 연장됩니다
A14: 시간 | B14: 순번 | C14: 날 짜 | D14: 성함 | E14: 동 | F14: 호수 | G14: 서명 | H14: 취소날짜 | I14: 취소서명 | J14: 비고
A15: 16:00 ~ 17:00 | B15: 1
B16: 2
B17: 3
B18: 4
B19: 5
B20: 6
B21: 7
B22: 8
B23: 9
B24: 10
B25: 11
B26: 12
B27: 13
... B34: 20
A35: =A1 -> 10월 농구교실(1~2학년 화 16시) 신청서
G38: =G4 -> 강사: 배준태
G39: =G5 -> 요일: 화 / 시간: 16시
A40: =A6 -> 1. 강습료는 월 4회 100,000원이며, 당월 관리비에 자동 부과됩니다.
A41: =A7 -> 2. 강습은 매주 화(주1회) 이며 국/공휴일은 강습이 없습니다. 보강수업은 진행하지 않습니다.(월 3회 강습 시 3회분만 부과)
A42: =A8 -> 3. 정원은 12명이며, 6명미만 접수시 폐강 할 수 있습니다.
A43: =A9 -> 4. 강습대상은 1~2학년이며, 성인은 불가능합니다. 강습양도 불가합니다.
A44: =A10 -> 5. 중도 등록, 취소시 일할계산(월4회 기준)되어 강습료 부과되며 강습 취소 미신청 시 전액부과됩니다.(당일 취소는 불가)
A45: =A11 -> 6. 중도취소 신청은 방문 신청만 가능합니다.(장소: 2단지 안내데스크 방문)
A46: =A12 -> 7. 강습은 재추첨은 없으며, 강습 기간중 중도 취소 하지 않는 경우 자동 연장됩니다
A48: 시간 | B48: 순번 | C48: 날 짜 | D48: 성함 | E48: 동 | F48: 호수 | G48: 서명 | H48: 취소날짜 | I48: 취소서명 | J48: 비고
A49: =A15 -> 16:00 ~ 17:00 | B49: 21
B50: 22
B51: 23
B52: 24
...

Sheet 2단지 농구교실(3~4학년화17시배준태)
A1: {=IF(ISNUMBER(월!A1), 월!A1 & "월 ", 월!A1 & " ") & SUBSTITUTE(SUBSTITUTE(SUBSTITUTE(SUBSTITUTE(MID(CELL("filename",A1),FIND("]",CELL("filename",A1))+1,255),"2단지 ",""),"배준태",""),"학년","학년 "),"화","화 ") & " 신청서"} -> 10월 농구교실(3~4학년 화 17시) 신청서
G4: 강사: 배준태
G5: 요일: 화 / 시간: 17시
A6: 1. 강습료는 월 4회 100,000원이며, 당월 관리비에 자동 부과됩니다.
A7: 2. 강습은 매주 화(주1회) 이며 국/공휴일은 강습이 없습니다. 보강수업은 진행하지 않습니다.(월 3회 강습 시 3회분만 부과)
A8: 3. 정원은 12명이며, 6명미만 접수시 폐강 할 수 있습니다.
A9: 4. 강습대상은 3~4학년이며, 성인은 불가능합니다. 강습양도 불가합니다.
A10: 5. 중도 등록, 취소시 일할계산(월4회 기준)되어 강습료 부과되며 강습 취소 미신청 시 전액부과됩니다.(당일 취소는 불가)
A11: 6. 중도취소 신청은 방문 신청만 가능합니다.(장소: 2단지 안내데스크 방문)
A12: 7. 강습은 재추첨은 없으며, 강습 기간중 중도 취소 하지 않는 경우 자동 연장됩니다
A14: 시간 | B14: 순번 | C14: 날 짜 | D14: 성함 | E14: 동 | F14: 호수 | G14: 서명 | H14: 취소날짜 | I14: 취소서명 | J14: 비고
A15: 17:00 ~ 18:00 | B15: 1
B16: 2
B17: 3
B18: 4
B19: 5
B20: 6
B21: 7
B22: 8
B23: 9
B24: 10
B25: 11
B26: 12
B27: 13
... B34: 20
A35: =A1 -> 10월 농구교실(3~4학년 화 17시) 신청서
G38: =G4 -> 강사: 배준태
G39: =G5 -> 요일: 화 / 시간: 17시
A40: =A6 -> 1. 강습료는 월 4회 100,000원이며, 당월 관리비에 자동 부과됩니다.
A41: =A7 -> 2. 강습은 매주 화(주1회) 이며 국/공휴일은 강습이 없습니다. 보강수업은 진행하지 않습니다.(월 3회 강습 시 3회분만 부과)
A42: =A8 -> 3. 정원은 12명이며, 6명미만 접수시 폐강 할 수 있습니다.
A43: =A9 -> 4. 강습대상은 3~4학년이며, 성인은 불가능합니다. 강습양도 불가합니다.
A44: =A10 -> 5. 중도 등록, 취소시 일할계산(월4회 기준)되어 강습료 부과되며 강습 취소 미신청 시 전액부과됩니다.(당일 취소는 불가)
A45: =A11 -> 6. 중도취소 신청은 방문 신청만 가능합니다.(장소: 2단지 안내데스크 방문)
A46: =A12 -> 7. 강습은 재추첨은 없으며, 강습 기간중 중도 취소 하지 않는 경우 자동 연장됩니다
A48: 시간 | B48: 순번 | C48: 날 짜 | D48: 성함 | E48: 동 | F48: 호수 | G48: 서명 | H48: 취소날짜 | I48: 취소서명 | J48: 비고
A49: =A15 -> 17:00 ~ 18:00 | B49: 21
B50: 22
B51: 23
B52: 24
...

Sheet 2단지 농구교실(5~6학년화18시배준태)
A1: =IF(ISNUMBER(월!A1), 월!A1 & "월 ", 월!A1 & " ") & SUBSTITUTE(SUBSTITUTE(SUBSTITUTE(SUBSTITUTE(MID(CELL("filename",A1),FIND("]",CELL("filename",A1))+1,255),"2단지 ",""),"배준태",""),"학년","학년 "),"화","화 ") & " 신청서" -> 10월 농구교실(5~6학년 화 18시) 신청서
G4: 강사: 배준태
G5: 요일: 화 / 시간: 18시
A6: 1. 강습료는 월 4회 100,000원이며, 당월 관리비에 자동 부과됩니다.
A7: 2. 강습은 매주 화(주1회) 이며 국/공휴일은 강습이 없습니다. 보강수업은 진행하지 않습니다.(월 3회 강습 시 3회분만 부과)
A8: 3. 정원은 12명이며, 6명미만 접수시 폐강 할 수 있습니다.
A9: 4. 강습대상은 5~6학년이며, 성인은 불가능합니다. 강습양도 불가합니다.
A10: 5. 중도 등록, 취소시 일할계산(월4회 기준)되어 강습료 부과되며 강습 취소 미신청 시 전액부과됩니다.(당일 취소는 불가)
A11: 6. 중도취소 신청은 방문 신청만 가능합니다.(장소: 2단지 안내데스크 방문)
A12: 7. 강습은 재추첨은 없으며, 강습 기간중 중도 취소 하지 않는 경우 자동 연장됩니다
A14: 시간 | B14: 순번 | C14: 날 짜 | D14: 성함 | E14: 동 | F14: 호수 | G14: 서명 | H14: 취소날짜 | I14: 취소서명 | J14: 비고
A15: 18:00 ~ 19:00 | B15: 1
B16: 2
B17: 3
B18: 4
B19: 5
B20: 6
B21: 7
B22: 8
B23: 9
B24: 10
B25: 11
B26: 12
B27: 13
... B34: 20
A35: =A1 -> 10월 농구교실(5~6학년 화 18시) 신청서
G38: =G4 -> 강사: 배준태
G39: =G5 -> 요일: 화 / 시간: 18시
A40: =A6 -> 1. 강습료는 월 4회 100,000원이며, 당월 관리비에 자동 부과됩니다.
A41: =A7 -> 2. 강습은 매주 화(주1회) 이며 국/공휴일은 강습이 없습니다. 보강수업은 진행하지 않습니다.(월 3회 강습 시 3회분만 부과)
A42: =A8 -> 3. 정원은 12명이며, 6명미만 접수시 폐강 할 수 있습니다.
A43: =A9 -> 4. 강습대상은 5~6학년이며, 성인은 불가능합니다. 강습양도 불가합니다.
A44: =A10 -> 5. 중도 등록, 취소시 일할계산(월4회 기준)되어 강습료 부과되며 강습 취소 미신청 시 전액부과됩니다.(당일 취소는 불가)
A45: =A11 -> 6. 중도취소 신청은 방문 신청만 가능합니다.(장소: 2단지 안내데스크 방문)
A46: =A12 -> 7. 강습은 재추첨은 없으며, 강습 기간중 중도 취소 하지 않는 경우 자동 연장됩니다
A48: 시간 | B48: 순번 | C48: 날 짜 | D48: 성함 | E48: 동 | F48: 호수 | G48: 서명 | H48: 취소날짜 | I48: 취소서명 | J48: 비고
A49: =A15 -> 18:00 ~ 19:00 | B49: 21
B50: 22
B51: 23
B52: 24
...

Sheet 2단지 농구교실(4~6학년화19시배준태)
A1: {=IF(ISNUMBER(월!A1), 월!A1 & "월 ", 월!A1 & " ") & SUBSTITUTE(SUBSTITUTE(SUBSTITUTE(SUBSTITUTE(MID(CELL("filename",A1),FIND("]",CELL("filename",A1))+1,255),"2단지 ",""),"배준태",""),"학년","학년 "),"화","화 ") & " 신청서"} -> 10월 농구교실(4~6학년 화 19시) 신청서
G4: 강사: 배준태
G5: 요일: 화 / 시간: 19시
A6: 1. 강습료는 월 4회 100,000원이며, 당월 관리비에 자동 부과됩니다.
A7: 2. 강습은 매주 화(주1회) 이며 국/공휴일은 강습이 없습니다. 보강수업은 진행하지 않습니다.(월 3회 강습 시 3회분만 부과)
A8: 3. 정원은 24명이며, 12명미만 접수시 폐강 할 수 있습니다. 9/1(화) 신규개강
A9: 4. 강습대상은 4~6학년이며, 성인은 불가능합니다. 강습양도 불가합니다.
A10: 5. 중도 등록, 취소시 일할계산(월4회 기준)되어 강습료 부과되며 강습 취소 미신청 시 전액부과됩니다.(당일 취소는 불가)
A11: 6. 중도취소 신청은 방문 신청만 가능합니다.(장소: 2단지 안내데스크 방문)
A12: 7. 강습은 재추첨은 없으며, 강습 기간중 중도 취소 하지 않는 경우 자동 연장됩니다
A14: 시간 | B14: 순번 | C14: 날 짜 | D14: 성함 | E14: 동 | F14: 호수 | G14: 서명 | H14: 취소날짜 | I14: 취소서명 | J14: 비고
A15: 19:00 ~ 20:00 | B15: 1
B16: 2
B17: 3
B18: 4
B19: 5
B20: 6
B21: 7
B22: 8
B23: 9
B24: 10
B25: 11
B26: 12
B27: 13
... B34: 20
A35: =A1 -> 10월 농구교실(4~6학년 화 19시) 신청서
G38: =G4 -> 강사: 배준태
G39: =G5 -> 요일: 화 / 시간: 19시
A40: =A6 -> 1. 강습료는 월 4회 100,000원이며, 당월 관리비에 자동 부과됩니다.
A41: =A7 -> 2. 강습은 매주 화(주1회) 이며 국/공휴일은 강습이 없습니다. 보강수업은 진행하지 않습니다.(월 3회 강습 시 3회분만 부과)
A42: =A8 -> 3. 정원은 24명이며, 12명미만 접수시 폐강 할 수 있습니다. 9/1(화) 신규개강
A43: =A9 -> 4. 강습대상은 4~6학년이며, 성인은 불가능합니다. 강습양도 불가합니다.
A44: =A10 -> 5. 중도 등록, 취소시 일할계산(월4회 기준)되어 강습료 부과되며 강습 취소 미신청 시 전액부과됩니다.(당일 취소는 불가)
A45: =A11 -> 6. 중도취소 신청은 방문 신청만 가능합니다.(장소: 2단지 안내데스크 방문)
A46: =A12 -> 7. 강습은 재추첨은 없으며, 강습 기간중 중도 취소 하지 않는 경우 자동 연장됩니다
A48: 시간 | B48: 순번 | C48: 날 짜 | D48: 성함 | E48: 동 | F48: 호수 | G48: 서명 | H48: 취소날짜 | I48: 취소서명 | J48: 비고
A49: =A15 -> 19:00 ~ 20:00 | B49: 21
B50: 22
B51: 23
B52: 24
...

Sheet 2단지 농구교실(1~2학년수16시배준태)
A1: {=IF(ISNUMBER(월!A1), 월!A1 & "월 ", 월!A1 & " ") & SUBSTITUTE(SUBSTITUTE(SUBSTITUTE(SUBSTITUTE(MID(CELL("filename",A1),FIND("]",CELL("filename",A1))+1,255),"2단지 ",""),"배준태",""),"학년","학년 "),"화","화 ") & " 신청서"} -> 10월 농구교실(1~2학년 수16시) 신청서
G4: 강사: 배준태
G5: 요일: 수 / 시간: 16시
A6: 1. 강습료는 월 4회 100,000원이며, 당월 관리비에 자동 부과됩니다.
A7: 2. 강습은 매주 수(주1회) 이며 국/공휴일은 강습이 없습니다. 보강수업은 진행하지 않습니다.(월 3회 강습 시 3회분만 부과)
A8: 3. 정원은 12명이며, 6명미만 접수시 폐강 할 수 있습니다.
A9: 4. 강습대상은 1~2학년이며, 성인은 불가능합니다. 강습양도 불가합니다.
A10: 5. 중도 등록, 취소시 일할계산(월4회 기준)되어 강습료 부과되며 강습 취소 미신청 시 전액부과됩니다.(당일 취소는 불가)
A11: 6. 중도취소 신청은 방문 신청만 가능합니다.(장소: 2단지 안내데스크 방문)
A12: 7. 강습은 재추첨은 없으며, 강습 기간중 중도 취소 하지 않는 경우 자동 연장됩니다
A14: 시간 | B14: 순번 | C14: 날 짜 | D14: 성함 | E14: 동 | F14: 호수 | G14: 서명 | H14: 취소날짜 | I14: 취소서명 | J14: 비고
A15: 16:00 ~ 17:00 | B15: 1
B16: 2
B17: 3
B18: 4
B19: 5
B20: 6
B21: 7
B22: 8
B23: 9
B24: 10
B25: 11
B26: 12
B27: 13
... B34: 20
A35: =A1 -> 10월 농구교실(1~2학년 수16시) 신청서
G38: =G4 -> 강사: 배준태
G39: =G5 -> 요일: 수 / 시간: 16시
A40: =A6 -> 1. 강습료는 월 4회 100,000원이며, 당월 관리비에 자동 부과됩니다.
A41: =A7 -> 2. 강습은 매주 수(주1회) 이며 국/공휴일은 강습이 없습니다. 보강수업은 진행하지 않습니다.(월 3회 강습 시 3회분만 부과)
A42: =A8 -> 3. 정원은 12명이며, 6명미만 접수시 폐강 할 수 있습니다.
A43: =A9 -> 4. 강습대상은 1~2학년이며, 성인은 불가능합니다. 강습양도 불가합니다.
A44: =A10 -> 5. 중도 등록, 취소시 일할계산(월4회 기준)되어 강습료 부과되며 강습 취소 미신청 시 전액부과됩니다.(당일 취소는 불가)
A45: =A11 -> 6. 중도취소 신청은 방문 신청만 가능합니다.(장소: 2단지 안내데스크 방문)
A46: =A12 -> 7. 강습은 재추첨은 없으며, 강습 기간중 중도 취소 하지 않는 경우 자동 연장됩니다
A48: 시간 | B48: 순번 | C48: 날 짜 | D48: 성함 | E48: 동 | F48: 호수 | G48: 서명 | H48: 취소날짜 | I48: 취소서명 | J48: 비고
A49: =A15 -> 16:00 ~ 17:00 | B49: 21
B50: 22
B51: 23
B52: 24
...

Sheet 2단지 농구교실(3~4학년수17시배준태)
A1: {=IF(ISNUMBER(월!A1), 월!A1 & "월 ", 월!A1 & " ") & SUBSTITUTE(SUBSTITUTE(SUBSTITUTE(SUBSTITUTE(MID(CELL("filename",A1),FIND("]",CELL("filename",A1))+1,255),"2단지 ",""),"배준태",""),"학년","학년 "),"화","화 ") & " 신청서"} -> 10월 농구교실(3~4학년 수17시) 신청서
G4: 강사: 배준태
G5: 요일: 수 / 시간: 17시
A6: 1. 강습료는 월 4회 100,000원이며, 당월 관리비에 자동 부과됩니다.
A7: 2. 강습은 매주 수(주1회) 이며 국/공휴일은 강습이 없습니다. 보강수업은 진행하지 않습니다.(월 3회 강습 시 3회분만 부과)
A8: 3. 정원은 12명이며, 6명미만 접수시 폐강 할 수 있습니다.
A9: 4. 강습대상은 3~4학년이며, 성인은 불가능합니다. 강습양도 불가합니다.
A10: 5. 중도 등록, 취소시 일할계산(월4회 기준)되어 강습료 부과되며 강습 취소 미신청 시 전액부과됩니다.(당일 취소는 불가)
A11: 6. 중도취소 신청은 방문 신청만 가능합니다.(장소: 2단지 안내데스크 방문)
A12: 7. 강습은 재추첨은 없으며, 강습 기간중 중도 취소 하지 않는 경우 자동 연장됩니다
A14: 시간 | B14: 순번 | C14: 날 짜 | D14: 성함 | E14: 동 | F14: 호수 | G14: 서명 | H14: 취소날짜 | I14: 취소서명 | J14: 비고
A15: 17:00 ~ 18:00 | B15: 1
B16: 2
B17: 3
B18: 4
B19: 5
B20: 6
B21: 7
B22: 8
B23: 9
B24: 10
B25: 11
B26: 12
B27: 13
... B34: 20
A35: =A1 -> 10월 농구교실(3~4학년 수17시) 신청서
G38: =G4 -> 강사: 배준태
G39: =G5 -> 요일: 수 / 시간: 17시
A40: =A6 -> 1. 강습료는 월 4회 100,000원이며, 당월 관리비에 자동 부과됩니다.
A41: =A7 -> 2. 강습은 매주 수(주1회) 이며 국/공휴일은 강습이 없습니다. 보강수업은 진행하지 않습니다.(월 3회 강습 시 3회분만 부과)
A42: =A8 -> 3. 정원은 12명이며, 6명미만 접수시 폐강 할 수 있습니다.
A43: =A9 -> 4. 강습대상은 3~4학년이며, 성인은 불가능합니다. 강습양도 불가합니다.
A44: =A10 -> 5. 중도 등록, 취소시 일할계산(월4회 기준)되어 강습료 부과되며 강습 취소 미신청 시 전액부과됩니다.(당일 취소는 불가)
A45: =A11 -> 6. 중도취소 신청은 방문 신청만 가능합니다.(장소: 2단지 안내데스크 방문)
A46: =A12 -> 7. 강습은 재추첨은 없으며, 강습 기간중 중도 취소 하지 않는 경우 자동 연장됩니다
A48: 시간 | B48: 순번 | C48: 날 짜 | D48: 성함 | E48: 동 | F48: 호수 | G48: 서명 | H48: 취소날짜 | I48: 취소서명 | J48: 비고
A49: =A15 -> 17:00 ~ 18:00 | B49: 21
B50: 22
B51: 23
B52: 24
...

Sheet 2단지 농구교실(5~6학년수18시배준태)
A1: {=IF(ISNUMBER(월!A1), 월!A1 & "월 ", 월!A1 & " ") & SUBSTITUTE(SUBSTITUTE(SUBSTITUTE(SUBSTITUTE(MID(CELL("filename",A1),FIND("]",CELL("filename",A1))+1,255),"2단지 ",""),"배준태",""),"학년","학년 "),"화","화 ") & " 신청서"} -> 10월 농구교실(5~6학년 수18시) 신청서
G4: 강사: 배준태
G5: 요일: 수 / 시간: 18시
A6: 1. 강습료는 월 4회 100,000원이며, 당월 관리비에 자동 부과됩니다.
A7: 2. 강습은 매주 수(주1회) 이며 국/공휴일은 강습이 없습니다. 보강수업은 진행하지 않습니다.(월 3회 강습 시 3회분만 부과)
A8: 3. 정원은 12명이며, 6명미만 접수시 폐강 할 수 있습니다.
A9: 4. 강습대상은 5~6학년이며, 성인은 불가능합니다. 강습양도 불가합니다.
A10: 5. 중도 등록, 취소시 일할계산(월4회 기준)되어 강습료 부과되며 강습 취소 미신청 시 전액부과됩니다.(당일 취소는 불가)
A11: 6. 중도취소 신청은 방문 신청만 가능합니다.(장소: 2단지 안내데스크 방문)
A12: 7. 강습은 재추첨은 없으며, 강습 기간중 중도 취소 하지 않는 경우 자동 연장됩니다
A14: 시간 | B14: 순번 | C14: 날 짜 | D14: 성함 | E14: 동 | F14: 호수 | G14: 서명 | H14: 취소날짜 | I14: 취소서명 | J14: 비고
A15: 18:00 ~ 19:00 | B15: 1
B16: 2
B17: 3
B18: 4
B19: 5
B20: 6
B21: 7
B22: 8
B23: 9
B24: 10
B25: 11
B26: 12
B27: 13
... B34: 20
A35: =A1 -> 10월 농구교실(5~6학년 수18시) 신청서
G38: =G4 -> 강사: 배준태
G39: =G5 -> 요일: 수 / 시간: 18시
A40: =A6 -> 1. 강습료는 월 4회 100,000원이며, 당월 관리비에 자동 부과됩니다.
A41: =A7 -> 2. 강습은 매주 수(주1회) 이며 국/공휴일은 강습이 없습니다. 보강수업은 진행하지 않습니다.(월 3회 강습 시 3회분만 부과)
A42: =A8 -> 3. 정원은 12명이며, 6명미만 접수시 폐강 할 수 있습니다.
A43: =A9 -> 4. 강습대상은 5~6학년이며, 성인은 불가능합니다. 강습양도 불가합니다.
A44: =A10 -> 5. 중도 등록, 취소시 일할계산(월4회 기준)되어 강습료 부과되며 강습 취소 미신청 시 전액부과됩니다.(당일 취소는 불가)
A45: =A11 -> 6. 중도취소 신청은 방문 신청만 가능합니다.(장소: 2단지 안내데스크 방문)
A46: =A12 -> 7. 강습은 재추첨은 없으며, 강습 기간중 중도 취소 하지 않는 경우 자동 연장됩니다
A48: 시간 | B48: 순번 | C48: 날 짜 | D48: 성함 | E48: 동 | F48: 호수 | G48: 서명 | H48: 취소날짜 | I48: 취소서명 | J48: 비고
A49: =A15 -> 18:00 ~ 19:00 | B49: 21
B50: 22
B51: 23
B52: 24
...

Sheet 2단지 농구교실(중학생수19시배준태)
A1: =INDIRECT("'월'!A1") & "월 농구교실(" & MID(REPLACE(CELL("filename",A1),1,FIND("]",CELL("filename",A1)),""), FIND("(", REPLACE(CELL("filename",A1),1,FIND("]",CELL("filename",A1)),""))+1, 3) & " " & MID(REPLACE(CELL("filename",A1),1,FIND("]",CELL("filename",A1)),""), FIND("(", REPLACE(CELL("filename",A1),1,FIND("]",CELL("filename",A1)),""))+4, 4) & " " & SUBSTITUTE(MID(REPLACE(CELL("filename",A1),1,FIND("]",CELL("filename",A1)),""), FIND("(", REPLACE(CELL("filename",A1),1,FIND("]",CELL("filename",A1)),""))+8, 255), ")", "") & ") 신청서" -> 10월 농구교실(중학생 수19시 배준태) 신청서
G4: 강사: 배준태
G5: 요일: 수 / 시간: 19시
A6: 1. 강습료는 월 4회 100,000원이며, 당월 관리비에 자동 부과됩니다.
A7: 2. 강습은 매주 수(주1회) 이며 국/공휴일은 강습이 없습니다. 보강수업은 진행하지 않습니다.(월 3회 강습 시 3회분만 부과)
A8: 3. 정원은 12명이며, 6명미만 접수시 폐강 할 수 있습니다.
A9: 4. 강습대상은 중1~3이며, 성인은 불가능합니다. 강습양도 불가합니다.
A10: 5. 중도 등록, 취소시 일할계산(월4회 기준)되어 강습료 부과되며 강습 취소 미신청 시 전액부과됩니다.(당일 취소는 불가)
A11: 6. 중도취소 신청은 방문 신청만 가능합니다.(장소: 2단지 안내데스크 방문)
A12: 7. 강습은 재추첨은 없으며, 강습 기간중 중도 취소 하지 않는 경우 자동 연장됩니다
A14: 시간 | B14: 순번 | C14: 날 짜 | D14: 성함 | E14: 동 | F14: 호수 | G14: 서명 | H14: 취소날짜 | I14: 취소서명 | J14: 비고
A15: 19:00 ~ 20:00 | B15: 1
B16: 2
B17: 3
B18: 4
B19: 5
B20: 6
B21: 7
B22: 8
B23: 9
B24: 10
B25: 11
B26: 12
B27: 13
... B34: 20
A35: =A1 -> 10월 농구교실(중학생 수19시 배준태) 신청서
G38: =G4 -> 강사: 배준태
G39: =G5 -> 요일: 수 / 시간: 19시
A40: =A6 -> 1. 강습료는 월 4회 100,000원이며, 당월 관리비에 자동 부과됩니다.
A41: =A7 -> 2. 강습은 매주 수(주1회) 이며 국/공휴일은 강습이 없습니다. 보강수업은 진행하지 않습니다.(월 3회 강습 시 3회분만 부과)
A42: =A8 -> 3. 정원은 12명이며, 6명미만 접수시 폐강 할 수 있습니다.
A43: =A9 -> 4. 강습대상은 중1~3이며, 성인은 불가능합니다. 강습양도 불가합니다.
A44: =A10 -> 5. 중도 등록, 취소시 일할계산(월4회 기준)되어 강습료 부과되며 강습 취소 미신청 시 전액부과됩니다.(당일 취소는 불가)
A45: =A11 -> 6. 중도취소 신청은 방문 신청만 가능합니다.(장소: 2단지 안내데스크 방문)
A46: =A12 -> 7. 강습은 재추첨은 없으며, 강습 기간중 중도 취소 하지 않는 경우 자동 연장됩니다
A48: 시간 | B48: 순번 | C48: 날 짜 | D48: 성함 | E48: 동 | F48: 호수 | G48: 서명 | H48: 취소날짜 | I48: 취소서명 | J48: 비고
A49: =A15 -> 19:00 ~ 20:00 | B49: 21
B50: 22
B51: 23
B52: 24
...

Sheet 2단지 농구교실(1~2학년목16시배준태)
A1: {=IF(ISNUMBER(월!A1), 월!A1 & "월 ", 월!A1 & " ") & SUBSTITUTE(SUBSTITUTE(SUBSTITUTE(SUBSTITUTE(MID(CELL("filename",A1),FIND("]",CELL("filename",A1))+1,255),"2단지 ",""),"배준태",""),"학년","학년 "),"화","화 ") & " 신청서"} -> 10월 농구교실(1~2학년 목16시) 신청서
G4: 강사: 배준태
G5: 요일: 목 / 시간: 16시
A6: 1. 강습료는 월 4회 100,000원이며, 당월 관리비에 자동 부과됩니다.
A7: 2. 강습은 매주 목(주1회) 이며 국/공휴일은 강습이 없습니다. 보강수업은 진행하지 않습니다.(월 3회 강습 시 3회분만 부과)
A8: 3. 정원은 12명이며, 6명미만 접수시 폐강 할 수 있습니다.
A9: 4. 강습대상은 1~2학년이며, 성인은 불가능합니다. 강습양도 불가합니다.
A10: 5. 중도 등록, 취소시 일할계산(월4회 기준)되어 강습료 부과되며 강습 취소 미신청 시 전액부과됩니다.(당일 취소는 불가)
A11: 6. 중도취소 신청은 방문 신청만 가능합니다.(장소: 2단지 안내데스크 방문)
A12: 7. 강습은 재추첨은 없으며, 강습 기간중 중도 취소 하지 않는 경우 자동 연장됩니다
A14: 시간 | B14: 순번 | C14: 날 짜 | D14: 성함 | E14: 동 | F14: 호수 | G14: 서명 | H14: 취소날짜 | I14: 취소서명 | J14: 비고
A15: 16:00 ~ 17:00 | B15: 1
B16: 2
B17: 3
B18: 4
B19: 5
B20: 6
B21: 7
B22: 8
B23: 9
B24: 10
B25: 11
B26: 12
B27: 13
... B34: 20
A35: =A1 -> 10월 농구교실(1~2학년 목16시) 신청서
G38: =G4 -> 강사: 배준태
G39: =G5 -> 요일: 목 / 시간: 16시
A40: =A6 -> 1. 강습료는 월 4회 100,000원이며, 당월 관리비에 자동 부과됩니다.
A41: =A7 -> 2. 강습은 매주 목(주1회) 이며 국/공휴일은 강습이 없습니다. 보강수업은 진행하지 않습니다.(월 3회 강습 시 3회분만 부과)
A42: =A8 -> 3. 정원은 12명이며, 6명미만 접수시 폐강 할 수 있습니다.
A43: =A9 -> 4. 강습대상은 1~2학년이며, 성인은 불가능합니다. 강습양도 불가합니다.
A44: =A10 -> 5. 중도 등록, 취소시 일할계산(월4회 기준)되어 강습료 부과되며 강습 취소 미신청 시 전액부과됩니다.(당일 취소는 불가)
A45: =A11 -> 6. 중도취소 신청은 방문 신청만 가능합니다.(장소: 2단지 안내데스크 방문)
A46: =A12 -> 7. 강습은 재추첨은 없으며, 강습 기간중 중도 취소 하지 않는 경우 자동 연장됩니다
A48: 시간 | B48: 순번 | C48: 날 짜 | D48: 성함 | E48: 동 | F48: 호수 | G48: 서명 | H48: 취소날짜 | I48: 취소서명 | J48: 비고
A49: =A15 -> 16:00 ~ 17:00 | B49: 21
B50: 22
B51: 23
B52: 24
...

Sheet 2단지 농구교실(3~4학년목17시배준태)
A1: {=IF(ISNUMBER(월!A1), 월!A1 & "월 ", 월!A1 & " ") & SUBSTITUTE(SUBSTITUTE(SUBSTITUTE(SUBSTITUTE(MID(CELL("filename",A1),FIND("]",CELL("filename",A1))+1,255),"2단지 ",""),"배준태",""),"학년","학년 "),"화","화 ") & " 신청서"} -> 10월 농구교실(3~4학년 목17시) 신청서
G4: 강사: 배준태
G5: 요일: 목 / 시간: 17시
A6: 1. 강습료는 월 4회 100,000원이며, 당월 관리비에 자동 부과됩니다.
A7: 2. 강습은 매주 목(주1회) 이며 국/공휴일은 강습이 없습니다. 보강수업은 진행하지 않습니다.(월 3회 강습 시 3회분만 부과)
A8: 3. 정원은 12명이며, 6명미만 접수시 폐강 할 수 있습니다.
A9: 4. 강습대상은 3~4학년이며, 성인은 불가능합니다. 강습양도 불가합니다.
A10: 5. 중도 등록, 취소시 일할계산(월4회 기준)되어 강습료 부과되며 강습 취소 미신청 시 전액부과됩니다.(당일 취소는 불가)
A11: 6. 중도취소 신청은 방문 신청만 가능합니다.(장소: 2단지 안내데스크 방문)
A12: 7. 강습은 재추첨은 없으며, 강습 기간중 중도 취소 하지 않는 경우 자동 연장됩니다
A14: 시간 | B14: 순번 | C14: 날 짜 | D14: 성함 | E14: 동 | F14: 호수 | G14: 서명 | H14: 취소날짜 | I14: 취소서명 | J14: 비고
A15: 17:00 ~ 18:00 | B15: 1
B16: 2
B17: 3
B18: 4
B19: 5
B20: 6
B21: 7
B22: 8
B23: 9
B24: 10
B25: 11
B26: 12
B27: 13
... B34: 20
A35: =A1 -> 10월 농구교실(3~4학년 목17시) 신청서
G38: =G4 -> 강사: 배준태
G39: =G5 -> 요일: 목 / 시간: 17시
A40: =A6 -> 1. 강습료는 월 4회 100,000원이며, 당월 관리비에 자동 부과됩니다.
A41: =A7 -> 2. 강습은 매주 목(주1회) 이며 국/공휴일은 강습이 없습니다. 보강수업은 진행하지 않습니다.(월 3회 강습 시 3회분만 부과)
A42: =A8 -> 3. 정원은 12명이며, 6명미만 접수시 폐강 할 수 있습니다.
A43: =A9 -> 4. 강습대상은 3~4학년이며, 성인은 불가능합니다. 강습양도 불가합니다.
A44: =A10 -> 5. 중도 등록, 취소시 일할계산(월4회 기준)되어 강습료 부과되며 강습 취소 미신청 시 전액부과됩니다.(당일 취소는 불가)
A45: =A11 -> 6. 중도취소 신청은 방문 신청만 가능합니다.(장소: 2단지 안내데스크 방문)
A46: =A12 -> 7. 강습은 재추첨은 없으며, 강습 기간중 중도 취소 하지 않는 경우 자동 연장됩니다
A48: 시간 | B48: 순번 | C48: 날 짜 | D48: 성함 | E48: 동 | F48: 호수 | G48: 서명 | H48: 취소날짜 | I48: 취소서명 | J48: 비고
A49: =A15 -> 17:00 ~ 18:00 | B49: 21
B50: 22
B51: 23
B52: 24
...

Sheet 2단지 농구교실(5~6학년목18시배준태)
A1: {=IF(ISNUMBER(월!A1), 월!A1 & "월 ", 월!A1 & " ") & SUBSTITUTE(SUBSTITUTE(SUBSTITUTE(SUBSTITUTE(MID(CELL("filename",A1),FIND("]",CELL("filename",A1))+1,255),"2단지 ",""),"배준태",""),"학년","학년 "),"화","화 ") & " 신청서"} -> 10월 농구교실(5~6학년 목18시) 신청서
G4: 강사: 배준태
G5: 요일: 목 / 시간: 18시
A6: 1. 강습료는 월 4회 100,000원이며, 당월 관리비에 자동 부과됩니다.
A7: 2. 강습은 매주 목(주1회) 이며 국/공휴일은 강습이 없습니다. 보강수업은 진행하지 않습니다.(월 3회 강습 시 3회분만 부과)
A8: 3. 정원은 12명이며, 6명미만 접수시 폐강 할 수 있습니다.
A9: 4. 강습대상은 5~6학년이며, 성인은 불가능합니다. 강습양도 불가합니다.
A10: 5. 중도 등록, 취소시 일할계산(월4회 기준)되어 강습료 부과되며 강습 취소 미신청 시 전액부과됩니다.(당일 취소는 불가)
A11: 6. 중도취소 신청은 방문 신청만 가능합니다.(장소: 2단지 안내데스크 방문)
A12: 7. 강습은 재추첨은 없으며, 강습 기간중 중도 취소 하지 않는 경우 자동 연장됩니다
A14: 시간 | B14: 순번 | C14: 날 짜 | D14: 성함 | E14: 동 | F14: 호수 | G14: 서명 | H14: 취소날짜 | I14: 취소서명 | J14: 비고
A15: 18:00 ~ 19:00 | B15: 1
B16: 2
B17: 3
B18: 4
B19: 5
B20: 6
B21: 7
B22: 8
B23: 9
B24: 10
B25: 11
B26: 12
B27: 13
... B34: 20
A35: =A1 -> 10월 농구교실(5~6학년 목18시) 신청서
G38: =G4 -> 강사: 배준태
G39: =G5 -> 요일: 목 / 시간: 18시
A40: =A6 -> 1. 강습료는 월 4회 100,000원이며, 당월 관리비에 자동 부과됩니다.
A41: =A7 -> 2. 강습은 매주 목(주1회) 이며 국/공휴일은 강습이 없습니다. 보강수업은 진행하지 않습니다.(월 3회 강습 시 3회분만 부과)
A42: =A8 -> 3. 정원은 12명이며, 6명미만 접수시 폐강 할 수 있습니다.
A43: =A9 -> 4. 강습대상은 5~6학년이며, 성인은 불가능합니다. 강습양도 불가합니다.
A44: =A10 -> 5. 중도 등록, 취소시 일할계산(월4회 기준)되어 강습료 부과되며 강습 취소 미신청 시 전액부과됩니다.(당일 취소는 불가)
A45: =A11 -> 6. 중도취소 신청은 방문 신청만 가능합니다.(장소: 2단지 안내데스크 방문)
A46: =A12 -> 7. 강습은 재추첨은 없으며, 강습 기간중 중도 취소 하지 않는 경우 자동 연장됩니다
A48: 시간 | B48: 순번 | C48: 날 짜 | D48: 성함 | E48: 동 | F48: 호수 | G48: 서명 | H48: 취소날짜 | I48: 취소서명 | J48: 비고
A49: =A15 -> 18:00 ~ 19:00 | B49: 21
B50: 22
B51: 23
B52: 24
...

Sheet 2단지 농구교실(중학생목19시배준태)
A1: =INDIRECT("'월'!A1") & "월 농구교실(" & MID(REPLACE(CELL("filename",A1),1,FIND("]",CELL("filename",A1)),""), FIND("(", REPLACE(CELL("filename",A1),1,FIND("]",CELL("filename",A1)),""))+1, 3) & " " & MID(REPLACE(CELL("filename",A1),1,FIND("]",CELL("filename",A1)),""), FIND("(", REPLACE(CELL("filename",A1),1,FIND("]",CELL("filename",A1)),""))+4, 4) & " " & SUBSTITUTE(MID(REPLACE(CELL("filename",A1),1,FIND("]",CELL("filename",A1)),""), FIND("(", REPLACE(CELL("filename",A1),1,FIND("]",CELL("filename",A1)),""))+8, 255), ")", "") & ") 신청서" -> 10월 농구교실(중학생 목19시 배준태) 신청서
G4: 강사: 배준태
G5: 요일: 목 / 시간: 19시
A6: 1. 강습료는 월 4회 100,000원이며, 당월 관리비에 자동 부과됩니다.
A7: 2. 강습은 매주 목(주1회) 이며 국/공휴일은 강습이 없습니다. 보강수업은 진행하지 않습니다.(월 3회 강습 시 3회분만 부과)
A8: 3. 정원은 12명이며, 6명미만 접수시 폐강 할 수 있습니다.
A9: 4. 강습대상은 중1~3이며, 성인은 불가능합니다. 강습양도 불가합니다.
A10: 5. 중도 등록, 취소시 일할계산(월4회 기준)되어 강습료 부과되며 강습 취소 미신청 시 전액부과됩니다.(당일 취소는 불가)
A11: 6. 중도취소 신청은 방문 신청만 가능합니다.(장소: 2단지 안내데스크 방문)
A12: 7. 강습은 재추첨은 없으며, 강습 기간중 중도 취소 하지 않는 경우 자동 연장됩니다
A14: 시간 | B14: 순번 | C14: 날 짜 | D14: 성함 | E14: 동 | F14: 호수 | G14: 서명 | H14: 취소날짜 | I14: 취소서명 | J14: 비고
A15: 19:00 ~ 20:00 | B15: 1
B16: 2
B17: 3
B18: 4
B19: 5
B20: 6
B21: 7
B22: 8
B23: 9
B24: 10
B25: 11
B26: 12
B27: 13
... B34: 20
A35: =A1 -> 10월 농구교실(중학생 목19시 배준태) 신청서
G38: =G4 -> 강사: 배준태
G39: =G5 -> 요일: 목 / 시간: 19시
A40: =A6 -> 1. 강습료는 월 4회 100,000원이며, 당월 관리비에 자동 부과됩니다.
A41: =A7 -> 2. 강습은 매주 목(주1회) 이며 국/공휴일은 강습이 없습니다. 보강수업은 진행하지 않습니다.(월 3회 강습 시 3회분만 부과)
A42: =A8 -> 3. 정원은 12명이며, 6명미만 접수시 폐강 할 수 있습니다.
A43: =A9 -> 4. 강습대상은 중1~3이며, 성인은 불가능합니다. 강습양도 불가합니다.
A44: =A10 -> 5. 중도 등록, 취소시 일할계산(월4회 기준)되어 강습료 부과되며 강습 취소 미신청 시 전액부과됩니다.(당일 취소는 불가)
A45: =A11 -> 6. 중도취소 신청은 방문 신청만 가능합니다.(장소: 2단지 안내데스크 방문)
A46: =A12 -> 7. 강습은 재추첨은 없으며, 강습 기간중 중도 취소 하지 않는 경우 자동 연장됩니다
A48: 시간 | B48: 순번 | C48: 날 짜 | D48: 성함 | E48: 동 | F48: 호수 | G48: 서명 | H48: 취소날짜 | I48: 취소서명 | J48: 비고
A49: =A15 -> 19:00 ~ 20:00 | B49: 21
B50: 22
B51: 23
B52: 24
...

Sheet 2단지 농구교실(1~2학년금16시배준태)
A1: {=IF(ISNUMBER(월!A1), 월!A1 & "월 ", 월!A1 & " ") & SUBSTITUTE(SUBSTITUTE(SUBSTITUTE(SUBSTITUTE(MID(CELL("filename",A1),FIND("]",CELL("filename",A1))+1,255),"2단지 ",""),"배준태",""),"학년","학년 "),"화","화 ") & " 신청서"} -> 10월 농구교실(1~2학년 금16시) 신청서
G4: 강사: 배준태
G5: 요일: 금 / 시간: 16시
A6: 1. 강습료는 월 4회 100,000원이며, 당월 관리비에 자동 부과됩니다.
A7: 2. 강습은 매주 금(주1회) 이며 국/공휴일은 강습이 없습니다. 보강수업은 진행하지 않습니다.(월 3회 강습 시 3회분만 부과)
A8: 3. 정원은 12명이며, 6명미만 접수시 폐강 할 수 있습니다.
A9: 4. 강습대상은 1~2학년이며, 성인은 불가능합니다. 강습양도 불가합니다.
A10: 5. 중도 등록, 취소시 일할계산(월4회 기준)되어 강습료 부과되며 강습 취소 미신청 시 전액부과됩니다.(당일 취소는 불가)
A11: 6. 중도취소 신청은 방문 신청만 가능합니다.(장소: 2단지 안내데스크 방문)
A12: 7. 강습은 재추첨은 없으며, 강습 기간중 중도 취소 하지 않는 경우 자동 연장됩니다
A14: 시간 | B14: 순번 | C14: 날 짜 | D14: 성함 | E14: 동 | F14: 호수 | G14: 서명 | H14: 취소날짜 | I14: 취소서명 | J14: 비고
A15: 16:00 ~ 17:00 | B15: 1
B16: 2
B17: 3
B18: 4
B19: 5
B20: 6
B21: 7
B22: 8 | V22: p
B23: 9
B24: 10
B25: 11
B26: 12
B27: 13
B28: 14
B29: 15
B30: 16
B31: 17
B32: 18
B33: 19
B34: 20
A35: =A1 -> 10월 농구교실(1~2학년 금16시) 신청서
G38: =G4 -> 강사: 배준태
G39: =G5 -> 요일: 금 / 시간: 16시
A40: =A6 -> 1. 강습료는 월 4회 100,000원이며, 당월 관리비에 자동 부과됩니다.
A41: =A7 -> 2. 강습은 매주 금(주1회) 이며 국/공휴일은 강습이 없습니다. 보강수업은 진행하지 않습니다.(월 3회 강습 시 3회분만 부과)
A42: =A8 -> 3. 정원은 12명이며, 6명미만 접수시 폐강 할 수 있습니다.
A43: =A9 -> 4. 강습대상은 1~2학년이며, 성인은 불가능합니다. 강습양도 불가합니다.
A44: =A10 -> 5. 중도 등록, 취소시 일할계산(월4회 기준)되어 강습료 부과되며 강습 취소 미신청 시 전액부과됩니다.(당일 취소는 불가)
A45: =A11 -> 6. 중도취소 신청은 방문 신청만 가능합니다.(장소: 2단지 안내데스크 방문)
...

Sheet 2단지 농구교실(3~4학년금17시배준태)
A1: {=IF(ISNUMBER(월!A1), 월!A1 & "월 ", 월!A1 & " ") & SUBSTITUTE(SUBSTITUTE(SUBSTITUTE(SUBSTITUTE(MID(CELL("filename",A1),FIND("]",CELL("filename",A1))+1,255),"2단지 ",""),"배준태",""),"학년","학년 "),"화","화 ") & " 신청서"} -> 10월 농구교실(3~4학년 금17시) 신청서
G4: 강사: 배준태
G5: 요일: 금 / 시간: 17시
A6: 1. 강습료는 월 4회 100,000원이며, 당월 관리비에 자동 부과됩니다.
A7: 2. 강습은 매주 금(주1회) 이며 국/공휴일은 강습이 없습니다. 보강수업은 진행하지 않습니다.(월 3회 강습 시 3회분만 부과)
A8: 3. 정원은 12명이며, 6명미만 접수시 폐강 할 수 있습니다.
A9: 4. 강습대상은 3~4학년이며, 성인은 불가능합니다. 강습양도 불가합니다.
A10: 5. 중도 등록, 취소시 일할계산(월4회 기준)되어 강습료 부과되며 강습 취소 미신청 시 전액부과됩니다.(당일 취소는 불가)
A11: 6. 중도취소 신청은 방문 신청만 가능합니다.(장소: 2단지 안내데스크 방문)
A12: 7. 강습은 재추첨은 없으며, 강습 기간중 중도 취소 하지 않는 경우 자동 연장됩니다
A14: 시간 | B14: 순번 | C14: 날 짜 | D14: 성함 | E14: 동 | F14: 호수 | G14: 서명 | H14: 취소날짜 | I14: 취소서명 | J14: 비고
A15: 17:00 ~ 18:00 | B15: 1
B16: 2
B17: 3
B18: 4
B19: 5
B20: 6
B21: 7
B22: 8
B23: 9
B24: 10
B25: 11
B26: 12
B27: 13
... B34: 20
A35: =A1 -> 10월 농구교실(3~4학년 금17시) 신청서
G38: =G4 -> 강사: 배준태
G39: =G5 -> 요일: 금 / 시간: 17시
A40: =A6 -> 1. 강습료는 월 4회 100,000원이며, 당월 관리비에 자동 부과됩니다.
A41: =A7 -> 2. 강습은 매주 금(주1회) 이며 국/공휴일은 강습이 없습니다. 보강수업은 진행하지 않습니다.(월 3회 강습 시 3회분만 부과)
A42: =A8 -> 3. 정원은 12명이며, 6명미만 접수시 폐강 할 수 있습니다.
A43: =A9 -> 4. 강습대상은 3~4학년이며, 성인은 불가능합니다. 강습양도 불가합니다.
A44: =A10 -> 5. 중도 등록, 취소시 일할계산(월4회 기준)되어 강습료 부과되며 강습 취소 미신청 시 전액부과됩니다.(당일 취소는 불가)
A45: =A11 -> 6. 중도취소 신청은 방문 신청만 가능합니다.(장소: 2단지 안내데스크 방문)
A46: =A12 -> 7. 강습은 재추첨은 없으며, 강습 기간중 중도 취소 하지 않는 경우 자동 연장됩니다
A48: 시간 | B48: 순번 | C48: 날 짜 | D48: 성함 | E48: 동 | F48: 호수 | G48: 서명 | H48: 취소날짜 | I48: 취소서명 | J48: 비고
A49: =A15 -> 17:00 ~ 18:00 | B49: 21
B50: 22
B51: 23
B52: 24
...

Sheet 2단지 농구교실(5~6학년금18시배준태)
A1: {=IF(ISNUMBER(월!A1), 월!A1 & "월 ", 월!A1 & " ") & SUBSTITUTE(SUBSTITUTE(SUBSTITUTE(SUBSTITUTE(MID(CELL("filename",A1),FIND("]",CELL("filename",A1))+1,255),"2단지 ",""),"배준태",""),"학년","학년 "),"화","화 ") & " 신청서"} -> 10월 농구교실(5~6학년 금18시) 신청서
G4: 강사: 배준태
G5: 요일: 금 / 시간: 18시
A6: 1. 강습료는 월 4회 100,000원이며, 당월 관리비에 자동 부과됩니다.
A7: 2. 강습은 매주 금(주1회) 이며 국/공휴일은 강습이 없습니다. 보강수업은 진행하지 않습니다.(월 3회 강습 시 3회분만 부과)
A8: 3. 정원은 12명이며, 6명미만 접수시 폐강 할 수 있습니다.
A9: 4. 강습대상은 5~6학년이며, 성인은 불가능합니다. 강습양도 불가합니다.
A10: 5. 중도 등록, 취소시 일할계산(월4회 기준)되어 강습료 부과되며 강습 취소 미신청 시 전액부과됩니다.(당일 취소는 불가)
A11: 6. 중도취소 신청은 방문 신청만 가능합니다.(장소: 2단지 안내데스크 방문)
A12: 7. 강습은 재추첨은 없으며, 강습 기간중 중도 취소 하지 않는 경우 자동 연장됩니다
A14: 시간 | B14: 순번 | C14: 날 짜 | D14: 성함 | E14: 동 | F14: 호수 | G14: 서명 | H14: 취소날짜 | I14: 취소서명 | J14: 비고
A15: 18:00 ~ 19:00 | B15: 1
B16: 2
B17: 3
B18: 4
B19: 5
B20: 6
B21: 7
B22: 8
B23: 9
B24: 10
B25: 11
B26: 12
B27: 13
... B34: 20
A35: =A1 -> 10월 농구교실(5~6학년 금18시) 신청서
G38: =G4 -> 강사: 배준태
G39: =G5 -> 요일: 금 / 시간: 18시
A40: =A6 -> 1. 강습료는 월 4회 100,000원이며, 당월 관리비에 자동 부과됩니다.
A41: =A7 -> 2. 강습은 매주 금(주1회) 이며 국/공휴일은 강습이 없습니다. 보강수업은 진행하지 않습니다.(월 3회 강습 시 3회분만 부과)
A42: =A8 -> 3. 정원은 12명이며, 6명미만 접수시 폐강 할 수 있습니다.
A43: =A9 -> 4. 강습대상은 5~6학년이며, 성인은 불가능합니다. 강습양도 불가합니다.
A44: =A10 -> 5. 중도 등록, 취소시 일할계산(월4회 기준)되어 강습료 부과되며 강습 취소 미신청 시 전액부과됩니다.(당일 취소는 불가)
A45: =A11 -> 6. 중도취소 신청은 방문 신청만 가능합니다.(장소: 2단지 안내데스크 방문)
A46: =A12 -> 7. 강습은 재추첨은 없으며, 강습 기간중 중도 취소 하지 않는 경우 자동 연장됩니다
A48: 시간 | B48: 순번 | C48: 날 짜 | D48: 성함 | E48: 동 | F48: 호수 | G48: 서명 | H48: 취소날짜 | I48: 취소서명 | J48: 비고
A49: =A15 -> 18:00 ~ 19:00 | B49: 21
B50: 22
B51: 23
B52: 24
...

Sheet 2단지 농구교실(중학생금19시배준태)
A1: =INDIRECT("'월'!A1") & "월 농구교실(" & MID(REPLACE(CELL("filename",A1),1,FIND("]",CELL("filename",A1)),""), FIND("(", REPLACE(CELL("filename",A1),1,FIND("]",CELL("filename",A1)),""))+1, 3) & " " & MID(REPLACE(CELL("filename",A1),1,FIND("]",CELL("filename",A1)),""), FIND("(", REPLACE(CELL("filename",A1),1,FIND("]",CELL("filename",A1)),""))+4, 4) & " " & SUBSTITUTE(MID(REPLACE(CELL("filename",A1),1,FIND("]",CELL("filename",A1)),""), FIND("(", REPLACE(CELL("filename",A1),1,FIND("]",CELL("filename",A1)),""))+8, 255), ")", "") & ") 신청서" -> 10월 농구교실(중학생 금19시 배준태) 신청서
G4: 강사: 배준태
G5: 요일: 금 / 시간: 19시
A6: 1. 강습료는 월 4회 100,000원이며, 당월 관리비에 자동 부과됩니다.
A7: 2. 강습은 매주 금(주1회) 이며 국/공휴일은 강습이 없습니다. 보강수업은 진행하지 않습니다.(월 3회 강습 시 3회분만 부과)
A8: 3. 정원은 12명이며, 6명미만 접수시 폐강 할 수 있습니다.
A9: 4. 강습대상은 중1~3이며, 성인은 불가능합니다. 강습양도 불가합니다.
A10: 5. 중도 등록, 취소시 일할계산(월4회 기준)되어 강습료 부과되며 강습 취소 미신청 시 전액부과됩니다.(당일 취소는 불가)
A11: 6. 중도취소 신청은 방문 신청만 가능합니다.(장소: 2단지 안내데스크 방문)
A12: 7. 강습은 재추첨은 없으며, 강습 기간중 중도 취소 하지 않는 경우 자동 연장됩니다
A14: 시간 | B14: 순번 | C14: 날 짜 | D14: 성함 | E14: 동 | F14: 호수 | G14: 서명 | H14: 취소날짜 | I14: 취소서명 | J14: 비고
A15: 19:00 ~ 20:00 | B15: 1
B16: 2
B17: 3
B18: 4
B19: 5
B20: 6
B21: 7
B22: 8
B23: 9
B24: 10
B25: 11
B26: 12
B27: 13
... B34: 20
A35: =A1 -> 10월 농구교실(중학생 금19시 배준태) 신청서
G38: =G4 -> 강사: 배준태
G39: =G5 -> 요일: 금 / 시간: 19시
A40: =A6 -> 1. 강습료는 월 4회 100,000원이며, 당월 관리비에 자동 부과됩니다.
A41: =A7 -> 2. 강습은 매주 금(주1회) 이며 국/공휴일은 강습이 없습니다. 보강수업은 진행하지 않습니다.(월 3회 강습 시 3회분만 부과)
A42: =A8 -> 3. 정원은 12명이며, 6명미만 접수시 폐강 할 수 있습니다.
A43: =A9 -> 4. 강습대상은 중1~3이며, 성인은 불가능합니다. 강습양도 불가합니다.
A44: =A10 -> 5. 중도 등록, 취소시 일할계산(월4회 기준)되어 강습료 부과되며 강습 취소 미신청 시 전액부과됩니다.(당일 취소는 불가)
A45: =A11 -> 6. 중도취소 신청은 방문 신청만 가능합니다.(장소: 2단지 안내데스크 방문)
A46: =A12 -> 7. 강습은 재추첨은 없으며, 강습 기간중 중도 취소 하지 않는 경우 자동 연장됩니다
A48: 시간 | B48: 순번 | C48: 날 짜 | D48: 성함 | E48: 동 | F48: 호수 | G48: 서명 | H48: 취소날짜 | I48: 취소서명 | J48: 비고
A49: =A15 -> 19:00 ~ 20:00 | B49: 21
B50: 22
B51: 23
B52: 24
...

Sheet 2단지 농구교실(1~3학년토10시배준태)
A1: {=IF(ISNUMBER(월!A1), 월!A1 & "월 ", 월!A1 & " ") & SUBSTITUTE(SUBSTITUTE(SUBSTITUTE(SUBSTITUTE(MID(CELL("filename",A1),FIND("]",CELL("filename",A1))+1,255),"2단지 ",""),"배준태",""),"학년","학년 "),"화","화 ") & " 신청서"} -> 10월 농구교실(1~3학년 토10시) 신청서
G4: 강사: 배준태
G5: 요일: 토 / 시간: 10시
A6: 1. 강습료는 월 4회 100,000원이며, 당월 관리비에 자동 부과됩니다.
A7: 2. 강습은 매주 금(주1회) 이며 국/공휴일은 강습이 없습니다. 보강수업은 진행하지 않습니다.(월 3회 강습 시 3회분만 부과)
A8: 3. 정원은 12명이며, 6명미만 접수시 폐강 할 수 있습니다.
A9: 4. 강습대상은 1~3학년이며, 성인은 불가능합니다. 강습양도 불가합니다.
A10: 5. 중도 등록, 취소시 일할계산(월4회 기준)되어 강습료 부과되며 강습 취소 미신청 시 전액부과됩니다.(당일 취소는 불가)
A11: 6. 중도취소 신청은 방문 신청만 가능합니다.(장소: 2단지 안내데스크 방문)
A12: 7. 강습은 재추첨은 없으며, 강습 기간중 중도 취소 하지 않는 경우 자동 연장됩니다
A14: 시간 | B14: 순번 | C14: 날 짜 | D14: 성함 | E14: 동 | F14: 호수 | G14: 서명 | H14: 취소날짜 | I14: 취소서명 | J14: 비고
A15: 10:00 ~ 11:10 | B15: 1
B16: 2
B17: 3
B18: 4
B19: 5
B20: 6
B21: 7
B22: 8
B23: 9
B24: 10
B25: 11
B26: 12
B27: 13
... B34: 20
A35: =A1 -> 10월 농구교실(1~3학년 토10시) 신청서
G38: =G4 -> 강사: 배준태
G39: =G5 -> 요일: 토 / 시간: 10시
A40: =A6 -> 1. 강습료는 월 4회 100,000원이며, 당월 관리비에 자동 부과됩니다.
A41: =A7 -> 2. 강습은 매주 금(주1회) 이며 국/공휴일은 강습이 없습니다. 보강수업은 진행하지 않습니다.(월 3회 강습 시 3회분만 부과)
A42: =A8 -> 3. 정원은 12명이며, 6명미만 접수시 폐강 할 수 있습니다.
A43: =A9 -> 4. 강습대상은 1~3학년이며, 성인은 불가능합니다. 강습양도 불가합니다.
A44: =A10 -> 5. 중도 등록, 취소시 일할계산(월4회 기준)되어 강습료 부과되며 강습 취소 미신청 시 전액부과됩니다.(당일 취소는 불가)
A45: =A11 -> 6. 중도취소 신청은 방문 신청만 가능합니다.(장소: 2단지 안내데스크 방문)
A46: =A12 -> 7. 강습은 재추첨은 없으며, 강습 기간중 중도 취소 하지 않는 경우 자동 연장됩니다
A48: 시간 | B48: 순번 | C48: 날 짜 | D48: 성함 | E48: 동 | F48: 호수 | G48: 서명 | H48: 취소날짜 | I48: 취소서명 | J48: 비고
A49: =A15 -> 10:00 ~ 11:10 | B49: 21
B50: 22
B51: 23
B52: 24
...

Sheet 2단지 농구교실(4~6학년토11시20분배준태)
A1: {=IF(ISNUMBER(월!A1), 월!A1 & "월 ", 월!A1 & " ") & SUBSTITUTE(SUBSTITUTE(SUBSTITUTE(SUBSTITUTE(MID(CELL("filename",A1),FIND("]",CELL("filename",A1))+1,255),"2단지 ",""),"배준태",""),"학년","학년 "),"화","화 ") & " 신청서"} -> 10월 농구교실(4~6학년 토11시20분) 신청서
G4: 강사: 배준태
G5: 요일: 토 / 시간: 11시 20분
A6: 1. 강습료는 월 4회 100,000원이며, 당월 관리비에 자동 부과됩니다.
A7: 2. 강습은 매주 금(주1회) 이며 국/공휴일은 강습이 없습니다. 보강수업은 진행하지 않습니다.(월 3회 강습 시 3회분만 부과)
A8: 3. 정원은 12명이며, 6명미만 접수시 폐강 할 수 있습니다.
A9: 4. 강습대상은 4~6학년이며, 성인은 불가능합니다. 강습양도 불가합니다.
A10: 5. 중도 등록, 취소시 일할계산(월4회 기준)되어 강습료 부과되며 강습 취소 미신청 시 전액부과됩니다.(당일 취소는 불가)
A11: 6. 중도취소 신청은 방문 신청만 가능합니다.(장소: 2단지 안내데스크 방문)
A12: 7. 강습은 재추첨은 없으며, 강습 기간중 중도 취소 하지 않는 경우 자동 연장됩니다
A14: 시간 | B14: 순번 | C14: 날 짜 | D14: 성함 | E14: 동 | F14: 호수 | G14: 서명 | H14: 취소날짜 | I14: 취소서명 | J14: 비고
A15: 11:20 ~ 12:30 | B15: 1
B16: 2
B17: 3
B18: 4
B19: 5
B20: 6
B21: 7
B22: 8
B23: 9
B24: 10
B25: 11
B26: 12
B27: 13
... B34: 20
A35: =A1 -> 10월 농구교실(4~6학년 토11시20분) 신청서
G38: =G4 -> 강사: 배준태
G39: =G5 -> 요일: 토 / 시간: 11시 20분
A40: =A6 -> 1. 강습료는 월 4회 100,000원이며, 당월 관리비에 자동 부과됩니다.
A41: =A7 -> 2. 강습은 매주 금(주1회) 이며 국/공휴일은 강습이 없습니다. 보강수업은 진행하지 않습니다.(월 3회 강습 시 3회분만 부과)
A42: =A8 -> 3. 정원은 12명이며, 6명미만 접수시 폐강 할 수 있습니다.
A43: =A9 -> 4. 강습대상은 4~6학년이며, 성인은 불가능합니다. 강습양도 불가합니다.
A44: =A10 -> 5. 중도 등록, 취소시 일할계산(월4회 기준)되어 강습료 부과되며 강습 취소 미신청 시 전액부과됩니다.(당일 취소는 불가)
A45: =A11 -> 6. 중도취소 신청은 방문 신청만 가능합니다.(장소: 2단지 안내데스크 방문)
A46: =A12 -> 7. 강습은 재추첨은 없으며, 강습 기간중 중도 취소 하지 않는 경우 자동 연장됩니다
A48: 시간 | B48: 순번 | C48: 날 짜 | D48: 성함 | E48: 동 | F48: 호수 | G48: 서명 | H48: 취소날짜 | I48: 취소서명 | J48: 비고
A49: =A15 -> 11:20 ~ 12:30 | B49: 21
B50: 22
B51: 23
B52: 24
...

Sheet 월
A1: 10
