Workbook

Sheet 2단지 성인수영-기초(화목06시30분손태환)
A1: =월!A1 & "월 " & LEFT(SUBSTITUTE(MID(CELL("filename",A1),FIND("]",CELL("filename",A1))+1,255),"2단지 ",""),FIND("(",SUBSTITUTE(MID(CELL("filename",A1),FIND("]",CELL("filename",A1))+1,255),"2단지 ",""))-1) & " " & MID(SUBSTITUTE(MID(CELL("filename",A1),FIND("]",CELL("filename",A1))+1,255),"2단지 ",""),MIN(FIND({0,1,2,3,4,5,6,7,8,9},MID(SUBSTITUTE(MID(CELL("filename",A1),FIND("]",CELL("filename",A1))+1,255),"2단지 ",""),FIND("(",SUBSTITUTE(MID(CELL("filename",A1),FIND("]",CELL("filename",A1))+1,255),"2단지 ",""))+1,255)&"0123456789"))+FIND("(",SUBSTITUTE(MID(CELL("filename",A1),FIND("]",CELL("filename",A1))+1,255),"2단지 ","")),IF(ISNUMBER(FIND("분",MID(SUBSTITUTE(MID(CELL("filename",A1),FIND("]",CELL("filename",A1))+1,255),"2단지 ",""),FIND("(",SUBSTITUTE(MID(CELL("filename",A1),FIND("]",CELL("filename",A1))+1,255),"2단지 ",""))+1,FIND(")",SUBSTITUTE(MID(CELL("filename",A1),FIND("]",CELL("filename",A1))+1,255),"2단지 ",""))-FIND("(",SUBSTITUTE(MID(CELL("filename",A1),FIND("]",CELL("filename",A1))+1,255),"2단지 ",""))-1))),FIND("분",MID(SUBSTITUTE(MID(CELL("filename",A1),FIND("]",CELL("filename",A1))+1,255),"2단지 ",""),FIND("(",SUBSTITUTE(MID(CELL("filename",A1),FIND("]",CELL("filename",A1))+1,255),"2단지 ",""))+1,255)),FIND("시",MID(SUBSTITUTE(MID(CELL("filename",A1),FIND("]",CELL("filename",A1))+1,255),"2단지 ",""),FIND("(",SUBSTITUTE(MID(CELL("filename",A1),FIND("]",CELL("filename",A1))+1,255),"2단지 ",""))+1,255)))-MIN(FIND({0,1,2,3,4,5,6,7,8,9},MID(SUBSTITUTE(MID(CELL("filename",A1),FIND("]",CELL("filename",A1))+1,255),"2단지 ",""),FIND("(",SUBSTITUTE(MID(CELL("filename",A1),FIND("]",CELL("filename",A1))+1,255),"2단지 ",""))+1,255)&"0123456789"))+1) & "(" & IF(LEN(LEFT(MID(SUBSTITUTE(MID(CELL("filename",A1),FIND("]",CELL("filename",A1))+1,255),"2단지 ",""),FIND("(",SUBSTITUTE(MID(CELL("filename",A1),FIND("]",CELL("filename",A1))+1,255),"2단지 ",""))+1,255),MIN(FIND({0,1,2,3,4,5,6,7,8,9},MID(SUBSTITUTE(MID(CELL("filename",A1),FIND("]",CELL("filename",A1))+1,255),"2단지 ",""),FIND("(",SUBSTITUTE(MID(CELL("filename",A1),FIND("]",CELL("filename",A1))+1,255),"2단지 ",""))+1,255)&"0123456789"))-1))=2, LEFT(MID(SUBSTITUTE(MID(CELL("filename",A1),FIND("]",CELL("filename",A1))+1,255),"2단지 ",""),FIND("(",SUBSTITUTE(MID(CELL("filename",A1),FIND("]",CELL("filename",A1))+1,255),"2단지 ",""))+1,2),1)&"/"&RIGHT(MID(SUBSTITUTE(MID(CELL("filename",A1),FIND("]",CELL("filename",A1))+1,255),"2단지 ",""),FIND("(",SUBSTITUTE(MID(CELL("filename",A1),FIND("]",CELL("filename",A1))+1,255),"2단지 ",""))+1,2),1), LEFT(MID(SUBSTITUTE(MID(CELL("filename",A1),FIND("]",CELL("filename",A1))+1,255),"2단지 ",""),FIND("(",SUBSTITUTE(MID(CELL("filename",A1),FIND("]",CELL("filename",A1))+1,255),"2단지 ",""))+1,255),MIN(FIND({0,1,2,3,4,5,6,7,8,9},MID(SUBSTITUTE(MID(CELL("filename",A1),FIND("]",CELL("filename",A1))+1,255),"2단지 ",""),FIND("(",SUBSTITUTE(MID(CELL("filename",A1),FIND("]",CELL("filename",A1))+1,255),"2단지 ",""))+1,255)&"0123456789"))-1)) & ") 신청서" -> 10월 성인수영-기초 06시30분(화/목) 신청서
G4: 강사: 손태환
G5: 요일: 화 , 목 / 시간: 06시30분
A6: 1. 강습료는 월 8회 50,000원이며, 당월 관리비에 자동 부과됩니다.
A7: 2. 강습은 매주 화,목(주2회) 이며 국/공휴일은 강습이 없습니다.
A8: 3. 각반 정원은 25명이며, 15명미만 접수시 폐강 할 수 있습니다.
A9: 4. 강습 대상은 성인이며, 청소년(중학생 이상)도 수강 가능합니다. 강습 양도는 불가합니다.
A10: 5. 중도 등록, 취소시 일할계산(월8회 기준)되어 강습료 부과되며 강습 취소 미신청 시 전액부과됩니다.(당일 취소는 불가)
A11: 6. 중도 취소/신청은 방문신청만 가능합니다.(장소: 2단지 안내데스크 방문)
A12: 7. 강습은 5개월 단위 재추첨하며, 강습 기간중 중도 취소 하지 않는 경우 26.9월까지 자동 재등록 됩니다.
A14: 시간 | B14: 순번 | C14: 날 짜 | D14: 성함 | E14: 동 | F14: 호수 | G14: 서명 | H14: 취소날짜 | I14: 취소서명 | J14: 비고
A15: 06:30 ~ 07:20 | B15: 1
B16: 2
B17: 3
B18: 4
B19: 5
B20: 6
B21: 7
B22: 8
B23: 9
B24: 10
B25: 11
B26: 12
B27: 13
... B34: 20
A35: =A1 -> 10월 성인수영-기초 06시30분(화/목) 신청서
G38: =G4 -> 강사: 손태환
G39: =G5 -> 요일: 화 , 목 / 시간: 06시30분
A40: =A6 -> 1. 강습료는 월 8회 50,000원이며, 당월 관리비에 자동 부과됩니다.
A41: =A7 -> 2. 강습은 매주 화,목(주2회) 이며 국/공휴일은 강습이 없습니다.
A42: =A8 -> 3. 각반 정원은 25명이며, 15명미만 접수시 폐강 할 수 있습니다.
A43: =A9 -> 4. 강습 대상은 성인이며, 청소년(중학생 이상)도 수강 가능합니다. 강습 양도는 불가합니다.
A44: =A10 -> 5. 중도 등록, 취소시 일할계산(월8회 기준)되어 강습료 부과되며 강습 취소 미신청 시 전액부과됩니다.(당일 취소는 불가)
A45: =A11 -> 6. 중도 취소/신청은 방문신청만 가능합니다.(장소: 2단지 안내데스크 방문)
A46: =A12 -> 7. 강습은 5개월 단위 재추첨하며, 강습 기간중 중도 취소 하지 않는 경우 26.9월까지 자동 재등록 됩니다.
A48: 시간 | B48: 순번 | C48: 날 짜 | D48: 성함 | E48: 동 | F48: 호수 | G48: 서명 | H48: 취소날짜 | I48: 취소서명 | J48: 비고
A49: =A15 -> 06:30 ~ 07:20 | B49: 21
B50: 22
B51: 23
B52: 24
...

Sheet 2단지 성인수영-초급(화목06시30분김소운)
A1: =월!A1 & "월 " & LEFT(SUBSTITUTE(MID(CELL("filename",A1),FIND("]",CELL("filename",A1))+1,255),"2단지 ",""),FIND("(",SUBSTITUTE(MID(CELL("filename",A1),FIND("]",CELL("filename",A1))+1,255),"2단지 ",""))-1) & " " & MID(SUBSTITUTE(MID(CELL("filename",A1),FIND("]",CELL("filename",A1))+1,255),"2단지 ",""),MIN(FIND({0,1,2,3,4,5,6,7,8,9},MID(SUBSTITUTE(MID(CELL("filename",A1),FIND("]",CELL("filename",A1))+1,255),"2단지 ",""),FIND("(",SUBSTITUTE(MID(CELL("filename",A1),FIND("]",CELL("filename",A1))+1,255),"2단지 ",""))+1,255)&"0123456789"))+FIND("(",SUBSTITUTE(MID(CELL("filename",A1),FIND("]",CELL("filename",A1))+1,255),"2단지 ","")),IF(ISNUMBER(FIND("분",MID(SUBSTITUTE(MID(CELL("filename",A1),FIND("]",CELL("filename",A1))+1,255),"2단지 ",""),FIND("(",SUBSTITUTE(MID(CELL("filename",A1),FIND("]",CELL("filename",A1))+1,255),"2단지 ",""))+1,FIND(")",SUBSTITUTE(MID(CELL("filename",A1),FIND("]",CELL("filename",A1))+1,255),"2단지 ",""))-FIND("(",SUBSTITUTE(MID(CELL("filename",A1),FIND("]",CELL("filename",A1))+1,255),"2단지 ",""))-1))),FIND("분",MID(SUBSTITUTE(MID(CELL("filename",A1),FIND("]",CELL("filename",A1))+1,255),"2단지 ",""),FIND("(",SUBSTITUTE(MID(CELL("filename",A1),FIND("]",CELL("filename",A1))+1,255),"2단지 ",""))+1,255)),FIND("시",MID(SUBSTITUTE(MID(CELL("filename",A1),FIND("]",CELL("filename",A1))+1,255),"2단지 ",""),FIND("(",SUBSTITUTE(MID(CELL("filename",A1),FIND("]",CELL("filename",A1))+1,255),"2단지 ",""))+1,255)))-MIN(FIND({0,1,2,3,4,5,6,7,8,9},MID(SUBSTITUTE(MID(CELL("filename",A1),FIND("]",CELL("filename",A1))+1,255),"2단지 ",""),FIND("(",SUBSTITUTE(MID(CELL("filename",A1),FIND("]",CELL("filename",A1))+1,255),"2단지 ",""))+1,255)&"0123456789"))+1) & "(" & IF(LEN(LEFT(MID(SUBSTITUTE(MID(CELL("filename",A1),FIND("]",CELL("filename",A1))+1,255),"2단지 ",""),FIND("(",SUBSTITUTE(MID(CELL("filename",A1),FIND("]",CELL("filename",A1))+1,255),"2단지 ",""))+1,255),MIN(FIND({0,1,2,3,4,5,6,7,8,9},MID(SUBSTITUTE(MID(CELL("filename",A1),FIND("]",CELL("filename",A1))+1,255),"2단지 ",""),FIND("(",SUBSTITUTE(MID(CELL("filename",A1),FIND("]",CELL("filename",A1))+1,255),"2단지 ",""))+1,255)&"0123456789"))-1))=2, LEFT(MID(SUBSTITUTE(MID(CELL("filename",A1),FIND("]",CELL("filename",A1))+1,255),"2단지 ",""),FIND("(",SUBSTITUTE(MID(CELL("filename",A1),FIND("]",CELL("filename",A1))+1,255),"2단지 ",""))+1,2),1)&"/"&RIGHT(MID(SUBSTITUTE(MID(CELL("filename",A1),FIND("]",CELL("filename",A1))+1,255),"2단지 ",""),FIND("(",SUBSTITUTE(MID(CELL("filename",A1),FIND("]",CELL("filename",A1))+1,255),"2단지 ",""))+1,2),1), LEFT(MID(SUBSTITUTE(MID(CELL("filename",A1),FIND("]",CELL("filename",A1))+1,255),"2단지 ",""),FIND("(",SUBSTITUTE(MID(CELL("filename",A1),FIND("]",CELL("filename",A1))+1,255),"2단지 ",""))+1,255),MIN(FIND({0,1,2,3,4,5,6,7,8,9},MID(SUBSTITUTE(MID(CELL("filename",A1),FIND("]",CELL("filename",A1))+1,255),"2단지 ",""),FIND("(",SUBSTITUTE(MID(CELL("filename",A1),FIND("]",CELL("filename",A1))+1,255),"2단지 ",""))+1,255)&"0123456789"))-1)) & ") 신청서" -> 10월 성인수영-초급 06시30분(화/목) 신청서
G4: 강사: 김소운
G5: 요일: 화 , 목 / 시간: 06시30분
A6: 1. 강습료는 월 8회 50,000원이며, 당월 관리비에 자동 부과됩니다.
A7: 2. 강습은 매주 화,목(주2회) 이며 국/공휴일은 강습이 없습니다.
A8: 3. 각반 정원은 25명이며, 15명미만 접수시 폐강 할 수 있습니다.
A9: 4. 강습 대상은 성인이며, 청소년(중학생 이상)도 수강 가능합니다. 강습 양도는 불가합니다.
A10: 5. 중도 등록, 취소시 일할계산(월8회 기준)되어 강습료 부과되며 강습 취소 미신청 시 전액부과됩니다.(당일 취소는 불가)
A11: 6. 중도 취소/신청은 방문신청만 가능합니다.(장소: 2단지 안내데스크 방문)
A12: 7. 강습은 5개월 단위 재추첨하며, 강습 기간중 중도 취소 하지 않는 경우 26.9월까지 자동 재등록 됩니다.
A14: 시간 | B14: 순번 | C14: 날 짜 | D14: 성함 | E14: 동 | F14: 호수 | G14: 서명 | H14: 취소날짜 | I14: 취소서명 | J14: 비고
A15: 06:30 ~ 07:20 | B15: 1
B16: 2
B17: 3
B18: 4
B19: 5
B20: 6
B21: 7
B22: 8
B23: 9
B24: 10
B25: 11
B26: 12
B27: 13
... B34: 20
A35: =A1 -> 10월 성인수영-초급 06시30분(화/목) 신청서
G38: =G4 -> 강사: 김소운
G39: =G5 -> 요일: 화 , 목 / 시간: 06시30분
A40: =A6 -> 1. 강습료는 월 8회 50,000원이며, 당월 관리비에 자동 부과됩니다.
A41: =A7 -> 2. 강습은 매주 화,목(주2회) 이며 국/공휴일은 강습이 없습니다.
A42: =A8 -> 3. 각반 정원은 25명이며, 15명미만 접수시 폐강 할 수 있습니다.
A43: =A9 -> 4. 강습 대상은 성인이며, 청소년(중학생 이상)도 수강 가능합니다. 강습 양도는 불가합니다.
A44: =A10 -> 5. 중도 등록, 취소시 일할계산(월8회 기준)되어 강습료 부과되며 강습 취소 미신청 시 전액부과됩니다.(당일 취소는 불가)
A45: =A11 -> 6. 중도 취소/신청은 방문신청만 가능합니다.(장소: 2단지 안내데스크 방문)
A46: =A12 -> 7. 강습은 5개월 단위 재추첨하며, 강습 기간중 중도 취소 하지 않는 경우 26.9월까지 자동 재등록 됩니다.
A48: 시간 | B48: 순번 | C48: 날 짜 | D48: 성함 | E48: 동 | F48: 호수 | G48: 서명 | H48: 취소날짜 | I48: 취소서명 | J48: 비고
A49: =A15 -> 06:30 ~ 07:20 | B49: 21
B50: 22
B51: 23
B52: 24
...

Sheet 2단지 성인수영-중급(화목06시30분이규상)
A1: =월!A1 & "월 " & LEFT(SUBSTITUTE(MID(CELL("filename",A1),FIND("]",CELL("filename",A1))+1,255),"2단지 ",""),FIND("(",SUBSTITUTE(MID(CELL("filename",A1),FIND("]",CELL("filename",A1))+1,255),"2단지 ",""))-1) & " " & MID(SUBSTITUTE(MID(CELL("filename",A1),FIND("]",CELL("filename",A1))+1,255),"2단지 ",""),MIN(FIND({0,1,2,3,4,5,6,7,8,9},MID(SUBSTITUTE(MID(CELL("filename",A1),FIND("]",CELL("filename",A1))+1,255),"2단지 ",""),FIND("(",SUBSTITUTE(MID(CELL("filename",A1),FIND("]",CELL("filename",A1))+1,255),"2단지 ",""))+1,255)&"0123456789"))+FIND("(",SUBSTITUTE(MID(CELL("filename",A1),FIND("]",CELL("filename",A1))+1,255),"2단지 ","")),IF(ISNUMBER(FIND("분",MID(SUBSTITUTE(MID(CELL("filename",A1),FIND("]",CELL("filename",A1))+1,255),"2단지 ",""),FIND("(",SUBSTITUTE(MID(CELL("filename",A1),FIND("]",CELL("filename",A1))+1,255),"2단지 ",""))+1,FIND(")",SUBSTITUTE(MID(CELL("filename",A1),FIND("]",CELL("filename",A1))+1,255),"2단지 ",""))-FIND("(",SUBSTITUTE(MID(CELL("filename",A1),FIND("]",CELL("filename",A1))+1,255),"2단지 ",""))-1))),FIND("분",MID(SUBSTITUTE(MID(CELL("filename",A1),FIND("]",CELL("filename",A1))+1,255),"2단지 ",""),FIND("(",SUBSTITUTE(MID(CELL("filename",A1),FIND("]",CELL("filename",A1))+1,255),"2단지 ",""))+1,255)),FIND("시",MID(SUBSTITUTE(MID(CELL("filename",A1),FIND("]",CELL("filename",A1))+1,255),"2단지 ",""),FIND("(",SUBSTITUTE(MID(CELL("filename",A1),FIND("]",CELL("filename",A1))+1,255),"2단지 ",""))+1,255)))-MIN(FIND({0,1,2,3,4,5,6,7,8,9},MID(SUBSTITUTE(MID(CELL("filename",A1),FIND("]",CELL("filename",A1))+1,255),"2단지 ",""),FIND("(",SUBSTITUTE(MID(CELL("filename",A1),FIND("]",CELL("filename",A1))+1,255),"2단지 ",""))+1,255)&"0123456789"))+1) & "(" & IF(LEN(LEFT(MID(SUBSTITUTE(MID(CELL("filename",A1),FIND("]",CELL("filename",A1))+1,255),"2단지 ",""),FIND("(",SUBSTITUTE(MID(CELL("filename",A1),FIND("]",CELL("filename",A1))+1,255),"2단지 ",""))+1,255),MIN(FIND({0,1,2,3,4,5,6,7,8,9},MID(SUBSTITUTE(MID(CELL("filename",A1),FIND("]",CELL("filename",A1))+1,255),"2단지 ",""),FIND("(",SUBSTITUTE(MID(CELL("filename",A1),FIND("]",CELL("filename",A1))+1,255),"2단지 ",""))+1,255)&"0123456789"))-1))=2, LEFT(MID(SUBSTITUTE(MID(CELL("filename",A1),FIND("]",CELL("filename",A1))+1,255),"2단지 ",""),FIND("(",SUBSTITUTE(MID(CELL("filename",A1),FIND("]",CELL("filename",A1))+1,255),"2단지 ",""))+1,2),1)&"/"&RIGHT(MID(SUBSTITUTE(MID(CELL("filename",A1),FIND("]",CELL("filename",A1))+1,255),"2단지 ",""),FIND("(",SUBSTITUTE(MID(CELL("filename",A1),FIND("]",CELL("filename",A1))+1,255),"2단지 ",""))+1,2),1), LEFT(MID(SUBSTITUTE(MID(CELL("filename",A1),FIND("]",CELL("filename",A1))+1,255),"2단지 ",""),FIND("(",SUBSTITUTE(MID(CELL("filename",A1),FIND("]",CELL("filename",A1))+1,255),"2단지 ",""))+1,255),MIN(FIND({0,1,2,3,4,5,6,7,8,9},MID(SUBSTITUTE(MID(CELL("filename",A1),FIND("]",CELL("filename",A1))+1,255),"2단지 ",""),FIND("(",SUBSTITUTE(MID(CELL("filename",A1),FIND("]",CELL("filename",A1))+1,255),"2단지 ",""))+1,255)&"0123456789"))-1)) & ") 신청서" -> 10월 성인수영-중급 06시30분(화/목) 신청서
G4: 강사: 이규상
G5: 요일: 화 , 목 / 시간: 06시30분
A6: 1. 강습료는 월 8회 50,000원이며, 당월 관리비에 자동 부과됩니다.
A7: 2. 강습은 매주 화,목(주2회) 이며 국/공휴일은 강습이 없습니다.
A8: 3. 각반 정원은 25명이며, 15명미만 접수시 폐강 할 수 있습니다.
A9: 4. 강습 대상은 성인이며, 청소년(중학생 이상)도 수강 가능합니다. 강습 양도는 불가합니다.
A10: 5. 중도 등록, 취소시 일할계산(월8회 기준)되어 강습료 부과되며 강습 취소 미신청 시 전액부과됩니다.(당일 취소는 불가)
A11: 6. 중도 취소/신청은 방문신청만 가능합니다.(장소: 2단지 안내데스크 방문)
A12: 7. 강습은 5개월 단위 재추첨하며, 강습 기간중 중도 취소 하지 않는 경우 26.9월까지 자동 재등록 됩니다.
A14: 시간 | B14: 순번 | C14: 날 짜 | D14: 성함 | E14: 동 | F14: 호수 | G14: 서명 | H14: 취소날짜 | I14: 취소서명 | J14: 비고
A15: 06:30 ~ 07:20 | B15: 1
B16: 2
B17: 3
B18: 4
B19: 5
B20: 6
B21: 7
B22: 8
B23: 9
B24: 10
B25: 11
B26: 12
B27: 13
... B34: 20
A35: =A1 -> 10월 성인수영-중급 06시30분(화/목) 신청서
G38: =G4 -> 강사: 이규상
G39: =G5 -> 요일: 화 , 목 / 시간: 06시30분
A40: =A6 -> 1. 강습료는 월 8회 50,000원이며, 당월 관리비에 자동 부과됩니다.
A41: =A7 -> 2. 강습은 매주 화,목(주2회) 이며 국/공휴일은 강습이 없습니다.
A42: =A8 -> 3. 각반 정원은 25명이며, 15명미만 접수시 폐강 할 수 있습니다.
A43: =A9 -> 4. 강습 대상은 성인이며, 청소년(중학생 이상)도 수강 가능합니다. 강습 양도는 불가합니다.
A44: =A10 -> 5. 중도 등록, 취소시 일할계산(월8회 기준)되어 강습료 부과되며 강습 취소 미신청 시 전액부과됩니다.(당일 취소는 불가)
A45: =A11 -> 6. 중도 취소/신청은 방문신청만 가능합니다.(장소: 2단지 안내데스크 방문)
A46: =A12 -> 7. 강습은 5개월 단위 재추첨하며, 강습 기간중 중도 취소 하지 않는 경우 26.9월까지 자동 재등록 됩니다.
A48: 시간 | B48: 순번 | C48: 날 짜 | D48: 성함 | E48: 동 | F48: 호수 | G48: 서명 | H48: 취소날짜 | I48: 취소서명 | J48: 비고
A49: =A15 -> 06:30 ~ 07:20 | B49: 21
B50: 22
B51: 23
B52: 24
...

Sheet 2단지 성인수영-상급(화목06시30분박범호)
A1: =월!A1 & "월 " & LEFT(SUBSTITUTE(MID(CELL("filename",A1),FIND("]",CELL("filename",A1))+1,255),"2단지 ",""),FIND("(",SUBSTITUTE(MID(CELL("filename",A1),FIND("]",CELL("filename",A1))+1,255),"2단지 ",""))-1) & " " & MID(SUBSTITUTE(MID(CELL("filename",A1),FIND("]",CELL("filename",A1))+1,255),"2단지 ",""),MIN(FIND({0,1,2,3,4,5,6,7,8,9},MID(SUBSTITUTE(MID(CELL("filename",A1),FIND("]",CELL("filename",A1))+1,255),"2단지 ",""),FIND("(",SUBSTITUTE(MID(CELL("filename",A1),FIND("]",CELL("filename",A1))+1,255),"2단지 ",""))+1,255)&"0123456789"))+FIND("(",SUBSTITUTE(MID(CELL("filename",A1),FIND("]",CELL("filename",A1))+1,255),"2단지 ","")),IF(ISNUMBER(FIND("분",MID(SUBSTITUTE(MID(CELL("filename",A1),FIND("]",CELL("filename",A1))+1,255),"2단지 ",""),FIND("(",SUBSTITUTE(MID(CELL("filename",A1),FIND("]",CELL("filename",A1))+1,255),"2단지 ",""))+1,FIND(")",SUBSTITUTE(MID(CELL("filename",A1),FIND("]",CELL("filename",A1))+1,255),"2단지 ",""))-FIND("(",SUBSTITUTE(MID(CELL("filename",A1),FIND("]",CELL("filename",A1))+1,255),"2단지 ",""))-1))),FIND("분",MID(SUBSTITUTE(MID(CELL("filename",A1),FIND("]",CELL("filename",A1))+1,255),"2단지 ",""),FIND("(",SUBSTITUTE(MID(CELL("filename",A1),FIND("]",CELL("filename",A1))+1,255),"2단지 ",""))+1,255)),FIND("시",MID(SUBSTITUTE(MID(CELL("filename",A1),FIND("]",CELL("filename",A1))+1,255),"2단지 ",""),FIND("(",SUBSTITUTE(MID(CELL("filename",A1),FIND("]",CELL("filename",A1))+1,255),"2단지 ",""))+1,255)))-MIN(FIND({0,1,2,3,4,5,6,7,8,9},MID(SUBSTITUTE(MID(CELL("filename",A1),FIND("]",CELL("filename",A1))+1,255),"2단지 ",""),FIND("(",SUBSTITUTE(MID(CELL("filename",A1),FIND("]",CELL("filename",A1))+1,255),"2단지 ",""))+1,255)&"0123456789"))+1) & "(" & IF(LEN(LEFT(MID(SUBSTITUTE(MID(CELL("filename",A1),FIND("]",CELL("filename",A1))+1,255),"2단지 ",""),FIND("(",SUBSTITUTE(MID(CELL("filename",A1),FIND("]",CELL("filename",A1))+1,255),"2단지 ",""))+1,255),MIN(FIND({0,1,2,3,4,5,6,7,8,9},MID(SUBSTITUTE(MID(CELL("filename",A1),FIND("]",CELL("filename",A1))+1,255),"2단지 ",""),FIND("(",SUBSTITUTE(MID(CELL("filename",A1),FIND("]",CELL("filename",A1))+1,255),"2단지 ",""))+1,255)&"0123456789"))-1))=2, LEFT(MID(SUBSTITUTE(MID(CELL("filename",A1),FIND("]",CELL("filename",A1))+1,255),"2단지 ",""),FIND("(",SUBSTITUTE(MID(CELL("filename",A1),FIND("]",CELL("filename",A1))+1,255),"2단지 ",""))+1,2),1)&"/"&RIGHT(MID(SUBSTITUTE(MID(CELL("filename",A1),FIND("]",CELL("filename",A1))+1,255),"2단지 ",""),FIND("(",SUBSTITUTE(MID(CELL("filename",A1),FIND("]",CELL("filename",A1))+1,255),"2단지 ",""))+1,2),1), LEFT(MID(SUBSTITUTE(MID(CELL("filename",A1),FIND("]",CELL("filename",A1))+1,255),"2단지 ",""),FIND("(",SUBSTITUTE(MID(CELL("filename",A1),FIND("]",CELL("filename",A1))+1,255),"2단지 ",""))+1,255),MIN(FIND({0,1,2,3,4,5,6,7,8,9},MID(SUBSTITUTE(MID(CELL("filename",A1),FIND("]",CELL("filename",A1))+1,255),"2단지 ",""),FIND("(",SUBSTITUTE(MID(CELL("filename",A1),FIND("]",CELL("filename",A1))+1,255),"2단지 ",""))+1,255)&"0123456789"))-1)) & ") 신청서" -> 10월 성인수영-상급 06시30분(화/목) 신청서
G4: 강사: 박범호
G5: 요일: 화 , 목 / 시간: 06시30분
A6: 1. 강습료는 월 8회 50,000원이며, 당월 관리비에 자동 부과됩니다.
A7: 2. 강습은 매주 화,목(주2회) 이며 국/공휴일은 강습이 없습니다.
A8: 3. 각반 정원은 25명이며, 15명미만 접수시 폐강 할 수 있습니다.
A9: 4. 강습 대상은 성인이며, 청소년(중학생 이상)도 수강 가능합니다. 강습 양도는 불가합니다.
A10: 5. 중도 등록, 취소시 일할계산(월8회 기준)되어 강습료 부과되며 강습 취소 미신청 시 전액부과됩니다.(당일 취소는 불가)
A11: 6. 중도 취소/신청은 방문신청만 가능합니다.(장소: 2단지 안내데스크 방문)
A12: 7. 강습은 5개월 단위 재추첨하며, 강습 기간중 중도 취소 하지 않는 경우 26.9월까지 자동 재등록 됩니다.
A14: 시간 | B14: 순번 | C14: 날 짜 | D14: 성함 | E14: 동 | F14: 호수 | G14: 서명 | H14: 취소날짜 | I14: 취소서명 | J14: 비고
A15: 06:30 ~ 07:20 | B15: 1
B16: 2
B17: 3
B18: 4
B19: 5
B20: 6
B21: 7
B22: 8
B23: 9
B24: 10
B25: 11
B26: 12
B27: 13
... B34: 20
A35: =A1 -> 10월 성인수영-상급 06시30분(화/목) 신청서
G38: =G4 -> 강사: 박범호
G39: =G5 -> 요일: 화 , 목 / 시간: 06시30분
A40: =A6 -> 1. 강습료는 월 8회 50,000원이며, 당월 관리비에 자동 부과됩니다.
A41: =A7 -> 2. 강습은 매주 화,목(주2회) 이며 국/공휴일은 강습이 없습니다.
A42: =A8 -> 3. 각반 정원은 25명이며, 15명미만 접수시 폐강 할 수 있습니다.
A43: =A9 -> 4. 강습 대상은 성인이며, 청소년(중학생 이상)도 수강 가능합니다. 강습 양도는 불가합니다.
A44: =A10 -> 5. 중도 등록, 취소시 일할계산(월8회 기준)되어 강습료 부과되며 강습 취소 미신청 시 전액부과됩니다.(당일 취소는 불가)
A45: =A11 -> 6. 중도 취소/신청은 방문신청만 가능합니다.(장소: 2단지 안내데스크 방문)
A46: =A12 -> 7. 강습은 5개월 단위 재추첨하며, 강습 기간중 중도 취소 하지 않는 경우 26.9월까지 자동 재등록 됩니다.
A48: 시간 | B48: 순번 | C48: 날 짜 | D48: 성함 | E48: 동 | F48: 호수 | G48: 서명 | H48: 취소날짜 | I48: 취소서명 | J48: 비고
A49: =A15 -> 06:30 ~ 07:20 | B49: 21
B50: 22
B51: 23
B52: 24
...

Sheet 2단지 성인수영-기초(화목07시30분손태환)
A1: =월!A1 & "월 " & LEFT(SUBSTITUTE(MID(CELL("filename",A1),FIND("]",CELL("filename",A1))+1,255),"2단지 ",""),FIND("(",SUBSTITUTE(MID(CELL("filename",A1),FIND("]",CELL("filename",A1))+1,255),"2단지 ",""))-1) & " " & MID(SUBSTITUTE(MID(CELL("filename",A1),FIND("]",CELL("filename",A1))+1,255),"2단지 ",""),MIN(FIND({0,1,2,3,4,5,6,7,8,9},MID(SUBSTITUTE(MID(CELL("filename",A1),FIND("]",CELL("filename",A1))+1,255),"2단지 ",""),FIND("(",SUBSTITUTE(MID(CELL("filename",A1),FIND("]",CELL("filename",A1))+1,255),"2단지 ",""))+1,255)&"0123456789"))+FIND("(",SUBSTITUTE(MID(CELL("filename",A1),FIND("]",CELL("filename",A1))+1,255),"2단지 ","")),IF(ISNUMBER(FIND("분",MID(SUBSTITUTE(MID(CELL("filename",A1),FIND("]",CELL("filename",A1))+1,255),"2단지 ",""),FIND("(",SUBSTITUTE(MID(CELL("filename",A1),FIND("]",CELL("filename",A1))+1,255),"2단지 ",""))+1,FIND(")",SUBSTITUTE(MID(CELL("filename",A1),FIND("]",CELL("filename",A1))+1,255),"2단지 ",""))-FIND("(",SUBSTITUTE(MID(CELL("filename",A1),FIND("]",CELL("filename",A1))+1,255),"2단지 ",""))-1))),FIND("분",MID(SUBSTITUTE(MID(CELL("filename",A1),FIND("]",CELL("filename",A1))+1,255),"2단지 ",""),FIND("(",SUBSTITUTE(MID(CELL("filename",A1),FIND("]",CELL("filename",A1))+1,255),"2단지 ",""))+1,255)),FIND("시",MID(SUBSTITUTE(MID(CELL("filename",A1),FIND("]",CELL("filename",A1))+1,255),"2단지 ",""),FIND("(",SUBSTITUTE(MID(CELL("filename",A1),FIND("]",CELL("filename",A1))+1,255),"2단지 ",""))+1,255)))-MIN(FIND({0,1,2,3,4,5,6,7,8,9},MID(SUBSTITUTE(MID(CELL("filename",A1),FIND("]",CELL("filename",A1))+1,255),"2단지 ",""),FIND("(",SUBSTITUTE(MID(CELL("filename",A1),FIND("]",CELL("filename",A1))+1,255),"2단지 ",""))+1,255)&"0123456789"))+1) & "(" & IF(LEN(LEFT(MID(SUBSTITUTE(MID(CELL("filename",A1),FIND("]",CELL("filename",A1))+1,255),"2단지 ",""),FIND("(",SUBSTITUTE(MID(CELL("filename",A1),FIND("]",CELL("filename",A1))+1,255),"2단지 ",""))+1,255),MIN(FIND({0,1,2,3,4,5,6,7,8,9},MID(SUBSTITUTE(MID(CELL("filename",A1),FIND("]",CELL("filename",A1))+1,255),"2단지 ",""),FIND("(",SUBSTITUTE(MID(CELL("filename",A1),FIND("]",CELL("filename",A1))+1,255),"2단지 ",""))+1,255)&"0123456789"))-1))=2, LEFT(MID(SUBSTITUTE(MID(CELL("filename",A1),FIND("]",CELL("filename",A1))+1,255),"2단지 ",""),FIND("(",SUBSTITUTE(MID(CELL("filename",A1),FIND("]",CELL("filename",A1))+1,255),"2단지 ",""))+1,2),1)&"/"&RIGHT(MID(SUBSTITUTE(MID(CELL("filename",A1),FIND("]",CELL("filename",A1))+1,255),"2단지 ",""),FIND("(",SUBSTITUTE(MID(CELL("filename",A1),FIND("]",CELL("filename",A1))+1,255),"2단지 ",""))+1,2),1), LEFT(MID(SUBSTITUTE(MID(CELL("filename",A1),FIND("]",CELL("filename",A1))+1,255),"2단지 ",""),FIND("(",SUBSTITUTE(MID(CELL("filename",A1),FIND("]",CELL("filename",A1))+1,255),"2단지 ",""))+1,255),MIN(FIND({0,1,2,3,4,5,6,7,8,9},MID(SUBSTITUTE(MID(CELL("filename",A1),FIND("]",CELL("filename",A1))+1,255),"2단지 ",""),FIND("(",SUBSTITUTE(MID(CELL("filename",A1),FIND("]",CELL("filename",A1))+1,255),"2단지 ",""))+1,255)&"0123456789"))-1)) & ") 신청서" -> 10월 성인수영-기초 07시30분(화/목) 신청서
G4: 강사: 손태환
G5: 요일: 화 , 목 / 시간: 07시30분
A6: 1. 강습료는 월 8회 50,000원이며, 당월 관리비에 자동 부과됩니다.
A7: 2. 강습은 매주 화,목(주2회) 이며 국/공휴일은 강습이 없습니다.
A8: 3. 각반 정원은 25명이며, 15명미만 접수시 폐강 할 수 있습니다.
A9: 4. 강습 대상은 성인이며, 청소년(중학생 이상)도 수강 가능합니다. 강습 양도는 불가합니다.
A10: 5. 중도 등록, 취소시 일할계산(월8회 기준)되어 강습료 부과되며 강습 취소 미신청 시 전액부과됩니다.(당일 취소는 불가)
A11: 6. 중도 취소/신청은 방문신청만 가능합니다.(장소: 2단지 안내데스크 방문)
A12: 7. 강습은 5개월 단위 재추첨하며, 강습 기간중 중도 취소 하지 않는 경우 26.9월까지 자동 재등록 됩니다.
A14: 시간 | B14: 순번 | C14: 날 짜 | D14: 성함 | E14: 동 | F14: 호수 | G14: 서명 | H14: 취소날짜 | I14: 취소서명 | J14: 비고
A15: 07:30 ~ 08:20 | B15: 1
B16: 2
B17: 3
B18: 4
B19: 5
B20: 6
B21: 7
B22: 8
B23: 9
B24: 10
B25: 11
B26: 12
B27: 13
... B34: 20
A35: =A1 -> 10월 성인수영-기초 07시30분(화/목) 신청서
G38: =G4 -> 강사: 손태환
G39: =G5 -> 요일: 화 , 목 / 시간: 07시30분
A40: =A6 -> 1. 강습료는 월 8회 50,000원이며, 당월 관리비에 자동 부과됩니다.
A41: =A7 -> 2. 강습은 매주 화,목(주2회) 이며 국/공휴일은 강습이 없습니다.
A42: =A8 -> 3. 각반 정원은 25명이며, 15명미만 접수시 폐강 할 수 있습니다.
A43: =A9 -> 4. 강습 대상은 성인이며, 청소년(중학생 이상)도 수강 가능합니다. 강습 양도는 불가합니다.
A44: =A10 -> 5. 중도 등록, 취소시 일할계산(월8회 기준)되어 강습료 부과되며 강습 취소 미신청 시 전액부과됩니다.(당일 취소는 불가)
A45: =A11 -> 6. 중도 취소/신청은 방문신청만 가능합니다.(장소: 2단지 안내데스크 방문)
A46: =A12 -> 7. 강습은 5개월 단위 재추첨하며, 강습 기간중 중도 취소 하지 않는 경우 26.9월까지 자동 재등록 됩니다.
A48: 시간 | B48: 순번 | C48: 날 짜 | D48: 성함 | E48: 동 | F48: 호수 | G48: 서명 | H48: 취소날짜 | I48: 취소서명 | J48: 비고
A49: =A15 -> 07:30 ~ 08:20 | B49: 21
B50: 22
B51: 23
B52: 24
...

Sheet 2단지 성인수영-초급(화목07시30분김소운)
A1: =월!A1 & "월 " & LEFT(SUBSTITUTE(MID(CELL("filename",A1),FIND("]",CELL("filename",A1))+1,255),"2단지 ",""),FIND("(",SUBSTITUTE(MID(CELL("filename",A1),FIND("]",CELL("filename",A1))+1,255),"2단지 ",""))-1) & " " & MID(SUBSTITUTE(MID(CELL("filename",A1),FIND("]",CELL("filename",A1))+1,255),"2단지 ",""),MIN(FIND({0,1,2,3,4,5,6,7,8,9},MID(SUBSTITUTE(MID(CELL("filename",A1),FIND("]",CELL("filename",A1))+1,255),"2단지 ",""),FIND("(",SUBSTITUTE(MID(CELL("filename",A1),FIND("]",CELL("filename",A1))+1,255),"2단지 ",""))+1,255)&"0123456789"))+FIND("(",SUBSTITUTE(MID(CELL("filename",A1),FIND("]",CELL("filename",A1))+1,255),"2단지 ","")),IF(ISNUMBER(FIND("분",MID(SUBSTITUTE(MID(CELL("filename",A1),FIND("]",CELL("filename",A1))+1,255),"2단지 ",""),FIND("(",SUBSTITUTE(MID(CELL("filename",A1),FIND("]",CELL("filename",A1))+1,255),"2단지 ",""))+1,FIND(")",SUBSTITUTE(MID(CELL("filename",A1),FIND("]",CELL("filename",A1))+1,255),"2단지 ",""))-FIND("(",SUBSTITUTE(MID(CELL("filename",A1),FIND("]",CELL("filename",A1))+1,255),"2단지 ",""))-1))),FIND("분",MID(SUBSTITUTE(MID(CELL("filename",A1),FIND("]",CELL("filename",A1))+1,255),"2단지 ",""),FIND("(",SUBSTITUTE(MID(CELL("filename",A1),FIND("]",CELL("filename",A1))+1,255),"2단지 ",""))+1,255)),FIND("시",MID(SUBSTITUTE(MID(CELL("filename",A1),FIND("]",CELL("filename",A1))+1,255),"2단지 ",""),FIND("(",SUBSTITUTE(MID(CELL("filename",A1),FIND("]",CELL("filename",A1))+1,255),"2단지 ",""))+1,255)))-MIN(FIND({0,1,2,3,4,5,6,7,8,9},MID(SUBSTITUTE(MID(CELL("filename",A1),FIND("]",CELL("filename",A1))+1,255),"2단지 ",""),FIND("(",SUBSTITUTE(MID(CELL("filename",A1),FIND("]",CELL("filename",A1))+1,255),"2단지 ",""))+1,255)&"0123456789"))+1) & "(" & IF(LEN(LEFT(MID(SUBSTITUTE(MID(CELL("filename",A1),FIND("]",CELL("filename",A1))+1,255),"2단지 ",""),FIND("(",SUBSTITUTE(MID(CELL("filename",A1),FIND("]",CELL("filename",A1))+1,255),"2단지 ",""))+1,255),MIN(FIND({0,1,2,3,4,5,6,7,8,9},MID(SUBSTITUTE(MID(CELL("filename",A1),FIND("]",CELL("filename",A1))+1,255),"2단지 ",""),FIND("(",SUBSTITUTE(MID(CELL("filename",A1),FIND("]",CELL("filename",A1))+1,255),"2단지 ",""))+1,255)&"0123456789"))-1))=2, LEFT(MID(SUBSTITUTE(MID(CELL("filename",A1),FIND("]",CELL("filename",A1))+1,255),"2단지 ",""),FIND("(",SUBSTITUTE(MID(CELL("filename",A1),FIND("]",CELL("filename",A1))+1,255),"2단지 ",""))+1,2),1)&"/"&RIGHT(MID(SUBSTITUTE(MID(CELL("filename",A1),FIND("]",CELL("filename",A1))+1,255),"2단지 ",""),FIND("(",SUBSTITUTE(MID(CELL("filename",A1),FIND("]",CELL("filename",A1))+1,255),"2단지 ",""))+1,2),1), LEFT(MID(SUBSTITUTE(MID(CELL("filename",A1),FIND("]",CELL("filename",A1))+1,255),"2단지 ",""),FIND("(",SUBSTITUTE(MID(CELL("filename",A1),FIND("]",CELL("filename",A1))+1,255),"2단지 ",""))+1,255),MIN(FIND({0,1,2,3,4,5,6,7,8,9},MID(SUBSTITUTE(MID(CELL("filename",A1),FIND("]",CELL("filename",A1))+1,255),"2단지 ",""),FIND("(",SUBSTITUTE(MID(CELL("filename",A1),FIND("]",CELL("filename",A1))+1,255),"2단지 ",""))+1,255)&"0123456789"))-1)) & ") 신청서" -> 10월 성인수영-초급 07시30분(화/목) 신청서
G4: 강사: 김소운
G5: 요일: 화 , 목 / 시간: 07시30분
A6: 1. 강습료는 월 8회 50,000원이며, 당월 관리비에 자동 부과됩니다.
A7: 2. 강습은 매주 화,목(주2회) 이며 국/공휴일은 강습이 없습니다.
A8: 3. 각반 정원은 25명이며, 15명미만 접수시 폐강 할 수 있습니다.
A9: 4. 강습 대상은 성인이며, 청소년(중학생 이상)도 수강 가능합니다. 강습 양도는 불가합니다.
A10: 5. 중도 등록, 취소시 일할계산(월8회 기준)되어 강습료 부과되며 강습 취소 미신청 시 전액부과됩니다.(당일 취소는 불가)
A11: 6. 중도 취소/신청은 방문신청만 가능합니다.(장소: 2단지 안내데스크 방문)
A12: 7. 강습은 5개월 단위 재추첨하며, 강습 기간중 중도 취소 하지 않는 경우 26.9월까지 자동 재등록 됩니다.
A14: 시간 | B14: 순번 | C14: 날 짜 | D14: 성함 | E14: 동 | F14: 호수 | G14: 서명 | H14: 취소날짜 | I14: 취소서명 | J14: 비고
A15: 07:30 ~ 08:20 | B15: 1
B16: 2
B17: 3
B18: 4
B19: 5
B20: 6
B21: 7
B22: 8
B23: 9
B24: 10
B25: 11
B26: 12
B27: 13
... B34: 20
A35: =A1 -> 10월 성인수영-초급 07시30분(화/목) 신청서
G38: =G4 -> 강사: 김소운
G39: =G5 -> 요일: 화 , 목 / 시간: 07시30분
A40: =A6 -> 1. 강습료는 월 8회 50,000원이며, 당월 관리비에 자동 부과됩니다.
A41: =A7 -> 2. 강습은 매주 화,목(주2회) 이며 국/공휴일은 강습이 없습니다.
A42: =A8 -> 3. 각반 정원은 25명이며, 15명미만 접수시 폐강 할 수 있습니다.
A43: =A9 -> 4. 강습 대상은 성인이며, 청소년(중학생 이상)도 수강 가능합니다. 강습 양도는 불가합니다.
A44: =A10 -> 5. 중도 등록, 취소시 일할계산(월8회 기준)되어 강습료 부과되며 강습 취소 미신청 시 전액부과됩니다.(당일 취소는 불가)
A45: =A11 -> 6. 중도 취소/신청은 방문신청만 가능합니다.(장소: 2단지 안내데스크 방문)
A46: =A12 -> 7. 강습은 5개월 단위 재추첨하며, 강습 기간중 중도 취소 하지 않는 경우 26.9월까지 자동 재등록 됩니다.
A48: 시간 | B48: 순번 | C48: 날 짜 | D48: 성함 | E48: 동 | F48: 호수 | G48: 서명 | H48: 취소날짜 | I48: 취소서명 | J48: 비고
A49: =A15 -> 07:30 ~ 08:20 | B49: 21
B50: 22
B51: 23
B52: 24
...

Sheet 2단지 성인수영-중급(화목07시30분이규상)
A1: =월!A1 & "월 " & LEFT(SUBSTITUTE(MID(CELL("filename",A1),FIND("]",CELL("filename",A1))+1,255),"2단지 ",""),FIND("(",SUBSTITUTE(MID(CELL("filename",A1),FIND("]",CELL("filename",A1))+1,255),"2단지 ",""))-1) & " " & MID(SUBSTITUTE(MID(CELL("filename",A1),FIND("]",CELL("filename",A1))+1,255),"2단지 ",""),MIN(FIND({0,1,2,3,4,5,6,7,8,9},MID(SUBSTITUTE(MID(CELL("filename",A1),FIND("]",CELL("filename",A1))+1,255),"2단지 ",""),FIND("(",SUBSTITUTE(MID(CELL("filename",A1),FIND("]",CELL("filename",A1))+1,255),"2단지 ",""))+1,255)&"0123456789"))+FIND("(",SUBSTITUTE(MID(CELL("filename",A1),FIND("]",CELL("filename",A1))+1,255),"2단지 ","")),IF(ISNUMBER(FIND("분",MID(SUBSTITUTE(MID(CELL("filename",A1),FIND("]",CELL("filename",A1))+1,255),"2단지 ",""),FIND("(",SUBSTITUTE(MID(CELL("filename",A1),FIND("]",CELL("filename",A1))+1,255),"2단지 ",""))+1,FIND(")",SUBSTITUTE(MID(CELL("filename",A1),FIND("]",CELL("filename",A1))+1,255),"2단지 ",""))-FIND("(",SUBSTITUTE(MID(CELL("filename",A1),FIND("]",CELL("filename",A1))+1,255),"2단지 ",""))-1))),FIND("분",MID(SUBSTITUTE(MID(CELL("filename",A1),FIND("]",CELL("filename",A1))+1,255),"2단지 ",""),FIND("(",SUBSTITUTE(MID(CELL("filename",A1),FIND("]",CELL("filename",A1))+1,255),"2단지 ",""))+1,255)),FIND("시",MID(SUBSTITUTE(MID(CELL("filename",A1),FIND("]",CELL("filename",A1))+1,255),"2단지 ",""),FIND("(",SUBSTITUTE(MID(CELL("filename",A1),FIND("]",CELL("filename",A1))+1,255),"2단지 ",""))+1,255)))-MIN(FIND({0,1,2,3,4,5,6,7,8,9},MID(SUBSTITUTE(MID(CELL("filename",A1),FIND("]",CELL("filename",A1))+1,255),"2단지 ",""),FIND("(",SUBSTITUTE(MID(CELL("filename",A1),FIND("]",CELL("filename",A1))+1,255),"2단지 ",""))+1,255)&"0123456789"))+1) & "(" & IF(LEN(LEFT(MID(SUBSTITUTE(MID(CELL("filename",A1),FIND("]",CELL("filename",A1))+1,255),"2단지 ",""),FIND("(",SUBSTITUTE(MID(CELL("filename",A1),FIND("]",CELL("filename",A1))+1,255),"2단지 ",""))+1,255),MIN(FIND({0,1,2,3,4,5,6,7,8,9},MID(SUBSTITUTE(MID(CELL("filename",A1),FIND("]",CELL("filename",A1))+1,255),"2단지 ",""),FIND("(",SUBSTITUTE(MID(CELL("filename",A1),FIND("]",CELL("filename",A1))+1,255),"2단지 ",""))+1,255)&"0123456789"))-1))=2, LEFT(MID(SUBSTITUTE(MID(CELL("filename",A1),FIND("]",CELL("filename",A1))+1,255),"2단지 ",""),FIND("(",SUBSTITUTE(MID(CELL("filename",A1),FIND("]",CELL("filename",A1))+1,255),"2단지 ",""))+1,2),1)&"/"&RIGHT(MID(SUBSTITUTE(MID(CELL("filename",A1),FIND("]",CELL("filename",A1))+1,255),"2단지 ",""),FIND("(",SUBSTITUTE(MID(CELL("filename",A1),FIND("]",CELL("filename",A1))+1,255),"2단지 ",""))+1,2),1), LEFT(MID(SUBSTITUTE(MID(CELL("filename",A1),FIND("]",CELL("filename",A1))+1,255),"2단지 ",""),FIND("(",SUBSTITUTE(MID(CELL("filename",A1),FIND("]",CELL("filename",A1))+1,255),"2단지 ",""))+1,255),MIN(FIND({0,1,2,3,4,5,6,7,8,9},MID(SUBSTITUTE(MID(CELL("filename",A1),FIND("]",CELL("filename",A1))+1,255),"2단지 ",""),FIND("(",SUBSTITUTE(MID(CELL("filename",A1),FIND("]",CELL("filename",A1))+1,255),"2단지 ",""))+1,255)&"0123456789"))-1)) & ") 신청서" -> 10월 성인수영-중급 07시30분(화/목) 신청서
G4: 강사: 이규상
G5: 요일: 화 , 목 / 시간: 07시30분
A6: 1. 강습료는 월 8회 50,000원이며, 당월 관리비에 자동 부과됩니다.
A7: 2. 강습은 매주 화,목(주2회) 이며 국/공휴일은 강습이 없습니다.
A8: 3. 각반 정원은 25명이며, 15명미만 접수시 폐강 할 수 있습니다.
A9: 4. 강습 대상은 성인이며, 청소년(중학생 이상)도 수강 가능합니다. 강습 양도는 불가합니다.
A10: 5. 중도 등록, 취소시 일할계산(월8회 기준)되어 강습료 부과되며 강습 취소 미신청 시 전액부과됩니다.(당일 취소는 불가)
A11: 6. 중도 취소/신청은 방문신청만 가능합니다.(장소: 2단지 안내데스크 방문)
A12: 7. 강습은 5개월 단위 재추첨하며, 강습 기간중 중도 취소 하지 않는 경우 26.9월까지 자동 재등록 됩니다.
A14: 시간 | B14: 순번 | C14: 날 짜 | D14: 성함 | E14: 동 | F14: 호수 | G14: 서명 | H14: 취소날짜 | I14: 취소서명 | J14: 비고
A15: 07:30 ~ 08:20 | B15: 1
B16: 2
B17: 3
B18: 4
B19: 5
B20: 6
B21: 7
B22: 8
B23: 9
B24: 10
B25: 11
B26: 12
B27: 13
... B34: 20
A35: =A1 -> 10월 성인수영-중급 07시30분(화/목) 신청서
G38: =G4 -> 강사: 이규상
G39: =G5 -> 요일: 화 , 목 / 시간: 07시30분
A40: =A6 -> 1. 강습료는 월 8회 50,000원이며, 당월 관리비에 자동 부과됩니다.
A41: =A7 -> 2. 강습은 매주 화,목(주2회) 이며 국/공휴일은 강습이 없습니다.
A42: =A8 -> 3. 각반 정원은 25명이며, 15명미만 접수시 폐강 할 수 있습니다.
A43: =A9 -> 4. 강습 대상은 성인이며, 청소년(중학생 이상)도 수강 가능합니다. 강습 양도는 불가합니다.
A44: =A10 -> 5. 중도 등록, 취소시 일할계산(월8회 기준)되어 강습료 부과되며 강습 취소 미신청 시 전액부과됩니다.(당일 취소는 불가)
A45: =A11 -> 6. 중도 취소/신청은 방문신청만 가능합니다.(장소: 2단지 안내데스크 방문)
A46: =A12 -> 7. 강습은 5개월 단위 재추첨하며, 강습 기간중 중도 취소 하지 않는 경우 26.9월까지 자동 재등록 됩니다.
A48: 시간 | B48: 순번 | C48: 날 짜 | D48: 성함 | E48: 동 | F48: 호수 | G48: 서명 | H48: 취소날짜 | I48: 취소서명 | J48: 비고
A49: =A15 -> 07:30 ~ 08:20 | B49: 21
B50: 22
B51: 23
B52: 24
...

Sheet 2단지 성인수영-상급(화목07시30분박범호)
A1: =월!A1 & "월 " & LEFT(SUBSTITUTE(MID(CELL("filename",A1),FIND("]",CELL("filename",A1))+1,255),"2단지 ",""),FIND("(",SUBSTITUTE(MID(CELL("filename",A1),FIND("]",CELL("filename",A1))+1,255),"2단지 ",""))-1) & " " & MID(SUBSTITUTE(MID(CELL("filename",A1),FIND("]",CELL("filename",A1))+1,255),"2단지 ",""),MIN(FIND({0,1,2,3,4,5,6,7,8,9},MID(SUBSTITUTE(MID(CELL("filename",A1),FIND("]",CELL("filename",A1))+1,255),"2단지 ",""),FIND("(",SUBSTITUTE(MID(CELL("filename",A1),FIND("]",CELL("filename",A1))+1,255),"2단지 ",""))+1,255)&"0123456789"))+FIND("(",SUBSTITUTE(MID(CELL("filename",A1),FIND("]",CELL("filename",A1))+1,255),"2단지 ","")),IF(ISNUMBER(FIND("분",MID(SUBSTITUTE(MID(CELL("filename",A1),FIND("]",CELL("filename",A1))+1,255),"2단지 ",""),FIND("(",SUBSTITUTE(MID(CELL("filename",A1),FIND("]",CELL("filename",A1))+1,255),"2단지 ",""))+1,FIND(")",SUBSTITUTE(MID(CELL("filename",A1),FIND("]",CELL("filename",A1))+1,255),"2단지 ",""))-FIND("(",SUBSTITUTE(MID(CELL("filename",A1),FIND("]",CELL("filename",A1))+1,255),"2단지 ",""))-1))),FIND("분",MID(SUBSTITUTE(MID(CELL("filename",A1),FIND("]",CELL("filename",A1))+1,255),"2단지 ",""),FIND("(",SUBSTITUTE(MID(CELL("filename",A1),FIND("]",CELL("filename",A1))+1,255),"2단지 ",""))+1,255)),FIND("시",MID(SUBSTITUTE(MID(CELL("filename",A1),FIND("]",CELL("filename",A1))+1,255),"2단지 ",""),FIND("(",SUBSTITUTE(MID(CELL("filename",A1),FIND("]",CELL("filename",A1))+1,255),"2단지 ",""))+1,255)))-MIN(FIND({0,1,2,3,4,5,6,7,8,9},MID(SUBSTITUTE(MID(CELL("filename",A1),FIND("]",CELL("filename",A1))+1,255),"2단지 ",""),FIND("(",SUBSTITUTE(MID(CELL("filename",A1),FIND("]",CELL("filename",A1))+1,255),"2단지 ",""))+1,255)&"0123456789"))+1) & "(" & IF(LEN(LEFT(MID(SUBSTITUTE(MID(CELL("filename",A1),FIND("]",CELL("filename",A1))+1,255),"2단지 ",""),FIND("(",SUBSTITUTE(MID(CELL("filename",A1),FIND("]",CELL("filename",A1))+1,255),"2단지 ",""))+1,255),MIN(FIND({0,1,2,3,4,5,6,7,8,9},MID(SUBSTITUTE(MID(CELL("filename",A1),FIND("]",CELL("filename",A1))+1,255),"2단지 ",""),FIND("(",SUBSTITUTE(MID(CELL("filename",A1),FIND("]",CELL("filename",A1))+1,255),"2단지 ",""))+1,255)&"0123456789"))-1))=2, LEFT(MID(SUBSTITUTE(MID(CELL("filename",A1),FIND("]",CELL("filename",A1))+1,255),"2단지 ",""),FIND("(",SUBSTITUTE(MID(CELL("filename",A1),FIND("]",CELL("filename",A1))+1,255),"2단지 ",""))+1,2),1)&"/"&RIGHT(MID(SUBSTITUTE(MID(CELL("filename",A1),FIND("]",CELL("filename",A1))+1,255),"2단지 ",""),FIND("(",SUBSTITUTE(MID(CELL("filename",A1),FIND("]",CELL("filename",A1))+1,255),"2단지 ",""))+1,2),1), LEFT(MID(SUBSTITUTE(MID(CELL("filename",A1),FIND("]",CELL("filename",A1))+1,255),"2단지 ",""),FIND("(",SUBSTITUTE(MID(CELL("filename",A1),FIND("]",CELL("filename",A1))+1,255),"2단지 ",""))+1,255),MIN(FIND({0,1,2,3,4,5,6,7,8,9},MID(SUBSTITUTE(MID(CELL("filename",A1),FIND("]",CELL("filename",A1))+1,255),"2단지 ",""),FIND("(",SUBSTITUTE(MID(CELL("filename",A1),FIND("]",CELL("filename",A1))+1,255),"2단지 ",""))+1,255)&"0123456789"))-1)) & ") 신청서" -> 10월 성인수영-상급 07시30분(화/목) 신청서
G4: 강사: 박범호
G5: 요일: 화 , 목 / 시간: 07시30분
A6: 1. 강습료는 월 8회 50,000원이며, 당월 관리비에 자동 부과됩니다.
A7: 2. 강습은 매주 화,목(주2회) 이며 국/공휴일은 강습이 없습니다.
A8: 3. 각반 정원은 25명이며, 15명미만 접수시 폐강 할 수 있습니다.
A9: 4. 강습 대상은 성인이며, 청소년(중학생 이상)도 수강 가능합니다. 강습 양도는 불가합니다.
A10: 5. 중도 등록, 취소시 일할계산(월8회 기준)되어 강습료 부과되며 강습 취소 미신청 시 전액부과됩니다.(당일 취소는 불가)
A11: 6. 중도 취소/신청은 방문신청만 가능합니다.(장소: 2단지 안내데스크 방문)
A12: 7. 강습은 5개월 단위 재추첨하며, 강습 기간중 중도 취소 하지 않는 경우 26.9월까지 자동 재등록 됩니다.
A14: 시간 | B14: 순번 | C14: 날 짜 | D14: 성함 | E14: 동 | F14: 호수 | G14: 서명 | H14: 취소날짜 | I14: 취소서명 | J14: 비고
A15: 07:30 ~ 08:20 | B15: 1
B16: 2
B17: 3
B18: 4
B19: 5
B20: 6
B21: 7
B22: 8
B23: 9
B24: 10
B25: 11
B26: 12
B27: 13
... B34: 20
A35: =A1 -> 10월 성인수영-상급 07시30분(화/목) 신청서
G38: =G4 -> 강사: 박범호
G39: =G5 -> 요일: 화 , 목 / 시간: 07시30분
A40: =A6 -> 1. 강습료는 월 8회 50,000원이며, 당월 관리비에 자동 부과됩니다.
A41: =A7 -> 2. 강습은 매주 화,목(주2회) 이며 국/공휴일은 강습이 없습니다.
A42: =A8 -> 3. 각반 정원은 25명이며, 15명미만 접수시 폐강 할 수 있습니다.
A43: =A9 -> 4. 강습 대상은 성인이며, 청소년(중학생 이상)도 수강 가능합니다. 강습 양도는 불가합니다.
A44: =A10 -> 5. 중도 등록, 취소시 일할계산(월8회 기준)되어 강습료 부과되며 강습 취소 미신청 시 전액부과됩니다.(당일 취소는 불가)
A45: =A11 -> 6. 중도 취소/신청은 방문신청만 가능합니다.(장소: 2단지 안내데스크 방문)
A46: =A12 -> 7. 강습은 5개월 단위 재추첨하며, 강습 기간중 중도 취소 하지 않는 경우 26.9월까지 자동 재등록 됩니다.
A48: 시간 | B48: 순번 | C48: 날 짜 | D48: 성함 | E48: 동 | F48: 호수 | G48: 서명 | H48: 취소날짜 | I48: 취소서명 | J48: 비고
A49: =A15 -> 07:30 ~ 08:20 | B49: 21
B50: 22
B51: 23
B52: 24
...

Sheet 2단지 성인수영-기초(화목09시손태환)
A1: =월!A1 & "월 " & LEFT(SUBSTITUTE(MID(CELL("filename",A1),FIND("]",CELL("filename",A1))+1,255),"2단지 ",""),FIND("(",SUBSTITUTE(MID(CELL("filename",A1),FIND("]",CELL("filename",A1))+1,255),"2단지 ",""))-1) & " " & MID(SUBSTITUTE(MID(CELL("filename",A1),FIND("]",CELL("filename",A1))+1,255),"2단지 ",""),MIN(FIND({0,1,2,3,4,5,6,7,8,9},MID(SUBSTITUTE(MID(CELL("filename",A1),FIND("]",CELL("filename",A1))+1,255),"2단지 ",""),FIND("(",SUBSTITUTE(MID(CELL("filename",A1),FIND("]",CELL("filename",A1))+1,255),"2단지 ",""))+1,255)&"0123456789"))+FIND("(",SUBSTITUTE(MID(CELL("filename",A1),FIND("]",CELL("filename",A1))+1,255),"2단지 ","")),IF(ISNUMBER(FIND("분",MID(SUBSTITUTE(MID(CELL("filename",A1),FIND("]",CELL("filename",A1))+1,255),"2단지 ",""),FIND("(",SUBSTITUTE(MID(CELL("filename",A1),FIND("]",CELL("filename",A1))+1,255),"2단지 ",""))+1,FIND(")",SUBSTITUTE(MID(CELL("filename",A1),FIND("]",CELL("filename",A1))+1,255),"2단지 ",""))-FIND("(",SUBSTITUTE(MID(CELL("filename",A1),FIND("]",CELL("filename",A1))+1,255),"2단지 ",""))-1))),FIND("분",MID(SUBSTITUTE(MID(CELL("filename",A1),FIND("]",CELL("filename",A1))+1,255),"2단지 ",""),FIND("(",SUBSTITUTE(MID(CELL("filename",A1),FIND("]",CELL("filename",A1))+1,255),"2단지 ",""))+1,255)),FIND("시",MID(SUBSTITUTE(MID(CELL("filename",A1),FIND("]",CELL("filename",A1))+1,255),"2단지 ",""),FIND("(",SUBSTITUTE(MID(CELL("filename",A1),FIND("]",CELL("filename",A1))+1,255),"2단지 ",""))+1,255)))-MIN(FIND({0,1,2,3,4,5,6,7,8,9},MID(SUBSTITUTE(MID(CELL("filename",A1),FIND("]",CELL("filename",A1))+1,255),"2단지 ",""),FIND("(",SUBSTITUTE(MID(CELL("filename",A1),FIND("]",CELL("filename",A1))+1,255),"2단지 ",""))+1,255)&"0123456789"))+1) & "(" & IF(LEN(LEFT(MID(SUBSTITUTE(MID(CELL("filename",A1),FIND("]",CELL("filename",A1))+1,255),"2단지 ",""),FIND("(",SUBSTITUTE(MID(CELL("filename",A1),FIND("]",CELL("filename",A1))+1,255),"2단지 ",""))+1,255),MIN(FIND({0,1,2,3,4,5,6,7,8,9},MID(SUBSTITUTE(MID(CELL("filename",A1),FIND("]",CELL("filename",A1))+1,255),"2단지 ",""),FIND("(",SUBSTITUTE(MID(CELL("filename",A1),FIND("]",CELL("filename",A1))+1,255),"2단지 ",""))+1,255)&"0123456789"))-1))=2, LEFT(MID(SUBSTITUTE(MID(CELL("filename",A1),FIND("]",CELL("filename",A1))+1,255),"2단지 ",""),FIND("(",SUBSTITUTE(MID(CELL("filename",A1),FIND("]",CELL("filename",A1))+1,255),"2단지 ",""))+1,2),1)&"/"&RIGHT(MID(SUBSTITUTE(MID(CELL("filename",A1),FIND("]",CELL("filename",A1))+1,255),"2단지 ",""),FIND("(",SUBSTITUTE(MID(CELL("filename",A1),FIND("]",CELL("filename",A1))+1,255),"2단지 ",""))+1,2),1), LEFT(MID(SUBSTITUTE(MID(CELL("filename",A1),FIND("]",CELL("filename",A1))+1,255),"2단지 ",""),FIND("(",SUBSTITUTE(MID(CELL("filename",A1),FIND("]",CELL("filename",A1))+1,255),"2단지 ",""))+1,255),MIN(FIND({0,1,2,3,4,5,6,7,8,9},MID(SUBSTITUTE(MID(CELL("filename",A1),FIND("]",CELL("filename",A1))+1,255),"2단지 ",""),FIND("(",SUBSTITUTE(MID(CELL("filename",A1),FIND("]",CELL("filename",A1))+1,255),"2단지 ",""))+1,255)&"0123456789"))-1)) & ") 신청서" -> 10월 성인수영-기초 09시(화/목) 신청서
G4: 강사: 손태환
G5: 요일: 화 , 목 / 시간: 09시
A6: 1. 강습료는 월 8회 50,000원이며, 당월 관리비에 자동 부과됩니다.
A7: 2. 강습은 매주 화,목(주2회) 이며 국/공휴일은 강습이 없습니다.
A8: 3. 각반 정원은 25명이며, 15명미만 접수시 폐강 할 수 있습니다.
A9: 4. 강습 대상은 성인이며, 청소년(중학생 이상)도 수강 가능합니다. 강습 양도는 불가합니다.
A10: 5. 중도 등록, 취소시 일할계산(월8회 기준)되어 강습료 부과되며 강습 취소 미신청 시 전액부과됩니다.(당일 취소는 불가)
A11: 6. 중도 취소/신청은 방문신청만 가능합니다.(장소: 2단지 안내데스크 방문)
A12: 7. 강습은 5개월 단위 재추첨하며, 강습 기간중 중도 취소 하지 않는 경우 26.9월까지 자동 재등록 됩니다.
A14: 시간 | B14: 순번 | C14: 날 짜 | D14: 성함 | E14: 동 | F14: 호수 | G14: 서명 | H14: 취소날짜 | I14: 취소서명 | J14: 비고
A15: 09:00 ~ 09:50 | B15: 1
B16: 2
B17: 3
B18: 4
B19: 5
B20: 6
B21: 7
B22: 8
B23: 9
B24: 10
B25: 11
B26: 12
B27: 13
... B34: 20
A35: =A1 -> 10월 성인수영-기초 09시(화/목) 신청서
G38: =G4 -> 강사: 손태환
G39: =G5 -> 요일: 화 , 목 / 시간: 09시
A40: =A6 -> 1. 강습료는 월 8회 50,000원이며, 당월 관리비에 자동 부과됩니다.
A41: =A7 -> 2. 강습은 매주 화,목(주2회) 이며 국/공휴일은 강습이 없습니다.
A42: =A8 -> 3. 각반 정원은 25명이며, 15명미만 접수시 폐강 할 수 있습니다.
A43: =A9 -> 4. 강습 대상은 성인이며, 청소년(중학생 이상)도 수강 가능합니다. 강습 양도는 불가합니다.
A44: =A10 -> 5. 중도 등록, 취소시 일할계산(월8회 기준)되어 강습료 부과되며 강습 취소 미신청 시 전액부과됩니다.(당일 취소는 불가)
A45: =A11 -> 6. 중도 취소/신청은 방문신청만 가능합니다.(장소: 2단지 안내데스크 방문)
A46: =A12 -> 7. 강습은 5개월 단위 재추첨하며, 강습 기간중 중도 취소 하지 않는 경우 26.9월까지 자동 재등록 됩니다.
A48: 시간 | B48: 순번 | C48: 날 짜 | D48: 성함 | E48: 동 | F48: 호수 | G48: 서명 | H48: 취소날짜 | I48: 취소서명 | J48: 비고
A49: =A15 -> 09:00 ~ 09:50 | B49: 21
B50: 22
B51: 23
B52: 24
...

Sheet 2단지 성인수영-초급(화목09시김소운)
A1: =월!A1 & "월 " & LEFT(SUBSTITUTE(MID(CELL("filename",A1),FIND("]",CELL("filename",A1))+1,255),"2단지 ",""),FIND("(",SUBSTITUTE(MID(CELL("filename",A1),FIND("]",CELL("filename",A1))+1,255),"2단지 ",""))-1) & " " & MID(SUBSTITUTE(MID(CELL("filename",A1),FIND("]",CELL("filename",A1))+1,255),"2단지 ",""),MIN(FIND({0,1,2,3,4,5,6,7,8,9},MID(SUBSTITUTE(MID(CELL("filename",A1),FIND("]",CELL("filename",A1))+1,255),"2단지 ",""),FIND("(",SUBSTITUTE(MID(CELL("filename",A1),FIND("]",CELL("filename",A1))+1,255),"2단지 ",""))+1,255)&"0123456789"))+FIND("(",SUBSTITUTE(MID(CELL("filename",A1),FIND("]",CELL("filename",A1))+1,255),"2단지 ","")),IF(ISNUMBER(FIND("분",MID(SUBSTITUTE(MID(CELL("filename",A1),FIND("]",CELL("filename",A1))+1,255),"2단지 ",""),FIND("(",SUBSTITUTE(MID(CELL("filename",A1),FIND("]",CELL("filename",A1))+1,255),"2단지 ",""))+1,FIND(")",SUBSTITUTE(MID(CELL("filename",A1),FIND("]",CELL("filename",A1))+1,255),"2단지 ",""))-FIND("(",SUBSTITUTE(MID(CELL("filename",A1),FIND("]",CELL("filename",A1))+1,255),"2단지 ",""))-1))),FIND("분",MID(SUBSTITUTE(MID(CELL("filename",A1),FIND("]",CELL("filename",A1))+1,255),"2단지 ",""),FIND("(",SUBSTITUTE(MID(CELL("filename",A1),FIND("]",CELL("filename",A1))+1,255),"2단지 ",""))+1,255)),FIND("시",MID(SUBSTITUTE(MID(CELL("filename",A1),FIND("]",CELL("filename",A1))+1,255),"2단지 ",""),FIND("(",SUBSTITUTE(MID(CELL("filename",A1),FIND("]",CELL("filename",A1))+1,255),"2단지 ",""))+1,255)))-MIN(FIND({0,1,2,3,4,5,6,7,8,9},MID(SUBSTITUTE(MID(CELL("filename",A1),FIND("]",CELL("filename",A1))+1,255),"2단지 ",""),FIND("(",SUBSTITUTE(MID(CELL("filename",A1),FIND("]",CELL("filename",A1))+1,255),"2단지 ",""))+1,255)&"0123456789"))+1) & "(" & IF(LEN(LEFT(MID(SUBSTITUTE(MID(CELL("filename",A1),FIND("]",CELL("filename",A1))+1,255),"2단지 ",""),FIND("(",SUBSTITUTE(MID(CELL("filename",A1),FIND("]",CELL("filename",A1))+1,255),"2단지 ",""))+1,255),MIN(FIND({0,1,2,3,4,5,6,7,8,9},MID(SUBSTITUTE(MID(CELL("filename",A1),FIND("]",CELL("filename",A1))+1,255),"2단지 ",""),FIND("(",SUBSTITUTE(MID(CELL("filename",A1),FIND("]",CELL("filename",A1))+1,255),"2단지 ",""))+1,255)&"0123456789"))-1))=2, LEFT(MID(SUBSTITUTE(MID(CELL("filename",A1),FIND("]",CELL("filename",A1))+1,255),"2단지 ",""),FIND("(",SUBSTITUTE(MID(CELL("filename",A1),FIND("]",CELL("filename",A1))+1,255),"2단지 ",""))+1,2),1)&"/"&RIGHT(MID(SUBSTITUTE(MID(CELL("filename",A1),FIND("]",CELL("filename",A1))+1,255),"2단지 ",""),FIND("(",SUBSTITUTE(MID(CELL("filename",A1),FIND("]",CELL("filename",A1))+1,255),"2단지 ",""))+1,2),1), LEFT(MID(SUBSTITUTE(MID(CELL("filename",A1),FIND("]",CELL("filename",A1))+1,255),"2단지 ",""),FIND("(",SUBSTITUTE(MID(CELL("filename",A1),FIND("]",CELL("filename",A1))+1,255),"2단지 ",""))+1,255),MIN(FIND({0,1,2,3,4,5,6,7,8,9},MID(SUBSTITUTE(MID(CELL("filename",A1),FIND("]",CELL("filename",A1))+1,255),"2단지 ",""),FIND("(",SUBSTITUTE(MID(CELL("filename",A1),FIND("]",CELL("filename",A1))+1,255),"2단지 ",""))+1,255)&"0123456789"))-1)) & ") 신청서" -> 10월 성인수영-초급 09시(화/목) 신청서
G4: 강사: 김소운
G5: 요일: 화 , 목 / 시간: 09시
A6: 1. 강습료는 월 8회 50,000원이며, 당월 관리비에 자동 부과됩니다.
A7: 2. 강습은 매주 화,목(주2회) 이며 국/공휴일은 강습이 없습니다.
A8: 3. 각반 정원은 25명이며, 15명미만 접수시 폐강 할 수 있습니다.
A9: 4. 강습 대상은 성인이며, 청소년(중학생 이상)도 수강 가능합니다. 강습 양도는 불가합니다.
A10: 5. 중도 등록, 취소시 일할계산(월8회 기준)되어 강습료 부과되며 강습 취소 미신청 시 전액부과됩니다.(당일 취소는 불가)
A11: 6. 중도 취소/신청은 방문신청만 가능합니다.(장소: 2단지 안내데스크 방문)
A12: 7. 강습은 5개월 단위 재추첨하며, 강습 기간중 중도 취소 하지 않는 경우 26.9월까지 자동 재등록 됩니다.
A14: 시간 | B14: 순번 | C14: 날 짜 | D14: 성함 | E14: 동 | F14: 호수 | G14: 서명 | H14: 취소날짜 | I14: 취소서명 | J14: 비고
A15: 09:00 ~ 09:50 | B15: 1
B16: 2
B17: 3
B18: 4
B19: 5
B20: 6
B21: 7
B22: 8
B23: 9
B24: 10
B25: 11
B26: 12
B27: 13
... B34: 20
A35: =A1 -> 10월 성인수영-초급 09시(화/목) 신청서
G38: =G4 -> 강사: 김소운
G39: =G5 -> 요일: 화 , 목 / 시간: 09시
A40: =A6 -> 1. 강습료는 월 8회 50,000원이며, 당월 관리비에 자동 부과됩니다.
A41: =A7 -> 2. 강습은 매주 화,목(주2회) 이며 국/공휴일은 강습이 없습니다.
A42: =A8 -> 3. 각반 정원은 25명이며, 15명미만 접수시 폐강 할 수 있습니다.
A43: =A9 -> 4. 강습 대상은 성인이며, 청소년(중학생 이상)도 수강 가능합니다. 강습 양도는 불가합니다.
A44: =A10 -> 5. 중도 등록, 취소시 일할계산(월8회 기준)되어 강습료 부과되며 강습 취소 미신청 시 전액부과됩니다.(당일 취소는 불가)
A45: =A11 -> 6. 중도 취소/신청은 방문신청만 가능합니다.(장소: 2단지 안내데스크 방문)
A46: =A12 -> 7. 강습은 5개월 단위 재추첨하며, 강습 기간중 중도 취소 하지 않는 경우 26.9월까지 자동 재등록 됩니다.
A48: 시간 | B48: 순번 | C48: 날 짜 | D48: 성함 | E48: 동 | F48: 호수 | G48: 서명 | H48: 취소날짜 | I48: 취소서명 | J48: 비고
A49: =A15 -> 09:00 ~ 09:50 | B49: 21
B50: 22
B51: 23
B52: 24
...

Sheet 2단지 성인수영-중급(화목09시이규상)
A1: =월!A1 & "월 " & LEFT(SUBSTITUTE(MID(CELL("filename",A1),FIND("]",CELL("filename",A1))+1,255),"2단지 ",""),FIND("(",SUBSTITUTE(MID(CELL("filename",A1),FIND("]",CELL("filename",A1))+1,255),"2단지 ",""))-1) & " " & MID(SUBSTITUTE(MID(CELL("filename",A1),FIND("]",CELL("filename",A1))+1,255),"2단지 ",""),MIN(FIND({0,1,2,3,4,5,6,7,8,9},MID(SUBSTITUTE(MID(CELL("filename",A1),FIND("]",CELL("filename",A1))+1,255),"2단지 ",""),FIND("(",SUBSTITUTE(MID(CELL("filename",A1),FIND("]",CELL("filename",A1))+1,255),"2단지 ",""))+1,255)&"0123456789"))+FIND("(",SUBSTITUTE(MID(CELL("filename",A1),FIND("]",CELL("filename",A1))+1,255),"2단지 ","")),IF(ISNUMBER(FIND("분",MID(SUBSTITUTE(MID(CELL("filename",A1),FIND("]",CELL("filename",A1))+1,255),"2단지 ",""),FIND("(",SUBSTITUTE(MID(CELL("filename",A1),FIND("]",CELL("filename",A1))+1,255),"2단지 ",""))+1,FIND(")",SUBSTITUTE(MID(CELL("filename",A1),FIND("]",CELL("filename",A1))+1,255),"2단지 ",""))-FIND("(",SUBSTITUTE(MID(CELL("filename",A1),FIND("]",CELL("filename",A1))+1,255),"2단지 ",""))-1))),FIND("분",MID(SUBSTITUTE(MID(CELL("filename",A1),FIND("]",CELL("filename",A1))+1,255),"2단지 ",""),FIND("(",SUBSTITUTE(MID(CELL("filename",A1),FIND("]",CELL("filename",A1))+1,255),"2단지 ",""))+1,255)),FIND("시",MID(SUBSTITUTE(MID(CELL("filename",A1),FIND("]",CELL("filename",A1))+1,255),"2단지 ",""),FIND("(",SUBSTITUTE(MID(CELL("filename",A1),FIND("]",CELL("filename",A1))+1,255),"2단지 ",""))+1,255)))-MIN(FIND({0,1,2,3,4,5,6,7,8,9},MID(SUBSTITUTE(MID(CELL("filename",A1),FIND("]",CELL("filename",A1))+1,255),"2단지 ",""),FIND("(",SUBSTITUTE(MID(CELL("filename",A1),FIND("]",CELL("filename",A1))+1,255),"2단지 ",""))+1,255)&"0123456789"))+1) & "(" & IF(LEN(LEFT(MID(SUBSTITUTE(MID(CELL("filename",A1),FIND("]",CELL("filename",A1))+1,255),"2단지 ",""),FIND("(",SUBSTITUTE(MID(CELL("filename",A1),FIND("]",CELL("filename",A1))+1,255),"2단지 ",""))+1,255),MIN(FIND({0,1,2,3,4,5,6,7,8,9},MID(SUBSTITUTE(MID(CELL("filename",A1),FIND("]",CELL("filename",A1))+1,255),"2단지 ",""),FIND("(",SUBSTITUTE(MID(CELL("filename",A1),FIND("]",CELL("filename",A1))+1,255),"2단지 ",""))+1,255)&"0123456789"))-1))=2, LEFT(MID(SUBSTITUTE(MID(CELL("filename",A1),FIND("]",CELL("filename",A1))+1,255),"2단지 ",""),FIND("(",SUBSTITUTE(MID(CELL("filename",A1),FIND("]",CELL("filename",A1))+1,255),"2단지 ",""))+1,2),1)&"/"&RIGHT(MID(SUBSTITUTE(MID(CELL("filename",A1),FIND("]",CELL("filename",A1))+1,255),"2단지 ",""),FIND("(",SUBSTITUTE(MID(CELL("filename",A1),FIND("]",CELL("filename",A1))+1,255),"2단지 ",""))+1,2),1), LEFT(MID(SUBSTITUTE(MID(CELL("filename",A1),FIND("]",CELL("filename",A1))+1,255),"2단지 ",""),FIND("(",SUBSTITUTE(MID(CELL("filename",A1),FIND("]",CELL("filename",A1))+1,255),"2단지 ",""))+1,255),MIN(FIND({0,1,2,3,4,5,6,7,8,9},MID(SUBSTITUTE(MID(CELL("filename",A1),FIND("]",CELL("filename",A1))+1,255),"2단지 ",""),FIND("(",SUBSTITUTE(MID(CELL("filename",A1),FIND("]",CELL("filename",A1))+1,255),"2단지 ",""))+1,255)&"0123456789"))-1)) & ") 신청서" -> 10월 성인수영-중급 09시(화/목) 신청서
G4: 강사: 이규상
G5: 요일: 화 , 목 / 시간: 09시
A6: 1. 강습료는 월 8회 50,000원이며, 당월 관리비에 자동 부과됩니다.
A7: 2. 강습은 매주 화,목(주2회) 이며 국/공휴일은 강습이 없습니다.
A8: 3. 각반 정원은 25명이며, 15명미만 접수시 폐강 할 수 있습니다.
A9: 4. 강습 대상은 성인이며, 청소년(중학생 이상)도 수강 가능합니다. 강습 양도는 불가합니다.
A10: 5. 중도 등록, 취소시 일할계산(월8회 기준)되어 강습료 부과되며 강습 취소 미신청 시 전액부과됩니다.(당일 취소는 불가)
A11: 6. 중도 취소/신청은 방문신청만 가능합니다.(장소: 2단지 안내데스크 방문)
A12: 7. 강습은 5개월 단위 재추첨하며, 강습 기간중 중도 취소 하지 않는 경우 26.9월까지 자동 재등록 됩니다.
A14: 시간 | B14: 순번 | C14: 날 짜 | D14: 성함 | E14: 동 | F14: 호수 | G14: 서명 | H14: 취소날짜 | I14: 취소서명 | J14: 비고
A15: 09:00 ~ 09:50 | B15: 1
B16: 2
B17: 3
B18: 4
B19: 5
B20: 6
B21: 7
B22: 8
B23: 9
B24: 10
B25: 11
B26: 12
B27: 13
... B34: 20
A35: =A1 -> 10월 성인수영-중급 09시(화/목) 신청서
G38: =G4 -> 강사: 이규상
G39: =G5 -> 요일: 화 , 목 / 시간: 09시
A40: =A6 -> 1. 강습료는 월 8회 50,000원이며, 당월 관리비에 자동 부과됩니다.
A41: =A7 -> 2. 강습은 매주 화,목(주2회) 이며 국/공휴일은 강습이 없습니다.
A42: =A8 -> 3. 각반 정원은 25명이며, 15명미만 접수시 폐강 할 수 있습니다.
A43: =A9 -> 4. 강습 대상은 성인이며, 청소년(중학생 이상)도 수강 가능합니다. 강습 양도는 불가합니다.
A44: =A10 -> 5. 중도 등록, 취소시 일할계산(월8회 기준)되어 강습료 부과되며 강습 취소 미신청 시 전액부과됩니다.(당일 취소는 불가)
A45: =A11 -> 6. 중도 취소/신청은 방문신청만 가능합니다.(장소: 2단지 안내데스크 방문)
A46: =A12 -> 7. 강습은 5개월 단위 재추첨하며, 강습 기간중 중도 취소 하지 않는 경우 26.9월까지 자동 재등록 됩니다.
A48: 시간 | B48: 순번 | C48: 날 짜 | D48: 성함 | E48: 동 | F48: 호수 | G48: 서명 | H48: 취소날짜 | I48: 취소서명 | J48: 비고
A49: =A15 -> 09:00 ~ 09:50 | B49: 21
B50: 22
B51: 23
B52: 24
...

Sheet 2단지 성인수영-상급(화목09시박범호)
A1: =월!A1 & "월 " & LEFT(SUBSTITUTE(MID(CELL("filename",A1),FIND("]",CELL("filename",A1))+1,255),"2단지 ",""),FIND("(",SUBSTITUTE(MID(CELL("filename",A1),FIND("]",CELL("filename",A1))+1,255),"2단지 ",""))-1) & " " & MID(SUBSTITUTE(MID(CELL("filename",A1),FIND("]",CELL("filename",A1))+1,255),"2단지 ",""),MIN(FIND({0,1,2,3,4,5,6,7,8,9},MID(SUBSTITUTE(MID(CELL("filename",A1),FIND("]",CELL("filename",A1))+1,255),"2단지 ",""),FIND("(",SUBSTITUTE(MID(CELL("filename",A1),FIND("]",CELL("filename",A1))+1,255),"2단지 ",""))+1,255)&"0123456789"))+FIND("(",SUBSTITUTE(MID(CELL("filename",A1),FIND("]",CELL("filename",A1))+1,255),"2단지 ","")),IF(ISNUMBER(FIND("분",MID(SUBSTITUTE(MID(CELL("filename",A1),FIND("]",CELL("filename",A1))+1,255),"2단지 ",""),FIND("(",SUBSTITUTE(MID(CELL("filename",A1),FIND("]",CELL("filename",A1))+1,255),"2단지 ",""))+1,FIND(")",SUBSTITUTE(MID(CELL("filename",A1),FIND("]",CELL("filename",A1))+1,255),"2단지 ",""))-FIND("(",SUBSTITUTE(MID(CELL("filename",A1),FIND("]",CELL("filename",A1))+1,255),"2단지 ",""))-1))),FIND("분",MID(SUBSTITUTE(MID(CELL("filename",A1),FIND("]",CELL("filename",A1))+1,255),"2단지 ",""),FIND("(",SUBSTITUTE(MID(CELL("filename",A1),FIND("]",CELL("filename",A1))+1,255),"2단지 ",""))+1,255)),FIND("시",MID(SUBSTITUTE(MID(CELL("filename",A1),FIND("]",CELL("filename",A1))+1,255),"2단지 ",""),FIND("(",SUBSTITUTE(MID(CELL("filename",A1),FIND("]",CELL("filename",A1))+1,255),"2단지 ",""))+1,255)))-MIN(FIND({0,1,2,3,4,5,6,7,8,9},MID(SUBSTITUTE(MID(CELL("filename",A1),FIND("]",CELL("filename",A1))+1,255),"2단지 ",""),FIND("(",SUBSTITUTE(MID(CELL("filename",A1),FIND("]",CELL("filename",A1))+1,255),"2단지 ",""))+1,255)&"0123456789"))+1) & "(" & IF(LEN(LEFT(MID(SUBSTITUTE(MID(CELL("filename",A1),FIND("]",CELL("filename",A1))+1,255),"2단지 ",""),FIND("(",SUBSTITUTE(MID(CELL("filename",A1),FIND("]",CELL("filename",A1))+1,255),"2단지 ",""))+1,255),MIN(FIND({0,1,2,3,4,5,6,7,8,9},MID(SUBSTITUTE(MID(CELL("filename",A1),FIND("]",CELL("filename",A1))+1,255),"2단지 ",""),FIND("(",SUBSTITUTE(MID(CELL("filename",A1),FIND("]",CELL("filename",A1))+1,255),"2단지 ",""))+1,255)&"0123456789"))-1))=2, LEFT(MID(SUBSTITUTE(MID(CELL("filename",A1),FIND("]",CELL("filename",A1))+1,255),"2단지 ",""),FIND("(",SUBSTITUTE(MID(CELL("filename",A1),FIND("]",CELL("filename",A1))+1,255),"2단지 ",""))+1,2),1)&"/"&RIGHT(MID(SUBSTITUTE(MID(CELL("filename",A1),FIND("]",CELL("filename",A1))+1,255),"2단지 ",""),FIND("(",SUBSTITUTE(MID(CELL("filename",A1),FIND("]",CELL("filename",A1))+1,255),"2단지 ",""))+1,2),1), LEFT(MID(SUBSTITUTE(MID(CELL("filename",A1),FIND("]",CELL("filename",A1))+1,255),"2단지 ",""),FIND("(",SUBSTITUTE(MID(CELL("filename",A1),FIND("]",CELL("filename",A1))+1,255),"2단지 ",""))+1,255),MIN(FIND({0,1,2,3,4,5,6,7,8,9},MID(SUBSTITUTE(MID(CELL("filename",A1),FIND("]",CELL("filename",A1))+1,255),"2단지 ",""),FIND("(",SUBSTITUTE(MID(CELL("filename",A1),FIND("]",CELL("filename",A1))+1,255),"2단지 ",""))+1,255)&"0123456789"))-1)) & ") 신청서" -> 10월 성인수영-상급 09시(화/목) 신청서
G4: 강사: 박범호
G5: 요일: 화 , 목 / 시간: 09시
A6: 1. 강습료는 월 8회 50,000원이며, 당월 관리비에 자동 부과됩니다.
A7: 2. 강습은 매주 화,목(주2회) 이며 국/공휴일은 강습이 없습니다.
A8: 3. 각반 정원은 25명이며, 15명미만 접수시 폐강 할 수 있습니다.
A9: 4. 강습 대상은 성인이며, 청소년(중학생 이상)도 수강 가능합니다. 강습 양도는 불가합니다.
A10: 5. 중도 등록, 취소시 일할계산(월8회 기준)되어 강습료 부과되며 강습 취소 미신청 시 전액부과됩니다.(당일 취소는 불가)
A11: 6. 중도 취소/신청은 방문신청만 가능합니다.(장소: 2단지 안내데스크 방문)
A12: 7. 강습은 5개월 단위 재추첨하며, 강습 기간중 중도 취소 하지 않는 경우 26.9월까지 자동 재등록 됩니다.
A14: 시간 | B14: 순번 | C14: 날 짜 | D14: 성함 | E14: 동 | F14: 호수 | G14: 서명 | H14: 취소날짜 | I14: 취소서명 | J14: 비고
A15: 09:00 ~ 09:50 | B15: 1
B16: 2
B17: 3
B18: 4
B19: 5
B20: 6
B21: 7
B22: 8
B23: 9
B24: 10
B25: 11
B26: 12
B27: 13
... B34: 20
A35: =A1 -> 10월 성인수영-상급 09시(화/목) 신청서
G38: =G4 -> 강사: 박범호
G39: =G5 -> 요일: 화 , 목 / 시간: 09시
A40: =A6 -> 1. 강습료는 월 8회 50,000원이며, 당월 관리비에 자동 부과됩니다.
A41: =A7 -> 2. 강습은 매주 화,목(주2회) 이며 국/공휴일은 강습이 없습니다.
A42: =A8 -> 3. 각반 정원은 25명이며, 15명미만 접수시 폐강 할 수 있습니다.
A43: =A9 -> 4. 강습 대상은 성인이며, 청소년(중학생 이상)도 수강 가능합니다. 강습 양도는 불가합니다.
A44: =A10 -> 5. 중도 등록, 취소시 일할계산(월8회 기준)되어 강습료 부과되며 강습 취소 미신청 시 전액부과됩니다.(당일 취소는 불가)
A45: =A11 -> 6. 중도 취소/신청은 방문신청만 가능합니다.(장소: 2단지 안내데스크 방문)
A46: =A12 -> 7. 강습은 5개월 단위 재추첨하며, 강습 기간중 중도 취소 하지 않는 경우 26.9월까지 자동 재등록 됩니다.
A48: 시간 | B48: 순번 | C48: 날 짜 | D48: 성함 | E48: 동 | F48: 호수 | G48: 서명 | H48: 취소날짜 | I48: 취소서명 | J48: 비고
A49: =A15 -> 09:00 ~ 09:50 | B49: 21
B50: 22
B51: 23
B52: 24
...

Sheet 2단지 성인수영-기초(화목10시손태환)
A1: =월!A1 & "월 " & LEFT(SUBSTITUTE(MID(CELL("filename",A1),FIND("]",CELL("filename",A1))+1,255),"2단지 ",""),FIND("(",SUBSTITUTE(MID(CELL("filename",A1),FIND("]",CELL("filename",A1))+1,255),"2단지 ",""))-1) & " " & MID(SUBSTITUTE(MID(CELL("filename",A1),FIND("]",CELL("filename",A1))+1,255),"2단지 ",""),MIN(FIND({0,1,2,3,4,5,6,7,8,9},MID(SUBSTITUTE(MID(CELL("filename",A1),FIND("]",CELL("filename",A1))+1,255),"2단지 ",""),FIND("(",SUBSTITUTE(MID(CELL("filename",A1),FIND("]",CELL("filename",A1))+1,255),"2단지 ",""))+1,255)&"0123456789"))+FIND("(",SUBSTITUTE(MID(CELL("filename",A1),FIND("]",CELL("filename",A1))+1,255),"2단지 ","")),IF(ISNUMBER(FIND("분",MID(SUBSTITUTE(MID(CELL("filename",A1),FIND("]",CELL("filename",A1))+1,255),"2단지 ",""),FIND("(",SUBSTITUTE(MID(CELL("filename",A1),FIND("]",CELL("filename",A1))+1,255),"2단지 ",""))+1,FIND(")",SUBSTITUTE(MID(CELL("filename",A1),FIND("]",CELL("filename",A1))+1,255),"2단지 ",""))-FIND("(",SUBSTITUTE(MID(CELL("filename",A1),FIND("]",CELL("filename",A1))+1,255),"2단지 ",""))-1))),FIND("분",MID(SUBSTITUTE(MID(CELL("filename",A1),FIND("]",CELL("filename",A1))+1,255),"2단지 ",""),FIND("(",SUBSTITUTE(MID(CELL("filename",A1),FIND("]",CELL("filename",A1))+1,255),"2단지 ",""))+1,255)),FIND("시",MID(SUBSTITUTE(MID(CELL("filename",A1),FIND("]",CELL("filename",A1))+1,255),"2단지 ",""),FIND("(",SUBSTITUTE(MID(CELL("filename",A1),FIND("]",CELL("filename",A1))+1,255),"2단지 ",""))+1,255)))-MIN(FIND({0,1,2,3,4,5,6,7,8,9},MID(SUBSTITUTE(MID(CELL("filename",A1),FIND("]",CELL("filename",A1))+1,255),"2단지 ",""),FIND("(",SUBSTITUTE(MID(CELL("filename",A1),FIND("]",CELL("filename",A1))+1,255),"2단지 ",""))+1,255)&"0123456789"))+1) & "(" & IF(LEN(LEFT(MID(SUBSTITUTE(MID(CELL("filename",A1),FIND("]",CELL("filename",A1))+1,255),"2단지 ",""),FIND("(",SUBSTITUTE(MID(CELL("filename",A1),FIND("]",CELL("filename",A1))+1,255),"2단지 ",""))+1,255),MIN(FIND({0,1,2,3,4,5,6,7,8,9},MID(SUBSTITUTE(MID(CELL("filename",A1),FIND("]",CELL("filename",A1))+1,255),"2단지 ",""),FIND("(",SUBSTITUTE(MID(CELL("filename",A1),FIND("]",CELL("filename",A1))+1,255),"2단지 ",""))+1,255)&"0123456789"))-1))=2, LEFT(MID(SUBSTITUTE(MID(CELL("filename",A1),FIND("]",CELL("filename",A1))+1,255),"2단지 ",""),FIND("(",SUBSTITUTE(MID(CELL("filename",A1),FIND("]",CELL("filename",A1))+1,255),"2단지 ",""))+1,2),1)&"/"&RIGHT(MID(SUBSTITUTE(MID(CELL("filename",A1),FIND("]",CELL("filename",A1))+1,255),"2단지 ",""),FIND("(",SUBSTITUTE(MID(CELL("filename",A1),FIND("]",CELL("filename",A1))+1,255),"2단지 ",""))+1,2),1), LEFT(MID(SUBSTITUTE(MID(CELL("filename",A1),FIND("]",CELL("filename",A1))+1,255),"2단지 ",""),FIND("(",SUBSTITUTE(MID(CELL("filename",A1),FIND("]",CELL("filename",A1))+1,255),"2단지 ",""))+1,255),MIN(FIND({0,1,2,3,4,5,6,7,8,9},MID(SUBSTITUTE(MID(CELL("filename",A1),FIND("]",CELL("filename",A1))+1,255),"2단지 ",""),FIND("(",SUBSTITUTE(MID(CELL("filename",A1),FIND("]",CELL("filename",A1))+1,255),"2단지 ",""))+1,255)&"0123456789"))-1)) & ") 신청서" -> 10월 성인수영-기초 10시(화/목) 신청서
G4: 강사: 손태환
G5: 요일: 화 , 목 / 시간: 10시
A6: 1. 강습료는 월 8회 50,000원이며, 당월 관리비에 자동 부과됩니다.
A7: 2. 강습은 매주 화,목(주2회) 이며 국/공휴일은 강습이 없습니다.
A8: 3. 각반 정원은 25명이며, 15명미만 접수시 폐강 할 수 있습니다.
A9: 4. 강습 대상은 성인이며, 청소년(중학생 이상)도 수강 가능합니다. 강습 양도는 불가합니다.
A10: 5. 중도 등록, 취소시 일할계산(월8회 기준)되어 강습료 부과되며 강습 취소 미신청 시 전액부과됩니다.(당일 취소는 불가)
A11: 6. 중도 취소/신청은 방문신청만 가능합니다.(장소: 2단지 안내데스크 방문)
A12: 7. 강습은 5개월 단위 재추첨하며, 강습 기간중 중도 취소 하지 않는 경우 26.9월까지 자동 재등록 됩니다.
A14: 시간 | B14: 순번 | C14: 날 짜 | D14: 성함 | E14: 동 | F14: 호수 | G14: 서명 | H14: 취소날짜 | I14: 취소서명 | J14: 비고
A15: 10:00 ~ 10:50 | B15: 1
B16: 2
B17: 3
B18: 4
B19: 5
B20: 6
B21: 7
B22: 8
B23: 9
B24: 10
B25: 11
B26: 12
B27: 13
... B34: 20
A35: =A1 -> 10월 성인수영-기초 10시(화/목) 신청서
G38: =G4 -> 강사: 손태환
G39: =G5 -> 요일: 화 , 목 / 시간: 10시
A40: =A6 -> 1. 강습료는 월 8회 50,000원이며, 당월 관리비에 자동 부과됩니다.
A41: =A7 -> 2. 강습은 매주 화,목(주2회) 이며 국/공휴일은 강습이 없습니다.
A42: =A8 -> 3. 각반 정원은 25명이며, 15명미만 접수시 폐강 할 수 있습니다.
A43: =A9 -> 4. 강습 대상은 성인이며, 청소년(중학생 이상)도 수강 가능합니다. 강습 양도는 불가합니다.
A44: =A10 -> 5. 중도 등록, 취소시 일할계산(월8회 기준)되어 강습료 부과되며 강습 취소 미신청 시 전액부과됩니다.(당일 취소는 불가)
A45: =A11 -> 6. 중도 취소/신청은 방문신청만 가능합니다.(장소: 2단지 안내데스크 방문)
A46: =A12 -> 7. 강습은 5개월 단위 재추첨하며, 강습 기간중 중도 취소 하지 않는 경우 26.9월까지 자동 재등록 됩니다.
A48: 시간 | B48: 순번 | C48: 날 짜 | D48: 성함 | E48: 동 | F48: 호수 | G48: 서명 | H48: 취소날짜 | I48: 취소서명 | J48: 비고
A49: =A15 -> 10:00 ~ 10:50 | B49: 21
B50: 22
B51: 23
B52: 24
...

Sheet 2단지 성인수영-초급(화목10시김소운)
A1: =월!A1 & "월 " & LEFT(SUBSTITUTE(MID(CELL("filename",A1),FIND("]",CELL("filename",A1))+1,255),"2단지 ",""),FIND("(",SUBSTITUTE(MID(CELL("filename",A1),FIND("]",CELL("filename",A1))+1,255),"2단지 ",""))-1) & " " & MID(SUBSTITUTE(MID(CELL("filename",A1),FIND("]",CELL("filename",A1))+1,255),"2단지 ",""),MIN(FIND({0,1,2,3,4,5,6,7,8,9},MID(SUBSTITUTE(MID(CELL("filename",A1),FIND("]",CELL("filename",A1))+1,255),"2단지 ",""),FIND("(",SUBSTITUTE(MID(CELL("filename",A1),FIND("]",CELL("filename",A1))+1,255),"2단지 ",""))+1,255)&"0123456789"))+FIND("(",SUBSTITUTE(MID(CELL("filename",A1),FIND("]",CELL("filename",A1))+1,255),"2단지 ","")),IF(ISNUMBER(FIND("분",MID(SUBSTITUTE(MID(CELL("filename",A1),FIND("]",CELL("filename",A1))+1,255),"2단지 ",""),FIND("(",SUBSTITUTE(MID(CELL("filename",A1),FIND("]",CELL("filename",A1))+1,255),"2단지 ",""))+1,FIND(")",SUBSTITUTE(MID(CELL("filename",A1),FIND("]",CELL("filename",A1))+1,255),"2단지 ",""))-FIND("(",SUBSTITUTE(MID(CELL("filename",A1),FIND("]",CELL("filename",A1))+1,255),"2단지 ",""))-1))),FIND("분",MID(SUBSTITUTE(MID(CELL("filename",A1),FIND("]",CELL("filename",A1))+1,255),"2단지 ",""),FIND("(",SUBSTITUTE(MID(CELL("filename",A1),FIND("]",CELL("filename",A1))+1,255),"2단지 ",""))+1,255)),FIND("시",MID(SUBSTITUTE(MID(CELL("filename",A1),FIND("]",CELL("filename",A1))+1,255),"2단지 ",""),FIND("(",SUBSTITUTE(MID(CELL("filename",A1),FIND("]",CELL("filename",A1))+1,255),"2단지 ",""))+1,255)))-MIN(FIND({0,1,2,3,4,5,6,7,8,9},MID(SUBSTITUTE(MID(CELL("filename",A1),FIND("]",CELL("filename",A1))+1,255),"2단지 ",""),FIND("(",SUBSTITUTE(MID(CELL("filename",A1),FIND("]",CELL("filename",A1))+1,255),"2단지 ",""))+1,255)&"0123456789"))+1) & "(" & IF(LEN(LEFT(MID(SUBSTITUTE(MID(CELL("filename",A1),FIND("]",CELL("filename",A1))+1,255),"2단지 ",""),FIND("(",SUBSTITUTE(MID(CELL("filename",A1),FIND("]",CELL("filename",A1))+1,255),"2단지 ",""))+1,255),MIN(FIND({0,1,2,3,4,5,6,7,8,9},MID(SUBSTITUTE(MID(CELL("filename",A1),FIND("]",CELL("filename",A1))+1,255),"2단지 ",""),FIND("(",SUBSTITUTE(MID(CELL("filename",A1),FIND("]",CELL("filename",A1))+1,255),"2단지 ",""))+1,255)&"0123456789"))-1))=2, LEFT(MID(SUBSTITUTE(MID(CELL("filename",A1),FIND("]",CELL("filename",A1))+1,255),"2단지 ",""),FIND("(",SUBSTITUTE(MID(CELL("filename",A1),FIND("]",CELL("filename",A1))+1,255),"2단지 ",""))+1,2),1)&"/"&RIGHT(MID(SUBSTITUTE(MID(CELL("filename",A1),FIND("]",CELL("filename",A1))+1,255),"2단지 ",""),FIND("(",SUBSTITUTE(MID(CELL("filename",A1),FIND("]",CELL("filename",A1))+1,255),"2단지 ",""))+1,2),1), LEFT(MID(SUBSTITUTE(MID(CELL("filename",A1),FIND("]",CELL("filename",A1))+1,255),"2단지 ",""),FIND("(",SUBSTITUTE(MID(CELL("filename",A1),FIND("]",CELL("filename",A1))+1,255),"2단지 ",""))+1,255),MIN(FIND({0,1,2,3,4,5,6,7,8,9},MID(SUBSTITUTE(MID(CELL("filename",A1),FIND("]",CELL("filename",A1))+1,255),"2단지 ",""),FIND("(",SUBSTITUTE(MID(CELL("filename",A1),FIND("]",CELL("filename",A1))+1,255),"2단지 ",""))+1,255)&"0123456789"))-1)) & ") 신청서" -> 10월 성인수영-초급 10시(화/목) 신청서
G4: 강사: 김소운
G5: 요일: 화 , 목 / 시간: 10시
A6: 1. 강습료는 월 8회 50,000원이며, 당월 관리비에 자동 부과됩니다.
A7: 2. 강습은 매주 화,목(주2회) 이며 국/공휴일은 강습이 없습니다.
A8: 3. 각반 정원은 25명이며, 15명미만 접수시 폐강 할 수 있습니다.
A9: 4. 강습 대상은 성인이며, 청소년(중학생 이상)도 수강 가능합니다. 강습 양도는 불가합니다.
A10: 5. 중도 등록, 취소시 일할계산(월8회 기준)되어 강습료 부과되며 강습 취소 미신청 시 전액부과됩니다.(당일 취소는 불가)
A11: 6. 중도 취소/신청은 방문신청만 가능합니다.(장소: 2단지 안내데스크 방문)
A12: 7. 강습은 5개월 단위 재추첨하며, 강습 기간중 중도 취소 하지 않는 경우 26.9월까지 자동 재등록 됩니다.
A14: 시간 | B14: 순번 | C14: 날 짜 | D14: 성함 | E14: 동 | F14: 호수 | G14: 서명 | H14: 취소날짜 | I14: 취소서명 | J14: 비고
A15: 10:00 ~ 10:50 | B15: 1
B16: 2
B17: 3
B18: 4
B19: 5
B20: 6
B21: 7
B22: 8
B23: 9
B24: 10
B25: 11
B26: 12
B27: 13
... B34: 20
